Workbook

Sheet JR คำนวณ
A1: JR ALUMINIUM & GLASS — บานยก ฟูจิ (HUNG) · หน้าคำนวณ · ซม.
B3: ① กรอกข้อมูล (เหลือง)
B4: กว้างช่อง (W) | C4: 104.3
B5: สูงช่อง (H) | C5: 288.8
B6: จำนวนชุด | C6: 1
B7: สีมือจับ → | C7: ดำ
A8: # | B8: โปรไฟล์ (ไทย / EN) | C8: รหัส | D8: ยาวตัด (ซม.) | E8: จำนวน | F8: หมายเหตุ
A9: 1 | B9: เฟรมบน (HEAD) | C9: B28009 | D9: =$C$4-$F$32 -> 99.3 | E9: =1*$C$6 -> 1 | F9: กว้าง−5
A10: 2 | B10: ตบปิดเฟรมบน (COVER HEAD) | C10: B28010 | D10: =$C$4-$F$33 -> 94.9 | E10: =1*$C$6 -> 1 | F10: กว้าง−9.4
A11: 3 | B11: กรอบบาน แนวนอน (SASH ↔) | C11: B28011 | D11: =$C$4-$F$34 -> 88.9 | E11: =4*$C$6 -> 4 | F11: กว้าง−15.4
A12: 4 | B12: กรอบบาน แนวตั้ง (SASH ↕) | C12: B28011 | D12: =($C$5-$F$35)/2-$F$36 -> 142 | E12: =4*$C$6 -> 4 | F12: (สูง−4.6)÷2−0.1
A13: 5 | B13: คิ้วยึดเสาเกี่ยว (ADAPTOR) | C13: B28012 | D13: =$C$4-$F$37 -> 91.1 | E13: =2*$C$6 -> 2 | F13: กว้าง−13.2
A14: 6 | B14: เสาเกี่ยว (INTERLOCK) | C14: B28013 | D14: =$C$4-$F$38 -> 93.1 | E14: =2*$C$6 -> 2 | F14: กว้าง−11.2
A15: 7 | B15: เฟรมล่าง (SILL) | C15: B28014 | D15: =$C$4-$F$32 -> 99.3 | E15: =1*$C$6 -> 1 | F15: กว้าง−5
A16: 8 | B16: เสาเสริมเฟรมข้าง (JAMB ADAPTOR) | C16: B28015 | D16: =$C$5-$F$39 -> 281.9 | E16: =2*$C$6 -> 2 | F16: สูง−6.9
A17: 9 | B17: เฟรมข้าง (NARROW FRAME) | C17: B10004 | D17: =$C$5 -> 288.8 | E17: =2*$C$6 -> 2 | F17: สูง
B19: ③ กระดานคำนวณ (แจกแจง) — ฐาน − ตัวลบ = ยาว
B20: โปรไฟล์ | C20: ฐาน | D20: ค่า | E20: − ตัวลบ | F20: ยาวตัด | G20: หมายเหตุ
B21: เฟรมบน | C21: กว้าง | D21: =$C$4 -> 104.3 | E21: =$F$32 -> 5 | F21: =$D$9 -> 99.3
B22: ตบปิดเฟรมบน | C22: กว้าง | D22: =$C$4 -> 104.3 | E22: =$F$33 -> 9.4 | F22: =$D$10 -> 94.9
B23: กรอบบานแนวนอน | C23: กว้าง | D23: =$C$4 -> 104.3 | E23: =$F$34 -> 15.4 | F23: =$D$11 -> 88.9
B24: กรอบบานแนวตั้ง | C24: (สูง−4.6)÷2 | D24: =($C$5-$F$35)/2 -> 142.1 | E24: =$F$36 -> 0.1 | F24: =$D$12 -> 142
B25: คิ้วยึดเสาเกี่ยว | C25: กว้าง | D25: =$C$4 -> 104.3 | E25: =$F$37 -> 13.2 | F25: =$D$13 -> 91.1
B26: เสาเกี่ยว | C26: กว้าง | D26: =$C$4 -> 104.3 | E26: =$F$38 -> 11.2 | F26: =$D$14 -> 93.1
B27: เฟรมล่าง | C27: กว้าง | D27: =$C$4 -> 104.3 | E27: =$F$32 -> 5 | F27: =$D$15 -> 99.3
B28: เสาเสริมเฟรมข้าง | C28: สูง | D28: =$C$5 -> 288.8 | E28: =$F$39 -> 6.9 | F28: =$D$16 -> 281.9
B29: เฟรมข้าง | C29: สูง | D29: =$C$5 -> 288.8 | F29: =$D$17 -> 288.8
B31: ④ แผงแก้สูตร — ตัวหักลบ (เหลือง)
B32: เฟรมบน/ล่าง — หัก (5) | F32: 5
B33: ตบปิดเฟรมบน — หัก (9.4) | F33: 9.4
B34: กรอบบานแนวนอน — หัก (15.4) | F34: 15.4
B35: กรอบบานแนวตั้ง — หักสูง (4.6) | F35: 4.6
B36: กรอบบานแนวตั้ง — ลบท้าย (0.1) | F36: 0.1
B37: คิ้วยึดเสาเกี่ยว — หัก (13.2) | F37: 13.2
B38: เสาเกี่ยว — หัก (11.2) | F38: 11.2
B39: เสาเสริมเฟรมข้าง — หัก (6.9) | F39: 6.9
B41: ⑤ อุปกรณ์ (ดึงสดจากชีท HUNG Takeoff · รหัส SKU JR เว้นว่างรอเติม)
B42: จำนวนไหลตามจำนวนชุด(C6)+ขนาดบานอัตโนมัติ · รหัสผู้ผลิต = Sup code เดิม
A43: # | B43: อุปกรณ์ | C43: รหัสผู้ผลิต | D43: รหัส SKU JR | E43: จำนวน | F43: หน่วย
B44: ① ฮาร์ดแวร์หลัก
...

Sheet HUNG dies
A2: HUNG PARTS LIST ชุดอุปกรณ์บานยก
C3: ตัวเลือก Standard กระจก
L4: =D6*F6/1000000 -> 3.012184
D5: H | F5: W | G5: QTY(SET) | H5: Rope cut length(mm)
C6: WINDOW SIZE(mm)= | D6: ='JR คำนวณ'!C5*10 -> 2888 | E6: X | F6: ='JR คำนวณ'!C4*10 -> 1043 | G6: ='JR คำนวณ'!C6 -> 1 | H6: ='FSA CORD calculate '!I16 -> 4163.5
C7: GLASS SIZE(mm)= | D7: =$H$13-24 -> 1396 | E7: X | F7: =$H$12+16 -> 905 | G7: =(D7*F7)/1000000 -> 1.26338 | H7: ตัดเชือกความยาวนี้อย่างละ 2 เส้น/ 1 ชุด | L7: ถอดจ.เส้นยาว | N7: ตัดได้กี่ท่อน | O7: เศษที่เหลือ/เส้น
A8: GROUP : EXTRUSION โปร์ไฟล์อลูมิเนียม | G8: (SQM) | K8: DxG | L8: 6400 | N8: LENGTH(mm)+5
A9: ITEM | B9: SMS CODE | C9: IMAGE | D9: DESCRIPTION | E9: EST.WT. | F9: จำนวนท่อนที่ใช้ | G9: CUTTING FORMULA | H9: ระยะตัด LENGTH(mm) | I9: ถอดจำนวนเส้นเต็ม 6.4ม. (เส้น) | K9: TOTAL LENGTH | L9: QTY Take off AL (pcs) | M9: Summarize QTY | N9: QTY small piece/length | O9: remnant (mm.)/length
A10: 1 | B10: B28009-12 | D10: HEAD เฟรมบน | E10: 0.897 | F10: =1*$G$6 -> 1 | G10: FW-50 | H10: =$F$6-50 -> 993 | I10: =M10 -> 1 | K10: =F10*H10 -> 993 | L10: =IF(N10>F10,ROUNDUP(F10/N10,0),IF(N10<F10,ROUNDUP(F10/N10,0),IF(N10=F10,F10/N10))) -> 1 | M10: =L10 -> 1 | N10: =ROUNDDOWN($L$8/(H10+5),0) -> 6 | O10: =$L$8-((H10+5)*N10) -> 412
A11: 2 | B11: B28010-12 | D11: COVER HEAD ตบปิดเฟรมบน | E11: 0.358 | F11: =1*$G$6 -> 1 | G11: FW-94 | H11: =$F$6-94 -> 949 | I11: =M11 -> 1 | K11: =F11*H11 -> 949 | L11: =IF(N11>F11,ROUNDUP(F11/N11,0),IF(N11<F11,ROUNDUP(F11/N11,0),IF(N11=F11,F11/N11))) -> 1 | M11: =L11 -> 1 | N11: =ROUNDDOWN($L$8/(H11+5),0) -> 6 | O11: =$L$8-((H11+5)*N11) -> 676
A12: 3 | B12: B28011-12 | D12: SASH กรอบบาน | E12: 0.528 | F12: =4*$G$6 -> 4 | G12: FW-154 | H12: =$F$6-154 -> 889 | I12: =M12 -> 2 | K12: =F12*H12 -> 3556 | L12: =IF(N12>F12,ROUNDUP(F12/N12,0),IF(N12<F12,ROUNDUP(F12/N12,0),IF(N12=F12,F12/N12))) -> 1 | M12: =L12+L13 -> 2 | N12: =ROUNDDOWN($L$8/(H12+5),0) -> 7 | O12: =$L$8-((H12+5)*N12) -> 142 | P12: #03/2568# ปรับสูตรให้ gap จาก 4.76mm เหลือ 4mm
F13: =4*$G$6 -> 4 | G13: [(FH-46)/2]-1 | H13: =(($D$6-46)/2)-1 -> 1420 | K13: =F13*H13 -> 5680 | L13: =IF(N13>F13,ROUNDUP(F13/N13,0),IF(N13<F13,ROUNDUP(F13/N13,0),IF(N13=F13,F13/N13))) -> 1 | N13: =ROUNDDOWN($L$8/(H13+5),0) -> 4 | O13: =$L$8-((H13+5)*N13) -> 700 | P13: #02/2568# ปรับสูตรให้มีบานสั้นลง2mm.
A14: 4 | B14: B28012-10 | D14: ADAPTOR INTERLOCK คิ้วยึดเสาเกี่ยว | E14: 0.051 | F14: =2*$G$6 -> 2 | G14: FW-132 | H14: =$F$6-132 -> 911 | I14: =M14 -> 1 | K14: =F14*H14 -> 1822 | L14: =IF(N14>F14,ROUNDUP(F14/N14,0),IF(N14<F14,ROUNDUP(F14/N14,0),IF(N14=F14,F14/N14))) -> 1 | M14: =L14 -> 1 | N14: =ROUNDDOWN($L$8/(H14+5),0) -> 6 | O14: =$L$8-((H14+5)*N14) -> 904 | P14: #03/2568# ปรับสูตรให้ gap จาก 4.76mm เหลือ 4mm
A15: 5 | B15: B28013-12 | D15: INTERLOCK เสาเกี่ยว | E15: 0.167 | F15: =2*$G$6 -> 2 | G15: FW-112 | H15: =$F$6-112 -> 931 | I15: =M15 -> 1 | K15: =F15*H15 -> 1862 | L15: =IF(N15>F15,ROUNDUP(F15/N15,0),IF(N15<F15,ROUNDUP(F15/N15,0),IF(N15=F15,F15/N15))) -> 1 | M15: =L15 -> 1 | N15: =ROUNDDOWN($L$8/(H15+5),0) -> 6 | O15: =$L$8-((H15+5)*N15) -> 784 | P15: #03/2568# ปรับสูตรให้ gap จาก 4.76mm เหลือ 4mm
A16: 6 | B16: B28014-12 | D16: SILL เฟรมล่าง | E16: 0.726 | F16: =1*$G$6 -> 1 | G16: FW-50 | H16: =$F$6-50 -> 993 | I16: =M16 -> 1 | K16: =F16*H16 -> 993 | L16: =IF(N16>F16,ROUNDUP(F16/N16,0),IF(N16<F16,ROUNDUP(F16/N16,0),IF(N16=F16,F16/N16))) -> 1 | M16: =L16 -> 1 | N16: =ROUNDDOWN($L$8/(H16+5),0) -> 6 | O16: =$L$8-((H16+5)*N16) -> 412
A17: 7 | B17: B28015-12 | D17: JAMB ADAPTOR เสาเสริมเฟรมข้าง | E17: 1.034 | F17: =2*$G$6 -> 2 | G17: FH-69 | H17: =$D$6-69 -> 2819 | I17: =M17 -> 1 | K17: =F17*H17 -> 5638 | L17: =IF(N17>F17,ROUNDUP(F17/N17,0),IF(N17<F17,ROUNDUP(F17/N17,0),IF(N17=F17,F17/N17))) -> 1 | M17: =L17 -> 1 | N17: =ROUNDDOWN($L$8/(H17+5),0) -> 2 | O17: =$L$8-((H17+5)*N17) -> 752 | P17: #02/2568# ปรับสูตรให้มีgap=2mm.
A18: 8 | B18: B10004-12 | D18: NARROW FRAME เฟรมข้าง | E18: 0.847 | F18: =2*$G$6 -> 2 | G18: FH | H18: =$D$6 -> 2888 | I18: =M18 -> 1 | K18: =F18*H18 -> 5776 | L18: =IF(N18>F18,ROUNDUP(F18/N18,0),IF(N18<F18,ROUNDUP(F18/N18,0),IF(N18=F18,F18/N18))) -> 1 | M18: =L18 -> 1 | N18: =ROUNDDOWN($L$8/(H18+5),0) -> 2 | O18: =$L$8-((H18+5)*N18) -> 614
B19: Remark
B20: คนเบิก/วันที่เบิก

Sheet HUNG Takeoff
A2: DOUBLE HUNG HARDWARE ฮาร์ดแวร์ชุดหน้าต่างบานยก
A3: No. | B3: Sup parts code | C3: Description | E3: Unit | F3: Qty
A4: DOUBLE HUNG STANDARD HARDWARE SET ชุดฮาร์ดแวร์สแตนดาร์ด
A5: 1 | B5: 06-003 | D5: COMPOSITE SASH GUIDE / ไกด์ประคองกรอบบานยก | E5: PCS | F5: =4*'HUNG dies'!$G$6 -> 4
A6: 2 | B6: 06-002 | D6: PIVOT PIN / ตะขอเกี่ยวตลับเชือกบานยก | E6: PCS | F6: =4*'HUNG dies'!$G$6 -> 4
A7: 3 | B7: 06-004 | D7: COUNTER BALANCE PULLEY MODULE / ตลับล้อพูเล่ย์บานยก | E7: PCS | F7: =2*'HUNG dies'!$G$6 -> 2
A8: 4 | B8: 06-001 | D8: COUNTER BALANCE CORD CLAMP & CLUTCH / ตลับใส่เชือกบานยก | E8: PCS | F8: =4*'HUNG dies'!$G$6 -> 4
A9: 5 | B9: 06-007 | D9: 6mm. NYLON CORD BLK - เส้นเชือกไนล่อนสีดำหนา 6มม. สำหรับบานยก | E9: M | F9: =('FSA CORD calculate '!$I$16*2)/1000 -> 8.327
A10: 6 | B10: 06-005 | D10: SASH CORNER ENDCAP / ฝาปิดมุมกรอบบานยกเข้า 90 องศา | E10: PCS | F10: =8*'HUNG dies'!$G$6 -> 8
A11: 7 | B11: 06-006 | D11: HUNG INTER LOCK(L&R) END CAP / ฝาปิดรูเสาเกี่ยวหน้าต่างบานยก (ข้างซ้าย&ข้างขวา) | E11: Pair | F11: =2*'HUNG dies'!$G$6 -> 2
A12: 8 | B12: 06-011 | D12: STOPPER / ตัวเบรคบาน | E12: PCS | F12: =2*'HUNG dies'!$G$6 -> 2
A13: 9 | B13: 02-031 | D13: JAMBLINER SEAL FOAM / ยางใส่เฟรมอะแดปเตอร์เฟรมข้าง | E13: M | F13: =ROUNDUP(('HUNG dies'!$H$17*4)/1000,0)*'HUNG dies'!$G$6 -> 12
A14: 10 | B14: 02-067 | D14: 5mm MOHAIR (ฐาน 5mm. ขนยาว 6mm.) | E14: M | F14: =ROUNDUP((('HUNG dies'!$H$17*4)+('HUNG dies'!$H$11*1)+('HUNG dies'!$H$16*1)+('HUNG dies'!$H$15*2))/1000,0)*'HUNG dies'!$G$6 -> 16
A15: 11 | B15: 06-012 | D15: DOUBLE HUNG HEAD SEAL PAD แผ่นประเก็นกันน้ำเฟรมบนบานยก | E15: Pair | F15: =1*'HUNG dies'!$G$6 -> 1
A16: 12 | B16: 06-010 | D16: DOUBLE HUNG SILL SEAL PAD แผ่นประเก็นกันน้ำเฟรมล่างบานยก | E16: Pair | F16: =1*'HUNG dies'!$G$6 -> 1
A17: 13 | B17: 06-014 | D17: #7x8 mm. SS CSK SELF TAPPING SCREW (สกรูหัวจม ใช้ใขันยึดร่วมกับ SASH GUIDE) | E17: PCS | F17: =4*'HUNG dies'!$G$6 -> 4
A18: 14 | B18: 06-015 | D18: #8x12 mm. SS CSK SELF TAPPING SCREW (สกรูหัวจม ใช้ติดตั้ง JAMBLINER, Endcap Interlock, Stopper, Wind Breaker และPivot Pin) | E18: PCS | F18: =32*'HUNG dies'!$G$6 -> 32
A19: 15 | B19: 06-016 | D19: #8x10 mm. SS PH SELF TAPPING SCREW (สกรูเกลียวปล่อยหัวนูน ใช้ติดตั้งกับเส้นอะแดปเตอร์ตบเรียบเสาเกี่ยว ADAPTOR INTERLOCK) | E19: PCS | F19: =8*'HUNG dies'!$G$6 -> 8
A20: 16 | B20: 06-017 | D20: #7x40 mm. SS PH SELF TAPPING SCREW (สกรูเกลียวปล่อยหัวนูน ใช้ติดตั้งกับกรอบบาน SASH) | E20: PCS | F20: =8*'HUNG dies'!$G$6 -> 8
A21: 17 | B21: 06-018 | D21: #8x38 mm. SS PH SELF TAPPING SCREW (สกรูเกลียวปล่อยหัวนูน ใช้ติดตั้งกับโครงเฟรมนอก) | E21: PCS | F21: =8*'HUNG dies'!$G$6 -> 8
A22: 18 | B22: 06-013 | D22: ยางกันลมบานยก | E22: PCS | F22: =2*'HUNG dies'!$G$6 -> 2
A23: 6mm. GLASS GASKET/ ยางอัดกระจกสำหรับกระจก 6มม.
A24: 19 | B24: 02-068 | D24: ยางอัดกระจกตัวใหญ่ | E24: M | F24: =ROUNDUP((((('HUNG dies'!$H$12*'HUNG dies'!$F$12)+('HUNG dies'!$H$13*'HUNG dies'!$F$13))*2)/1000)*'HUNG dies'!$G$6,0) -> 19
A25: 8mm. GLASS GASKET/ ยางอัดกระจกสำหรับกระจก 8มม.
A26: 19 | B26: 02-068 | D26: ยางอัดกระจกตัวใหญ่ | E26: M | F26: =ROUNDUP(((('HUNG dies'!$H$12*'HUNG dies'!$F$12)+('HUNG dies'!$H$13*'HUNG dies'!$F$13))/1000)*'HUNG dies'!$G$6,0) -> 10
A27: 20 | B27: 02-069 | D27: ยางอัดกระจกตัวเล็ก | E27: M | F27: =ROUNDUP(((('HUNG dies'!$H$12*'HUNG dies'!$F$12)+('HUNG dies'!$H$13*'HUNG dies'!$F$13))/1000)*'HUNG dies'!$G$6,0) -> 10
A28: ACCESSORY OPTION ชุดอุปกรณ์เสริม
A29: 1 | B29: 06-008-BL | D29: SASH LIFT HANDLE (BLACK) / มือจับหน้าต่างบานยกสีดำ | E29: PCS | F29: =1*'HUNG dies'!$G$6 -> 1
B30: 06-008-WH | D30: SASH LIFT HANDLE (WHITE) / มือจับหน้าต่างบานยกสีขาว | E30: PCS | F30: =1*'HUNG dies'!$G$6 -> 1
B31: 06-008-GS | D31: SASH LIFT HANDLE (SAHARA GREY) / มือจับหน้าต่างบานยกสีเทาซาฮาร่า | E31: PCS | F31: =1*'HUNG dies'!$G$6 -> 1
B32: 06-008-WMH | D32: SASH LIFT HANDLE (WOODGRAIN MAHOGANY)/ มือจับหน้าต่างบานยกสีลายไม้มะฮอกกานี | E32: PCS | F32: =1*'HUNG dies'!$G$6 -> 1
B33: 06-008-WGT | D33: SASH LIFT HANDLE (WOODGRAIN GOLDEN TEAK) / มือจับหน้าต่างบานยกสีลายไม้สักทอง | E33: PCS | F33: =1*'HUNG dies'!$G$6 -> 1
A34: 2 | B34: 06-019 | D34: LATCH / ล็อคกลางบานยก | E34: PCS | F34: =1*'HUNG dies'!$G$6 -> 1
A35: 3 | B35: 06-020 | D35: KEEPER / ขอล็อคกลางบานยก | E35: PCS | F35: =1*'HUNG dies'!$G$6 -> 1

Sheet FSA CORD calculate 
B1: คำนวณความยาวเชือก (ใส่ระยะความสูงรวม)
A2: Overall Frame Height (OFH) | B2: Internal Frame Height (IFH) Dim "A" | C2: Overall Sash Height (OSH) | D2: Inside (I) | E2: Outside (O) | F2: Sash Height | G2: Pulley (PC) | H2: Cord Length (CL) | I2: Total Cord Length (TCL) | J2: Cord Cut Setting (CCS)
A3: 1025 | B3: =EVOALU[[#This Row],[Overall Frame Height (OFH)]]-12-17 -> 996 | C3: =EVOALU[[#This Row],[Internal Frame Height (IFH) Dim "A"]]-15-2 -> 979 | D3: =(EVOALU[[#This Row],[Internal Frame Height (IFH) Dim "A"]])-150-38 -> 808 | E3: =(EVOALU[[#This Row],[Internal Frame Height (IFH) Dim "A"]]/2)-137-38 -> 323 | F3: =EVOALU[[#This Row],[Overall Sash Height (OSH)]]/2+13 -> 502.5 | G3: 108 | H3: =G3+E3+D3 -> 1239 | I3: =EVOALU[[#This Row],[Cord Length (CL)]]+65+65 -> 1369 | J3: =(EVOALU[[#This Row],[Cord Length (CL)]]-EVOALU[[#This Row],[Pulley (PC)]])/2 -> 565.5 | L3: =EVOALU[[#This Row],[Internal Frame Height (IFH) Dim "A"]]*1.5 -> 1494 | M3: =L3-245+65+65 -> 1379
A4: 1200 | B4: =EVOALU[[#This Row],[Overall Frame Height (OFH)]]-12-17 -> 1171 | C4: =EVOALU[[#This Row],[Internal Frame Height (IFH) Dim "A"]]-15-2 -> 1154 | D4: =(EVOALU[[#This Row],[Internal Frame Height (IFH) Dim "A"]])-150-38 -> 983 | E4: =(EVOALU[[#This Row],[Internal Frame Height (IFH) Dim "A"]]/2)-137-38 -> 410.5 | F4: =EVOALU[[#This Row],[Overall Sash Height (OSH)]]/2+13 -> 590 | G4: 108 | H4: =G4+E4+D4 -> 1501.5 | I4: =EVOALU[[#This Row],[Cord Length (CL)]]+65+65 -> 1631.5 | J4: =(EVOALU[[#This Row],[Cord Length (CL)]]-EVOALU[[#This Row],[Pulley (PC)]])/2 -> 696.75 | L4: =EVOALU[[#This Row],[Internal Frame Height (IFH) Dim "A"]]*1.5 -> 1756.5 | M4: =L4-245+65+65 -> 1641.5
A5: 1300 | B5: =EVOALU[[#This Row],[Overall Frame Height (OFH)]]-12-17 -> 1271 | C5: =EVOALU[[#This Row],[Internal Frame Height (IFH) Dim "A"]]-15-2 -> 1254 | D5: =(EVOALU[[#This Row],[Internal Frame Height (IFH) Dim "A"]])-150-38 -> 1083 | E5: =(EVOALU[[#This Row],[Internal Frame Height (IFH) Dim "A"]]/2)-137-38 -> 460.5 | F5: =EVOALU[[#This Row],[Overall Sash Height (OSH)]]/2+13 -> 640 | G5: 108 | H5: =G5+E5+D5 -> 1651.5 | I5: =EVOALU[[#This Row],[Cord Length (CL)]]+65+65 -> 1781.5 | J5: =(EVOALU[[#This Row],[Cord Length (CL)]]-EVOALU[[#This Row],[Pulley (PC)]])/2 -> 771.75 | L5: =EVOALU[[#This Row],[Internal Frame Height (IFH) Dim "A"]]*1.5 -> 1906.5 | M5: =L5-245+65+65 -> 1791.5
A6: 1400 | B6: =EVOALU[[#This Row],[Overall Frame Height (OFH)]]-12-17 -> 1371 | C6: =EVOALU[[#This Row],[Internal Frame Height (IFH) Dim "A"]]-15-2 -> 1354 | D6: =(EVOALU[[#This Row],[Internal Frame Height (IFH) Dim "A"]])-150-38 -> 1183 | E6: =(EVOALU[[#This Row],[Internal Frame Height (IFH) Dim "A"]]/2)-137-38 -> 510.5 | F6: =EVOALU[[#This Row],[Overall Sash Height (OSH)]]/2+13 -> 690 | G6: 108 | H6: =G6+E6+D6 -> 1801.5 | I6: =EVOALU[[#This Row],[Cord Length (CL)]]+65+65 -> 1931.5 | J6: =(EVOALU[[#This Row],[Cord Length (CL)]]-EVOALU[[#This Row],[Pulley (PC)]])/2 -> 846.75 | L6: =EVOALU[[#This Row],[Internal Frame Height (IFH) Dim "A"]]*1.5 -> 2056.5 | M6: =L6-245+65+65 -> 1941.5
A7: 1500 | B7: =EVOALU[[#This Row],[Overall Frame Height (OFH)]]-12-17 -> 1471 | C7: =EVOALU[[#This Row],[Internal Frame Height (IFH) Dim "A"]]-15-2 -> 1454 | D7: =(EVOALU[[#This Row],[Internal Frame Height (IFH) Dim "A"]])-150-38 -> 1283 | E7: =(EVOALU[[#This Row],[Internal Frame Height (IFH) Dim "A"]]/2)-137-38 -> 560.5 | F7: =EVOALU[[#This Row],[Overall Sash Height (OSH)]]/2+13 -> 740 | G7: 108 | H7: =G7+E7+D7 -> 1951.5 | I7: =EVOALU[[#This Row],[Cord Length (CL)]]+65+65 -> 2081.5 | J7: =(EVOALU[[#This Row],[Cord Length (CL)]]-EVOALU[[#This Row],[Pulley (PC)]])/2 -> 921.75 | L7: =EVOALU[[#This Row],[Internal Frame Height (IFH) Dim "A"]]*1.5 -> 2206.5 | M7: =L7-245+65+65 -> 2091.5
A8: 1600 | B8: =EVOALU[[#This Row],[Overall Frame Height (OFH)]]-12-17 -> 1571 | C8: =EVOALU[[#This Row],[Internal Frame Height (IFH) Dim "A"]]-15-2 -> 1554 | D8: =(EVOALU[[#This Row],[Internal Frame Height (IFH) Dim "A"]])-150-38 -> 1383 | E8: =(EVOALU[[#This Row],[Internal Frame Height (IFH) Dim "A"]]/2)-137-38 -> 610.5 | F8: =EVOALU[[#This Row],[Overall Sash Height (OSH)]]/2+13 -> 790 | G8: 108 | H8: =G8+E8+D8 -> 2101.5 | I8: =EVOALU[[#This Row],[Cord Length (CL)]]+65+65 -> 2231.5 | J8: =(EVOALU[[#This Row],[Cord Length (CL)]]-EVOALU[[#This Row],[Pulley (PC)]])/2 -> 996.75 | L8: =EVOALU[[#This Row],[Internal Frame Height (IFH) Dim "A"]]*1.5 -> 2356.5 | M8: =L8-245+65+65 -> 2241.5
A9: 1700 | B9: =EVOALU[[#This Row],[Overall Frame Height (OFH)]]-12-17 -> 1671 | C9: =EVOALU[[#This Row],[Internal Frame Height (IFH) Dim "A"]]-15-2 -> 1654 | D9: =(EVOALU[[#This Row],[Internal Frame Height (IFH) Dim "A"]])-150-38 -> 1483 | E9: =(EVOALU[[#This Row],[Internal Frame Height (IFH) Dim "A"]]/2)-137-38 -> 660.5 | F9: =EVOALU[[#This Row],[Overall Sash Height (OSH)]]/2+13 -> 840 | G9: 108 | H9: =G9+E9+D9 -> 2251.5 | I9: =EVOALU[[#This Row],[Cord Length (CL)]]+65+65 -> 2381.5 | J9: =(EVOALU[[#This Row],[Cord Length (CL)]]-EVOALU[[#This Row],[Pulley (PC)]])/2 -> 1071.75 | L9: =EVOALU[[#This Row],[Internal Frame Height (IFH) Dim "A"]]*1.5 -> 2506.5 | M9: =L9-245+65+65 -> 2391.5
A10: 1800 | B10: =EVOALU[[#This Row],[Overall Frame Height (OFH)]]-12-17 -> 1771 | C10: =EVOALU[[#This Row],[Internal Frame Height (IFH) Dim "A"]]-15-2 -> 1754 | D10: =(EVOALU[[#This Row],[Internal Frame Height (IFH) Dim "A"]])-150-38 -> 1583 | E10: =(EVOALU[[#This Row],[Internal Frame Height (IFH) Dim "A"]]/2)-137-38 -> 710.5 | F10: =EVOALU[[#This Row],[Overall Sash Height (OSH)]]/2+13 -> 890 | G10: 108 | H10: =G10+E10+D10 -> 2401.5 | I10: =EVOALU[[#This Row],[Cord Length (CL)]]+65+65 -> 2531.5 | J10: =(EVOALU[[#This Row],[Cord Length (CL)]]-EVOALU[[#This Row],[Pulley (PC)]])/2 -> 1146.75 | L10: =EVOALU[[#This Row],[Internal Frame Height (IFH) Dim "A"]]*1.5 -> 2656.5 | M10: =L10-245+65+65 -> 2541.5
A11: 2000 | B11: =EVOALU[[#This Row],[Overall Frame Height (OFH)]]-12-17 -> 1971 | C11: =EVOALU[[#This Row],[Internal Frame Height (IFH) Dim "A"]]-15-2 -> 1954 | D11: =(EVOALU[[#This Row],[Internal Frame Height (IFH) Dim "A"]])-150-38 -> 1783 | E11: =(EVOALU[[#This Row],[Internal Frame Height (IFH) Dim "A"]]/2)-137-38 -> 810.5 | F11: =EVOALU[[#This Row],[Overall Sash Height (OSH)]]/2+13 -> 990 | G11: 108 | H11: =G11+E11+D11 -> 2701.5 | I11: =EVOALU[[#This Row],[Cord Length (CL)]]+65+65 -> 2831.5 | J11: =(EVOALU[[#This Row],[Cord Length (CL)]]-EVOALU[[#This Row],[Pulley (PC)]])/2 -> 1296.75 | L11: =EVOALU[[#This Row],[Internal Frame Height (IFH) Dim "A"]]*1.5 -> 2956.5 | M11: =L11-245+65+65 -> 2841.5
A12: 2100 | B12: =EVOALU[[#This Row],[Overall Frame Height (OFH)]]-12-17 -> 2071 | C12: =EVOALU[[#This Row],[Internal Frame Height (IFH) Dim "A"]]-15-2 -> 2054 | D12: =(EVOALU[[#This Row],[Internal Frame Height (IFH) Dim "A"]])-150-38 -> 1883 | E12: =(EVOALU[[#This Row],[Internal Frame Height (IFH) Dim "A"]]/2)-137-38 -> 860.5 | F12: =EVOALU[[#This Row],[Overall Sash Height (OSH)]]/2+13 -> 1040 | G12: 108 | H12: =G12+E12+D12 -> 2851.5 | I12: =EVOALU[[#This Row],[Cord Length (CL)]]+65+65 -> 2981.5 | J12: =(EVOALU[[#This Row],[Cord Length (CL)]]-EVOALU[[#This Row],[Pulley (PC)]])/2 -> 1371.75 | L12: =EVOALU[[#This Row],[Internal Frame Height (IFH) Dim "A"]]*1.5 -> 3106.5 | M12: =L12-245+65+65 -> 2991.5
A13: 2400 | B13: =EVOALU[[#This Row],[Overall Frame Height (OFH)]]-12-17 -> 2371 | C13: =EVOALU[[#This Row],[Internal Frame Height (IFH) Dim "A"]]-15-2 -> 2354 | D13: =(EVOALU[[#This Row],[Internal Frame Height (IFH) Dim "A"]])-150-38 -> 2183 | E13: =(EVOALU[[#This Row],[Internal Frame Height (IFH) Dim "A"]]/2)-137-38 -> 1010.5 | F13: =EVOALU[[#This Row],[Overall Sash Height (OSH)]]/2+13 -> 1190 | G13: 108 | H13: =G13+E13+D13 -> 3301.5 | I13: =EVOALU[[#This Row],[Cord Length (CL)]]+65+65 -> 3431.5 | J13: =(EVOALU[[#This Row],[Cord Length (CL)]]-EVOALU[[#This Row],[Pulley (PC)]])/2 -> 1596.75 | L13: =EVOALU[[#This Row],[Internal Frame Height (IFH) Dim "A"]]*1.5 -> 3556.5 | M13: =L13-245+65+65 -> 3441.5
A14: 2700 | B14: =EVOALU[[#This Row],[Overall Frame Height (OFH)]]-12-17 -> 2671 | C14: =EVOALU[[#This Row],[Internal Frame Height (IFH) Dim "A"]]-15-2 -> 2654 | D14: =(EVOALU[[#This Row],[Internal Frame Height (IFH) Dim "A"]])-150-38 -> 2483 | E14: =(EVOALU[[#This Row],[Internal Frame Height (IFH) Dim "A"]]/2)-137-38 -> 1160.5 | F14: =EVOALU[[#This Row],[Overall Sash Height (OSH)]]/2+13 -> 1340 | G14: 108 | H14: =G14+E14+D14 -> 3751.5 | I14: =EVOALU[[#This Row],[Cord Length (CL)]]+65+65 -> 3881.5 | J14: =(EVOALU[[#This Row],[Cord Length (CL)]]-EVOALU[[#This Row],[Pulley (PC)]])/2 -> 1821.75 | L14: =EVOALU[[#This Row],[Internal Frame Height (IFH) Dim "A"]]*1.5 -> 4006.5 | M14: =L14-245+65+65 -> 3891.5
A15: 3000 | B15: =EVOALU[[#This Row],[Overall Frame Height (OFH)]]-12-17 -> 2971 | C15: =EVOALU[[#This Row],[Internal Frame Height (IFH) Dim "A"]]-15-2 -> 2954 | D15: =(EVOALU[[#This Row],[Internal Frame Height (IFH) Dim "A"]])-150-38 -> 2783 | E15: =(EVOALU[[#This Row],[Internal Frame Height (IFH) Dim "A"]]/2)-137-38 -> 1310.5 | F15: =EVOALU[[#This Row],[Overall Sash Height (OSH)]]/2+13 -> 1490 | G15: 108 | H15: =G15+E15+D15 -> 4201.5 | I15: =EVOALU[[#This Row],[Cord Length (CL)]]+65+65 -> 4331.5 | J15: =(EVOALU[[#This Row],[Cord Length (CL)]]-EVOALU[[#This Row],[Pulley (PC)]])/2 -> 2046.75 | L15: =EVOALU[[#This Row],[Internal Frame Height (IFH) Dim "A"]]*1.5 -> 4456.5 | M15: =L15-245+65+65 -> 4341.5
A16: ='HUNG dies'!$D$6 -> 2888 | B16: =EVOALU[[#This Row],[Overall Frame Height (OFH)]]-12-17 -> 2859 | C16: =EVOALU[[#This Row],[Internal Frame Height (IFH) Dim "A"]]-15-2 -> 2842 | D16: =(EVOALU[[#This Row],[Internal Frame Height (IFH) Dim "A"]])-150-38 -> 2671 | E16: =(EVOALU[[#This Row],[Internal Frame Height (IFH) Dim "A"]]/2)-137-38 -> 1254.5 | F16: =EVOALU[[#This Row],[Overall Sash Height (OSH)]]/2+13 -> 1434 | G16: 108 | H16: =G16+E16+D16 -> 4033.5 | I16: =EVOALU[[#This Row],[Cord Length (CL)]]+65+65 -> 4163.5 | J16: =(EVOALU[[#This Row],[Cord Length (CL)]]-EVOALU[[#This Row],[Pulley (PC)]])/2 -> 1962.75
J18: ตัดความยาวนี้อย่างละ 2 เส้น
A19: Clutch | B19: 148 | C19: overall length
A20: Pivot Pin Ctr | B20: 10 | C20: from bottom of clutch
A21: Clutch | B21: 1 | C21: distance from bottom of sash to bottom of clutch
A22: Clutch | B22: 150 | C22: top of clutch from bottom of sash
A23: Cord | B23: 65 | C23: approx additional for cord in clutch for holding
A24: MRH | B24: 26 | C24: Meeting Rail Height
A25: Pulley (PC) | B25: 108 | C25: amount of Cord in Pulley
