Workbook
Name SlimLuxGlass: 'คิดทุน SlimLux'!$AA$1:$AA$21
Name mult_sms: 'อัปเดตราคาอลู'!$C$4
Name mult_euro: 'อัปเดตราคาอลู'!$C$5
Name mult_slim: 'อัปเดตราคาอลู'!$C$6
Name mult_velora: 'อัปเดตราคาอลู'!$C$7
Name mult_mtong: 'อัปเดตราคาอลู'!$C$8
Name rate_grey: 'อัปเดตราคาอลู'!$B$13
Name rate_special: 'อัปเดตราคาอลู'!$B$14
Name rate_woodbake: 'อัปเดตราคาอลู'!$B$15
Name rate_woodstock: 'อัปเดตราคาอลู'!$B$16
Name MungList: ราคามุ้ง!$G$1:$G$15
Name ClothList: ราคามุ้ง!$I$2:$I$5
Name mult_wood: 'อัปเดตราคาอลู'!$C$20
Name MungReady: 'ราคามุ้ง'!$G$1:$G$12
Name GlassNames: ราคาวัสดุกลาง!$H$2:$H$106
Name rate_anodize: 'อัปเดตราคาอลู'!$B$18
Name buf_scrap: 'อัปเดตราคาอลู'!$B$22

Sheet สารบัญ
B1: 📑 สารบัญ — กดลิงก์กระโดดไปหน้าที่ต้องการ
B3: 🔶 ปรับราคา / ค่าวัสดุ (แก้ราคาที่นี่ ทุกชีทขยับเอง)
B4: ▶ อัปเดตราคาอลู | C4: ราคาอลู/กก. ทุกแบรนด์ + ค่าอบสี ★
B5: ▶ ราคาสี | C5: ราคาสีอบ/เทาซาฮารา/ลายไม้
B6: ▶ ราคาวัสดุกลาง | C6: กระจก 98 รุ่น + เฟรม/เสา/อุปกรณ์
B7: ▶ ราคาวัสดุ | C7: วัสดุหลังคา (จันทัน/แป/แผ่น/ราง)
B8: ▶ ราคาออโต้ | C8: มอเตอร์/ออโต้
B9: ▶ ราคามุ้ง | C9: มุ้งซื้อสำเร็จ + ค่าแรงติดตั้ง
B10: ▶ ค่าแรง | C10: ค่าแรงผลิต+ติดตั้ง ทุกแบบ
B11: ▶ น้ำหนักโปรไฟล์ | C11: น้ำหนัก กก./เส้น ทุกโปรไฟล์
B12: ▶ ราคาสี (รวมแล้ว) | C12: ราคา/เส้น ทุกโปรไฟล์ (คำนวณ)
B13: 📊 สรุป / ภาพรวม
B14: ▶ หน้าตารางรวม | D14: ▶ สรุปงานเสริม | F14: ▶ สรุปค่าแรง
B15: 🚪 คิดทุน — ประตู/หน้าต่าง อลู
B16: ▶ SMS | D16: ▶ ยูโร | F16: ▶ SlimLux
B17: ▶ Velora | D17: ▶ E-series | F17: ▶ บานเปิด
B18: ▶ PC Door | D18: ▶ กระทุ้ง | F18: ▶ บานยก
B19: ▶ เฟี้ยม | D19: ▶ เฟี้ยมยูโร | F19: ▶ ติดตาย
B20: ▶ บานเลื่อนรางบน
B21: 🌀 คิดทุน — ดัดโค้ง
B22: ▶ ตายดัดโค้ง | D22: ▶ เปิดดัดโค้ง
B23: ▦ คิดทุน — ระแนง / ประตูรั้ว
B24: ▶ ระแนง | D24: ▶ ระแนงสลับ | F24: ▶ ระแนงสลับ_ประตู
B25: ▶ ประตูรั้ว | D25: ▶ บานเกล็ด | F25: ▶ ระแนงหมุน
B26: 🏠 คิดทุน — หลังคา
B27: ▶ หลังคา (รวม) | D27: ▶ หลังคา | F27: ▶ หลังคาจั่ว
B28: ▶ หลังคาเลื่อน | D28: ▶ ทุนไวนิล | F28: ▶ ทุนดีไลท์
B29: ▶ ทุนโพลีตัน | D29: ▶ ทุนชินโคร์ HC | F29: ▶ ทุนชินโคร์ Sup
B30: ▶ ทุนเมทัลชีท | D30: ▶ ทุนกระจก 4+4 | F30: ▶ ทุนกระจก 5+5
B31: 🧱 คิดทุน — ฝ้า / ผนัง / งานไฟ
B32: ▶ ฝ้ายิปซัม | D32: ▶ สมาร์ทบอร์ด | F32: ▶ ไอโซวอล
B33: ▶ งานไฟ | D33: ▶ ฝ้าไม้เทียม | F33: ▶ LUT_ฝ้าไม้เทียม
B34: ▶ สีฝ้าไม้เทียม
B35: 📐 เทียบ R3.9 / เช็ก
B36: ▶ เทียบ R3.9 SMS | D36: ▶ เทียบ R3.9 ยูโร | F36: ▶ เทียบ E-series
B37: ▶ เทียบ เฟี้ยมยูโร | D37: ▶ เทียบ R3.9 | F37: ▶ log กระจก
B38: ▶ เช็กขนาดกระจก

Sheet อัปเดตราคาอลู
A1: ⚠️ แก้ราคาที่นี่ → 📈 อัปเดตราคาวัสดุ — กรอก "ราคา/กก. ตอนนี้" ทับเมื่อราคาขึ้น (วิธีที่ 1) | G1: 🏠 สารบัญ
A3: แบรนด์ | B3: ราคาอลู/กก. ตอนนี้ | C3: ตัวคูณ | D3: ครอบคลุมบาน | F3: ตั้งต้น (ล็อก-อย่าแก้)
A4: SMS | B4: 187 | C4: =B4/F4 | D4: SMS · E-series | F4: 187
A5: ยูโรฟูจิ | B5: 187 | C5: =B5/F5 | D5: ยูโร·บานเปิด·PCDoor·กระทุ้ง·บานยก·เฟี้ยม·เฟี้ยมยูโร | F5: 187
A6: SlimLux | B6: 170 | C6: =B6/F6 | D6: SlimLux | F6: 170
A7: Velora | B7: 240 | C7: =B7/F7 | D7: Velora | F7: 240
A8: เมืองทอง (กล่อง/ฉาก/Z) | B8: 188 | C8: =B8/F8 | D8: ระแนง·ประตู·บานเกล็ด·ติดตาย·หลังคา | F8: 188
A10: วิธีใช้: ร้านอลูขึ้นราคา → พิมพ์ราคา/กก. ใหม่ทับช่อง B (เช่น เมืองทอง 188→196) → ทุกโปรไฟล์แบรนด์นั้นขยับ % เท่ากันอัตโนมัติ
A12: ค่าอบสี / ลายไม้ — ราคา บาท/กก. (กรอกทับเมื่อขึ้น · ชุดเดียวทุกแบรนด์)
A13: เทาซาฮาร่า | B13: 100 | C13: ค่าอบเทา 100/กก. (ไม่มีค่าล้างสี)
A14: สีอบพิเศษ | B14: 173 | C14: 138 ค่าอบ + 35 ค่าล้างสี (พี่นัทเคาะ 18 มิ.ย.)
A15: สีลายไม้อบพิเศษ | B15: 190 | C15: 155 ค่าอบ + 35 ค่าล้างสี (พี่นัทเคาะ 18 มิ.ย.)
A16: ลายไม้ stock | B16: 112.5 | C16: factor กล่องเมืองทอง · SMS/ยูโร ลายไม้=ราคาตรงต่อเส้น
A17: + ค่าเปิดตู้อบ 2,000 บาท/งาน เฉพาะสีอบพิเศษ/สีลายไม้อบพิเศษ (คงที่ ไม่ขึ้นตาม กก.)
A18: ค่าชุบเหมา (อโนไดซ์) | B18: 200 | C18: บาท/กก. · บวกบนราคาขาว-ดำ · แก้ที่เดียว
A19: ── ตัวคูณลายไม้สต็อค (เส้น SMS/ยูโร) — แยกจากเนื้ออลู ──
A20: ลายไม้สต็อค บาท/กก. | B20: 277 | C20: =B20/F20 | D20: ตอนนี้ 277 (ของจริง) ÷ ตั้งต้น 258 (ที่ฝังไว้) = ตัวคูณลายไม้ | F20: 277
A22: เผื่อเศษอลู (× ตัดเท่าไหร่คิดเท่านั้น) | B22: 1.3 | C22: แก้ที่เดียว · 1.30 = เผื่อเศษ 30%

Sheet ราคาสี
A1: ⚠️ แก้ราคาที่นี่ → ราคาสี/เส้น (จาก Stock.xlsx · ลายไม้เอา max กับที่น้องพิมพ์) — อบพิเศษ/ลายไม้พิเศษ คิดสูตร base+ค่าอบ×นน. · เพิ่มเมืองทอง/SlimLux/Velora/E-series (ราคาประเมิน นน×เรต+ค่าอบ) | K1: ⬇ ราคาใหม่อัตโนมัติเมื่อแก้ราคา/กก. (สีใหม่เติมฐานแล้วขึ้นเอง · ดำ=เทาเสมอ) | S1: ⬇ น้ำหนักคำนวณ | V1: ⬇ สีชุบ (อโนไดซ์)
A2: รหัส | B2: ชื่อ | C2: ระบบ | D2: ขาว/ดำ | E2: เทาซาฮาร่า | F2: ดำซาฮาร่า | G2: แอทแทคเกรย์ | H2: ลายไม้สต็อค | I2: ลายไม้ มะฮอกกานี | J2: ลายไม้ ไวท์โอ๊ค | K2: ตัวคูณ (จาก/กก.) | L2: ขาว/ดำ ปัจจุบัน | M2: เทา ปัจจุบัน | N2: ดำซาฮาร่า ปัจจุบัน | O2: แอทแทคเกรย์ ปัจจุบัน | P2: ลายไม้ ปัจจุบัน | Q2: มะฮอกกานี ปัจจุบัน | R2: ไวท์โอ๊ค ปัจจุบัน | S2: น้ำหนัก กก./เส้น | T2: น้ำหนัก กก./ม. | U2: เพิ่มขึ้น /เส้น | V2: สีชุบ ฿/เส้น
A3: B20001 | B3: เฟรมบนบานเลื่อน | C3: อลูมิเนียม sms | D3: 1125 | E3: 1225 | F3: =E3 | H3: 1825 | K3: =IF(ISNUMBER(SEARCH("เมืองทอง",C3)),mult_mtong,IF(ISNUMBER(SEARCH("SlimLux",C3)),mult_slim,IF(ISNUMBER(SEARCH("Velora",C3)),mult_velora,IF(ISNUMBER(SEARCH("Fuji",C3)),mult_euro,mult_sms)))) | L3: =ROUND(D3*K3,0) | M3: =IF(E3="",ROUND(L3+'อัปเดตราคาอลู'!$B$13*S3,0),ROUND(E3*K3,0)) | N3: =M3 | O3: =IF(G3="",ROUND(L3+rate_special*S3,0),ROUND(G3*mult_euro,0)) | P3: =IF(H3="",ROUND(L3+rate_woodbake*S3,0),ROUND(H3*mult_wood,0)) | Q3: =IF(I3="",ROUND(L3+rate_woodbake*S3,0),ROUND(I3*mult_wood,0)) | R3: =IF(J3="",ROUND(L3+rate_woodbake*S3,0),ROUND(J3*mult_wood,0)) | S3: =ROUND(D3/(IF(ISNUMBER(SEARCH("เมืองทอง",C3)),'อัปเดตราคาอลู'!$F$8,IF(ISNUMBER(SEARCH("SlimLux",C3)),'อัปเดตราคาอลู'!$F$6,IF(ISNUMBER(SEARCH("Velora",C3)),'อัปเดตราคาอลู'!$F$7,IF(ISNUMBER(SEARCH("Fuji",C3)),'อัปเดตราคาอลู'!$F$5,'อัปเดตราคาอลู'!$F$4))))),3) | T3: =ROUND(P3/(IF(OR(ISNUMBER(SEARCH("เมืองทอง",C3)),ISNUMBER(SEARCH("SlimLux",C3)),ISNUMBER(SEARCH("Velora",C3))),6,6.4)),3) | U3: =ROUND(L3-D3,0) | V3: =IF(D3="","",ROUND(D3+rate_anodize*S3,0))
A4: B20002 | B4: เฟรมล่างบานเลื่อน | C4: อลูมิเนียม sms | D4: 1205 | E4: 1310 | F4: =E4 | H4: 1925 | K4: =IF(ISNUMBER(SEARCH("เมืองทอง",C4)),mult_mtong,IF(ISNUMBER(SEARCH("SlimLux",C4)),mult_slim,IF(ISNUMBER(SEARCH("Velora",C4)),mult_velora,IF(ISNUMBER(SEARCH("Fuji",C4)),mult_euro,mult_sms)))) | L4: =ROUND(D4*K4,0) | M4: =IF(E4="",ROUND(L4+'อัปเดตราคาอลู'!$B$13*S4,0),ROUND(E4*K4,0)) | N4: =M4 | O4: =IF(G4="",ROUND(L4+rate_special*S4,0),ROUND(G4*mult_euro,0)) | P4: =IF(H4="",ROUND(L4+rate_woodbake*S4,0),ROUND(H4*mult_wood,0)) | Q4: =IF(I4="",ROUND(L4+rate_woodbake*S4,0),ROUND(I4*mult_wood,0)) | R4: =IF(J4="",ROUND(L4+rate_woodbake*S4,0),ROUND(J4*mult_wood,0)) | S4: =ROUND(D4/(IF(ISNUMBER(SEARCH("เมืองทอง",C4)),'อัปเดตราคาอลู'!$F$8,IF(ISNUMBER(SEARCH("SlimLux",C4)),'อัปเดตราคาอลู'!$F$6,IF(ISNUMBER(SEARCH("Velora",C4)),'อัปเดตราคาอลู'!$F$7,IF(ISNUMBER(SEARCH("Fuji",C4)),'อัปเดตราคาอลู'!$F$5,'อัปเดตราคาอลู'!$F$4))))),3) | T4: =ROUND(P4/(IF(OR(ISNUMBER(SEARCH("เมืองทอง",C4)),ISNUMBER(SEARCH("SlimLux",C4)),ISNUMBER(SEARCH("Velora",C4))),6,6.4)),3) | U4: =ROUND(L4-D4,0) | V4: =IF(D4="","",ROUND(D4+rate_anodize*S4,0))
A5: B20003 | B5: เฟรมข้างบานเลื่อน | C5: อลูมิเนียม sms | D5: 870 | E5: 950 | F5: =E5 | H5: 1395 | K5: =IF(ISNUMBER(SEARCH("เมืองทอง",C5)),mult_mtong,IF(ISNUMBER(SEARCH("SlimLux",C5)),mult_slim,IF(ISNUMBER(SEARCH("Velora",C5)),mult_velora,IF(ISNUMBER(SEARCH("Fuji",C5)),mult_euro,mult_sms)))) | L5: =ROUND(D5*K5,0) | M5: =IF(E5="",ROUND(L5+'อัปเดตราคาอลู'!$B$13*S5,0),ROUND(E5*K5,0)) | N5: =M5 | O5: =IF(G5="",ROUND(L5+rate_special*S5,0),ROUND(G5*mult_euro,0)) | P5: =IF(H5="",ROUND(L5+rate_woodbake*S5,0),ROUND(H5*mult_wood,0)) | Q5: =IF(I5="",ROUND(L5+rate_woodbake*S5,0),ROUND(I5*mult_wood,0)) | R5: =IF(J5="",ROUND(L5+rate_woodbake*S5,0),ROUND(J5*mult_wood,0)) | S5: =ROUND(D5/(IF(ISNUMBER(SEARCH("เมืองทอง",C5)),'อัปเดตราคาอลู'!$F$8,IF(ISNUMBER(SEARCH("SlimLux",C5)),'อัปเดตราคาอลู'!$F$6,IF(ISNUMBER(SEARCH("Velora",C5)),'อัปเดตราคาอลู'!$F$7,IF(ISNUMBER(SEARCH("Fuji",C5)),'อัปเดตราคาอลู'!$F$5,'อัปเดตราคาอลู'!$F$4))))),3) | T5: =ROUND(P5/(IF(OR(ISNUMBER(SEARCH("เมืองทอง",C5)),ISNUMBER(SEARCH("SlimLux",C5)),ISNUMBER(SEARCH("Velora",C5))),6,6.4)),3) | U5: =ROUND(L5-D5,0) | V5: =IF(D5="","",ROUND(D5+rate_anodize*S5,0))
A6: B20004 | B6: เฟรมบนเสริมร่องกระจก | C6: อลูมิเนียม sms | D6: 870 | E6: 950 | F6: =E6 | H6: 1395 | K6: =IF(ISNUMBER(SEARCH("เมืองทอง",C6)),mult_mtong,IF(ISNUMBER(SEARCH("SlimLux",C6)),mult_slim,IF(ISNUMBER(SEARCH("Velora",C6)),mult_velora,IF(ISNUMBER(SEARCH("Fuji",C6)),mult_euro,mult_sms)))) | L6: =ROUND(D6*K6,0) | M6: =IF(E6="",ROUND(L6+'อัปเดตราคาอลู'!$B$13*S6,0),ROUND(E6*K6,0)) | N6: =M6 | O6: =IF(G6="",ROUND(L6+rate_special*S6,0),ROUND(G6*mult_euro,0)) | P6: =IF(H6="",ROUND(L6+rate_woodbake*S6,0),ROUND(H6*mult_wood,0)) | Q6: =IF(I6="",ROUND(L6+rate_woodbake*S6,0),ROUND(I6*mult_wood,0)) | R6: =IF(J6="",ROUND(L6+rate_woodbake*S6,0),ROUND(J6*mult_wood,0)) | S6: =ROUND(D6/(IF(ISNUMBER(SEARCH("เมืองทอง",C6)),'อัปเดตราคาอลู'!$F$8,IF(ISNUMBER(SEARCH("SlimLux",C6)),'อัปเดตราคาอลู'!$F$6,IF(ISNUMBER(SEARCH("Velora",C6)),'อัปเดตราคาอลู'!$F$7,IF(ISNUMBER(SEARCH("Fuji",C6)),'อัปเดตราคาอลู'!$F$5,'อัปเดตราคาอลู'!$F$4))))),3) | T6: =ROUND(P6/(IF(OR(ISNUMBER(SEARCH("เมืองทอง",C6)),ISNUMBER(SEARCH("SlimLux",C6)),ISNUMBER(SEARCH("Velora",C6))),6,6.4)),3) | U6: =ROUND(L6-D6,0) | V6: =IF(D6="","",ROUND(D6+rate_anodize*S6,0))
A7: B20007 | B7: เสากุญแจ (ตูดตัน) | C7: อลูมิเนียม sms | D7: 660 | E7: 725 | F7: =E7 | H7: 1065 | K7: =IF(ISNUMBER(SEARCH("เมืองทอง",C7)),mult_mtong,IF(ISNUMBER(SEARCH("SlimLux",C7)),mult_slim,IF(ISNUMBER(SEARCH("Velora",C7)),mult_velora,IF(ISNUMBER(SEARCH("Fuji",C7)),mult_euro,mult_sms)))) | L7: =ROUND(D7*K7,0) | M7: =IF(E7="",ROUND(L7+'อัปเดตราคาอลู'!$B$13*S7,0),ROUND(E7*K7,0)) | N7: =M7 | O7: =IF(G7="",ROUND(L7+rate_special*S7,0),ROUND(G7*mult_euro,0)) | P7: =IF(H7="",ROUND(L7+rate_woodbake*S7,0),ROUND(H7*mult_wood,0)) | Q7: =IF(I7="",ROUND(L7+rate_woodbake*S7,0),ROUND(I7*mult_wood,0)) | R7: =IF(J7="",ROUND(L7+rate_woodbake*S7,0),ROUND(J7*mult_wood,0)) | S7: =ROUND(D7/(IF(ISNUMBER(SEARCH("เมืองทอง",C7)),'อัปเดตราคาอลู'!$F$8,IF(ISNUMBER(SEARCH("SlimLux",C7)),'อัปเดตราคาอลู'!$F$6,IF(ISNUMBER(SEARCH("Velora",C7)),'อัปเดตราคาอลู'!$F$7,IF(ISNUMBER(SEARCH("Fuji",C7)),'อัปเดตราคาอลู'!$F$5,'อัปเดตราคาอลู'!$F$4))))),3) | T7: =ROUND(P7/(IF(OR(ISNUMBER(SEARCH("เมืองทอง",C7)),ISNUMBER(SEARCH("SlimLux",C7)),ISNUMBER(SEARCH("Velora",C7))),6,6.4)),3) | U7: =ROUND(L7-D7,0) | V7: =IF(D7="","",ROUND(D7+rate_anodize*S7,0))
A8: B20008 | B8: เสากุญแจแบบรับแรง | C8: อลูมิเนียม sms | D8: 1125 | E8: 1225 | F8: =E8 | H8: 1800 | K8: =IF(ISNUMBER(SEARCH("เมืองทอง",C8)),mult_mtong,IF(ISNUMBER(SEARCH("SlimLux",C8)),mult_slim,IF(ISNUMBER(SEARCH("Velora",C8)),mult_velora,IF(ISNUMBER(SEARCH("Fuji",C8)),mult_euro,mult_sms)))) | L8: =ROUND(D8*K8,0) | M8: =IF(E8="",ROUND(L8+'อัปเดตราคาอลู'!$B$13*S8,0),ROUND(E8*K8,0)) | N8: =M8 | O8: =IF(G8="",ROUND(L8+rate_special*S8,0),ROUND(G8*mult_euro,0)) | P8: =IF(H8="",ROUND(L8+rate_woodbake*S8,0),ROUND(H8*mult_wood,0)) | Q8: =IF(I8="",ROUND(L8+rate_woodbake*S8,0),ROUND(I8*mult_wood,0)) | R8: =IF(J8="",ROUND(L8+rate_woodbake*S8,0),ROUND(J8*mult_wood,0)) | S8: =ROUND(D8/(IF(ISNUMBER(SEARCH("เมืองทอง",C8)),'อัปเดตราคาอลู'!$F$8,IF(ISNUMBER(SEARCH("SlimLux",C8)),'อัปเดตราคาอลู'!$F$6,IF(ISNUMBER(SEARCH("Velora",C8)),'อัปเดตราคาอลู'!$F$7,IF(ISNUMBER(SEARCH("Fuji",C8)),'อัปเดตราคาอลู'!$F$5,'อัปเดตราคาอลู'!$F$4))))),3) | T8: =ROUND(P8/(IF(OR(ISNUMBER(SEARCH("เมืองทอง",C8)),ISNUMBER(SEARCH("SlimLux",C8)),ISNUMBER(SEARCH("Velora",C8))),6,6.4)),3) | U8: =ROUND(L8-D8,0) | V8: =IF(D8="","",ROUND(D8+rate_anodize*S8,0))
A9: B20009 | B9: เสาเกี่ยว (ธรรมดา) | C9: อลูมิเนียม sms | D9: 690 | E9: 750 | F9: =E9 | H9: 1105 | K9: =IF(ISNUMBER(SEARCH("เมืองทอง",C9)),mult_mtong,IF(ISNUMBER(SEARCH("SlimLux",C9)),mult_slim,IF(ISNUMBER(SEARCH("Velora",C9)),mult_velora,IF(ISNUMBER(SEARCH("Fuji",C9)),mult_euro,mult_sms)))) | L9: =ROUND(D9*K9,0) | M9: =IF(E9="",ROUND(L9+'อัปเดตราคาอลู'!$B$13*S9,0),ROUND(E9*K9,0)) | N9: =M9 | O9: =IF(G9="",ROUND(L9+rate_special*S9,0),ROUND(G9*mult_euro,0)) | P9: =IF(H9="",ROUND(L9+rate_woodbake*S9,0),ROUND(H9*mult_wood,0)) | Q9: =IF(I9="",ROUND(L9+rate_woodbake*S9,0),ROUND(I9*mult_wood,0)) | R9: =IF(J9="",ROUND(L9+rate_woodbake*S9,0),ROUND(J9*mult_wood,0)) | S9: =ROUND(D9/(IF(ISNUMBER(SEARCH("เมืองทอง",C9)),'อัปเดตราคาอลู'!$F$8,IF(ISNUMBER(SEARCH("SlimLux",C9)),'อัปเดตราคาอลู'!$F$6,IF(ISNUMBER(SEARCH("Velora",C9)),'อัปเดตราคาอลู'!$F$7,IF(ISNUMBER(SEARCH("Fuji",C9)),'อัปเดตราคาอลู'!$F$5,'อัปเดตราคาอลู'!$F$4))))),3) | T9: =ROUND(P9/(IF(OR(ISNUMBER(SEARCH("เมืองทอง",C9)),ISNUMBER(SEARCH("SlimLux",C9)),ISNUMBER(SEARCH("Velora",C9))),6,6.4)),3) | U9: =ROUND(L9-D9,0) | V9: =IF(D9="","",ROUND(D9+rate_anodize*S9,0))
A10: B20010 | B10: เสาเกี่ยวนอก (สูง 2.4 m) | C10: อลูมิเนียม sms | D10: 1235 | E10: 1345 | F10: =E10 | H10: 1975 | K10: =IF(ISNUMBER(SEARCH("เมืองทอง",C10)),mult_mtong,IF(ISNUMBER(SEARCH("SlimLux",C10)),mult_slim,IF(ISNUMBER(SEARCH("Velora",C10)),mult_velora,IF(ISNUMBER(SEARCH("Fuji",C10)),mult_euro,mult_sms)))) | L10: =ROUND(D10*K10,0) | M10: =IF(E10="",ROUND(L10+'อัปเดตราคาอลู'!$B$13*S10,0),ROUND(E10*K10,0)) | N10: =M10 | O10: =IF(G10="",ROUND(L10+rate_special*S10,0),ROUND(G10*mult_euro,0)) | P10: =IF(H10="",ROUND(L10+rate_woodbake*S10,0),ROUND(H10*mult_wood,0)) | Q10: =IF(I10="",ROUND(L10+rate_woodbake*S10,0),ROUND(I10*mult_wood,0)) | R10: =IF(J10="",ROUND(L10+rate_woodbake*S10,0),ROUND(J10*mult_wood,0)) | S10: =ROUND(D10/(IF(ISNUMBER(SEARCH("เมืองทอง",C10)),'อัปเดตราคาอลู'!$F$8,IF(ISNUMBER(SEARCH("SlimLux",C10)),'อัปเดตราคาอลู'!$F$6,IF(ISNUMBER(SEARCH("Velora",C10)),'อัปเดตราคาอลู'!$F$7,IF(ISNUMBER(SEARCH("Fuji",C10)),'อัปเดตราคาอลู'!$F$5,'อัปเดตราคาอลู'!$F$4))))),3) | T10: =ROUND(P10/(IF(OR(ISNUMBER(SEARCH("เมืองทอง",C10)),ISNUMBER(SEARCH("SlimLux",C10)),ISNUMBER(SEARCH("Velora",C10))),6,6.4)),3) | U10: =ROUND(L10-D10,0) | V10: =IF(D10="","",ROUND(D10+rate_anodize*S10,0))
A11: B20019 | B11: ฝาปิดเฟรมข้าง | C11: อลูมิเนียม sms | D11: 175 | E11: 190 | F11: =E11 | H11: 280 | K11: =IF(ISNUMBER(SEARCH("เมืองทอง",C11)),mult_mtong,IF(ISNUMBER(SEARCH("SlimLux",C11)),mult_slim,IF(ISNUMBER(SEARCH("Velora",C11)),mult_velora,IF(ISNUMBER(SEARCH("Fuji",C11)),mult_euro,mult_sms)))) | L11: =ROUND(D11*K11,0) | M11: =IF(E11="",ROUND(L11+'อัปเดตราคาอลู'!$B$13*S11,0),ROUND(E11*K11,0)) | N11: =M11 | O11: =IF(G11="",ROUND(L11+rate_special*S11,0),ROUND(G11*mult_euro,0)) | P11: =IF(H11="",ROUND(L11+rate_woodbake*S11,0),ROUND(H11*mult_wood,0)) | Q11: =IF(I11="",ROUND(L11+rate_woodbake*S11,0),ROUND(I11*mult_wood,0)) | R11: =IF(J11="",ROUND(L11+rate_woodbake*S11,0),ROUND(J11*mult_wood,0)) | S11: =ROUND(D11/(IF(ISNUMBER(SEARCH("เมืองทอง",C11)),'อัปเดตราคาอลู'!$F$8,IF(ISNUMBER(SEARCH("SlimLux",C11)),'อัปเดตราคาอลู'!$F$6,IF(ISNUMBER(SEARCH("Velora",C11)),'อัปเดตราคาอลู'!$F$7,IF(ISNUMBER(SEARCH("Fuji",C11)),'อัปเดตราคาอลู'!$F$5,'อัปเดตราคาอลู'!$F$4))))),3) | T11: =ROUND(P11/(IF(OR(ISNUMBER(SEARCH("เมืองทอง",C11)),ISNUMBER(SEARCH("SlimLux",C11)),ISNUMBER(SEARCH("Velora",C11))),6,6.4)),3) | U11: =ROUND(L11-D11,0) | V11: =IF(D11="","",ROUND(D11+rate_anodize*S11,0))
A12: B20024 | B12: คิ้วกันตก | C12: อลูมิเนียม sms | D12: 185 | E12: 200 | F12: =E12 | H12: 295 | K12: =IF(ISNUMBER(SEARCH("เมืองทอง",C12)),mult_mtong,IF(ISNUMBER(SEARCH("SlimLux",C12)),mult_slim,IF(ISNUMBER(SEARCH("Velora",C12)),mult_velora,IF(ISNUMBER(SEARCH("Fuji",C12)),mult_euro,mult_sms)))) | L12: =ROUND(D12*K12,0) | M12: =IF(E12="",ROUND(L12+'อัปเดตราคาอลู'!$B$13*S12,0),ROUND(E12*K12,0)) | N12: =M12 | O12: =IF(G12="",ROUND(L12+rate_special*S12,0),ROUND(G12*mult_euro,0)) | P12: =IF(H12="",ROUND(L12+rate_woodbake*S12,0),ROUND(H12*mult_wood,0)) | Q12: =IF(I12="",ROUND(L12+rate_woodbake*S12,0),ROUND(I12*mult_wood,0)) | R12: =IF(J12="",ROUND(L12+rate_woodbake*S12,0),ROUND(J12*mult_wood,0)) | S12: =ROUND(D12/(IF(ISNUMBER(SEARCH("เมืองทอง",C12)),'อัปเดตราคาอลู'!$F$8,IF(ISNUMBER(SEARCH("SlimLux",C12)),'อัปเดตราคาอลู'!$F$6,IF(ISNUMBER(SEARCH("Velora",C12)),'อัปเดตราคาอลู'!$F$7,IF(ISNUMBER(SEARCH("Fuji",C12)),'อัปเดตราคาอลู'!$F$5,'อัปเดตราคาอลู'!$F$4))))),3) | T12: =ROUND(P12/(IF(OR(ISNUMBER(SEARCH("เมืองทอง",C12)),ISNUMBER(SEARCH("SlimLux",C12)),ISNUMBER(SEARCH("Velora",C12))),6,6.4)),3) | U12: =ROUND(L12-D12,0) | V12: =IF(D12="","",ROUND(D12+rate_anodize*S12,0))
A13: B20041 | B13: เฟรมบานเลื่อน (3รางเสียบ) | C13: อลูมิเนียม sms | D13: 2070 | E13: 2255 | F13: =E13 | H13: 3424 | K13: =IF(ISNUMBER(SEARCH("เมืองทอง",C13)),mult_mtong,IF(ISNUMBER(SEARCH("SlimLux",C13)),mult_slim,IF(ISNUMBER(SEARCH("Velora",C13)),mult_velora,IF(ISNUMBER(SEARCH("Fuji",C13)),mult_euro,mult_sms)))) | L13: =ROUND(D13*K13,0) | M13: =IF(E13="",ROUND(L13+'อัปเดตราคาอลู'!$B$13*S13,0),ROUND(E13*K13,0)) | N13: =M13 | O13: =IF(G13="",ROUND(L13+rate_special*S13,0),ROUND(G13*mult_euro,0)) | P13: =IF(H13="",ROUND(L13+rate_woodbake*S13,0),ROUND(H13*mult_wood,0)) | Q13: =IF(I13="",ROUND(L13+rate_woodbake*S13,0),ROUND(I13*mult_wood,0)) | R13: =IF(J13="",ROUND(L13+rate_woodbake*S13,0),ROUND(J13*mult_wood,0)) | S13: =ROUND(D13/(IF(ISNUMBER(SEARCH("เมืองทอง",C13)),'อัปเดตราคาอลู'!$F$8,IF(ISNUMBER(SEARCH("SlimLux",C13)),'อัปเดตราคาอลู'!$F$6,IF(ISNUMBER(SEARCH("Velora",C13)),'อัปเดตราคาอลู'!$F$7,IF(ISNUMBER(SEARCH("Fuji",C13)),'อัปเดตราคาอลู'!$F$5,'อัปเดตราคาอลู'!$F$4))))),3) | T13: =ROUND(P13/(IF(OR(ISNUMBER(SEARCH("เมืองทอง",C13)),ISNUMBER(SEARCH("SlimLux",C13)),ISNUMBER(SEARCH("Velora",C13))),6,6.4)),3) | U13: =ROUND(L13-D13,0) | V13: =IF(D13="","",ROUND(D13+rate_anodize*S13,0))
A14: B20048 | B14: ตัวตบรางมุ้ง | C14: อลูมิเนียม sms | D14: 310 | E14: 340 | F14: =E14 | H14: 495 | K14: =IF(ISNUMBER(SEARCH("เมืองทอง",C14)),mult_mtong,IF(ISNUMBER(SEARCH("SlimLux",C14)),mult_slim,IF(ISNUMBER(SEARCH("Velora",C14)),mult_velora,IF(ISNUMBER(SEARCH("Fuji",C14)),mult_euro,mult_sms)))) | L14: =ROUND(D14*K14,0) | M14: =IF(E14="",ROUND(L14+'อัปเดตราคาอลู'!$B$13*S14,0),ROUND(E14*K14,0)) | N14: =M14 | O14: =IF(G14="",ROUND(L14+rate_special*S14,0),ROUND(G14*mult_euro,0)) | P14: =IF(H14="",ROUND(L14+rate_woodbake*S14,0),ROUND(H14*mult_wood,0)) | Q14: =IF(I14="",ROUND(L14+rate_woodbake*S14,0),ROUND(I14*mult_wood,0)) | R14: =IF(J14="",ROUND(L14+rate_woodbake*S14,0),ROUND(J14*mult_wood,0)) | S14: =ROUND(D14/(IF(ISNUMBER(SEARCH("เมืองทอง",C14)),'อัปเดตราคาอลู'!$F$8,IF(ISNUMBER(SEARCH("SlimLux",C14)),'อัปเดตราคาอลู'!$F$6,IF(ISNUMBER(SEARCH("Velora",C14)),'อัปเดตราคาอลู'!$F$7,IF(ISNUMBER(SEARCH("Fuji",C14)),'อัปเดตราคาอลู'!$F$5,'อัปเดตราคาอลู'!$F$4))))),3) | T14: =ROUND(P14/(IF(OR(ISNUMBER(SEARCH("เมืองทอง",C14)),ISNUMBER(SEARCH("SlimLux",C14)),ISNUMBER(SEARCH("Velora",C14))),6,6.4)),3) | U14: =ROUND(L14-D14,0) | V14: =IF(D14="","",ROUND(D14+rate_anodize*S14,0))
... A35: B30006 | B35: กรอบมุ้ง | C35: อลูมิเนียม sms | D35: 625 | E35: 680 | F35: =E35 | H35: 1000 | K35: =IF(ISNUMBER(SEARCH("เมืองทอง",C35)),mult_mtong,IF(ISNUMBER(SEARCH("SlimLux",C35)),mult_slim,IF(ISNUMBER(SEARCH("Velora",C35)),mult_velora,IF(ISNUMBER(SEARCH("Fuji",C35)),mult_euro,mult_sms)))) | L35: =ROUND(D35*K35,0) | M35: =IF(E35="",ROUND(L35+'อัปเดตราคาอลู'!$B$13*S35,0),ROUND(E35*K35,0)) | N35: =M35 | O35: =IF(G35="",ROUND(L35+rate_special*S35,0),ROUND(G35*mult_euro,0)) | P35: =IF(H35="",ROUND(L35+rate_woodbake*S35,0),ROUND(H35*mult_wood,0)) | Q35: =IF(I35="",ROUND(L35+rate_woodbake*S35,0),ROUND(I35*mult_wood,0)) | R35: =IF(J35="",ROUND(L35+rate_woodbake*S35,0),ROUND(J35*mult_wood,0)) | S35: =ROUND(D35/(IF(ISNUMBER(SEARCH("เมืองทอง",C35)),'อัปเดตราคาอลู'!$F$8,IF(ISNUMBER(SEARCH("SlimLux",C35)),'อัปเดตราคาอลู'!$F$6,IF(ISNUMBER(SEARCH("Velora",C35)),'อัปเดตราคาอลู'!$F$7,IF(ISNUMBER(SEARCH("Fuji",C35)),'อัปเดตราคาอลู'!$F$5,'อัปเดตราคาอลู'!$F$4))))),3) | T35: =ROUND(P35/(IF(OR(ISNUMBER(SEARCH("เมืองทอง",C35)),ISNUMBER(SEARCH("SlimLux",C35)),ISNUMBER(SEARCH("Velora",C35))),6,6.4)),3) | U35: =ROUND(L35-D35,0) | V35: =IF(D35="","",ROUND(D35+rate_anodize*S35,0))
A36: F7976 | B36: เฟรมบน-ล่างบานเลื่อน 3 ราง | C36: อลูมิเนียม Fuji | D36: 2310 | E36: 2475 | F36: =E36 | G36: 2500 | H36: 3350 | I36: 3485 | J36: 3460 | K36: =IF(ISNUMBER(SEARCH("เมืองทอง",C36)),mult_mtong,IF(ISNUMBER(SEARCH("SlimLux",C36)),mult_slim,IF(ISNUMBER(SEARCH("Velora",C36)),mult_velora,IF(ISNUMBER(SEARCH("Fuji",C36)),mult_euro,mult_sms)))) | L36: =ROUND(D36*K36,0) | M36: =IF(E36="",ROUND(L36+'อัปเดตราคาอลู'!$B$13*S36,0),ROUND(E36*K36,0)) | N36: =M36 | O36: =IF(G36="",ROUND(L36+rate_special*S36,0),ROUND(G36*mult_euro,0)) | P36: =IF(H36="",ROUND(L36+rate_woodbake*S36,0),ROUND(H36*mult_wood,0)) | Q36: =IF(I36="",ROUND(L36+rate_woodbake*S36,0),ROUND(I36*mult_wood,0)) | R36: =IF(J36="",ROUND(L36+rate_woodbake*S36,0),ROUND(J36*mult_wood,0)) | S36: =ROUND(D36/(IF(ISNUMBER(SEARCH("เมืองทอง",C36)),'อัปเดตราคาอลู'!$F$8,IF(ISNUMBER(SEARCH("SlimLux",C36)),'อัปเดตราคาอลู'!$F$6,IF(ISNUMBER(SEARCH("Velora",C36)),'อัปเดตราคาอลู'!$F$7,IF(ISNUMBER(SEARCH("Fuji",C36)),'อัปเดตราคาอลู'!$F$5,'อัปเดตราคาอลู'!$F$4))))),3) | T36: =ROUND(P36/(IF(OR(ISNUMBER(SEARCH("เมืองทอง",C36)),ISNUMBER(SEARCH("SlimLux",C36)),ISNUMBER(SEARCH("Velora",C36))),6,6.4)),3) | U36: =ROUND(L36-D36,0) | V36: =IF(D36="","",ROUND(D36+rate_anodize*S36,0))
A37: F7869 | B37: เฟรมบน-ล่างบานเลื่อน 3 ราง (ตัวหนา) | C37: อลูมิเนียม Fuji | D37: 2780 | E37: 2980 | F37: =E37 | G37: 3010 | H37: 4005 | I37: 4195 | J37: 4165 | K37: =IF(ISNUMBER(SEARCH("เมืองทอง",C37)),mult_mtong,IF(ISNUMBER(SEARCH("SlimLux",C37)),mult_slim,IF(ISNUMBER(SEARCH("Velora",C37)),mult_velora,IF(ISNUMBER(SEARCH("Fuji",C37)),mult_euro,mult_sms)))) | L37: =ROUND(D37*K37,0) | M37: =IF(E37="",ROUND(L37+'อัปเดตราคาอลู'!$B$13*S37,0),ROUND(E37*K37,0)) | N37: =M37 | O37: =IF(G37="",ROUND(L37+rate_special*S37,0),ROUND(G37*mult_euro,0)) | P37: =IF(H37="",ROUND(L37+rate_woodbake*S37,0),ROUND(H37*mult_wood,0)) | Q37: =IF(I37="",ROUND(L37+rate_woodbake*S37,0),ROUND(I37*mult_wood,0)) | R37: =IF(J37="",ROUND(L37+rate_woodbake*S37,0),ROUND(J37*mult_wood,0)) | S37: =ROUND(D37/(IF(ISNUMBER(SEARCH("เมืองทอง",C37)),'อัปเดตราคาอลู'!$F$8,IF(ISNUMBER(SEARCH("SlimLux",C37)),'อัปเดตราคาอลู'!$F$6,IF(ISNUMBER(SEARCH("Velora",C37)),'อัปเดตราคาอลู'!$F$7,IF(ISNUMBER(SEARCH("Fuji",C37)),'อัปเดตราคาอลู'!$F$5,'อัปเดตราคาอลู'!$F$4))))),3) | T37: =ROUND(P37/(IF(OR(ISNUMBER(SEARCH("เมืองทอง",C37)),ISNUMBER(SEARCH("SlimLux",C37)),ISNUMBER(SEARCH("Velora",C37))),6,6.4)),3) | U37: =ROUND(L37-D37,0) | V37: =IF(D37="","",ROUND(D37+rate_anodize*S37,0))
A38: F7977 | B38: เฟรมบน-ล่างบานเลื่อน 2 ราง | C38: อลูมิเนียม Fuji | D38: 1535 | E38: 1645 | F38: =E38 | G38: 1665 | H38: 2250 | I38: 2320 | J38: 2300 | K38: =IF(ISNUMBER(SEARCH("เมืองทอง",C38)),mult_mtong,IF(ISNUMBER(SEARCH("SlimLux",C38)),mult_slim,IF(ISNUMBER(SEARCH("Velora",C38)),mult_velora,IF(ISNUMBER(SEARCH("Fuji",C38)),mult_euro,mult_sms)))) | L38: =ROUND(D38*K38,0) | M38: =IF(E38="",ROUND(L38+'อัปเดตราคาอลู'!$B$13*S38,0),ROUND(E38*K38,0)) | N38: =M38 | O38: =IF(G38="",ROUND(L38+rate_special*S38,0),ROUND(G38*mult_euro,0)) | P38: =IF(H38="",ROUND(L38+rate_woodbake*S38,0),ROUND(H38*mult_wood,0)) | Q38: =IF(I38="",ROUND(L38+rate_woodbake*S38,0),ROUND(I38*mult_wood,0)) | R38: =IF(J38="",ROUND(L38+rate_woodbake*S38,0),ROUND(J38*mult_wood,0)) | S38: =ROUND(D38/(IF(ISNUMBER(SEARCH("เมืองทอง",C38)),'อัปเดตราคาอลู'!$F$8,IF(ISNUMBER(SEARCH("SlimLux",C38)),'อัปเดตราคาอลู'!$F$6,IF(ISNUMBER(SEARCH("Velora",C38)),'อัปเดตราคาอลู'!$F$7,IF(ISNUMBER(SEARCH("Fuji",C38)),'อัปเดตราคาอลู'!$F$5,'อัปเดตราคาอลู'!$F$4))))),3) | T38: =ROUND(P38/(IF(OR(ISNUMBER(SEARCH("เมืองทอง",C38)),ISNUMBER(SEARCH("SlimLux",C38)),ISNUMBER(SEARCH("Velora",C38))),6,6.4)),3) | U38: =ROUND(L38-D38,0) | V38: =IF(D38="","",ROUND(D38+rate_anodize*S38,0))
A39: F7990 | B39: ต่อเฟรมบน-ล่างบานเลื่อน | C39: อลูมิเนียม Fuji | D39: 1035 | E39: 1105 | F39: =E39 | G39: 1120 | H39: 1485 | I39: 1560 | J39: 1550 | K39: =IF(ISNUMBER(SEARCH("เมืองทอง",C39)),mult_mtong,IF(ISNUMBER(SEARCH("SlimLux",C39)),mult_slim,IF(ISNUMBER(SEARCH("Velora",C39)),mult_velora,IF(ISNUMBER(SEARCH("Fuji",C39)),mult_euro,mult_sms)))) | L39: =ROUND(D39*K39,0) | M39: =IF(E39="",ROUND(L39+'อัปเดตราคาอลู'!$B$13*S39,0),ROUND(E39*K39,0)) | N39: =M39 | O39: =IF(G39="",ROUND(L39+rate_special*S39,0),ROUND(G39*mult_euro,0)) | P39: =IF(H39="",ROUND(L39+rate_woodbake*S39,0),ROUND(H39*mult_wood,0)) | Q39: =IF(I39="",ROUND(L39+rate_woodbake*S39,0),ROUND(I39*mult_wood,0)) | R39: =IF(J39="",ROUND(L39+rate_woodbake*S39,0),ROUND(J39*mult_wood,0)) | S39: =ROUND(D39/(IF(ISNUMBER(SEARCH("เมืองทอง",C39)),'อัปเดตราคาอลู'!$F$8,IF(ISNUMBER(SEARCH("SlimLux",C39)),'อัปเดตราคาอลู'!$F$6,IF(ISNUMBER(SEARCH("Velora",C39)),'อัปเดตราคาอลู'!$F$7,IF(ISNUMBER(SEARCH("Fuji",C39)),'อัปเดตราคาอลู'!$F$5,'อัปเดตราคาอลู'!$F$4))))),3) | T39: =ROUND(P39/(IF(OR(ISNUMBER(SEARCH("เมืองทอง",C39)),ISNUMBER(SEARCH("SlimLux",C39)),ISNUMBER(SEARCH("Velora",C39))),6,6.4)),3) | U39: =ROUND(L39-D39,0) | V39: =IF(D39="","",ROUND(D39+rate_anodize*S39,0))
A40: F7902 | B40: เฟรมล่างบานเลื่อน 3 ราง (ตัวเตี้ย) | C40: อลูมิเนียม Fuji | D40: 1225 | E40: 1315 | F40: =E40 | G40: 1325 | H40: 1795 | I40: 1850 | J40: 1835 | K40: =IF(ISNUMBER(SEARCH("เมืองทอง",C40)),mult_mtong,IF(ISNUMBER(SEARCH("SlimLux",C40)),mult_slim,IF(ISNUMBER(SEARCH("Velora",C40)),mult_velora,IF(ISNUMBER(SEARCH("Fuji",C40)),mult_euro,mult_sms)))) | L40: =ROUND(D40*K40,0) | M40: =IF(E40="",ROUND(L40+'อัปเดตราคาอลู'!$B$13*S40,0),ROUND(E40*K40,0)) | N40: =M40 | O40: =IF(G40="",ROUND(L40+rate_special*S40,0),ROUND(G40*mult_euro,0)) | P40: =IF(H40="",ROUND(L40+rate_woodbake*S40,0),ROUND(H40*mult_wood,0)) | Q40: =IF(I40="",ROUND(L40+rate_woodbake*S40,0),ROUND(I40*mult_wood,0)) | R40: =IF(J40="",ROUND(L40+rate_woodbake*S40,0),ROUND(J40*mult_wood,0)) | S40: =ROUND(D40/(IF(ISNUMBER(SEARCH("เมืองทอง",C40)),'อัปเดตราคาอลู'!$F$8,IF(ISNUMBER(SEARCH("SlimLux",C40)),'อัปเดตราคาอลู'!$F$6,IF(ISNUMBER(SEARCH("Velora",C40)),'อัปเดตราคาอลู'!$F$7,IF(ISNUMBER(SEARCH("Fuji",C40)),'อัปเดตราคาอลู'!$F$5,'อัปเดตราคาอลู'!$F$4))))),3) | T40: =ROUND(P40/(IF(OR(ISNUMBER(SEARCH("เมืองทอง",C40)),ISNUMBER(SEARCH("SlimLux",C40)),ISNUMBER(SEARCH("Velora",C40))),6,6.4)),3) | U40: =ROUND(L40-D40,0) | V40: =IF(D40="","",ROUND(D40+rate_anodize*S40,0))
A41: F7978 | B41: เฟรมข้างบานเลื่อน 3 ราง | C41: อลูมิเนียม Fuji | D41: 860 | E41: 925 | F41: =E41 | G41: 935 | H41: 1395 | I41: 1300 | J41: 1290 | K41: =IF(ISNUMBER(SEARCH("เมืองทอง",C41)),mult_mtong,IF(ISNUMBER(SEARCH("SlimLux",C41)),mult_slim,IF(ISNUMBER(SEARCH("Velora",C41)),mult_velora,IF(ISNUMBER(SEARCH("Fuji",C41)),mult_euro,mult_sms)))) | L41: =ROUND(D41*K41,0) | M41: =IF(E41="",ROUND(L41+'อัปเดตราคาอลู'!$B$13*S41,0),ROUND(E41*K41,0)) | N41: =M41 | O41: =IF(G41="",ROUND(L41+rate_special*S41,0),ROUND(G41*mult_euro,0)) | P41: =IF(H41="",ROUND(L41+rate_woodbake*S41,0),ROUND(H41*mult_wood,0)) | Q41: =IF(I41="",ROUND(L41+rate_woodbake*S41,0),ROUND(I41*mult_wood,0)) | R41: =IF(J41="",ROUND(L41+rate_woodbake*S41,0),ROUND(J41*mult_wood,0)) | S41: =ROUND(D41/(IF(ISNUMBER(SEARCH("เมืองทอง",C41)),'อัปเดตราคาอลู'!$F$8,IF(ISNUMBER(SEARCH("SlimLux",C41)),'อัปเดตราคาอลู'!$F$6,IF(ISNUMBER(SEARCH("Velora",C41)),'อัปเดตราคาอลู'!$F$7,IF(ISNUMBER(SEARCH("Fuji",C41)),'อัปเดตราคาอลู'!$F$5,'อัปเดตราคาอลู'!$F$4))))),3) | T41: =ROUND(P41/(IF(OR(ISNUMBER(SEARCH("เมืองทอง",C41)),ISNUMBER(SEARCH("SlimLux",C41)),ISNUMBER(SEARCH("Velora",C41))),6,6.4)),3) | U41: =ROUND(L41-D41,0) | V41: =IF(D41="","",ROUND(D41+rate_anodize*S41,0))
A42: F7870 | B42: เฟรมข้างบานเลื่อน 3 ราง (ตัวหนา) | C42: อลูมิเนียม Fuji | D42: 1115 | E42: 1195 | F42: =E42 | G42: 1210 | H42: 1635 | I42: 1685 | J42: 1670 | K42: =IF(ISNUMBER(SEARCH("เมืองทอง",C42)),mult_mtong,IF(ISNUMBER(SEARCH("SlimLux",C42)),mult_slim,IF(ISNUMBER(SEARCH("Velora",C42)),mult_velora,IF(ISNUMBER(SEARCH("Fuji",C42)),mult_euro,mult_sms)))) | L42: =ROUND(D42*K42,0) | M42: =IF(E42="",ROUND(L42+'อัปเดตราคาอลู'!$B$13*S42,0),ROUND(E42*K42,0)) | N42: =M42 | O42: =IF(G42="",ROUND(L42+rate_special*S42,0),ROUND(G42*mult_euro,0)) | P42: =IF(H42="",ROUND(L42+rate_woodbake*S42,0),ROUND(H42*mult_wood,0)) | Q42: =IF(I42="",ROUND(L42+rate_woodbake*S42,0),ROUND(I42*mult_wood,0)) | R42: =IF(J42="",ROUND(L42+rate_woodbake*S42,0),ROUND(J42*mult_wood,0)) | S42: =ROUND(D42/(IF(ISNUMBER(SEARCH("เมืองทอง",C42)),'อัปเดตราคาอลู'!$F$8,IF(ISNUMBER(SEARCH("SlimLux",C42)),'อัปเดตราคาอลู'!$F$6,IF(ISNUMBER(SEARCH("Velora",C42)),'อัปเดตราคาอลู'!$F$7,IF(ISNUMBER(SEARCH("Fuji",C42)),'อัปเดตราคาอลู'!$F$5,'อัปเดตราคาอลู'!$F$4))))),3) | T42: =ROUND(P42/(IF(OR(ISNUMBER(SEARCH("เมืองทอง",C42)),ISNUMBER(SEARCH("SlimLux",C42)),ISNUMBER(SEARCH("Velora",C42))),6,6.4)),3) | U42: =ROUND(L42-D42,0) | V42: =IF(D42="","",ROUND(D42+rate_anodize*S42,0))
A43: F7979 | B43: เฟรมข้างบานเลื่อน 2 ราง | C43: อลูมิเนียม Fuji | D43: 695 | E43: 745 | F43: =E43 | G43: 750 | H43: 1030 | I43: 1050 | J43: 1040 | K43: =IF(ISNUMBER(SEARCH("เมืองทอง",C43)),mult_mtong,IF(ISNUMBER(SEARCH("SlimLux",C43)),mult_slim,IF(ISNUMBER(SEARCH("Velora",C43)),mult_velora,IF(ISNUMBER(SEARCH("Fuji",C43)),mult_euro,mult_sms)))) | L43: =ROUND(D43*K43,0) | M43: =IF(E43="",ROUND(L43+'อัปเดตราคาอลู'!$B$13*S43,0),ROUND(E43*K43,0)) | N43: =M43 | O43: =IF(G43="",ROUND(L43+rate_special*S43,0),ROUND(G43*mult_euro,0)) | P43: =IF(H43="",ROUND(L43+rate_woodbake*S43,0),ROUND(H43*mult_wood,0)) | Q43: =IF(I43="",ROUND(L43+rate_woodbake*S43,0),ROUND(I43*mult_wood,0)) | R43: =IF(J43="",ROUND(L43+rate_woodbake*S43,0),ROUND(J43*mult_wood,0)) | S43: =ROUND(D43/(IF(ISNUMBER(SEARCH("เมืองทอง",C43)),'อัปเดตราคาอลู'!$F$8,IF(ISNUMBER(SEARCH("SlimLux",C43)),'อัปเดตราคาอลู'!$F$6,IF(ISNUMBER(SEARCH("Velora",C43)),'อัปเดตราคาอลู'!$F$7,IF(ISNUMBER(SEARCH("Fuji",C43)),'อัปเดตราคาอลู'!$F$5,'อัปเดตราคาอลู'!$F$4))))),3) | T43: =ROUND(P43/(IF(OR(ISNUMBER(SEARCH("เมืองทอง",C43)),ISNUMBER(SEARCH("SlimLux",C43)),ISNUMBER(SEARCH("Velora",C43))),6,6.4)),3) | U43: =ROUND(L43-D43,0) | V43: =IF(D43="","",ROUND(D43+rate_anodize*S43,0))
A44: F7986 | B44: ตบรับล็อกเฟรมข้าง | C44: อลูมิเนียม Fuji | D44: 230 | E44: 250 | F44: =E44 | G44: 250 | H44: 430 | I44: 350 | J44: 350 | K44: =IF(ISNUMBER(SEARCH("เมืองทอง",C44)),mult_mtong,IF(ISNUMBER(SEARCH("SlimLux",C44)),mult_slim,IF(ISNUMBER(SEARCH("Velora",C44)),mult_velora,IF(ISNUMBER(SEARCH("Fuji",C44)),mult_euro,mult_sms)))) | L44: =ROUND(D44*K44,0) | M44: =IF(E44="",ROUND(L44+'อัปเดตราคาอลู'!$B$13*S44,0),ROUND(E44*K44,0)) | N44: =M44 | O44: =IF(G44="",ROUND(L44+rate_special*S44,0),ROUND(G44*mult_euro,0)) | P44: =IF(H44="",ROUND(L44+rate_woodbake*S44,0),ROUND(H44*mult_wood,0)) | Q44: =IF(I44="",ROUND(L44+rate_woodbake*S44,0),ROUND(I44*mult_wood,0)) | R44: =IF(J44="",ROUND(L44+rate_woodbake*S44,0),ROUND(J44*mult_wood,0)) | S44: =ROUND(D44/(IF(ISNUMBER(SEARCH("เมืองทอง",C44)),'อัปเดตราคาอลู'!$F$8,IF(ISNUMBER(SEARCH("SlimLux",C44)),'อัปเดตราคาอลู'!$F$6,IF(ISNUMBER(SEARCH("Velora",C44)),'อัปเดตราคาอลู'!$F$7,IF(ISNUMBER(SEARCH("Fuji",C44)),'อัปเดตราคาอลู'!$F$5,'อัปเดตราคาอลู'!$F$4))))),3) | T44: =ROUND(P44/(IF(OR(ISNUMBER(SEARCH("เมืองทอง",C44)),ISNUMBER(SEARCH("SlimLux",C44)),ISNUMBER(SEARCH("Velora",C44))),6,6.4)),3) | U44: =ROUND(L44-D44,0) | V44: =IF(D44="","",ROUND(D44+rate_anodize*S44,0))
A45: F7989 | B45: กล่องต่อเฟรมข้างบานเลื่อน | C45: อลูมิเนียม Fuji | D45: 340 | E45: 365 | F45: =E45 | G45: 365 | H45: 480 | I45: 510 | J45: 505 | K45: =IF(ISNUMBER(SEARCH("เมืองทอง",C45)),mult_mtong,IF(ISNUMBER(SEARCH("SlimLux",C45)),mult_slim,IF(ISNUMBER(SEARCH("Velora",C45)),mult_velora,IF(ISNUMBER(SEARCH("Fuji",C45)),mult_euro,mult_sms)))) | L45: =ROUND(D45*K45,0) | M45: =IF(E45="",ROUND(L45+'อัปเดตราคาอลู'!$B$13*S45,0),ROUND(E45*K45,0)) | N45: =M45 | O45: =IF(G45="",ROUND(L45+rate_special*S45,0),ROUND(G45*mult_euro,0)) | P45: =IF(H45="",ROUND(L45+rate_woodbake*S45,0),ROUND(H45*mult_wood,0)) | Q45: =IF(I45="",ROUND(L45+rate_woodbake*S45,0),ROUND(I45*mult_wood,0)) | R45: =IF(J45="",ROUND(L45+rate_woodbake*S45,0),ROUND(J45*mult_wood,0)) | S45: =ROUND(D45/(IF(ISNUMBER(SEARCH("เมืองทอง",C45)),'อัปเดตราคาอลู'!$F$8,IF(ISNUMBER(SEARCH("SlimLux",C45)),'อัปเดตราคาอลู'!$F$6,IF(ISNUMBER(SEARCH("Velora",C45)),'อัปเดตราคาอลู'!$F$7,IF(ISNUMBER(SEARCH("Fuji",C45)),'อัปเดตราคาอลู'!$F$5,'อัปเดตราคาอลู'!$F$4))))),3) | T45: =ROUND(P45/(IF(OR(ISNUMBER(SEARCH("เมืองทอง",C45)),ISNUMBER(SEARCH("SlimLux",C45)),ISNUMBER(SEARCH("Velora",C45))),6,6.4)),3) | U45: =ROUND(L45-D45,0) | V45: =IF(D45="","",ROUND(D45+rate_anodize*S45,0))
A46: F7867 | B46: กรอบบานเลื่อน ประตู (ตัวบาง) | C46: อลูมิเนียม Fuji | D46: 1265 | E46: 1355 | F46: =E46 | G46: 1370 | H46: 1755 | I46: 1910 | J46: 1895 | K46: =IF(ISNUMBER(SEARCH("เมืองทอง",C46)),mult_mtong,IF(ISNUMBER(SEARCH("SlimLux",C46)),mult_slim,IF(ISNUMBER(SEARCH("Velora",C46)),mult_velora,IF(ISNUMBER(SEARCH("Fuji",C46)),mult_euro,mult_sms)))) | L46: =ROUND(D46*K46,0) | M46: =IF(E46="",ROUND(L46+'อัปเดตราคาอลู'!$B$13*S46,0),ROUND(E46*K46,0)) | N46: =M46 | O46: =IF(G46="",ROUND(L46+rate_special*S46,0),ROUND(G46*mult_euro,0)) | P46: =IF(H46="",ROUND(L46+rate_woodbake*S46,0),ROUND(H46*mult_wood,0)) | Q46: =IF(I46="",ROUND(L46+rate_woodbake*S46,0),ROUND(I46*mult_wood,0)) | R46: =IF(J46="",ROUND(L46+rate_woodbake*S46,0),ROUND(J46*mult_wood,0)) | S46: =ROUND(D46/(IF(ISNUMBER(SEARCH("เมืองทอง",C46)),'อัปเดตราคาอลู'!$F$8,IF(ISNUMBER(SEARCH("SlimLux",C46)),'อัปเดตราคาอลู'!$F$6,IF(ISNUMBER(SEARCH("Velora",C46)),'อัปเดตราคาอลู'!$F$7,IF(ISNUMBER(SEARCH("Fuji",C46)),'อัปเดตราคาอลู'!$F$5,'อัปเดตราคาอลู'!$F$4))))),3) | T46: =ROUND(P46/(IF(OR(ISNUMBER(SEARCH("เมืองทอง",C46)),ISNUMBER(SEARCH("SlimLux",C46)),ISNUMBER(SEARCH("Velora",C46))),6,6.4)),3) | U46: =ROUND(L46-D46,0) | V46: =IF(D46="","",ROUND(D46+rate_anodize*S46,0))
A47: F7980 | B47: กรอบบานเลื่อนประตู | C47: อลูมิเนียม Fuji | D47: 1535 | E47: 1645 | F47: =E47 | G47: 1665 | H47: 2170 | I47: 2320 | J47: 2300 | K47: =IF(ISNUMBER(SEARCH("เมืองทอง",C47)),mult_mtong,IF(ISNUMBER(SEARCH("SlimLux",C47)),mult_slim,IF(ISNUMBER(SEARCH("Velora",C47)),mult_velora,IF(ISNUMBER(SEARCH("Fuji",C47)),mult_euro,mult_sms)))) | L47: =ROUND(D47*K47,0) | M47: =IF(E47="",ROUND(L47+'อัปเดตราคาอลู'!$B$13*S47,0),ROUND(E47*K47,0)) | N47: =M47 | O47: =IF(G47="",ROUND(L47+rate_special*S47,0),ROUND(G47*mult_euro,0)) | P47: =IF(H47="",ROUND(L47+rate_woodbake*S47,0),ROUND(H47*mult_wood,0)) | Q47: =IF(I47="",ROUND(L47+rate_woodbake*S47,0),ROUND(I47*mult_wood,0)) | R47: =IF(J47="",ROUND(L47+rate_woodbake*S47,0),ROUND(J47*mult_wood,0)) | S47: =ROUND(D47/(IF(ISNUMBER(SEARCH("เมืองทอง",C47)),'อัปเดตราคาอลู'!$F$8,IF(ISNUMBER(SEARCH("SlimLux",C47)),'อัปเดตราคาอลู'!$F$6,IF(ISNUMBER(SEARCH("Velora",C47)),'อัปเดตราคาอลู'!$F$7,IF(ISNUMBER(SEARCH("Fuji",C47)),'อัปเดตราคาอลู'!$F$5,'อัปเดตราคาอลู'!$F$4))))),3) | T47: =ROUND(P47/(IF(OR(ISNUMBER(SEARCH("เมืองทอง",C47)),ISNUMBER(SEARCH("SlimLux",C47)),ISNUMBER(SEARCH("Velora",C47))),6,6.4)),3) | U47: =ROUND(L47-D47,0) | V47: =IF(D47="","",ROUND(D47+rate_anodize*S47,0))
... A62: F7988 | B62: ตบปิดร่อง | C62: อลูมิเนียม Fuji | D62: 100 | E62: 110 | F62: =E62 | G62: 115 | H62: 170 | I62: 135 | J62: 130 | K62: =IF(ISNUMBER(SEARCH("เมืองทอง",C62)),mult_mtong,IF(ISNUMBER(SEARCH("SlimLux",C62)),mult_slim,IF(ISNUMBER(SEARCH("Velora",C62)),mult_velora,IF(ISNUMBER(SEARCH("Fuji",C62)),mult_euro,mult_sms)))) | L62: =ROUND(D62*K62,0) | M62: =IF(E62="",ROUND(L62+'อัปเดตราคาอลู'!$B$13*S62,0),ROUND(E62*K62,0)) | N62: =M62 | O62: =IF(G62="",ROUND(L62+rate_special*S62,0),ROUND(G62*mult_euro,0)) | P62: =IF(H62="",ROUND(L62+rate_woodbake*S62,0),ROUND(H62*mult_wood,0)) | Q62: =IF(I62="",ROUND(L62+rate_woodbake*S62,0),ROUND(I62*mult_wood,0)) | R62: =IF(J62="",ROUND(L62+rate_woodbake*S62,0),ROUND(J62*mult_wood,0)) | S62: =ROUND(D62/(IF(ISNUMBER(SEARCH("เมืองทอง",C62)),'อัปเดตราคาอลู'!$F$8,IF(ISNUMBER(SEARCH("SlimLux",C62)),'อัปเดตราคาอลู'!$F$6,IF(ISNUMBER(SEARCH("Velora",C62)),'อัปเดตราคาอลู'!$F$7,IF(ISNUMBER(SEARCH("Fuji",C62)),'อัปเดตราคาอลู'!$F$5,'อัปเดตราคาอลู'!$F$4))))),3) | T62: =ROUND(P62/(IF(OR(ISNUMBER(SEARCH("เมืองทอง",C62)),ISNUMBER(SEARCH("SlimLux",C62)),ISNUMBER(SEARCH("Velora",C62))),6,6.4)),3) | U62: =ROUND(L62-D62,0) | V62: =IF(D62="","",ROUND(D62+rate_anodize*S62,0))
A63: F7994 | B63: เส้นรางเลื่อน | C63: อลูมิเนียม Fuji | D63: 150 | F63: =E63 | K63: =IF(ISNUMBER(SEARCH("เมืองทอง",C63)),mult_mtong,IF(ISNUMBER(SEARCH("SlimLux",C63)),mult_slim,IF(ISNUMBER(SEARCH("Velora",C63)),mult_velora,IF(ISNUMBER(SEARCH("Fuji",C63)),mult_euro,mult_sms)))) | L63: =ROUND(D63*K63,0) | M63: =IF(E63="",ROUND(L63+'อัปเดตราคาอลู'!$B$13*S63,0),ROUND(E63*K63,0)) | N63: =M63 | O63: =IF(G63="",ROUND(L63+rate_special*S63,0),ROUND(G63*mult_euro,0)) | P63: =IF(H63="",ROUND(L63+rate_woodbake*S63,0),ROUND(H63*mult_wood,0)) | Q63: =IF(I63="",ROUND(L63+rate_woodbake*S63,0),ROUND(I63*mult_wood,0)) | R63: =IF(J63="",ROUND(L63+rate_woodbake*S63,0),ROUND(J63*mult_wood,0)) | S63: =ROUND(D63/(IF(ISNUMBER(SEARCH("เมืองทอง",C63)),'อัปเดตราคาอลู'!$F$8,IF(ISNUMBER(SEARCH("SlimLux",C63)),'อัปเดตราคาอลู'!$F$6,IF(ISNUMBER(SEARCH("Velora",C63)),'อัปเดตราคาอลู'!$F$7,IF(ISNUMBER(SEARCH("Fuji",C63)),'อัปเดตราคาอลู'!$F$5,'อัปเดตราคาอลู'!$F$4))))),3) | T63: =ROUND(P63/(IF(OR(ISNUMBER(SEARCH("เมืองทอง",C63)),ISNUMBER(SEARCH("SlimLux",C63)),ISNUMBER(SEARCH("Velora",C63))),6,6.4)),3) | U63: =ROUND(L63-D63,0) | V63: =IF(D63="","",ROUND(D63+rate_anodize*S63,0))
A64: F7987 | B64: คิ้วมุ้งบานเลื่อน | C64: อลูมิเนียม Fuji | D64: 175 | E64: 185 | F64: =E64 | G64: 190 | H64: 270 | I64: 260 | J64: 260 | K64: =IF(ISNUMBER(SEARCH("เมืองทอง",C64)),mult_mtong,IF(ISNUMBER(SEARCH("SlimLux",C64)),mult_slim,IF(ISNUMBER(SEARCH("Velora",C64)),mult_velora,IF(ISNUMBER(SEARCH("Fuji",C64)),mult_euro,mult_sms)))) | L64: =ROUND(D64*K64,0) | M64: =IF(E64="",ROUND(L64+'อัปเดตราคาอลู'!$B$13*S64,0),ROUND(E64*K64,0)) | N64: =M64 | O64: =IF(G64="",ROUND(L64+rate_special*S64,0),ROUND(G64*mult_euro,0)) | P64: =IF(H64="",ROUND(L64+rate_woodbake*S64,0),ROUND(H64*mult_wood,0)) | Q64: =IF(I64="",ROUND(L64+rate_woodbake*S64,0),ROUND(I64*mult_wood,0)) | R64: =IF(J64="",ROUND(L64+rate_woodbake*S64,0),ROUND(J64*mult_wood,0)) | S64: =ROUND(D64/(IF(ISNUMBER(SEARCH("เมืองทอง",C64)),'อัปเดตราคาอลู'!$F$8,IF(ISNUMBER(SEARCH("SlimLux",C64)),'อัปเดตราคาอลู'!$F$6,IF(ISNUMBER(SEARCH("Velora",C64)),'อัปเดตราคาอลู'!$F$7,IF(ISNUMBER(SEARCH("Fuji",C64)),'อัปเดตราคาอลู'!$F$5,'อัปเดตราคาอลู'!$F$4))))),3) | T64: =ROUND(P64/(IF(OR(ISNUMBER(SEARCH("เมืองทอง",C64)),ISNUMBER(SEARCH("SlimLux",C64)),ISNUMBER(SEARCH("Velora",C64))),6,6.4)),3) | U64: =ROUND(L64-D64,0) | V64: =IF(D64="","",ROUND(D64+rate_anodize*S64,0))
A65: F7996 | B65: คิ้วลอยช่องแสง | C65: อลูมิเนียม Fuji | D65: 425 | E65: 455 | F65: =E65 | G65: 460 | H65: 725 | I65: 645 | J65: 640 | K65: =IF(ISNUMBER(SEARCH("เมืองทอง",C65)),mult_mtong,IF(ISNUMBER(SEARCH("SlimLux",C65)),mult_slim,IF(ISNUMBER(SEARCH("Velora",C65)),mult_velora,IF(ISNUMBER(SEARCH("Fuji",C65)),mult_euro,mult_sms)))) | L65: =ROUND(D65*K65,0) | M65: =IF(E65="",ROUND(L65+'อัปเดตราคาอลู'!$B$13*S65,0),ROUND(E65*K65,0)) | N65: =M65 | O65: =IF(G65="",ROUND(L65+rate_special*S65,0),ROUND(G65*mult_euro,0)) | P65: =IF(H65="",ROUND(L65+rate_woodbake*S65,0),ROUND(H65*mult_wood,0)) | Q65: =IF(I65="",ROUND(L65+rate_woodbake*S65,0),ROUND(I65*mult_wood,0)) | R65: =IF(J65="",ROUND(L65+rate_woodbake*S65,0),ROUND(J65*mult_wood,0)) | S65: =ROUND(D65/(IF(ISNUMBER(SEARCH("เมืองทอง",C65)),'อัปเดตราคาอลู'!$F$8,IF(ISNUMBER(SEARCH("SlimLux",C65)),'อัปเดตราคาอลู'!$F$6,IF(ISNUMBER(SEARCH("Velora",C65)),'อัปเดตราคาอลู'!$F$7,IF(ISNUMBER(SEARCH("Fuji",C65)),'อัปเดตราคาอลู'!$F$5,'อัปเดตราคาอลู'!$F$4))))),3) | T65: =ROUND(P65/(IF(OR(ISNUMBER(SEARCH("เมืองทอง",C65)),ISNUMBER(SEARCH("SlimLux",C65)),ISNUMBER(SEARCH("Velora",C65))),6,6.4)),3) | U65: =ROUND(L65-D65,0) | V65: =IF(D65="","",ROUND(D65+rate_anodize*S65,0))
A66: F7919 | B66: คิ้วกรอบบาน | C66: อลูมิเนียม Fuji | D66: 225 | E66: 240 | F66: =E66 | G66: 240 | H66: 295 | I66: 335 | J66: 335 | K66: =IF(ISNUMBER(SEARCH("เมืองทอง",C66)),mult_mtong,IF(ISNUMBER(SEARCH("SlimLux",C66)),mult_slim,IF(ISNUMBER(SEARCH("Velora",C66)),mult_velora,IF(ISNUMBER(SEARCH("Fuji",C66)),mult_euro,mult_sms)))) | L66: =ROUND(D66*K66,0) | M66: =IF(E66="",ROUND(L66+'อัปเดตราคาอลู'!$B$13*S66,0),ROUND(E66*K66,0)) | N66: =M66 | O66: =IF(G66="",ROUND(L66+rate_special*S66,0),ROUND(G66*mult_euro,0)) | P66: =IF(H66="",ROUND(L66+rate_woodbake*S66,0),ROUND(H66*mult_wood,0)) | Q66: =IF(I66="",ROUND(L66+rate_woodbake*S66,0),ROUND(I66*mult_wood,0)) | R66: =IF(J66="",ROUND(L66+rate_woodbake*S66,0),ROUND(J66*mult_wood,0)) | S66: =ROUND(D66/(IF(ISNUMBER(SEARCH("เมืองทอง",C66)),'อัปเดตราคาอลู'!$F$8,IF(ISNUMBER(SEARCH("SlimLux",C66)),'อัปเดตราคาอลู'!$F$6,IF(ISNUMBER(SEARCH("Velora",C66)),'อัปเดตราคาอลู'!$F$7,IF(ISNUMBER(SEARCH("Fuji",C66)),'อัปเดตราคาอลู'!$F$5,'อัปเดตราคาอลู'!$F$4))))),3) | T66: =ROUND(P66/(IF(OR(ISNUMBER(SEARCH("เมืองทอง",C66)),ISNUMBER(SEARCH("SlimLux",C66)),ISNUMBER(SEARCH("Velora",C66))),6,6.4)),3) | U66: =ROUND(L66-D66,0) | V66: =IF(D66="","",ROUND(D66+rate_anodize*S66,0))
A67: F7917 | B67: คิ้วกรอบบาน | C67: อลูมิเนียม Fuji | D67: 175 | E67: 185 | F67: =E67 | G67: 190 | H67: 255 | I67: 260 | J67: 260 | K67: =IF(ISNUMBER(SEARCH("เมืองทอง",C67)),mult_mtong,IF(ISNUMBER(SEARCH("SlimLux",C67)),mult_slim,IF(ISNUMBER(SEARCH("Velora",C67)),mult_velora,IF(ISNUMBER(SEARCH("Fuji",C67)),mult_euro,mult_sms)))) | L67: =ROUND(D67*K67,0) | M67: =IF(E67="",ROUND(L67+'อัปเดตราคาอลู'!$B$13*S67,0),ROUND(E67*K67,0)) | N67: =M67 | O67: =IF(G67="",ROUND(L67+rate_special*S67,0),ROUND(G67*mult_euro,0)) | P67: =IF(H67="",ROUND(L67+rate_woodbake*S67,0),ROUND(H67*mult_wood,0)) | Q67: =IF(I67="",ROUND(L67+rate_woodbake*S67,0),ROUND(I67*mult_wood,0)) | R67: =IF(J67="",ROUND(L67+rate_woodbake*S67,0),ROUND(J67*mult_wood,0)) | S67: =ROUND(D67/(IF(ISNUMBER(SEARCH("เมืองทอง",C67)),'อัปเดตราคาอลู'!$F$8,IF(ISNUMBER(SEARCH("SlimLux",C67)),'อัปเดตราคาอลู'!$F$6,IF(ISNUMBER(SEARCH("Velora",C67)),'อัปเดตราคาอลู'!$F$7,IF(ISNUMBER(SEARCH("Fuji",C67)),'อัปเดตราคาอลู'!$F$5,'อัปเดตราคาอลู'!$F$4))))),3) | T67: =ROUND(P67/(IF(OR(ISNUMBER(SEARCH("เมืองทอง",C67)),ISNUMBER(SEARCH("SlimLux",C67)),ISNUMBER(SEARCH("Velora",C67))),6,6.4)),3) | U67: =ROUND(L67-D67,0) | V67: =IF(D67="","",ROUND(D67+rate_anodize*S67,0))
A68: F7950 | B68: คิ้วกรอบบาน | C68: อลูมิเนียม Fuji | D68: 175 | E68: 185 | F68: =E68 | G68: 190 | H68: 255 | I68: 260 | J68: 260 | K68: =IF(ISNUMBER(SEARCH("เมืองทอง",C68)),mult_mtong,IF(ISNUMBER(SEARCH("SlimLux",C68)),mult_slim,IF(ISNUMBER(SEARCH("Velora",C68)),mult_velora,IF(ISNUMBER(SEARCH("Fuji",C68)),mult_euro,mult_sms)))) | L68: =ROUND(D68*K68,0) | M68: =IF(E68="",ROUND(L68+'อัปเดตราคาอลู'!$B$13*S68,0),ROUND(E68*K68,0)) | N68: =M68 | O68: =IF(G68="",ROUND(L68+rate_special*S68,0),ROUND(G68*mult_euro,0)) | P68: =IF(H68="",ROUND(L68+rate_woodbake*S68,0),ROUND(H68*mult_wood,0)) | Q68: =IF(I68="",ROUND(L68+rate_woodbake*S68,0),ROUND(I68*mult_wood,0)) | R68: =IF(J68="",ROUND(L68+rate_woodbake*S68,0),ROUND(J68*mult_wood,0)) | S68: =ROUND(D68/(IF(ISNUMBER(SEARCH("เมืองทอง",C68)),'อัปเดตราคาอลู'!$F$8,IF(ISNUMBER(SEARCH("SlimLux",C68)),'อัปเดตราคาอลู'!$F$6,IF(ISNUMBER(SEARCH("Velora",C68)),'อัปเดตราคาอลู'!$F$7,IF(ISNUMBER(SEARCH("Fuji",C68)),'อัปเดตราคาอลู'!$F$5,'อัปเดตราคาอลู'!$F$4))))),3) | T68: =ROUND(P68/(IF(OR(ISNUMBER(SEARCH("เมืองทอง",C68)),ISNUMBER(SEARCH("SlimLux",C68)),ISNUMBER(SEARCH("Velora",C68))),6,6.4)),3) | U68: =ROUND(L68-D68,0) | V68: =IF(D68="","",ROUND(D68+rate_anodize*S68,0))
A69: F7952 | B69: แผ่นยึดเฟรมล่าง | C69: อลูมิเนียม Fuji | D69: 585 | E69: 625 | F69: =E69 | G69: 635 | H69: 855 | I69: 885 | J69: 875 | K69: =IF(ISNUMBER(SEARCH("เมืองทอง",C69)),mult_mtong,IF(ISNUMBER(SEARCH("SlimLux",C69)),mult_slim,IF(ISNUMBER(SEARCH("Velora",C69)),mult_velora,IF(ISNUMBER(SEARCH("Fuji",C69)),mult_euro,mult_sms)))) | L69: =ROUND(D69*K69,0) | M69: =IF(E69="",ROUND(L69+'อัปเดตราคาอลู'!$B$13*S69,0),ROUND(E69*K69,0)) | N69: =M69 | O69: =IF(G69="",ROUND(L69+rate_special*S69,0),ROUND(G69*mult_euro,0)) | P69: =IF(H69="",ROUND(L69+rate_woodbake*S69,0),ROUND(H69*mult_wood,0)) | Q69: =IF(I69="",ROUND(L69+rate_woodbake*S69,0),ROUND(I69*mult_wood,0)) | R69: =IF(J69="",ROUND(L69+rate_woodbake*S69,0),ROUND(J69*mult_wood,0)) | S69: =ROUND(D69/(IF(ISNUMBER(SEARCH("เมืองทอง",C69)),'อัปเดตราคาอลู'!$F$8,IF(ISNUMBER(SEARCH("SlimLux",C69)),'อัปเดตราคาอลู'!$F$6,IF(ISNUMBER(SEARCH("Velora",C69)),'อัปเดตราคาอลู'!$F$7,IF(ISNUMBER(SEARCH("Fuji",C69)),'อัปเดตราคาอลู'!$F$5,'อัปเดตราคาอลู'!$F$4))))),3) | T69: =ROUND(P69/(IF(OR(ISNUMBER(SEARCH("เมืองทอง",C69)),ISNUMBER(SEARCH("SlimLux",C69)),ISNUMBER(SEARCH("Velora",C69))),6,6.4)),3) | U69: =ROUND(L69-D69,0) | V69: =IF(D69="","",ROUND(D69+rate_anodize*S69,0))
A70: F7879 | B70: ตบธรณีเรียบตัวกลาง | C70: อลูมิเนียม Fuji | D70: 375 | E70: 400 | F70: =E70 | G70: 405 | H70: 560 | I70: 565 | J70: 560 | K70: =IF(ISNUMBER(SEARCH("เมืองทอง",C70)),mult_mtong,IF(ISNUMBER(SEARCH("SlimLux",C70)),mult_slim,IF(ISNUMBER(SEARCH("Velora",C70)),mult_velora,IF(ISNUMBER(SEARCH("Fuji",C70)),mult_euro,mult_sms)))) | L70: =ROUND(D70*K70,0) | M70: =IF(E70="",ROUND(L70+'อัปเดตราคาอลู'!$B$13*S70,0),ROUND(E70*K70,0)) | N70: =M70 | O70: =IF(G70="",ROUND(L70+rate_special*S70,0),ROUND(G70*mult_euro,0)) | P70: =IF(H70="",ROUND(L70+rate_woodbake*S70,0),ROUND(H70*mult_wood,0)) | Q70: =IF(I70="",ROUND(L70+rate_woodbake*S70,0),ROUND(I70*mult_wood,0)) | R70: =IF(J70="",ROUND(L70+rate_woodbake*S70,0),ROUND(J70*mult_wood,0)) | S70: =ROUND(D70/(IF(ISNUMBER(SEARCH("เมืองทอง",C70)),'อัปเดตราคาอลู'!$F$8,IF(ISNUMBER(SEARCH("SlimLux",C70)),'อัปเดตราคาอลู'!$F$6,IF(ISNUMBER(SEARCH("Velora",C70)),'อัปเดตราคาอลู'!$F$7,IF(ISNUMBER(SEARCH("Fuji",C70)),'อัปเดตราคาอลู'!$F$5,'อัปเดตราคาอลู'!$F$4))))),3) | T70: =ROUND(P70/(IF(OR(ISNUMBER(SEARCH("เมืองทอง",C70)),ISNUMBER(SEARCH("SlimLux",C70)),ISNUMBER(SEARCH("Velora",C70))),6,6.4)),3) | U70: =ROUND(L70-D70,0) | V70: =IF(D70="","",ROUND(D70+rate_anodize*S70,0))
A71: F7880 | B71: ตบธรณีเรียบตัวริม | C71: อลูมิเนียม Fuji | D71: 375 | E71: 400 | F71: =E71 | G71: 405 | H71: 560 | I71: 565 | J71: 560 | K71: =IF(ISNUMBER(SEARCH("เมืองทอง",C71)),mult_mtong,IF(ISNUMBER(SEARCH("SlimLux",C71)),mult_slim,IF(ISNUMBER(SEARCH("Velora",C71)),mult_velora,IF(ISNUMBER(SEARCH("Fuji",C71)),mult_euro,mult_sms)))) | L71: =ROUND(D71*K71,0) | M71: =IF(E71="",ROUND(L71+'อัปเดตราคาอลู'!$B$13*S71,0),ROUND(E71*K71,0)) | N71: =M71 | O71: =IF(G71="",ROUND(L71+rate_special*S71,0),ROUND(G71*mult_euro,0)) | P71: =IF(H71="",ROUND(L71+rate_woodbake*S71,0),ROUND(H71*mult_wood,0)) | Q71: =IF(I71="",ROUND(L71+rate_woodbake*S71,0),ROUND(I71*mult_wood,0)) | R71: =IF(J71="",ROUND(L71+rate_woodbake*S71,0),ROUND(J71*mult_wood,0)) | S71: =ROUND(D71/(IF(ISNUMBER(SEARCH("เมืองทอง",C71)),'อัปเดตราคาอลู'!$F$8,IF(ISNUMBER(SEARCH("SlimLux",C71)),'อัปเดตราคาอลู'!$F$6,IF(ISNUMBER(SEARCH("Velora",C71)),'อัปเดตราคาอลู'!$F$7,IF(ISNUMBER(SEARCH("Fuji",C71)),'อัปเดตราคาอลู'!$F$5,'อัปเดตราคาอลู'!$F$4))))),3) | T71: =ROUND(P71/(IF(OR(ISNUMBER(SEARCH("เมืองทอง",C71)),ISNUMBER(SEARCH("SlimLux",C71)),ISNUMBER(SEARCH("Velora",C71))),6,6.4)),3) | U71: =ROUND(L71-D71,0) | V71: =IF(D71="","",ROUND(D71+rate_anodize*S71,0))
A72: F7859 | B72: เฟรมบานกระทุ้ง ไม่มีรูระบายน้ำ | C72: อลูมิเนียม Fuji | D72: 1045 | E72: 1120 | F72: =E72 | G72: 1130 | H72: 1700 | I72: 1575 | J72: 1565 | K72: =IF(ISNUMBER(SEARCH("เมืองทอง",C72)),mult_mtong,IF(ISNUMBER(SEARCH("SlimLux",C72)),mult_slim,IF(ISNUMBER(SEARCH("Velora",C72)),mult_velora,IF(ISNUMBER(SEARCH("Fuji",C72)),mult_euro,mult_sms)))) | L72: =ROUND(D72*K72,0) | M72: =IF(E72="",ROUND(L72+'อัปเดตราคาอลู'!$B$13*S72,0),ROUND(E72*K72,0)) | N72: =M72 | O72: =IF(G72="",ROUND(L72+rate_special*S72,0),ROUND(G72*mult_euro,0)) | P72: =IF(H72="",ROUND(L72+rate_woodbake*S72,0),ROUND(H72*mult_wood,0)) | Q72: =IF(I72="",ROUND(L72+rate_woodbake*S72,0),ROUND(I72*mult_wood,0)) | R72: =IF(J72="",ROUND(L72+rate_woodbake*S72,0),ROUND(J72*mult_wood,0)) | S72: =ROUND(D72/(IF(ISNUMBER(SEARCH("เมืองทอง",C72)),'อัปเดตราคาอลู'!$F$8,IF(ISNUMBER(SEARCH("SlimLux",C72)),'อัปเดตราคาอลู'!$F$6,IF(ISNUMBER(SEARCH("Velora",C72)),'อัปเดตราคาอลู'!$F$7,IF(ISNUMBER(SEARCH("Fuji",C72)),'อัปเดตราคาอลู'!$F$5,'อัปเดตราคาอลู'!$F$4))))),3) | T72: =ROUND(P72/(IF(OR(ISNUMBER(SEARCH("เมืองทอง",C72)),ISNUMBER(SEARCH("SlimLux",C72)),ISNUMBER(SEARCH("Velora",C72))),6,6.4)),3) | U72: =ROUND(L72-D72,0) | V72: =IF(D72="","",ROUND(D72+rate_anodize*S72,0))
A73: F7858 | B73: เฟรมบานตายคิ้วไม่มีรูระบายน้ำ | C73: อลูมิเนียม Fuji | D73: 1305 | E73: 1395 | F73: =E73 | G73: 1410 | H73: 2130 | I73: 1965 | J73: 1950 | K73: =IF(ISNUMBER(SEARCH("เมืองทอง",C73)),mult_mtong,IF(ISNUMBER(SEARCH("SlimLux",C73)),mult_slim,IF(ISNUMBER(SEARCH("Velora",C73)),mult_velora,IF(ISNUMBER(SEARCH("Fuji",C73)),mult_euro,mult_sms)))) | L73: =ROUND(D73*K73,0) | M73: =IF(E73="",ROUND(L73+'อัปเดตราคาอลู'!$B$13*S73,0),ROUND(E73*K73,0)) | N73: =M73 | O73: =IF(G73="",ROUND(L73+rate_special*S73,0),ROUND(G73*mult_euro,0)) | P73: =IF(H73="",ROUND(L73+rate_woodbake*S73,0),ROUND(H73*mult_wood,0)) | Q73: =IF(I73="",ROUND(L73+rate_woodbake*S73,0),ROUND(I73*mult_wood,0)) | R73: =IF(J73="",ROUND(L73+rate_woodbake*S73,0),ROUND(J73*mult_wood,0)) | S73: =ROUND(D73/(IF(ISNUMBER(SEARCH("เมืองทอง",C73)),'อัปเดตราคาอลู'!$F$8,IF(ISNUMBER(SEARCH("SlimLux",C73)),'อัปเดตราคาอลู'!$F$6,IF(ISNUMBER(SEARCH("Velora",C73)),'อัปเดตราคาอลู'!$F$7,IF(ISNUMBER(SEARCH("Fuji",C73)),'อัปเดตราคาอลู'!$F$5,'อัปเดตราคาอลู'!$F$4))))),3) | T73: =ROUND(P73/(IF(OR(ISNUMBER(SEARCH("เมืองทอง",C73)),ISNUMBER(SEARCH("SlimLux",C73)),ISNUMBER(SEARCH("Velora",C73))),6,6.4)),3) | U73: =ROUND(L73-D73,0) | V73: =IF(D73="","",ROUND(D73+rate_anodize*S73,0))
A74: F7937 | B74: เฟรมบานตายคิ้วใน | C74: อลูมิเนียม Fuji | D74: 1200 | E74: 1290 | F74: =E74 | G74: 1300 | H74: 1875 | I74: 1815 | J74: 1800 | K74: =IF(ISNUMBER(SEARCH("เมืองทอง",C74)),mult_mtong,IF(ISNUMBER(SEARCH("SlimLux",C74)),mult_slim,IF(ISNUMBER(SEARCH("Velora",C74)),mult_velora,IF(ISNUMBER(SEARCH("Fuji",C74)),mult_euro,mult_sms)))) | L74: =ROUND(D74*K74,0) | M74: =IF(E74="",ROUND(L74+'อัปเดตราคาอลู'!$B$13*S74,0),ROUND(E74*K74,0)) | N74: =M74 | O74: =IF(G74="",ROUND(L74+rate_special*S74,0),ROUND(G74*mult_euro,0)) | P74: =IF(H74="",ROUND(L74+rate_woodbake*S74,0),ROUND(H74*mult_wood,0)) | Q74: =IF(I74="",ROUND(L74+rate_woodbake*S74,0),ROUND(I74*mult_wood,0)) | R74: =IF(J74="",ROUND(L74+rate_woodbake*S74,0),ROUND(J74*mult_wood,0)) | S74: =ROUND(D74/(IF(ISNUMBER(SEARCH("เมืองทอง",C74)),'อัปเดตราคาอลู'!$F$8,IF(ISNUMBER(SEARCH("SlimLux",C74)),'อัปเดตราคาอลู'!$F$6,IF(ISNUMBER(SEARCH("Velora",C74)),'อัปเดตราคาอลู'!$F$7,IF(ISNUMBER(SEARCH("Fuji",C74)),'อัปเดตราคาอลู'!$F$5,'อัปเดตราคาอลู'!$F$4))))),3) | T74: =ROUND(P74/(IF(OR(ISNUMBER(SEARCH("เมืองทอง",C74)),ISNUMBER(SEARCH("SlimLux",C74)),ISNUMBER(SEARCH("Velora",C74))),6,6.4)),3) | U74: =ROUND(L74-D74,0) | V74: =IF(D74="","",ROUND(D74+rate_anodize*S74,0))
...

Sheet บันทึกราคาขึ้น
A1: 📈 บันทึกราคาขึ้น — ทุน @ บานมาตรฐาน 150×150 ซม (2.25 ตร.ม.) | I1: 🏠 สารบัญ
A2: ทุก ครั้งที่อลู/กก. ขึ้น → มดเพิ่มคอลัมน์วันที่ใหม่ + %ขึ้น · ดูได้ว่าบานไหนขึ้นเท่าไหร่ + ตรวจว่าเพิ่มถูก (ทุน=วัสดุ อลู+กระจก+อุปกรณ์ ไม่รวมค่าแรง · อลูเท่านั้นที่ขึ้นตาม/กก.)
A4: ① ประวัติเรตอลู (บาท/กก.)
A5: วันที่ | B5: SMS | C5: ยูโร/Fuji | D5: SlimLux | E5: Velora | F5: เมืองทอง
A6: 25/6/69 | B6: ='อัปเดตราคาอลู'!B4 | C6: ='อัปเดตราคาอลู'!B5 | D6: ='อัปเดตราคาอลู'!B6 | E6: ='อัปเดตราคาอลู'!B7 | F6: ='อัปเดตราคาอลู'!B8
A9: ② ทุน @150×150 ต่อบาน (บาท)
A10: บาน | B10: config | C10: ทุนอลูฐาน | D10: กระจก+อุปกรณ์ | E10: ทุนรวม ปัจจุบัน (สูตร live) | F10: 25/6/69 (บันทึก) | G10: %ขึ้น
A11: บานเลื่อน SMS | B11: 2 บาน | C11: 7365 | D11: 1881 | E11: =ROUND(C11*mult_sms+D11,0) | F11: 9246 | G11: ฐาน
A12: บานเลื่อน ยูโร | B12: 2 บาน | C12: 11220 | D12: 2145 | E12: =ROUND(C12*mult_euro+D12,0) | F12: 13365 | G12: ฐาน
A13: บานเลื่อน SlimLux | B13: 2 บาน | C13: 5968 | D13: 6953 | E13: =ROUND(C13*mult_slim+D13,0) | F13: 12921 | G13: ฐาน
A14: บานเลื่อน Velora | B14: 2 บาน | C14: 2207 | D14: 3263 | E14: =ROUND(C14*mult_velora+D14,0) | F14: 5470 | G14: ฐาน
A15: บานเลื่อน E-series | B15: 2 บาน | C15: 11158 | D15: 1527 | E15: =ROUND(C15*mult_sms+D15,0) | F15: 12685 | G15: ฐาน
A16: บานเปิด (ยูโร) | B16: 2 บาน | C16: 8560 | D16: 3255 | E16: =ROUND(C16*mult_euro+D16,0) | F16: 11815 | G16: ฐาน
A17: PC Door | B17: 1 บาน | C17: 5430 | D17: 3044 | E17: =ROUND(C17*mult_euro+D17,0) | F17: 8474 | G17: ฐาน
A18: บานกระทุ้ง | B18: 1 บาน | C18: 4340 | D18: 1924 | E18: =ROUND(C18*mult_euro+D18,0) | F18: 6264 | G18: ฐาน
A19: บานยก | B19: 1 บาน | C19: 5005 | D19: 3419 | E19: =ROUND(C19*mult_euro+D19,0) | F19: 8424 | G19: ฐาน
A20: บานเฟี้ยม | B20: 4 บาน | C20: 10470 | D20: 6807 | E20: =ROUND(C20*mult_euro+D20,0) | F20: 17277 | G20: ฐาน
A21: เฟี้ยมยูโร | B21: 4 บาน | C21: 13294 | D21: 2917 | E21: =ROUND(C21*mult_euro+D21,0) | F21: 16211 | G21: ฐาน
A22: บานติดตาย | B22: - | C22: 3240 | D22: 764 | E22: =ROUND(C22*mult_mtong+D22,0) | F22: 4004 | G22: ฐาน
A23: ตายดัดโค้ง | B23: - | C23: 0 | D23: 5100 | E23: =ROUND(C23*mult_mtong+D23,0) | F23: 5100 | G23: ฐาน
A24: เปิดดัดโค้ง | B24: 2 บาน | C24: 0 | D24: 28077 | E24: =ROUND(C24*mult_mtong+D24,0) | F24: 28077 | G24: ฐาน
A25: บานเลื่อนรางบน | B25: 2 บาน | C25: 4770 | D25: 7803 | E25: =ROUND(2990*mult_mtong+1780*mult_sms+D25,0) | F25: 12573 | G25: ฐาน
A27: 🔧 วิธีเพิ่มรอบใหม่เมื่ออลูขึ้น:
A28: 1) แก้ราคา/กก. ที่ชีท "อัปเดตราคาอลู" → ช่อง "ทุนรวม ปัจจุบัน(สูตร)" ขยับเอง
A29: 2) มดเพิ่ม 2 คอลัมน์ใหม่ (วันที่ + %ขึ้น) คัดค่าจากช่องสูตร + เพิ่มแถวเรตใน ① → ได้ประวัติว่าบานไหนขึ้นเท่าไหร่
A30: หมายเหตุ: ตายดัดโค้ง/เปิดดัดโค้ง อลูตั้งราคาตายตัว ไม่ขึ้นตาม/กก. · รางบน/เฟี้ยม สูตร live ประมาณ (เลขเป๊ะดูคอลัมน์บันทึกวันที่)
A32: ⚠️ ทุนอลูฐาน(ส้ม)/กระจก+อุปกรณ์(เทา) = ค่าคงที่ @150×150 · ทุนรวม(เขียว) = อลูฐาน×ตัวคูณ + อื่นๆ → ขึ้นเองเมื่อ/กก.ขึ้น

Sheet ราคางานเสริม
A1: ⚠️ แก้ราคาที่นี่ → 📋 ราคาวัสดุงานเสริม — แก้ราคาที่นี่ที่เดียว (ช่องเหลือง) · ทุกชีทดึงไปใช้อัตโนมัติ | G1: 🏠 สารบัญ
A3: ▶ ฝ้ายิปซัม
A4: งาน | B4: วัสดุ | C4: หน่วย | D4: ราคา (บาท)
A5: ฝ้ายิปซัม | B5: แผ่นยิปซัม 9มม | C5: แผ่น | D5: 284
A6: ฝ้ายิปซัม | B6: โครงซีไลน์ (ฟิวริ่ง) | C6: เส้น | D6: 50
A7: ฝ้ายิปซัม | B7: โครงเคร่าหลัก (อาบ) | C7: เส้น | D7: 50
A8: ฝ้ายิปซัม | B8: ขาแขวน | C8: เส้น | D8: 50
A9: ฝ้ายิปซัม | B9: สกรูยึดแผ่น | C9: ตัว | D9: 0.5
A10: ฝ้ายิปซัม | B10: สกรูยึดโครง | C10: ตัว | D10: 0.5
A11: ฝ้ายิปซัม | B11: ปูนฉาบรอยต่อ | C11: ถุง | D11: 240
A12: ฝ้ายิปซัม | B12: เทป/ตาข่าย | C12: ม้วน | D12: 70
A13: ฝ้ายิปซัม | B13: ฉากโอบ อลู 4หุน | C13: เส้น | D13: 70
A14: ฝ้ายิปซัม | B14: ฉนวน rockwool 3" | C14: แผ่น | D14: 130
A15: ▶ งานไฟ
A16: งาน | B16: วัสดุ | C16: หน่วย | D16: ราคา (บาท)
A17: งานไฟ | B17: ไฟดาวน์ไลท์ | C17: ดวง | D17: 117
A18: งานไฟ | B18: เต้ารับ+หน้ากาก | C18: จุด | D18: 105
A19: งานไฟ | B19: สวิตช์+หน้ากาก | C19: จุด | D19: 45
A20: งานไฟ | B20: กล่องไฟ | C20: กล่อง | D20: 35
A21: งานไฟ | B21: สายไฟ THW/VAF | C21: เมตร | D21: 25
A22: งานไฟ | B22: ท่อ PVC+ข้อต่อ | C22: เมตร | D22: 6.6666667
A23: งานไฟ | B23: เทป+เบ็ดเตล็ด | C23: งาน | D23: 400
A24: ▶ สมาร์ทบอร์ด
A25: งาน | B25: วัสดุ | C25: หน่วย | D25: ราคา (บาท)
A26: สมาร์ทบอร์ด | B26: แผ่นสมาร์ทบอร์ด 12มม | C26: แผ่น | D26: 500
A27: สมาร์ทบอร์ด | B27: โครงเหล็กกรอบ 1½×3" | C27: เส้น | D27: 440
A28: สมาร์ทบอร์ด | B28: ซีไลน์ 3" ดิ่ง | C28: เส้น | D28: 62
A29: สมาร์ทบอร์ด | B29: ซีไลน์ 3" นอน | C29: เส้น | D29: 62
A30: สมาร์ทบอร์ด | B30: ฉนวน 3" | C30: แผ่น | D30: 130
A31: สมาร์ทบอร์ด | B31: สกรูยึดแผ่น | C31: ตัว | D31: 0.5
A32: สมาร์ทบอร์ด | B32: สกรูยึดโครง | C32: ตัว | D32: 0.5
A33: สมาร์ทบอร์ด | B33: ปูนฉาบรอยต่อ | C33: ถุง | D33: 240
A34: สมาร์ทบอร์ด | B34: เทป/ตาข่าย | C34: ม้วน | D34: 70
A35: ▶ ไอโซวอล
A36: งาน | B36: วัสดุ | C36: หน่วย | D36: ราคา (บาท)
A37: ไอโซวอล | B37: แผ่นไอโซวอล ≤2.4ม | C37: แผ่น | D37: 2016
A38: ไอโซวอล | B38: แผ่นไอโซวอล >2.4ม | C38: แผ่น | D38: 2520
A39: ไอโซวอล | B39: กล่อง 1.6×4" โครงรอบ | C39: เส้น | D39: 1220
A40: ไอโซวอล | B40: ฉาก 4หุน | C40: เส้น | D40: 70
A41: ไอโซวอล | B41: สกรู/รีเวท | C41: งาน | D41: 50
...

Sheet ราคาออโต้
A1: ⚠️ แก้ราคาที่นี่ → ราคาออโต้/มอเตอร์ (ทุน) — มดอัปเดตที่นี่ที่เดียว · ชีทบานติ๊กเลือกแล้วดึงมาใช้ | G1: 🏠 สารบัญ
A2: หมวด/บาน | B2: รุ่น/รายการ | C2: ราคา | D2: ค่าส่ง | E2: หน่วย/เงื่อนไข
A3: บานยก / เฟี้ยมยก | B3: ยก 80 กก. | C3: 4500 | D3: 1700
B4: ยก 300 กก. | C4: 12500 | D4: 1700
A5: หลังคาเลื่อน | B5: 80 กก. | C5: 4500 | D5: 1700
B6: 300 กก. | C6: 12500 | D6: 1700
B7: 1500 กก. | C7: 13325 | D7: 1700 | E7: มีฟันเฟือง+เซนเซอร์
B8: ฟันเฟือง (เฉพาะ1500) | C8: 340 | E8: บาท/ม. × ระยะยื่น
B9: เซนเซอร์กันฝน (ออป,1500) | C9: 1100 | E9: ออปชั่น
A10: บานเกล็ด 38.1 | B10: มอเตอร์บานเกล็ด | C10: 1800 | E10: ไม่มีค่าส่ง
A11: ระแนงหมุน | B11: มอเตอร์ระแนงหมุน | C11: 1800 | E11: รวมส่งแล้ว
A12: บานกระทุ้ง | B12: โช็ค เปิด 50 | C12: 3575 | D12: 1700 | E12: 2 ตัว→+อุปกรณ์พิเศษ
B13: โช็ค เปิด 80 | C13: 3725 | D13: 1700 | E13: 2 ตัว→+อุปกรณ์พิเศษ
B14: โซ่เดี่ยว 50 | C14: 1900 | D14: 1700
B15: โซ่คู่ 50 | C15: 2600 | D15: 1700
B16: อุปกรณ์พิเศษ (โช็ค 2 ตัว) | C16: 600 | E16: บวกเมื่อใช้ 2 ตัว
A17: เลื่อน SMS/ยูโร | B17: Evecca (จีน) | C17: 13480 | D17: 1700 | E17: 1 บาน
B18: สายพาน Evecca | C18: 75 | E18: บาท/ม. = กว้างช่อง×2
B19: ออป Smart lock | C19: 6500 | E19: ออปชั่น Evecca
B20: ช่างแซก | C20: 8000 | E20: ไม่มีค่าส่ง
B21: เซฟตี้ตาแมว (บังคับช่างแซก) | C21: 1000 | E21: บวกทุกชุดช่างแซก
B22: ราง ช่างแซก | C22: 950 | E22: บาท/ม. = กว้างช่อง
B23: ออป Touch Switch (ช่างแซก) | C23: 1000 | E23: ออปชั่น
B24: ออป Infrared (ช่างแซก) | C24: 9000 | E24: ออปชั่น
A25: SlimLux | B25: ชุด SlimLux (บานแรก) | C25: 6900 | D25: 1700 | E25: บานแรก
B26: บานเพิ่ม | C26: 2250 | E26: บาท/บานเพิ่ม
B27: ราง SlimLux | C27: 1100 | E27: บาท/ม. = กว้างช่อง×จำนวนบาน
B28: ออป สแกนหน้า (บังคับเลือก1) | C28: 2750 | E28: เลือก 1 ใน 2
B29: ออป Touch Switch (บังคับเลือก1) | C29: 100 | E29: เลือก 1 ใน 2

Sheet ราคาวัสดุ
A1: ⚠️ แก้ราคาที่นี่ → 📋 ราคาวัสดุกลาง — แก้ที่นี่ที่เดียวเมื่อราคาขึ้น | F1: 🏠 สารบัญ | G1: อลูเมืองทองขึ้นราคา? แก้ที่ชีท "อัปเดตราคาอลู" ช่องเมืองทอง (บาท/กก.) → จันทัน/แป/ฉาก/แซด/คาน ขยับเอง
A2: โปรไฟล์อลูมิเนียม (เส้นยาว 6 ม.) | G2: ◀ ราคาอลู (บาท/กก.) · เหล็กแก้ราคา/เส้น ในตารางเลย (สีเหลือง) | H2: 180
B3: วัสดุ | C3: หน่วย | D3: ราคา (บาท) | E3: หมายเหตุ | F3: ราคาฐาน | I3: น้ำหนัก/เส้น(กก.)
B4: กล่อง 1.6"×4" | C4: เส้น | D4: =ROUND(F4*mult_mtong,0) | E4: แกนหลัก / จันทัน | F4: 1220 | I4: =ROUND(F4/180,3)
B5: กล่อง 1.6"×1.6" | C5: เส้น | D5: =ROUND(F5*mult_mtong,0) | E5: แป — แปเดี่ยว | F5: 770 | I5: =ROUND(F5/180,3)
B6: กล่อง 1"×1½" | C6: เส้น | D6: =ROUND(F6*mult_mtong,0) | E6: แป — แปคู่ | F6: 393 | I6: =ROUND(F6/180,3)
B7: ฉาก 6 หุน | C7: เส้น | D7: =ROUND(F7*mult_mtong,0) | E7: ยึดติดผนัง | F7: 140 | I7: =ROUND(F7/180,3)
B8: แซด 4" | C8: เส้น | D8: =ROUND(F8*mult_mtong,0) | E8: ร่องน้ำ / ขอบ | F8: 140 | I8: =ROUND(F8/180,3)
B9: กล่องเหล็ก 1"×1" | C9: เส้น | D9: ='ราคาเหล็ก'!D4 | E9: เสริมโครง | F9: 170
B10: เพลทเหล็ก | C10: แผ่น | D10: 15 | E10: ยึดด้านหลัง | F10: 15
B11: กล่อง 4"×4" | C11: เส้น | D11: =ROUND(2208*mult_mtong,0) | E11: คาน T หลังคาจั่ว | F11: 2208
A12: วัสดุปิดผิว
B13: วัสดุ | C13: หน่วย | D13: ราคา (บาท) | E13: หมายเหตุ
B14: ไวนิล | C14: แผ่น (7 ม.) | D14: 1540 | E14: จันทันห่าง ≤100 ซม.
B15: ฝาครอบไวนิล | C15: เส้น (7 ม.) | D15: 245 | E15: 1 เส้น/แผ่นไวนิล
B16: ดีไลท์ | C16: แผ่น (6 ม.) | D16: 4700 | E16: ฝาครอบแถมฟรี
B17: โพลีตัน | C17: เมตร | D17: 1200 | E17: จันทันห่าง ≤122 ซม.
B18: ตัวครอบโพลีตัน | C18: จุด/จันทัน | D18: 420 | E18: 1 จุดต่อ 1 จันทัน
B19: ชินโคร์ไลท์ Heat Cut | C19: ตร.ม. | D19: 2800 | E19: รวมฝาครอบ
B20: ชินโคร์ไลท์ Superior | C20: ตร.ม. | D20: 2100 | E20: รวมฝาครอบ
B21: เมทัลชีท PU 2" Snap | C21: ตร.ม. | D21: 2200 | E21: จันทันห่าง ≤100 ซม.
B22: กระจกลามิเนต 4+4 | C22: ตร.ม. | D22: 1065 | E22: ฟิล์มเขียว/ใส 0.38
B23: กระจกลามิเนต 5+5 | C23: ตร.ม. | D23: 1270 | E23: ฟิล์มเขียว/ใส 0.38
B24: ชินโคร์ Shade 4มม. | C24: ตร.ม. | D24: 1050 | E24: กว้าง 1.38ม. · CPP 01-05-69
B25: ชินโคร์ Prime 10มม. | C25: ตร.ม. | D25: 4348 | E25: กว้าง 1.38ม. · N828/562
B26: รางหลังคาเลื่อน | C26: เส้น | D26: 4080
B27: เมทัลชีท EPS 2" | C27: ตร.ม. | D27: 1400 | E27: จันทันห่าง ไม่เกิน 100 ซม.

Sheet ราคาเหล็ก
A1: ⚠️ แก้ราคาที่นี่ → ราคาเหล็กกล่อง (เส้นยาว 6 ม.) — แก้ช่อง "ราคา/เส้น" เมื่อเหล็กขึ้น
A2: เหล็กกล่อง (โครงหลังคา / รั้ว / โครงเสริม)
A3: รายการ | B3: ขนาด (นิ้ว) | C3: ยาว/เส้น (ม.) | D3: ราคา/เส้น (บาท) | E3: ราคา/เมตร (บาท)
A4: กล่องเหล็ก | B4: 1"×1" | C4: 6 | D4: 170 | E4: =ROUND(D4/C4,2)
A5: กล่องเหล็ก | B5: 1½"×3" | C5: 6 | D5: 460 | E5: =ROUND(D5/C5,2)
