Workbook
Name buf_roof: อัปเดตราคาอลู!$B$23
Name buf_scrap: อัปเดตราคาอลู!$B$22
Name ClothList: ราคามุ้ง!$I$2:$I$5
Name GlassNames: ราคากระจก!$A$3:$A$112
Name mult_euro: อัปเดตราคาอลู!$C$5
Name mult_mtong: อัปเดตราคาอลู!$C$8
Name mult_slim: อัปเดตราคาอลู!$C$6
Name mult_sms: อัปเดตราคาอลู!$C$4
Name mult_velora: อัปเดตราคาอลู!$C$7
Name mult_wood: อัปเดตราคาอลู!$C$20
Name MungList: ราคามุ้ง!$G$1:$G$15
Name MungReady: ราคามุ้ง!$G$1:$G$12
Name rate_anodize: อัปเดตราคาอลู!$B$18
Name rate_grey: อัปเดตราคาอลู!$B$13
Name rate_special: อัปเดตราคาอลู!$B$14
Name rate_woodbake: อัปเดตราคาอลู!$B$15
Name rate_woodstock: อัปเดตราคาอลู!$B$16
Name SlimLuxGlass: 'คิดทุน SlimLux'!$AA$1:$AA$21

Sheet สารบัญ
B1: 📑 สารบัญ — กดลิงก์กระโดดไปหน้าที่ต้องการ
B2: 🟡 เหลือง = แก้ราคาที่นี่ (แก้แล้วทุกชีทขยับเอง) ⬜ เทา = ดูอย่างเดียว ห้ามแก้
B3: 🔶 ปรับราคา / ค่าวัสดุ — 🟡 เหลือง = แก้ราคาที่นี่ ทุกชีทขยับเอง
B4: ▶ อัปเดตราคาอลู | C4: ราคาอลู/กก. ทุกแบรนด์ + ค่าอบสี ★
B5: ▶ ราคาสี | C5: ราคาสีอบ / เทาซาฮาร่า / ลายไม้ — ราคา/เส้น
B6: ▶ ราคากระจก | C6: ราคากระจก 105 รุ่น (ทุน/ตร.ม.) + ประวัติราคาอยู่ด้านล่าง ★
B7: ▶ ราคาหลังคา | C7: แผ่นหลังคา ไวนิล/ดีไลท์/โพลีตัน/ชินโคร์/เมทัลชีท + ราง
B8: ▶ ราคาออโต้ | C8: มอเตอร์ / ชุดออโต้
B9: ▶ ราคามุ้ง | C9: มุ้งซื้อสำเร็จ + ค่าแรงติดตั้ง
B10: ▶ ราคาเหล็ก | C10: เหล็กกล่อง / ยูเหล็ก
B11: ▶ ราคางานเสริม | C11: งานเสริม ฝ้า/ผนัง/ไฟ
B12: ▶ ค่าแรง | C12: ค่าแรงผลิต + ติดตั้ง ทุกแบบ ★
B13: ▶ น้ำหนักโปรไฟล์ | C13: น้ำหนัก กก./เส้น ทุกโปรไฟล์
B14: ▶ ชีทอุปกรณ์ | C14: ราคาอุปกรณ์กลาง (บานพับ/ล้อ/มือจับ)
B15: ▶ ราคาฝ้าไม้เทียม | C15: ราคาฝ้าไม้เทียม 24 รุ่น 4 ร้าน
B16: ▶ บันทึกราคาขึ้น | C16: ประวัติการขึ้นราคา — 👁 ดูอย่างเดียว ไม่ใช่หน้าแก้ราคา
B18: 📊 สรุป / ภาพรวม
B19: ▶ หน้าตารางรวม | D19: ▶ สรุปงานเสริม | F19: ▶ สรุปค่าแรง
B21: 🚪 คิดทุน — ประตู / หน้าต่าง / บาน
B22: ▶ SMS | D22: ▶ ยูโร | F22: ▶ SlimLux
B23: ▶ Velora | D23: ▶ E-series | F23: ▶ PC Door
B24: ▶ บานเปิด | D24: ▶ กระทุ้ง | F24: ▶ บานยก
B25: ▶ บานหมุน | D25: ▶ บานเลื่อนรางบน | F25: ▶ บานระแนงเลื่อน
B26: ▶ เฟี้ยม | D26: ▶ เฟี้ยมยูโร | F26: ▶ เฟี้ยมยก
B27: ▶ ติดตาย | D27: ▶ บานโซลิด | F27: ▶ บานเปลือย
B28: ▶ บานตู้ Futuretech | D28: ▶ ชุด Shower | F28: ▶ ราวกันตก
B29: ▶ YKK / Tostem (บานสำเร็จ)
B31: 🌀 คิดทุน — ดัดโค้ง
B32: ▶ ตายดัดโค้ง | D32: ▶ เปิดดัดโค้ง
B34: ▦ คิดทุน — ระแนง / ประตูรั้ว
B35: ▶ ระแนง | D35: ▶ ระแนงสลับ | F35: ▶ ระแนงสลับ_ประตู
B36: ▶ ประตูรั้ว | D36: ▶ บานเกล็ด | F36: ▶ ระแนงหมุน
B38: 🏠 คิดทุน — หลังคา
B39: ▶ หลังคา (รวม) | D39: ▶ หลังคา 🔒 | F39: ▶ หลังคาจั่ว 🔒
B40: ▶ หลังคาเลื่อน 🔒
B42: 🧱 คิดทุน — ฝ้า / ผนัง / พื้น / งานไฟ
B43: ▶ ฝ้ายิปซัม | D43: ▶ ฝ้าไม้เทียม | F43: ▶ สีฝ้าไม้เทียม
B44: ▶ สมาร์ทบอร์ด | D44: ▶ สมาร์ทบอร์ดพื้น | F44: ▶ ไอโซวอล
B45: ▶ งานไฟ
B47: 📐 เทียบราคา / ตรวจสอบ
...

Sheet อัปเดตราคาอลู
A1: ⚠️ แก้ราคาที่นี่ → 📈 อัปเดตราคาวัสดุ — กรอก "ราคา/กก. ตอนนี้" ทับเมื่อราคาขึ้น (วิธีที่ 1) | G1: 🏠 สารบัญ
A2: วันที่อัปเดตล่าสุด → | B2: 24/8/69 | C2: พิมพ์วันที่ทุกครั้งที่แก้ราคา/กก. → ชีทบันทึกราคาขึ้นดึงไปแสดงเอง
A3: แบรนด์ | B3: ราคาอลู/กก. ตอนนี้ | C3: ตัวคูณ | D3: ครอบคลุมบาน | F3: ตั้งต้น (ล็อก-อย่าแก้)
A4: SMS | B4: 187 | C4: =B4/F4 -> 1 | D4: SMS · E-series · บานเลื่อนรางบน · บานระแนงเลื่อน | F4: 187
A5: ยูโรฟูจิ | B5: 187 | C5: =B5/F5 -> 1 | D5: ยูโร · บานเปิด · บานหมุน · กระทุ้ง · เฟี้ยม · เฟี้ยมยูโร · เฟี้ยมยก · PC Door · บานยก · บานโซลิด | F5: 187
A6: SlimLux | B6: 164 | C6: =B6/F6 -> 1 | D6: SlimLux (อย่างเดียว) | F6: 164 | G6: ตั้งต้นคิดจากใบ KOYO: (764.8+480+272+284.8+868.8+84.8) ÷ 16.836 กก. = 163.7
A7: Velora | B7: 230 | C7: =B7/F7 -> 1 | D7: Velora (อย่างเดียว) | F7: 230 | G7: ตั้งต้นคิดจากใบ KOYO: (768+720) ÷ 6.462 กก. = 230.3
A8: เมืองทอง (กล่อง/ฉาก/Z) | B8: 188 | C8: =B8/F8 -> 1 | D8: ระแนง · ระแนงหมุน · ประตูรั้ว · บานเกล็ด · ติดตาย · บานเลื่อนรางบน · หลังคาทุกชีท · ลูกฟูก (บานโซลิด/บานระแนงเลื่อน) | F8: 188
A10: วิธีใช้: ร้านอลูขึ้นราคา → พิมพ์ราคา/กก. ใหม่ทับช่อง B (เช่น เมืองทอง 188→196) → ทุกโปรไฟล์แบรนด์นั้นขยับ % เท่ากันอัตโนมัติ
A12: ค่าอบสี / ลายไม้ — ราคา บาท/กก. (กรอกทับเมื่อขึ้น · ชุดเดียวทุกแบรนด์)
A13: เทาซาฮาร่า | B13: 100 | C13: ค่าอบเทา 100/กก. (ไม่มีค่าล้างสี)
A14: สีอบพิเศษ | B14: 173 | C14: 138 ค่าอบ + 35 ค่าล้างสี (พี่นัทเคาะ 18 มิ.ย.)
A15: สีลายไม้อบพิเศษ | B15: 190 | C15: 155 ค่าอบ + 35 ค่าล้างสี (พี่นัทเคาะ 18 มิ.ย.)
A16: ลายไม้ stock | B16: 112.5 | C16: factor กล่องเมืองทอง · SMS/ยูโร ลายไม้=ราคาตรงต่อเส้น
A17: ค่าเปิดตู้อบ | B17: 2000 | C17: บาท/งาน · เฉพาะสีอบพิเศษ/ลายไม้อบพิเศษ (คงที่ ไม่ขึ้นตาม กก.) · แก้ที่เดียว ทุกชีทขยับ
A18: ค่าชุบเหมา (อโนไดซ์) | B18: 200 | C18: บาท/กก. · บวกบนราคาขาว-ดำ · แก้ที่เดียว
A19: ── ตัวคูณลายไม้สต็อค (เส้น SMS/ยูโร) — แยกจากเนื้ออลู ──
A20: ลายไม้สต็อค บาท/กก. | B20: 277 | C20: =B20/F20 -> 1 | D20: ตอนนี้ 277 (ของจริง) ÷ ตั้งต้น 258 (ที่ฝังไว้) = ตัวคูณลายไม้ | F20: 277
A22: เผื่อเศษอลู (× ตัดเท่าไหร่คิดเท่านั้น) | B22: 1.3 | C22: แก้ที่เดียว · 1.30 = เผื่อเศษ 30%
A23: เผื่อเศษแผ่นหลังคา (ตัดเสีย/ซ้อนแผ่น) | B23: 1.2 | C23: 1.20 = เผื่อเศษ 20% · ใช้กับแผ่นหลังคาทุกชนิด — แก้ที่นี่ที่เดียว

Sheet ราคาสี
A1: ⚠️ แก้ราคาที่นี่ → ราคาสี/เส้น (จาก Stock.xlsx · ลายไม้เอา max กับที่น้องพิมพ์) — อบพิเศษ/ลายไม้พิเศษ คิดสูตร base+ค่าอบ×นน. · เพิ่มเมืองทอง/SlimLux/Velora/E-series (ราคาประเมิน นน×เรต+ค่าอบ) | K1: ⬛ ช่องเทา = ไม่มีสีนั้นขาย (ถ้าจะใช้ ให้เลือก "สีอบพิเศษ" ในดรอปดาวน์หน้าคิดทุน ระบบคิดค่าอบให้เอง) | L1: ⬅ คอลัมน์นี้บอกว่าราคาแถวนั้นถูกชีทไหนดึงไปใช้ · แถวสีแดง = ยังไม่มีชีทคิดทุนใช้ (แก้ไปก็ไม่มีอะไรขยับ) | M1: ⬇ ราคาปัจจุบัน (คิดตัวคูณจากหน้า "อัปเดตราคาอลู" ให้แล้ว) — ช่องเทา ห้ามพิมพ์ทับ · พิมพ์ราคา/กก. ใหม่ที่หน้าอัปเดตราคาอลู แล้วตัวเลขชุดนี้ขยับเอง
A2: รหัส | B2: ชื่อ | C2: ระบบ | D2: ขาว/ดำ | E2: เทาซาฮาร่า | F2: ดำซาฮาร่า | G2: แอทแทคเกรย์ | H2: ลายไม้สต็อค | I2: ลายไม้ มะฮอกกานี | J2: ลายไม้ ไวท์โอ๊ค | L2: ใช้ในชีทไหน | M2: ขาว/ดำ ตอนนี้ | N2: เทาซาฮาร่า ตอนนี้ | O2: ดำซาฮาร่า ตอนนี้ | P2: แอทแทคเกรย์ ตอนนี้ | Q2: ลายไม้สต็อค ตอนนี้ | R2: มะฮอกกานี ตอนนี้ | S2: ไวท์โอ๊ค ตอนนี้ | T2: ตัวคูณ
A3: B20001 | B3: เฟรมบนบานเลื่อน | C3: อลูมิเนียม sms | D3: 1265 | E3: 1375 | F3: =E3 -> 1375 | H3: 2050 | K3: หนา 1.5 มม. — KC SMS 16-05-26 | L3: SMS | M3: =IF($D$3="","",ROUND($D$3*mult_sms,0)) -> 1265 | N3: =IF($E$3="","",ROUND($E$3*mult_sms,0)) -> 1375 | O3: =IF($F$3="","",ROUND($F$3*mult_sms,0)) -> 1375 | P3: =IF($G$3="","",ROUND($G$3*mult_sms,0)) | Q3: =IF($H$3="","",ROUND($H$3*mult_wood,0)) -> 2050 | R3: =IF($I$3="","",ROUND($I$3*mult_wood,0)) | S3: =IF($J$3="","",ROUND($J$3*mult_wood,0)) | T3: =mult_sms -> 1
A4: B20002 | B4: เฟรมล่างบานเลื่อน | C4: อลูมิเนียม sms | D4: 1205 | E4: 1310 | F4: =E4 -> 1310 | H4: 1925 | L4: 🚫 เลิกใช้แล้ว — ของเดิม (บานเลื่อน 2 ราง) ไม่ต้องแก้ราคา | M4: =IF($D$4="","",ROUND($D$4*mult_sms,0)) -> 1205 | N4: =IF($E$4="","",ROUND($E$4*mult_sms,0)) -> 1310 | O4: =IF($F$4="","",ROUND($F$4*mult_sms,0)) -> 1310 | P4: =IF($G$4="","",ROUND($G$4*mult_sms,0)) | Q4: =IF($H$4="","",ROUND($H$4*mult_wood,0)) -> 1925 | R4: =IF($I$4="","",ROUND($I$4*mult_wood,0)) | S4: =IF($J$4="","",ROUND($J$4*mult_wood,0)) | T4: =mult_sms -> 1
A5: B20003 | B5: เฟรมข้างบานเลื่อน | C5: อลูมิเนียม sms | D5: 990 | E5: 1080 | F5: =E5 -> 1080 | H5: 1585 | K5: หนา 1.5 มม. — KC SMS 16-05-26 | L5: SMS | M5: =IF($D$5="","",ROUND($D$5*mult_sms,0)) -> 990 | N5: =IF($E$5="","",ROUND($E$5*mult_sms,0)) -> 1080 | O5: =IF($F$5="","",ROUND($F$5*mult_sms,0)) -> 1080 | P5: =IF($G$5="","",ROUND($G$5*mult_sms,0)) | Q5: =IF($H$5="","",ROUND($H$5*mult_wood,0)) -> 1585 | R5: =IF($I$5="","",ROUND($I$5*mult_wood,0)) | S5: =IF($J$5="","",ROUND($J$5*mult_wood,0)) | T5: =mult_sms -> 1
A6: B20004 | B6: เฟรมบนเสริมร่องกระจก | C6: อลูมิเนียม sms | D6: 870 | E6: 950 | F6: =E6 -> 950 | H6: 1395 | L6: ⚠️ ยังไม่มีชีทคิดทุนใช้ (เก็บเป็นราคาอ้างอิง) | M6: =IF($D$6="","",ROUND($D$6*mult_sms,0)) -> 870 | N6: =IF($E$6="","",ROUND($E$6*mult_sms,0)) -> 950 | O6: =IF($F$6="","",ROUND($F$6*mult_sms,0)) -> 950 | P6: =IF($G$6="","",ROUND($G$6*mult_sms,0)) | Q6: =IF($H$6="","",ROUND($H$6*mult_wood,0)) -> 1395 | R6: =IF($I$6="","",ROUND($I$6*mult_wood,0)) | S6: =IF($J$6="","",ROUND($J$6*mult_wood,0)) | T6: =mult_sms -> 1
A7: B20007 | B7: เสากุญแจ (ตูดตัน) | C7: อลูมิเนียม sms | D7: 660 | E7: 725 | F7: =E7 -> 725 | H7: 1065 | L7: ⚠️ ยังไม่มีชีทคิดทุนใช้ (เก็บเป็นราคาอ้างอิง) | M7: =IF($D$7="","",ROUND($D$7*mult_sms,0)) -> 660 | N7: =IF($E$7="","",ROUND($E$7*mult_sms,0)) -> 725 | O7: =IF($F$7="","",ROUND($F$7*mult_sms,0)) -> 725 | P7: =IF($G$7="","",ROUND($G$7*mult_sms,0)) | Q7: =IF($H$7="","",ROUND($H$7*mult_wood,0)) -> 1065 | R7: =IF($I$7="","",ROUND($I$7*mult_wood,0)) | S7: =IF($J$7="","",ROUND($J$7*mult_wood,0)) | T7: =mult_sms -> 1
A8: B20008 | B8: เสากุญแจแบบรับแรง | C8: อลูมิเนียม sms | D8: 1125 | E8: 1225 | F8: =E8 -> 1225 | H8: 1800 | L8: ⚠️ ยังไม่มีชีทคิดทุนใช้ (เก็บเป็นราคาอ้างอิง) | M8: =IF($D$8="","",ROUND($D$8*mult_sms,0)) -> 1125 | N8: =IF($E$8="","",ROUND($E$8*mult_sms,0)) -> 1225 | O8: =IF($F$8="","",ROUND($F$8*mult_sms,0)) -> 1225 | P8: =IF($G$8="","",ROUND($G$8*mult_sms,0)) | Q8: =IF($H$8="","",ROUND($H$8*mult_wood,0)) -> 1800 | R8: =IF($I$8="","",ROUND($I$8*mult_wood,0)) | S8: =IF($J$8="","",ROUND($J$8*mult_wood,0)) | T8: =mult_sms -> 1
A9: B20009 | B9: เสาเกี่ยว (ธรรมดา) | C9: อลูมิเนียม sms | D9: 690 | E9: 750 | F9: =E9 -> 750 | H9: 1105 | L9: SMS · บานระแนงเลื่อน | M9: =IF($D$9="","",ROUND($D$9*mult_sms,0)) -> 690 | N9: =IF($E$9="","",ROUND($E$9*mult_sms,0)) -> 750 | O9: =IF($F$9="","",ROUND($F$9*mult_sms,0)) -> 750 | P9: =IF($G$9="","",ROUND($G$9*mult_sms,0)) | Q9: =IF($H$9="","",ROUND($H$9*mult_wood,0)) -> 1105 | R9: =IF($I$9="","",ROUND($I$9*mult_wood,0)) | S9: =IF($J$9="","",ROUND($J$9*mult_wood,0)) | T9: =mult_sms -> 1
A10: B20010 | B10: เสาเกี่ยวนอก (สูง 2.4 m) | C10: อลูมิเนียม sms | D10: 1235 | E10: 1345 | F10: =E10 -> 1345 | H10: 1975 | L10: SMS · บานระแนงเลื่อน | M10: =IF($D$10="","",ROUND($D$10*mult_sms,0)) -> 1235 | N10: =IF($E$10="","",ROUND($E$10*mult_sms,0)) -> 1345 | O10: =IF($F$10="","",ROUND($F$10*mult_sms,0)) -> 1345 | P10: =IF($G$10="","",ROUND($G$10*mult_sms,0)) | Q10: =IF($H$10="","",ROUND($H$10*mult_wood,0)) -> 1975 | R10: =IF($I$10="","",ROUND($I$10*mult_wood,0)) | S10: =IF($J$10="","",ROUND($J$10*mult_wood,0)) | T10: =mult_sms -> 1
A11: B20019 | B11: ฝาปิดเฟรมข้าง | C11: อลูมิเนียม sms | D11: 175 | E11: 190 | F11: =E11 -> 190 | H11: 280 | L11: SMS · บานระแนงเลื่อน | M11: =IF($D$11="","",ROUND($D$11*mult_sms,0)) -> 175 | N11: =IF($E$11="","",ROUND($E$11*mult_sms,0)) -> 190 | O11: =IF($F$11="","",ROUND($F$11*mult_sms,0)) -> 190 | P11: =IF($G$11="","",ROUND($G$11*mult_sms,0)) | Q11: =IF($H$11="","",ROUND($H$11*mult_wood,0)) -> 280 | R11: =IF($I$11="","",ROUND($I$11*mult_wood,0)) | S11: =IF($J$11="","",ROUND($J$11*mult_wood,0)) | T11: =mult_sms -> 1
A12: B20024 | B12: คิ้วกันตก | C12: อลูมิเนียม sms | D12: 185 | E12: 200 | F12: =E12 -> 200 | H12: 295 | L12: ⚠️ ยังไม่มีชีทคิดทุนใช้ (เก็บเป็นราคาอ้างอิง) | M12: =IF($D$12="","",ROUND($D$12*mult_sms,0)) -> 185 | N12: =IF($E$12="","",ROUND($E$12*mult_sms,0)) -> 200 | O12: =IF($F$12="","",ROUND($F$12*mult_sms,0)) -> 200 | P12: =IF($G$12="","",ROUND($G$12*mult_sms,0)) | Q12: =IF($H$12="","",ROUND($H$12*mult_wood,0)) -> 295 | R12: =IF($I$12="","",ROUND($I$12*mult_wood,0)) | S12: =IF($J$12="","",ROUND($J$12*mult_wood,0)) | T12: =mult_sms -> 1
A13: B20041 | B13: เฟรมบานเลื่อน (3รางเสียบ) | C13: อลูมิเนียม sms | D13: 2070 | E13: 2255 | F13: =E13 -> 2255 | H13: 3424 | L13: SMS · บานระแนงเลื่อน | M13: =IF($D$13="","",ROUND($D$13*mult_sms,0)) -> 2070 | N13: =IF($E$13="","",ROUND($E$13*mult_sms,0)) -> 2255 | O13: =IF($F$13="","",ROUND($F$13*mult_sms,0)) -> 2255 | P13: =IF($G$13="","",ROUND($G$13*mult_sms,0)) | Q13: =IF($H$13="","",ROUND($H$13*mult_wood,0)) -> 3424 | R13: =IF($I$13="","",ROUND($I$13*mult_wood,0)) | S13: =IF($J$13="","",ROUND($J$13*mult_wood,0)) | T13: =mult_sms -> 1
A14: B20048 | B14: ตัวตบรางมุ้ง | C14: อลูมิเนียม sms | D14: 310 | E14: 340 | F14: =E14 -> 340 | H14: 495 | L14: ⚠️ ยังไม่มีชีทคิดทุนใช้ (เก็บเป็นราคาอ้างอิง) | M14: =IF($D$14="","",ROUND($D$14*mult_sms,0)) -> 310 | N14: =IF($E$14="","",ROUND($E$14*mult_sms,0)) -> 340 | O14: =IF($F$14="","",ROUND($F$14*mult_sms,0)) -> 340 | P14: =IF($G$14="","",ROUND($G$14*mult_sms,0)) | Q14: =IF($H$14="","",ROUND($H$14*mult_wood,0)) -> 495 | R14: =IF($I$14="","",ROUND($I$14*mult_wood,0)) | S14: =IF($J$14="","",ROUND($J$14*mult_wood,0)) | T14: =mult_sms -> 1
A15: B20046 | B15: ตัวต่อมัลติพ้อยท์ล็อค (ชนกลางบานเลื่อน) | C15: อลูมิเนียม sms | D15: 240 | E15: 260 | F15: =E15 -> 260 | H15: 380 | L15: ⚠️ ยังไม่มีชีทคิดทุนใช้ (เก็บเป็นราคาอ้างอิง) | M15: =IF($D$15="","",ROUND($D$15*mult_sms,0)) -> 240 | N15: =IF($E$15="","",ROUND($E$15*mult_sms,0)) -> 260 | O15: =IF($F$15="","",ROUND($F$15*mult_sms,0)) -> 260 | P15: =IF($G$15="","",ROUND($G$15*mult_sms,0)) | Q15: =IF($H$15="","",ROUND($H$15*mult_wood,0)) -> 380 | R15: =IF($I$15="","",ROUND($I$15*mult_wood,0)) | S15: =IF($J$15="","",ROUND($J$15*mult_wood,0)) | T15: =mult_sms -> 1
A16: B20047 | B16: เฟรมล่างบานเลื่อนภายใน 3 รางเสียบภายใน | C16: อลูมิเนียม sms | D16: 825 | E16: 895 | F16: =E16 -> 895 | H16: 1320 | L16: SMS · บานระแนงเลื่อน | M16: =IF($D$16="","",ROUND($D$16*mult_sms,0)) -> 825 | N16: =IF($E$16="","",ROUND($E$16*mult_sms,0)) -> 895 | O16: =IF($F$16="","",ROUND($F$16*mult_sms,0)) -> 895 | P16: =IF($G$16="","",ROUND($G$16*mult_sms,0)) | Q16: =IF($H$16="","",ROUND($H$16*mult_wood,0)) -> 1320 | R16: =IF($I$16="","",ROUND($I$16*mult_wood,0)) | S16: =IF($J$16="","",ROUND($J$16*mult_wood,0)) | T16: =mult_sms -> 1
A17: B20050 | B17: ฝาตบปิดรางภายใน | C17: อลูมิเนียม sms | D17: 145 | E17: 155 | F17: =E17 -> 155 | H17: 230 | L17: SMS · บานระแนงเลื่อน | M17: =IF($D$17="","",ROUND($D$17*mult_sms,0)) -> 145 | N17: =IF($E$17="","",ROUND($E$17*mult_sms,0)) -> 155 | O17: =IF($F$17="","",ROUND($F$17*mult_sms,0)) -> 155 | P17: =IF($G$17="","",ROUND($G$17*mult_sms,0)) | Q17: =IF($H$17="","",ROUND($H$17*mult_wood,0)) -> 230 | R17: =IF($I$17="","",ROUND($I$17*mult_wood,0)) | S17: =IF($J$17="","",ROUND($J$17*mult_wood,0)) | T17: =mult_sms -> 1
A18: B20051 | B18: กรอบบานมัลติพ้อยท์ล็อค | C18: อลูมิเนียม sms | D18: 885 | E18: 965 | F18: =E18 -> 965 | H18: 1458 | L18: SMS · บานเลื่อนรางบน · บานระแนงเลื่อน | M18: =IF($D$18="","",ROUND($D$18*mult_sms,0)) -> 885 | N18: =IF($E$18="","",ROUND($E$18*mult_sms,0)) -> 965 | O18: =IF($F$18="","",ROUND($F$18*mult_sms,0)) -> 965 | P18: =IF($G$18="","",ROUND($G$18*mult_sms,0)) | Q18: =IF($H$18="","",ROUND($H$18*mult_wood,0)) -> 1458 | R18: =IF($I$18="","",ROUND($I$18*mult_wood,0)) | S18: =IF($J$18="","",ROUND($J$18*mult_wood,0)) | T18: =mult_sms -> 1
A19: B20053 | B19: กรอบบานมัลติพ้อยท์ล็อคร่องปกติมีมือจับ | C19: อลูมิเนียม sms | D19: 1550 | E19: 1690 | F19: =E19 -> 1690 | H19: 2480 | L19: ⚠️ ยังไม่มีชีทคิดทุนใช้ (เก็บเป็นราคาอ้างอิง) | M19: =IF($D$19="","",ROUND($D$19*mult_sms,0)) -> 1550 | N19: =IF($E$19="","",ROUND($E$19*mult_sms,0)) -> 1690 | O19: =IF($F$19="","",ROUND($F$19*mult_sms,0)) -> 1690 | P19: =IF($G$19="","",ROUND($G$19*mult_sms,0)) | Q19: =IF($H$19="","",ROUND($H$19*mult_wood,0)) -> 2480 | R19: =IF($I$19="","",ROUND($I$19*mult_wood,0)) | S19: =IF($J$19="","",ROUND($J$19*mult_wood,0)) | T19: =mult_sms -> 1
A20: B20054 | B20: ขวางล่างใส่ล้อตลับขวางบน/ขวางล่าง | C20: อลูมิเนียม sms | D20: 1060 | E20: 1155 | F20: =E20 -> 1155 | H20: 1700 | L20: SMS · บานระแนงเลื่อน | M20: =IF($D$20="","",ROUND($D$20*mult_sms,0)) -> 1060 | N20: =IF($E$20="","",ROUND($E$20*mult_sms,0)) -> 1155 | O20: =IF($F$20="","",ROUND($F$20*mult_sms,0)) -> 1155 | P20: =IF($G$20="","",ROUND($G$20*mult_sms,0)) | Q20: =IF($H$20="","",ROUND($H$20*mult_wood,0)) -> 1700 | R20: =IF($I$20="","",ROUND($I$20*mult_wood,0)) | S20: =IF($J$20="","",ROUND($J$20*mult_wood,0)) | T20: =mult_sms -> 1
A21: B22001 | B21: เฟรมบนบานเลื่อน 45 มม. | C21: อลูมิเนียม sms | D21: 1465 | E21: 1595 | F21: =E21 -> 1595 | H21: 1955 | K21: หนา 1.5 มม. — KC SMS 16-05-26 | L21: บานระแนงเลื่อน | M21: =IF($D$21="","",ROUND($D$21*mult_sms,0)) -> 1465 | N21: =IF($E$21="","",ROUND($E$21*mult_sms,0)) -> 1595 | O21: =IF($F$21="","",ROUND($F$21*mult_sms,0)) -> 1595 | P21: =IF($G$21="","",ROUND($G$21*mult_sms,0)) | Q21: =IF($H$21="","",ROUND($H$21*mult_wood,0)) -> 1955 | R21: =IF($I$21="","",ROUND($I$21*mult_wood,0)) | S21: =IF($J$21="","",ROUND($J$21*mult_wood,0)) | T21: =mult_sms -> 1
A22: B22002 | B22: เฟรมข้างบานเลื่อน 45 มม. | C22: อลูมิเนียม sms | D22: 1030 | E22: 1120 | F22: =E22 -> 1120 | H22: 1451 | L22: บานระแนงเลื่อน | M22: =IF($D$22="","",ROUND($D$22*mult_sms,0)) -> 1030 | N22: =IF($E$22="","",ROUND($E$22*mult_sms,0)) -> 1120 | O22: =IF($F$22="","",ROUND($F$22*mult_sms,0)) -> 1120 | P22: =IF($G$22="","",ROUND($G$22*mult_sms,0)) | Q22: =IF($H$22="","",ROUND($H$22*mult_wood,0)) -> 1451 | R22: =IF($I$22="","",ROUND($I$22*mult_wood,0)) | S22: =IF($J$22="","",ROUND($J$22*mult_wood,0)) | T22: =mult_sms -> 1
A23: B22004 | B23: คิ้วรางข้างตบร่อง | C23: อลูมิเนียม sms | D23: 305 | E23: 330 | F23: =E23 -> 330 | H23: 485 | L23: ⚠️ ยังไม่มีชีทคิดทุนใช้ (เก็บเป็นราคาอ้างอิง) | M23: =IF($D$23="","",ROUND($D$23*mult_sms,0)) -> 305 | N23: =IF($E$23="","",ROUND($E$23*mult_sms,0)) -> 330 | O23: =IF($F$23="","",ROUND($F$23*mult_sms,0)) -> 330 | P23: =IF($G$23="","",ROUND($G$23*mult_sms,0)) | Q23: =IF($H$23="","",ROUND($H$23*mult_wood,0)) -> 485 | R23: =IF($I$23="","",ROUND($I$23*mult_wood,0)) | S23: =IF($J$23="","",ROUND($J$23*mult_wood,0)) | T23: =mult_sms -> 1
A24: B24001 | B24: เฟรมบนบานเฟี้ยม | C24: อลูมิเนียม sms | D24: 2105 | E24: 2290 | F24: =E24 -> 2290 | H24: 3590 | L24: เฟี้ยม | M24: =IF($D$24="","",ROUND($D$24*mult_sms,0)) -> 2105 | N24: =IF($E$24="","",ROUND($E$24*mult_sms,0)) -> 2290 | O24: =IF($F$24="","",ROUND($F$24*mult_sms,0)) -> 2290 | P24: =IF($G$24="","",ROUND($G$24*mult_sms,0)) | Q24: =IF($H$24="","",ROUND($H$24*mult_wood,0)) -> 3590 | R24: =IF($I$24="","",ROUND($I$24*mult_wood,0)) | S24: =IF($J$24="","",ROUND($J$24*mult_wood,0)) | T24: =mult_sms -> 1
A25: B24002 | B25: คิ้วเฟรมบน | C25: อลูมิเนียม sms | D25: 320 | E25: 345 | F25: =E25 -> 345 | H25: 550 | L25: เฟี้ยม | M25: =IF($D$25="","",ROUND($D$25*mult_sms,0)) -> 320 | N25: =IF($E$25="","",ROUND($E$25*mult_sms,0)) -> 345 | O25: =IF($F$25="","",ROUND($F$25*mult_sms,0)) -> 345 | P25: =IF($G$25="","",ROUND($G$25*mult_sms,0)) | Q25: =IF($H$25="","",ROUND($H$25*mult_wood,0)) -> 550 | R25: =IF($I$25="","",ROUND($I$25*mult_wood,0)) | S25: =IF($J$25="","",ROUND($J$25*mult_wood,0)) | T25: =mult_sms -> 1
A26: B24003 | B26: เฟรมล่างบานเฟี้ยม | C26: อลูมิเนียม sms | D26: 1455 | E26: 1585 | F26: =E26 -> 1585 | H26: 2505 | L26: เฟี้ยม | M26: =IF($D$26="","",ROUND($D$26*mult_sms,0)) -> 1455 | N26: =IF($E$26="","",ROUND($E$26*mult_sms,0)) -> 1585 | O26: =IF($F$26="","",ROUND($F$26*mult_sms,0)) -> 1585 | P26: =IF($G$26="","",ROUND($G$26*mult_sms,0)) | Q26: =IF($H$26="","",ROUND($H$26*mult_wood,0)) -> 2505 | R26: =IF($I$26="","",ROUND($I$26*mult_wood,0)) | S26: =IF($J$26="","",ROUND($J$26*mult_wood,0)) | T26: =mult_sms -> 1
A27: B24004 | B27: ตบธรณี | C27: อลูมิเนียม sms | D27: 570 | E27: 620 | F27: =E27 -> 620 | H27: 965 | L27: เฟี้ยม | M27: =IF($D$27="","",ROUND($D$27*mult_sms,0)) -> 570 | N27: =IF($E$27="","",ROUND($E$27*mult_sms,0)) -> 620 | O27: =IF($F$27="","",ROUND($F$27*mult_sms,0)) -> 620 | P27: =IF($G$27="","",ROUND($G$27*mult_sms,0)) | Q27: =IF($H$27="","",ROUND($H$27*mult_wood,0)) -> 965 | R27: =IF($I$27="","",ROUND($I$27*mult_wood,0)) | S27: =IF($J$27="","",ROUND($J$27*mult_wood,0)) | T27: =mult_sms -> 1
A28: B24005 | B28: เฟรมข้างบานเฟี้ยม | C28: อลูมิเนียม sms | D28: 1000 | E28: 1085 | F28: =E28 -> 1085 | H28: 1746 | L28: เฟี้ยม | M28: =IF($D$28="","",ROUND($D$28*mult_sms,0)) -> 1000 | N28: =IF($E$28="","",ROUND($E$28*mult_sms,0)) -> 1085 | O28: =IF($F$28="","",ROUND($F$28*mult_sms,0)) -> 1085 | P28: =IF($G$28="","",ROUND($G$28*mult_sms,0)) | Q28: =IF($H$28="","",ROUND($H$28*mult_wood,0)) -> 1746 | R28: =IF($I$28="","",ROUND($I$28*mult_wood,0)) | S28: =IF($J$28="","",ROUND($J$28*mult_wood,0)) | T28: =mult_sms -> 1
A29: B24006 | B29: คิ้วเฟรมข้างประตู | C29: อลูมิเนียม sms | D29: 280 | E29: 305 | F29: =E29 -> 305 | H29: 500 | L29: เฟี้ยม | M29: =IF($D$29="","",ROUND($D$29*mult_sms,0)) -> 280 | N29: =IF($E$29="","",ROUND($E$29*mult_sms,0)) -> 305 | O29: =IF($F$29="","",ROUND($F$29*mult_sms,0)) -> 305 | P29: =IF($G$29="","",ROUND($G$29*mult_sms,0)) | Q29: =IF($H$29="","",ROUND($H$29*mult_wood,0)) -> 500 | R29: =IF($I$29="","",ROUND($I$29*mult_wood,0)) | S29: =IF($J$29="","",ROUND($J$29*mult_wood,0)) | T29: =mult_sms -> 1
A30: B24007 | B30: เสาบานเฟี้ยม | C30: อลูมิเนียม sms | D30: 1210 | E30: 1320 | F30: =E30 -> 1320 | H30: 1940 | L30: เฟี้ยม | M30: =IF($D$30="","",ROUND($D$30*mult_sms,0)) -> 1210 | N30: =IF($E$30="","",ROUND($E$30*mult_sms,0)) -> 1320 | O30: =IF($F$30="","",ROUND($F$30*mult_sms,0)) -> 1320 | P30: =IF($G$30="","",ROUND($G$30*mult_sms,0)) | Q30: =IF($H$30="","",ROUND($H$30*mult_wood,0)) -> 1940 | R30: =IF($I$30="","",ROUND($I$30*mult_wood,0)) | S30: =IF($J$30="","",ROUND($J$30*mult_wood,0)) | T30: =mult_sms -> 1
A31: B24008 | B31: คิ้วตบกระจก 5-6 มม. | C31: อลูมิเนียม sms | D31: 265 | E31: 285 | F31: =E31 -> 285 | H31: 460 | L31: เฟี้ยม | M31: =IF($D$31="","",ROUND($D$31*mult_sms,0)) -> 265 | N31: =IF($E$31="","",ROUND($E$31*mult_sms,0)) -> 285 | O31: =IF($F$31="","",ROUND($F$31*mult_sms,0)) -> 285 | P31: =IF($G$31="","",ROUND($G$31*mult_sms,0)) | Q31: =IF($H$31="","",ROUND($H$31*mult_wood,0)) -> 460 | R31: =IF($I$31="","",ROUND($I$31*mult_wood,0)) | S31: =IF($J$31="","",ROUND($J$31*mult_wood,0)) | T31: =mult_sms -> 1
A32: B24009 | B32: บังใบเสาประตูบานเฟี้ยม | C32: อลูมิเนียม sms | D32: 270 | E32: 295 | F32: =E32 -> 295 | H32: 460 | L32: เฟี้ยม | M32: =IF($D$32="","",ROUND($D$32*mult_sms,0)) -> 270 | N32: =IF($E$32="","",ROUND($E$32*mult_sms,0)) -> 295 | O32: =IF($F$32="","",ROUND($F$32*mult_sms,0)) -> 295 | P32: =IF($G$32="","",ROUND($G$32*mult_sms,0)) | Q32: =IF($H$32="","",ROUND($H$32*mult_wood,0)) -> 460 | R32: =IF($I$32="","",ROUND($I$32*mult_wood,0)) | S32: =IF($J$32="","",ROUND($J$32*mult_wood,0)) | T32: =mult_sms -> 1
A33: B24017 | B33: รางยู sms | C33: อลูมิเนียม sms | D33: 305 | E33: 330 | F33: =E33 -> 330 | H33: 485 | L33: เฟี้ยม · เฟี้ยมยูโร | M33: =IF($D$33="","",ROUND($D$33*mult_sms,0)) -> 305 | N33: =IF($E$33="","",ROUND($E$33*mult_sms,0)) -> 330 | O33: =IF($F$33="","",ROUND($F$33*mult_sms,0)) -> 330 | P33: =IF($G$33="","",ROUND($G$33*mult_sms,0)) | Q33: =IF($H$33="","",ROUND($H$33*mult_wood,0)) -> 485 | R33: =IF($I$33="","",ROUND($I$33*mult_wood,0)) | S33: =IF($J$33="","",ROUND($J$33*mult_wood,0)) | T33: =mult_sms -> 1
A34: B24018 | B34: รางบานเฟี้ยมภายใน sms | C34: อลูมิเนียม sms | D34: 905 | E34: 985 | F34: =E34 -> 985 | H34: 1445 | L34: เฟี้ยม | M34: =IF($D$34="","",ROUND($D$34*mult_sms,0)) -> 905 | N34: =IF($E$34="","",ROUND($E$34*mult_sms,0)) -> 985 | O34: =IF($F$34="","",ROUND($F$34*mult_sms,0)) -> 985 | P34: =IF($G$34="","",ROUND($G$34*mult_sms,0)) | Q34: =IF($H$34="","",ROUND($H$34*mult_wood,0)) -> 1445 | R34: =IF($I$34="","",ROUND($I$34*mult_wood,0)) | S34: =IF($J$34="","",ROUND($J$34*mult_wood,0)) | T34: =mult_sms -> 1
A35: B30006 | B35: กรอบมุ้ง | C35: อลูมิเนียม sms | D35: 625 | E35: 680 | F35: =E35 -> 680 | H35: 1000 | L35: ⚠️ ยังไม่มีชีทคิดทุนใช้ (เก็บเป็นราคาอ้างอิง) | M35: =IF($D$35="","",ROUND($D$35*mult_sms,0)) -> 625 | N35: =IF($E$35="","",ROUND($E$35*mult_sms,0)) -> 680 | O35: =IF($F$35="","",ROUND($F$35*mult_sms,0)) -> 680 | P35: =IF($G$35="","",ROUND($G$35*mult_sms,0)) | Q35: =IF($H$35="","",ROUND($H$35*mult_wood,0)) -> 1000 | R35: =IF($I$35="","",ROUND($I$35*mult_wood,0)) | S35: =IF($J$35="","",ROUND($J$35*mult_wood,0)) | T35: =mult_sms -> 1
A36: F7976 | B36: เฟรมบน-ล่างบานเลื่อน 3 ราง | C36: อลูมิเนียม Fuji | D36: 2450 | E36: 2610 | F36: =E36 -> 2610 | G36: 2665 | H36: 3576 | I36: 3685 | J36: 3685 | K36: หนา 1.5 มม. — PPS Fuji Eurotec 05-26 | L36: ⚠️ ยังไม่มีชีทคิดทุนใช้ (เก็บเป็นราคาอ้างอิง) | M36: =IF($D$36="","",ROUND($D$36*mult_euro,0)) -> 2450 | N36: =IF($E$36="","",ROUND($E$36*mult_euro,0)) -> 2610 | O36: =IF($F$36="","",ROUND($F$36*mult_euro,0)) -> 2610 | P36: =IF($G$36="","",ROUND($G$36*mult_euro,0)) -> 2665 | Q36: =IF($H$36="","",ROUND($H$36*mult_wood,0)) -> 3576 | R36: =IF($I$36="","",ROUND($I$36*mult_wood,0)) -> 3685 | S36: =IF($J$36="","",ROUND($J$36*mult_wood,0)) -> 3685 | T36: =mult_euro -> 1
A37: F7869 | B37: เฟรมบน-ล่างบานเลื่อน 3 ราง (ตัวหนา) | C37: อลูมิเนียม Fuji | D37: 2765 | E37: 2950 | F37: =E37 -> 2950 | G37: 3010 | H37: 4005 | I37: 4165 | J37: 4165 | K37: ตรงกับใบราคา PPS Fuji Eurotec 05-26 | L37: ยูโร | M37: =IF($D$37="","",ROUND($D$37*mult_euro,0)) -> 2765 | N37: =IF($E$37="","",ROUND($E$37*mult_euro,0)) -> 2950 | O37: =IF($F$37="","",ROUND($F$37*mult_euro,0)) -> 2950 | P37: =IF($G$37="","",ROUND($G$37*mult_euro,0)) -> 3010 | Q37: =IF($H$37="","",ROUND($H$37*mult_wood,0)) -> 4005 | R37: =IF($I$37="","",ROUND($I$37*mult_wood,0)) -> 4165 | S37: =IF($J$37="","",ROUND($J$37*mult_wood,0)) -> 4165 | T37: =mult_euro -> 1
A38: F7977 | B38: เฟรมบน-ล่างบานเลื่อน 2 ราง | C38: อลูมิเนียม Fuji | D38: 1530 | E38: 1630 | F38: =E38 -> 1630 | G38: 1665 | H38: 2250 | I38: 2300 | J38: 2300 | K38: ตรงกับใบราคา PPS Fuji Eurotec 05-26 | L38: 🚫 ไม่ใช้ — ทำ 3 ราง ทั้งหมด (JR ยืนยัน 21 ส.ค. 69) | M38: =IF($D$38="","",ROUND($D$38*mult_euro,0)) -> 1530 | N38: =IF($E$38="","",ROUND($E$38*mult_euro,0)) -> 1630 | O38: =IF($F$38="","",ROUND($F$38*mult_euro,0)) -> 1630 | P38: =IF($G$38="","",ROUND($G$38*mult_euro,0)) -> 1665 | Q38: =IF($H$38="","",ROUND($H$38*mult_wood,0)) -> 2250 | R38: =IF($I$38="","",ROUND($I$38*mult_wood,0)) -> 2300 | S38: =IF($J$38="","",ROUND($J$38*mult_wood,0)) -> 2300 | T38: =mult_euro -> 1
A39: F7990 | B39: ต่อเฟรมบน-ล่างบานเลื่อน | C39: อลูมิเนียม Fuji | D39: 1030 | E39: 1095 | F39: =E39 -> 1095 | G39: 1120 | H39: 1485 | I39: 1550 | J39: 1550 | K39: ตรงกับใบราคา PPS Fuji Eurotec 05-26 | L39: ⚠️ ยังไม่มีชีทคิดทุนใช้ (เก็บเป็นราคาอ้างอิง) | M39: =IF($D$39="","",ROUND($D$39*mult_euro,0)) -> 1030 | N39: =IF($E$39="","",ROUND($E$39*mult_euro,0)) -> 1095 | O39: =IF($F$39="","",ROUND($F$39*mult_euro,0)) -> 1095 | P39: =IF($G$39="","",ROUND($G$39*mult_euro,0)) -> 1120 | Q39: =IF($H$39="","",ROUND($H$39*mult_wood,0)) -> 1485 | R39: =IF($I$39="","",ROUND($I$39*mult_wood,0)) -> 1550 | S39: =IF($J$39="","",ROUND($J$39*mult_wood,0)) -> 1550 | T39: =mult_euro -> 1
A40: F7902 | B40: เฟรมล่างบานเลื่อน 3 ราง (ตัวเตี้ย) | C40: อลูมิเนียม Fuji | D40: 1220 | E40: 1300 | F40: =E40 -> 1300 | G40: 1325 | H40: 1795 | I40: 1835 | J40: 1835 | K40: ตรงกับใบราคา PPS Fuji Eurotec 05-26 | L40: ⚠️ ยังไม่มีชีทคิดทุนใช้ (เก็บเป็นราคาอ้างอิง) | M40: =IF($D$40="","",ROUND($D$40*mult_euro,0)) -> 1220 | N40: =IF($E$40="","",ROUND($E$40*mult_euro,0)) -> 1300 | O40: =IF($F$40="","",ROUND($F$40*mult_euro,0)) -> 1300 | P40: =IF($G$40="","",ROUND($G$40*mult_euro,0)) -> 1325 | Q40: =IF($H$40="","",ROUND($H$40*mult_wood,0)) -> 1795 | R40: =IF($I$40="","",ROUND($I$40*mult_wood,0)) -> 1835 | S40: =IF($J$40="","",ROUND($J$40*mult_wood,0)) -> 1835 | T40: =mult_euro -> 1
...

Sheet บันทึกราคาขึ้น
A1: 📈 บันทึกราคาขึ้น — ทุน @ บานมาตรฐาน 150×150 ซม (2.25 ตร.ม.) | I1: 🏠 สารบัญ
A2: ทุก ครั้งที่อลู/กก. ขึ้น → มดเพิ่มคอลัมน์วันที่ใหม่ + %ขึ้น · ดูได้ว่าบานไหนขึ้นเท่าไหร่ + ตรวจว่าเพิ่มถูก (ทุน=วัสดุ อลู+กระจก+อุปกรณ์ ไม่รวมค่าแรง · อลูเท่านั้นที่ขึ้นตาม/กก.)
A4: ① ประวัติเรตอลู (บาท/กก.)
A5: วันที่ | B5: SMS | C5: ยูโร/Fuji | D5: SlimLux | E5: Velora | F5: เมืองทอง | H5: 📌 เก็บประวัติ: เลือกแถว "ปัจจุบัน" ทั้งแถว → Ctrl+C → คลิกแถวว่างข้างล่าง → คลิกขวา → วางค่า (123) → เสร็จ · แล้วไปแก้ราคา+วันที่ที่ชีท "อัปเดตราคาอลู"
A6: =อัปเดตราคาอลู!$B$2 -> 24/8/69 | B6: =อัปเดตราคาอลู!B4 -> 187 | C6: =อัปเดตราคาอลู!B5 -> 187 | D6: =อัปเดตราคาอลู!B6 -> 164 | E6: =อัปเดตราคาอลู!B7 -> 230 | F6: =อัปเดตราคาอลู!B8 -> 188
A14: ② ทุน @150×150 ต่อบาน (บาท)
A15: บาน | B15: config | C15: ทุนอลูฐาน | D15: กระจก+อุปกรณ์ | E15: ทุนรวม ปัจจุบัน (สูตร live) | F15: 25/6/69 (บันทึก) | G15: %ขึ้น
A16: บานเลื่อน SMS | B16: 2 บาน | C16: 7365 | D16: 1881 | E16: =ROUND(C16*mult_sms+D16,0) -> 9246 | F16: 9246 | G16: ฐาน
A17: บานเลื่อน ยูโร | B17: 2 บาน | C17: 11220 | D17: 2145 | E17: =ROUND(C17*mult_euro+D17,0) -> 13365 | F17: 13365 | G17: ฐาน
A18: บานเลื่อน SlimLux | B18: 2 บาน | C18: 5968 | D18: 6953 | E18: =ROUND(C18*mult_slim+D18,0) -> 12921 | F18: 12921 | G18: ฐาน
A19: บานเลื่อน Velora | B19: 2 บาน | C19: 2207 | D19: 3263 | E19: =ROUND(C19*mult_velora+D19,0) -> 5470 | F19: 5470 | G19: ฐาน
A20: บานเลื่อน E-series | B20: 2 บาน | C20: 11158 | D20: 1527 | E20: =ROUND(C20*mult_sms+D20,0) -> 12685 | F20: 12685 | G20: ฐาน
A21: บานเปิด (ยูโร) | B21: 2 บาน | C21: 8560 | D21: 3255 | E21: =ROUND(C21*mult_euro+D21,0) -> 11815 | F21: 11815 | G21: ฐาน
A22: PC Door | B22: 1 บาน | C22: 5430 | D22: 3044 | E22: =ROUND(C22*mult_euro+D22,0) -> 8474 | F22: 8474 | G22: ฐาน
A23: บานกระทุ้ง | B23: 1 บาน | C23: 4340 | D23: 1924 | E23: =ROUND(C23*mult_euro+D23,0) -> 6264 | F23: 6264 | G23: ฐาน
A24: บานยก | B24: 1 บาน | C24: 5005 | D24: 3419 | E24: =ROUND(C24*mult_euro+D24,0) -> 8424 | F24: 8424 | G24: ฐาน
A25: บานเฟี้ยม | B25: 4 บาน | C25: 10470 | D25: 6807 | E25: =ROUND(C25*mult_euro+D25,0) -> 17277 | F25: 17277 | G25: ฐาน
A26: เฟี้ยมยูโร | B26: 4 บาน | C26: 13294 | D26: 2917 | E26: =ROUND(C26*mult_euro+D26,0) -> 16211 | F26: 16211 | G26: ฐาน
A27: บานติดตาย | B27: - | C27: 3240 | D27: 764 | E27: =ROUND(C27*mult_mtong+D27,0) -> 4004 | F27: 4004 | G27: ฐาน
A28: ตายดัดโค้ง | B28: - | C28: 0 | D28: 5100 | E28: =ROUND(C28*mult_mtong+D28,0) -> 5100 | F28: 5100 | G28: ฐาน
A29: เปิดดัดโค้ง | B29: 2 บาน | C29: 0 | D29: 28077 | E29: =ROUND(C29*mult_mtong+D29,0) -> 28077 | F29: 28077 | G29: ฐาน
A30: บานเลื่อนรางบน | B30: 2 บาน | C30: 4770 | D30: 7803 | E30: =ROUND(2990*mult_mtong+1780*mult_sms+D30,0) -> 12573 | F30: 12573 | G30: ฐาน
A32: 🔧 วิธีเพิ่มรอบใหม่เมื่ออลูขึ้น:
A33: 1) แก้ราคา/กก. ที่ชีท "อัปเดตราคาอลู" → ช่อง "ทุนรวม ปัจจุบัน(สูตร)" ขยับเอง
A34: 2) มดเพิ่ม 2 คอลัมน์ใหม่ (วันที่ + %ขึ้น) คัดค่าจากช่องสูตร + เพิ่มแถวเรตใน ① → ได้ประวัติว่าบานไหนขึ้นเท่าไหร่
A35: หมายเหตุ: ตายดัดโค้ง/เปิดดัดโค้ง อลูตั้งราคาตายตัว ไม่ขึ้นตาม/กก. · รางบน/เฟี้ยม สูตร live ประมาณ (เลขเป๊ะดูคอลัมน์บันทึกวันที่)
A37: ⚠️ ทุนอลูฐาน(ส้ม)/กระจก+อุปกรณ์(เทา) = ค่าคงที่ @150×150 · ทุนรวม(เขียว) = อลูฐาน×ตัวคูณ + อื่นๆ → ขึ้นเองเมื่อ/กก.ขึ้น

Sheet ราคางานเสริม
A1: ⚠️ แก้ราคาที่นี่ → 📋 ราคาวัสดุงานเสริม — แก้ราคาที่นี่ที่เดียว (ช่องเหลือง) · ทุกชีทดึงไปใช้อัตโนมัติ | G1: 🏠 สารบัญ
A3: ▶ ฝ้ายิปซัม
A4: งาน | B4: วัสดุ | C4: หน่วย | D4: ราคา (บาท)
A5: ฝ้ายิปซัม | B5: แผ่นยิปซัม 9มม | C5: แผ่น | D5: 284
A6: ฝ้ายิปซัม | B6: โครงซีไลน์ (ฟิวริ่ง) | C6: เส้น | D6: 50
A7: ฝ้ายิปซัม | B7: โครงเคร่าหลัก (อาบ) | C7: เส้น | D7: 50
A8: ฝ้ายิปซัม | B8: ขาแขวน | C8: เส้น | D8: 50
A9: ฝ้ายิปซัม | B9: สกรูยึดแผ่น | C9: ตัว | D9: 0.5
A10: ฝ้ายิปซัม | B10: สกรูยึดโครง | C10: ตัว | D10: 0.5
A11: ฝ้ายิปซัม | B11: ปูนฉาบรอยต่อ | C11: ถุง | D11: 240
A12: ฝ้ายิปซัม | B12: เทป/ตาข่าย | C12: ม้วน | D12: 70
A13: ฝ้ายิปซัม | B13: ฉากโอบ อลู 4หุน | C13: เส้น | D13: 70
A14: ฝ้ายิปซัม | B14: ฉนวน rockwool 3" | C14: แผ่น | D14: 130
A15: ▶ งานไฟ
A16: งาน | B16: วัสดุ | C16: หน่วย | D16: ราคา (บาท)
A17: งานไฟ | B17: ไฟดาวน์ไลท์ | C17: ดวง | D17: 300
A18: งานไฟ | B18: เต้ารับ+หน้ากาก | C18: จุด | D18: 300
A19: งานไฟ | B19: สวิตช์+หน้ากาก | C19: จุด | D19: 300
A20: งานไฟ | B20: กล่องไฟ | C20: กล่อง | D20: 35
A21: งานไฟ | B21: สายไฟ THW/VAF | C21: เมตร | D21: 40
A22: งานไฟ | B22: ท่อ PVC+ข้อต่อ | C22: เมตร | D22: 6.6666667
A23: งานไฟ | B23: เทป+เบ็ดเตล็ด | C23: งาน | D23: 400
A24: ▶ สมาร์ทบอร์ด
A25: งาน | B25: วัสดุ | C25: หน่วย | D25: ราคา (บาท)
A26: สมาร์ทบอร์ด | B26: แผ่นสมาร์ทบอร์ด 12มม | C26: แผ่น | D26: 500
A27: สมาร์ทบอร์ด | B27: โครงเหล็กกรอบ 1½×3" | C27: เส้น | D27: 440
A28: สมาร์ทบอร์ด | B28: ซีไลน์ 3" ดิ่ง | C28: เส้น | D28: 62
A29: สมาร์ทบอร์ด | B29: ซีไลน์ 3" นอน | C29: เส้น | D29: 62
A30: สมาร์ทบอร์ด | B30: ฉนวน 3" | C30: แผ่น | D30: 130
A31: สมาร์ทบอร์ด | B31: สกรูยึดแผ่น | C31: ตัว | D31: 0.5
A32: สมาร์ทบอร์ด | B32: สกรูยึดโครง | C32: ตัว | D32: 0.5
A33: สมาร์ทบอร์ด | B33: ปูนฉาบรอยต่อ | C33: ถุง | D33: 240
A34: สมาร์ทบอร์ด | B34: เทป/ตาข่าย | C34: ม้วน | D34: 70
A35: ▶ ไอโซวอล
A36: งาน | B36: วัสดุ | C36: หน่วย | D36: ราคา (บาท)
A37: ไอโซวอล | B37: แผ่นไอโซวอล ≤2.4ม | C37: แผ่น | D37: 2016
A38: ไอโซวอล | B38: แผ่นไอโซวอล >2.4ม | C38: แผ่น | D38: 2520
A39: ไอโซวอล | B39: กล่อง 1.6×4" โครงรอบ | C39: เส้น | D39: 1220
A40: ไอโซวอล | B40: ฉาก 4หุน | C40: เส้น | D40: 70
A41: ไอโซวอล | B41: สกรู/รีเวท | C41: งาน | D41: 50
...

Sheet ราคาออโต้
A1: ⚠️ แก้ราคาที่นี่ → ราคาออโต้/มอเตอร์ (ทุน) — มดอัปเดตที่นี่ที่เดียว · ชีทบานติ๊กเลือกแล้วดึงมาใช้ | G1: 🏠 สารบัญ
A2: หมวด/บาน | B2: รุ่น/รายการ | C2: ราคา | D2: ค่าส่ง | E2: หน่วย/เงื่อนไข
A3: บานยก / เฟี้ยมยก | B3: ยก 80 กก. | C3: 4500 | D3: 1700
B4: ยก 300 กก. | C4: 12500 | D4: 1700
A5: หลังคาเลื่อน | B5: 80 กก. | C5: 4500 | D5: 1700
B6: 300 กก. | C6: 12500 | D6: 1700
B7: 1500 กก. | C7: 13325 | D7: 1700 | E7: รวมฟันเฟือง+เซนเซอร์อัตโนมัติ (ระบบบวกให้แล้ว)
B8: ฟันเฟือง (เฉพาะ1500) | C8: 340 | E8: บาท/ม. × ระยะเลื่อน · บวกอัตโนมัติเมื่อเลือก 1500 กก.
B9: เซนเซอร์กันฝน (ออป,1500) | C9: 1100 | E9: บวกอัตโนมัติเมื่อเลือก 1500 กก. (บังคับ ไม่ใช่ออปชั่นแล้ว)
A10: บานเกล็ด 38.1 | B10: มอเตอร์บานเกล็ด | C10: 1800 | E10: ไม่มีค่าส่ง
A11: ระแนงหมุน | B11: มอเตอร์ระแนงหมุน | C11: 1800 | E11: รวมส่งแล้ว
A12: บานกระทุ้ง | B12: โช็ค เปิด 50 | C12: 3575 | D12: 1700 | E12: 2 ตัว→+อุปกรณ์พิเศษ
B13: โช็ค เปิด 80 | C13: 3725 | D13: 1700 | E13: 2 ตัว→+อุปกรณ์พิเศษ
B14: โซ่เดี่ยว 50 | C14: 1900 | D14: 1700
B15: โซ่คู่ 50 | C15: 2600 | D15: 1700
B16: อุปกรณ์พิเศษ (โช็ค 2 ตัว) | C16: 600 | E16: บวกเมื่อใช้ 2 ตัว
A17: เลื่อน SMS/ยูโร | B17: Evecca (จีน) | C17: 13480 | D17: 1700 | E17: 1 บาน
B18: สายพาน Evecca | C18: 75 | E18: บาท/ม. = กว้างช่อง×2
B19: ออป Smart lock | C19: 6500 | E19: ออปชั่น Evecca
B20: ช่างแซก | C20: 8000 | E20: ไม่มีค่าส่ง
B21: เซฟตี้ตาแมว (บังคับช่างแซก) | C21: 1000 | E21: บวกทุกชุดช่างแซก
B22: ราง ช่างแซก | C22: 950 | E22: บาท/ม. = กว้างช่อง
B23: ออป Touch Switch (ช่างแซก) | C23: 1000 | E23: ออปชั่น
B24: ออป Infrared (ช่างแซก) | C24: 9000 | E24: ออปชั่น
A25: SlimLux | B25: ชุด SlimLux (บานแรก) | C25: 6900 | D25: 1700 | E25: บานแรก
B26: บานเพิ่ม | C26: 2250 | E26: บาท/บานเพิ่ม
B27: ราง SlimLux | C27: 1100 | E27: บาท/ม. = กว้างช่อง×จำนวนบาน
B28: ออป สแกนหน้า (บังคับเลือก1) | C28: 2750 | E28: เลือก 1 ใน 2
B29: ออป Touch Switch (บังคับเลือก1) | C29: 100 | E29: เลือก 1 ใน 2
A30: ประตูรั้ว | B30: มอเตอร์ประตูรั้ว | C30: 10000 | E30: บาท/ชุด
B31: รีโมทประตูรั้ว | C31: 500 | E31: บาท/ตัว
B32: เดินไฟ ประตูรั้ว (เหมา) | C32: 2000 | E32: บาท/ชุด (เหมา)

Sheet ราคาหลังคา
A1: ⚠️ แก้ราคาที่นี่ → ราคาแผ่นหลังคา + วัสดุปิดผิว (โปรไฟล์อลูดูที่ชีทราคาสี · เหล็กดูที่ชีทราคาเหล็ก) | F1: 🏠 สารบัญ
A2: วัสดุปิดผิว
B3: วัสดุ | C3: หน่วย | D3: ราคา (บาท) | E3: หมายเหตุ
B4: ไวนิล | C4: แผ่น (7 ม.) | D4: 1540 | E4: จันทันห่าง ≤100 ซม.
B5: ฝาครอบไวนิล | C5: เส้น (7 ม.) | D5: 245 | E5: 1 เส้น/แผ่นไวนิล
B6: ดีไลท์ | C6: แผ่น (6 ม.) | D6: 4700 | E6: ฝาครอบแถมฟรี
B7: โพลีตัน | C7: เมตร | D7: 1200 | E7: จันทันห่าง ≤122 ซม.
B8: ตัวครอบโพลีตัน | C8: จุด/จันทัน | D8: 420 | E8: 1 จุดต่อ 1 จันทัน
B9: ชินโคร์ไลท์ Heat Cut | C9: ตร.ม. | D9: 2800 | E9: รวมฝาครอบ
B10: ชินโคร์ไลท์ Superior | C10: ตร.ม. | D10: 2100 | E10: รวมฝาครอบ
B11: เมทัลชีท PU 2" Snap | C11: ตร.ม. | D11: 2200 | E11: จันทันห่าง ≤100 ซม.
B12: กระจกลามิเนต 4+4 | C12: ตร.ม. | D12: =ราคากระจก!$B$32 -> 883 | E12: ดึงจากชีท "ราคากระจก" — แก้ที่นั่น
B13: กระจกลามิเนต 5+5 | C13: ตร.ม. | D13: =ราคากระจก!$B$33 -> 861 | E13: ดึงจากชีท "ราคากระจก" — แก้ที่นั่น
B14: ชินโคร์ Shade 4มม. | C14: ตร.ม. | D14: 1050 | E14: กว้าง 1.38ม. · CPP 01-05-69
B15: ชินโคร์ Prime 10มม. | C15: ตร.ม. | D15: 4348 | E15: กว้าง 1.38ม. · N828/562
B16: รางหลังคาเลื่อน | C16: เส้น | D16: 4080
B17: เมทัลชีท EPS 2" | C17: ตร.ม. | D17: 1400 | E17: จันทันห่าง ไม่เกิน 100 ซม.
A19: ▶ ปลายหลังคา / รางน้ำ
B20: รางน้ำสแตนเลส M | C20: เมตร | D20: 990 | E20: สแตนเลส — ไม่คูณตัวคูณอลู
B21: รางน้ำสแตนเลส L | C21: เมตร | D21: 1035 | E21: สแตนเลส — ไม่คูณตัวคูณอลู

Sheet ราคาเหล็ก
A1: ⚠️ แก้ราคาที่นี่ → ราคาเหล็กกล่อง (เหล็กชุบซิงค์) เส้นยาว 6 ม. — แก้ช่อง "ราคา/เส้น" เมื่อเหล็กขึ้น | F1: 🏠 สารบัญ
A2: เหล็กกล่องชุบซิงค์ (โครงหลังคา / รั้ว / โครงเสริม)
A3: รายการ | B3: ขนาด (นิ้ว) | C3: ยาว/เส้น (ม.) | D3: ราคา/เส้น (บาท) | E3: ราคา/เมตร (บาท) | F3: ใช้ที่ไหน
A4: กล่องเหล็กชุบซิงค์ | B4: 1"×1" | C4: 6 | D4: 170 | E4: =ROUND(D4/C4,2) -> 28.33 | F4: หลังคาทุกชนิด (เสริมโครง) · ทุน* ทุกชีท — ใช้ตลอด
A5: กล่องเหล็กชุบซิงค์ | B5: 1½"×3" | C5: 6 | D5: 460 | E5: =ROUND(D5/C5,2) -> 76.67 | F5: ⚠ ยังไม่ได้เสียบใช้งาน (เก็บไว้เผื่ออนาคต)
A6: กล่องเหล็กชุบซิงค์ | B6: 2"×4" | C6: 6 | D6: 600 | E6: =ROUND(D6/C6,2) -> 100 | F6: สมาร์ทบอร์ดพื้น (ตง/คาน) ใช้ตลอด · จันทันหลังคา เฉพาะเลือกโครง "เหล็กชุบซิงค์"
A7: กล่องเหล็กชุบซิงค์ | B7: 4"×4" | C7: 6 | D7: 940 | E7: =ROUND(D7/C7,2) -> 156.67 | F7: ⚠ ยังไม่ได้เสียบใช้งาน (เก็บไว้เผื่ออนาคต)
A8: กล่องเหล็กชุบซิงค์ | B8: 1"×2" | C8: 6 | D8: 280 | E8: =ROUND(D8/C8,2) -> 46.67 | F8: แปหลังคา เฉพาะเลือกโครง "เหล็กชุบซิงค์" (ที่ คิดทุน หลังคา (รวม) ช่อง F3)
A9: เพลทเหล็กชุบซิงค์ | B9: - | C9: - | D9: 15 | F9: ยึดด้านหลัง — หลังคาทุกชนิด
A10: เหล็กยัดเสา (ในกล่องอลู 4"x4") | B10: - | C10: 6 | D10: 860 | F10: ประตูรั้ว — ยัดในเสาอลู

Sheet ค่าแรง
A1: ⚠️ แก้ราคาที่นี่ → ค่าแรง ผลิต + ติดตั้ง (สูตร: ค่าเริ่มต้น + เรต×ตร.ม.) — จากไฟล์ค่าแรง นิด | G1: 🏠 สารบัญ
A3: เลือกแบบ → | B3: Velora
A4: พื้นที่ (ตร.ม.) → | B4: 15.4
A5: ค่าแรงผลิต = | B5: =MAX(0,VLOOKUP(B3,$A$12:$E$58,2,0)+VLOOKUP(B3,$A$12:$E$58,3,0)*B4) -> 1373.75
A6: ค่าแรงติดตั้ง = | B6: =MAX(0,VLOOKUP(B3,$A$12:$E$58,4,0)+VLOOKUP(B3,$A$12:$E$58,5,0)*B4) -> 1723.75
A7: รวมค่าแรง (ผลิต+ติดตั้ง) = | B7: =B5+B6 -> 3097.5
A10: ตารางค่าแรง (แก้ที่นี่ถ้าค่าแรงเปลี่ยน) — ค่าแรง/ชม.=87.5 | G10: ค่าแรง/ชม. (แก้ช่องเดียว) → | I10: 87.5 | N10: 🟡 ช่องเหลือง = แก้ตรงนี้ · เทา = คิดให้อัตโนมัติ
A11: แบบบาน | B11: ผลิต: ค่าเริ่มต้น | C11: ผลิต: /ตร.ม. | D11: ติดตั้ง: ค่าเริ่มต้น | E11: ติดตั้ง: /ตร.ม. | G11: ชม.ฐานผลิต | H11: ชม.ฐานติดตั้ง | I11: ค่าแรง/ชม. | J11: ชม.เพิ่มผลิต/ตร.ม. | K11: ชม.เพิ่มติดตั้ง/ตร.ม. | L11: คนผลิต | M11: คนติดตั้ง | N11: แก้ตรงไหน
A12: บานเลื่อน SMS | B12: =G12*I12*L12 -> 787.5 | C12: =J12*I12*L12 -> 43.3125 | D12: =H12*I12*M12 -> 1225 | E12: =K12*I12*M12 -> 29.75 | G12: 6 | H12: 7 | I12: =$I$10 -> 87.5 | J12: 0.33 | K12: 0.17 | L12: 1.5 | M12: 2 | N12: ฐาน+เพิ่ม/ตร.ม. → แก้ G,H (ฐานชม.) · J,K (เพิ่มชม./ตร.ม.)
A13: บานเลื่อน ยูโร | B13: =G13*I13*L13 -> 787.5 | C13: =J13*I13*L13 -> 49.875 | D13: =H13*I13*M13 -> 1050 | E13: =K13*I13*M13 -> 38.5 | G13: 6 | H13: 6 | I13: =$I$10 -> 87.5 | J13: 0.38 | K13: 0.22 | L13: 1.5 | M13: 2 | N13: ฐาน+เพิ่ม/ตร.ม. → แก้ G,H (ฐานชม.) · J,K (เพิ่มชม./ตร.ม.)
A14: บานเลื่อนรางบน | B14: =G14*I14*L14 -> 918.75 | C14: =J14*I14*L14 -> 32.8125 | D14: =H14*I14*M14 -> 1837.5 | E14: =K14*I14*M14 -> 65.625 | G14: 7 | H14: 7 | I14: =$I$10 -> 87.5 | J14: 0.25 | K14: 0.25 | L14: 1.5 | M14: 3 | N14: ฐาน+เพิ่ม/ตร.ม. → G,H (ฐานชม.) · J,K (เพิ่มชม./ตร.ม.) · L,M (คน)
A15: SlimLux | B15: =G15*I15*L15 -> 918.75 | C15: =J15*I15*L15 -> 59.0625 | D15: =H15*I15*M15 -> 1837.5 | E15: =K15*I15*M15 -> 65.625 | G15: 7 | H15: 7 | I15: =$I$10 -> 87.5 | J15: 0.45 | K15: 0.25 | L15: 1.5 | M15: 3 | N15: ฐาน+เพิ่ม/ตร.ม. → แก้ G,H (ฐานชม.) · J,K (เพิ่มชม./ตร.ม.)
A16: Velora | B16: =G16*I16*L16 -> 700 | C16: =J16*I16*L16 -> 43.75 | D16: =H16*I16*M16 -> 1050 | E16: =K16*I16*M16 -> 43.75 | G16: 8 | H16: 6 | I16: =$I$10 -> 87.5 | J16: 0.5 | K16: 0.25 | L16: 1 | M16: 2 | N16: ฐาน+เพิ่ม/ตร.ม. → แก้ G,H (ฐานชม.) · J,K (เพิ่มชม./ตร.ม.)
A17: บานเปิด (ยูโร) | B17: =G17*I17*L17 -> 787.5 | C17: =J17*I17*L17 -> 32.8125 | D17: =H17*I17*M17 -> 1225 | E17: =K17*I17*M17 -> 43.75 | G17: 6 | H17: 7 | I17: =$I$10 -> 87.5 | J17: 0.25 | K17: 0.25 | L17: 1.5 | M17: 2 | N17: ฐาน+เพิ่ม/ตร.ม. → แก้ G,H (ฐานชม.) · J,K (เพิ่มชม./ตร.ม.)
A18: เปิดดัดโค้ง | B18: =G18*I18*L18 -> 0 | C18: =J18*I18*L18 -> 52.5 | D18: =H18*I18*M18 -> 1225 | E18: =K18*I18*M18 -> 17.5 | G18: 0 | H18: 7 | I18: =$I$10 -> 87.5 | J18: 0.4 | K18: 0.1 | L18: 1.5 | M18: 2 | N18: ฐาน+เพิ่ม/ตร.ม. → G,H (ฐานชม.) · J,K (เพิ่มชม./ตร.ม.) · L,M (คน)
A19: บานกระทุ้ง (ยูโร) | B19: =G19*I19*L19 -> 787.5 | C19: =J19*I19*L19 -> 35.4375 | D19: =H19*I19*M19 -> 743.75 | E19: =K19*I19*M19 -> 45.5 | G19: 6 | H19: 2.125 | I19: =$I$10 -> 87.5 | J19: 0.27 | K19: 0.13 | L19: 1.5 | M19: 4 | N19: ฐาน+เพิ่ม/ตร.ม. → แก้ G,H (ฐานชม.) · J,K (เพิ่มชม./ตร.ม.)
A20: บานหมุน | B20: =G20*I20*L20 -> 1050 | C20: =J20*I20*L20 -> 35.4375 | D20: =H20*I20*M20 -> 2450 | E20: =K20*I20*M20 -> 82.6875 | G20: 8 | H20: 8 | I20: =$I$10 -> 87.5 | J20: 0.27 | K20: 0.27 | L20: 1.5 | M20: 3.5 | N20: ฐาน+เพิ่ม/ตร.ม. → G,H (ฐานชม.) · J,K (เพิ่มชม./ตร.ม.) · L,M (คน)
A21: บานเฟี้ยม (sms) | B21: =G21*I21*L21 -> 525 | C21: =J21*I21*L21 -> 0 | D21: =H21*I21*M21 -> 525 | E21: =K21*I21*M21 -> 0 | G21: 3 | H21: 3 | I21: =$I$10 -> 87.5 | J21: 0 | K21: 0 | L21: 2 | M21: 2 | N21: คิดต่อ 1 บานเฟี้ยม — ชีทคูณจำนวนบานให้เอง (ไม่ใช้ช่องต่อ ตร.ม.)
A22: บานเฟี้ยมยูโร | B22: =G22*I22*L22 -> 525 | C22: =J22*I22*L22 -> 0 | D22: =H22*I22*M22 -> 525 | E22: =K22*I22*M22 -> 0 | G22: 3 | H22: 3 | I22: =$I$10 -> 87.5 | J22: 0 | K22: 0 | L22: 2 | M22: 2 | N22: คิดต่อ 1 บานเฟี้ยม — ชีทคูณจำนวนบานให้เอง (ไม่ใช้ช่องต่อ ตร.ม.)
A23: บานเฟี้ยมยก | B23: =G23*I23*L23 -> 3062.5 | C23: =J23*I23*L23 -> 63.4375 | D23: =H23*I23*M23 -> 2450 | E23: =K23*I23*M23 -> 55.125 | G23: 14 | H23: 8 | I23: =$I$10 -> 87.5 | J23: 0.29 | K23: 0.18 | L23: 2.5 | M23: 3.5 | N23: ฐาน+เพิ่ม/ตร.ม. → G,H (ฐานชม.) · J,K (เพิ่มชม./ตร.ม.) · L,M (คน)
... A32: บานตู้ Futuretech | B32: =G32*I32*L32 -> 306.25 | C32: =J32*I32*L32 -> 31.0625 | D32: =H32*I32*M32 -> 1225 | E32: =K32*I32*M32 -> 24.5 | G32: 7 | H32: 7 | I32: =$I$10 -> 87.5 | J32: 0.71 | K32: 0.14 | L32: 0.5 | M32: 2 | N32: ฐาน+เพิ่ม/ตร.ม. → G,H (ฐานชม.) · J,K (เพิ่มชม./ตร.ม.) · L,M (คน)
A33: ▶ มุ้ง (ย้ายมาจากชีทราคามุ้ง — แก้ที่นี่ที่เดียว)
A34: มุ้งจีบ | B34: =G34*I34*L34 -> 0 | C34: =J34*I34*L34 -> 0 | D34: =H34*I34*M34 -> 875 | E34: =K34*I34*M34 -> 0 | G34: 0 | H34: 5 | I34: =$I$10 -> 87.5 | J34: 0 | K34: 0 | L34: 2 | M34: 2 | N34: ฐาน+เพิ่ม/ตร.ม. → แก้ G,H (ฐานชม.) · J,K (เพิ่มชม./ตร.ม.)
A35: มุ้งม้วน ขาว/ดำ/น้ำตาล | B35: =G35*I35*L35 -> 0 | C35: =J35*I35*L35 -> 0 | D35: =H35*I35*M35 -> 875 | E35: =K35*I35*M35 -> 0 | G35: 0 | H35: 5 | I35: =$I$10 -> 87.5 | J35: 0 | K35: 0 | L35: 2 | M35: 2 | N35: ฐาน+เพิ่ม/ตร.ม. → แก้ G,H (ฐานชม.) · J,K (เพิ่มชม./ตร.ม.)
A36: มุ้งม้วน ซาฮาร่า | B36: =G36*I36*L36 -> 0 | C36: =J36*I36*L36 -> 0 | D36: =H36*I36*M36 -> 875 | E36: =K36*I36*M36 -> 0 | G36: 0 | H36: 5 | I36: =$I$10 -> 87.5 | J36: 0 | K36: 0 | L36: 2 | M36: 2 | N36: ฐาน+เพิ่ม/ตร.ม. → แก้ G,H (ฐานชม.) · J,K (เพิ่มชม./ตร.ม.)
A37: มุ้งม้วน ลายไม้สักทอง | B37: =G37*I37*L37 -> 0 | C37: =J37*I37*L37 -> 0 | D37: =H37*I37*M37 -> 875 | E37: =K37*I37*M37 -> 0 | G37: 0 | H37: 5 | I37: =$I$10 -> 87.5 | J37: 0 | K37: 0 | L37: 2 | M37: 2 | N37: ฐาน+เพิ่ม/ตร.ม. → แก้ G,H (ฐานชม.) · J,K (เพิ่มชม./ตร.ม.)
A38: มุ้งม้วน ไลท์โอ๊ค | B38: =G38*I38*L38 -> 0 | C38: =J38*I38*L38 -> 0 | D38: =H38*I38*M38 -> 875 | E38: =K38*I38*M38 -> 0 | G38: 0 | H38: 5 | I38: =$I$10 -> 87.5 | J38: 0 | K38: 0 | L38: 2 | M38: 2 | N38: ฐาน+เพิ่ม/ตร.ม. → แก้ G,H (ฐานชม.) · J,K (เพิ่มชม./ตร.ม.)
A39: มุ้งจีบนิรภัย ≤3ม. ขาว/ดำ | B39: =G39*I39*L39 -> 0 | C39: =J39*I39*L39 -> 0 | D39: =H39*I39*M39 -> 875 | E39: =K39*I39*M39 -> 90 | G39: 0 | H39: 5 | I39: =$I$10 -> 87.5 | J39: 0 | K39: 0.51428571 | L39: 2 | M39: 2 | N39: ฐาน+เพิ่ม/ตร.ม. → แก้ G,H (ฐานชม.) · J,K (เพิ่มชม./ตร.ม.)
A40: มุ้งจีบนิรภัย ≤3ม. ซาฮาร่า | B40: =G40*I40*L40 -> 0 | C40: =J40*I40*L40 -> 0 | D40: =H40*I40*M40 -> 875 | E40: =K40*I40*M40 -> 90 | G40: 0 | H40: 5 | I40: =$I$10 -> 87.5 | J40: 0 | K40: 0.51428571 | L40: 2 | M40: 2 | N40: ฐาน+เพิ่ม/ตร.ม. → แก้ G,H (ฐานชม.) · J,K (เพิ่มชม./ตร.ม.)
A41: มุ้งจีบนิรภัย ≤3ม. สักทอง | B41: =G41*I41*L41 -> 0 | C41: =J41*I41*L41 -> 0 | D41: =H41*I41*M41 -> 875 | E41: =K41*I41*M41 -> 90 | G41: 0 | H41: 5 | I41: =$I$10 -> 87.5 | J41: 0 | K41: 0.51428571 | L41: 2 | M41: 2 | N41: ฐาน+เพิ่ม/ตร.ม. → แก้ G,H (ฐานชม.) · J,K (เพิ่มชม./ตร.ม.)
A42: มุ้งจีบนิรภัย >3ม. ขาว/ดำ | B42: =G42*I42*L42 -> 0 | C42: =J42*I42*L42 -> 0 | D42: =H42*I42*M42 -> 875 | E42: =K42*I42*M42 -> 90 | G42: 0 | H42: 5 | I42: =$I$10 -> 87.5 | J42: 0 | K42: 0.51428571 | L42: 2 | M42: 2 | N42: ฐาน+เพิ่ม/ตร.ม. → แก้ G,H (ฐานชม.) · J,K (เพิ่มชม./ตร.ม.)
A43: มุ้งจีบนิรภัย >3ม. ซาฮาร่า | B43: =G43*I43*L43 -> 0 | C43: =J43*I43*L43 -> 0 | D43: =H43*I43*M43 -> 875 | E43: =K43*I43*M43 -> 90 | G43: 0 | H43: 5 | I43: =$I$10 -> 87.5 | J43: 0 | K43: 0.51428571 | L43: 2 | M43: 2 | N43: ฐาน+เพิ่ม/ตร.ม. → แก้ G,H (ฐานชม.) · J,K (เพิ่มชม./ตร.ม.)
A44: มุ้งจีบนิรภัย >3ม. สักทอง | B44: =G44*I44*L44 -> 0 | C44: =J44*I44*L44 -> 0 | D44: =H44*I44*M44 -> 875 | E44: =K44*I44*M44 -> 90 | G44: 0 | H44: 5 | I44: =$I$10 -> 87.5 | J44: 0 | K44: 0.51428571 | L44: 2 | M44: 2 | N44: ฐาน+เพิ่ม/ตร.ม. → แก้ G,H (ฐานชม.) · J,K (เพิ่มชม./ตร.ม.)
A45: มุ้งเฟรมเล็ก | B45: =G45*I45*L45 -> 240 | C45: =J45*I45*L45 -> 60 | D45: =H45*I45*M45 -> 175 | E45: =K45*I45*M45 -> 45 | G45: 1.3714286 | H45: 0.8 | I45: =$I$10 -> 87.5 | J45: 0.34285714 | K45: 0.20571429 | L45: 2 | M45: 2.5 | N45: ฐาน+เพิ่ม/ตร.ม. → แก้ G,H (ฐานชม.) · J,K (เพิ่มชม./ตร.ม.)
... A47: มุ้งนิรภัย | B47: =G47*I47*L47 -> 176 | C47: =J47*I47*L47 -> 0 | D47: =H47*I47*M47 -> 110 | E47: =K47*I47*M47 -> 0 | G47: 1.0057143 | H47: 0.50285714 | I47: =$I$10 -> 87.5 | J47: 0 | K47: 0 | L47: 2 | M47: 2.5 | N47: ฐาน+เพิ่ม/ตร.ม. → แก้ G,H (ฐานชม.) · J,K (เพิ่มชม./ตร.ม.)
A48: ▶ ระแนง / รั้ว / ราวกันตก / Shower
A49: ระแนงสลับ | B49: =G49*I49*L49 -> 1575 | C49: =J49*I49*L49 -> 107.625 | D49: =H49*I49*M49 -> 3500 | E49: =K49*I49*M49 -> 73.5 | G49: 12 | H49: 10 | I49: =$I$10 -> 87.5 | J49: 0.82 | K49: 0.21 | L49: 1.5 | M49: 4 | N49: ฐาน+เพิ่ม/ตร.ม. → G,H (ฐานชม.) · J,K (เพิ่มชม./ตร.ม.) · L,M (คน)
A50: ระแนง | B50: =G50*I50*L50 -> 1750 | C50: =J50*I50*L50 -> 75.25 | D50: =H50*I50*M50 -> 3500 | E50: =K50*I50*M50 -> 101.5 | G50: 10 | H50: 10 | I50: =$I$10 -> 87.5 | J50: 0.43 | K50: 0.29 | L50: 2 | M50: 4 | N50: ฐาน+เพิ่ม/ตร.ม. → G,H (ฐานชม.) · J,K (เพิ่มชม./ตร.ม.) · L,M (คน)
A51: ระแนงหมุน | B51: =G51*I51*L51 -> 1443.75 | C51: =J51*I51*L51 -> 98.4375 | D51: =H51*I51*M51 -> 3500 | E51: =K51*I51*M51 -> 133 | G51: 11 | H51: 10 | I51: =$I$10 -> 87.5 | J51: 0.75 | K51: 0.38 | L51: 1.5 | M51: 4 | N51: ฐาน+เพิ่ม/ตร.ม. → G,H (ฐานชม.) · J,K (เพิ่มชม./ตร.ม.) · L,M (คน)
A52: ประตูรั้ว | B52: =G52*I52*L52 -> 1837.5 | C52: =J52*I52*L52 -> 108.9375 | D52: =H52*I52*M52 -> 10500 | E52: =K52*I52*M52 -> 118.125 | G52: 14 | H52: 24 | I52: =$I$10 -> 87.5 | J52: 0.83 | K52: 0.27 | L52: 1.5 | M52: 5 | N52: ฐาน+เพิ่ม/ตร.ม. → G,H (ฐานชม.) · J,K (เพิ่มชม./ตร.ม.) · L,M (คน)
...

Sheet ราคามุ้ง
A1: ⚠️ แก้ราคาช่องเหลืองที่นี่ — ทุกบานลิงก์อัตโนมัติ | B1: ราคา ฿/ตร.ม. | C1: ประเภท | D1: บานที่เข้าได้ | E1: หมายเหตุ | F1: ค่าแรงมุ้ง → ดูที่ชีท "ค่าแรง" บล็อก ▶ มุ้ง | G1: ไม่มีมุ้ง | H1: 🏠 สารบัญ | I1: ผ้ามุ้ง (กรอกราคา/ม้วน เหลือง → /ตร.ม.คิดเอง) | J1: ฿/ตร.ม. | K1: ราคา/ม้วน (36.6 ตร.ม.)
A2: มุ้งจีบ | B2: 1179 | C2: ซื้อสำเร็จ | D2: ALL | E2: ทุกบาน | G2: มุ้งจีบ | I2: ไฟเบอร์ | J2: =ROUND(K2/36.6,0) -> 23 | K2: 842
A3: มุ้งม้วน ขาว/ดำ/น้ำตาล | B3: 1300 | C3: ซื้อสำเร็จ | D3: ALL | G3: มุ้งม้วน ขาว/ดำ/น้ำตาล | I3: ไนล่อน | J3: =ROUND(K3/36.6,0) -> 38 | K3: 1391
A4: มุ้งม้วน ซาฮาร่า | B4: 1500 | C4: ซื้อสำเร็จ | D4: ALL | G4: มุ้งม้วน ซาฮาร่า | I4: สแตนเลส | J4: =ROUND(K4/36.6,0) -> 352 | K4: 12883
A5: มุ้งม้วน ลายไม้สักทอง | B5: 1600 | C5: ซื้อสำเร็จ | D5: ALL | G5: มุ้งม้วน ลายไม้สักทอง | I5: กันแมว | J5: =ROUND(K5/36.6,0) -> 82 | K5: 3001
A6: มุ้งม้วน ไลท์โอ๊ค | B6: 1700 | C6: ซื้อสำเร็จ | D6: ALL | G6: มุ้งม้วน ไลท์โอ๊ค
A7: มุ้งจีบนิรภัย ≤3ม. ขาว/ดำ | B7: 2750 | C7: ซื้อสำเร็จ | D7: ALL | G7: มุ้งจีบนิรภัย ≤3ม. ขาว/ดำ
A8: มุ้งจีบนิรภัย ≤3ม. ซาฮาร่า | B8: 3150 | C8: ซื้อสำเร็จ | D8: ALL | E8: +400 | G8: มุ้งจีบนิรภัย ≤3ม. ซาฮาร่า
A9: มุ้งจีบนิรภัย ≤3ม. สักทอง | B9: 3250 | C9: ซื้อสำเร็จ | D9: ALL | E9: +500 | G9: มุ้งจีบนิรภัย ≤3ม. สักทอง
A10: มุ้งจีบนิรภัย >3ม. ขาว/ดำ | B10: 4050 | C10: ซื้อสำเร็จ | D10: ALL | G10: มุ้งจีบนิรภัย >3ม. ขาว/ดำ
A11: มุ้งจีบนิรภัย >3ม. ซาฮาร่า | B11: 4450 | C11: ซื้อสำเร็จ | D11: ALL | E11: +400 | G11: มุ้งจีบนิรภัย >3ม. ซาฮาร่า
A12: มุ้งจีบนิรภัย >3ม. สักทอง | B12: 4550 | C12: ซื้อสำเร็จ | D12: ALL | E12: +500 | G12: มุ้งจีบนิรภัย >3ม. สักทอง
A13: มุ้งเฟรมเล็ก | B13: 0 | C13: ผลิตเอง | D13: SMS|เปิด|กระทุ้ง | E13: กรอบ+ยาง+ผ้า+ค่าแรง | G13: มุ้งเฟรมเล็ก
A14: มุ้งเฟรมใหญ่ | B14: 0 | C14: ผลิตเอง | D14: SMS|ยูโร|เปิด|กระทุ้ง | E14: โปรไฟล์บาน+ยาง+ผ้า+ค่าแรง | G14: มุ้งเฟรมใหญ่
A15: มุ้งนิรภัย | B15: 0 | C15: ผลิตเอง | D15: SMS|ยูโร|เปิด|กระทุ้ง | E15: โปรไฟล์บาน+ยาง+ผ้านิรภัย650+ค่าแรง | G15: มุ้งนิรภัย
A17: 🟢 มุ้งผลิตเอง — แก้ค่ากรอบ(เหลือง)/ยาง/ผ้า · ราคาโชว์อัตโนมัติ
A18: รุ่นมุ้ง | B18: ค่ากรอบ /เส้น | C18: ผ้าที่ใช้ได้ (บาท/ตร.ม.) | D18: ยางอัด /ม. | E18: ค่าแรงผลิต | F18: ค่าแรงติดตั้ง
A19: เฟรมเล็ก | B19: 625 | C19: ="ไฟเบอร์ "&J2&" · ไนล่อน "&J3&" · สแตนเลส "&J4&" · กันแมว "&J5 -> ไฟเบอร์ 23 · ไนล่อน 38 · สแตนเลส 352 · กันแมว 82 | D19: 5 | E19: =ค่าแรง!$B$45&IF(ค่าแรง!$C$45>0," +"&ค่าแรง!$C$45&"/ตร.ม."," (เหมา)") -> 240 +60/ตร.ม. | F19: =ค่าแรง!$D$45&IF(ค่าแรง!$E$45>0," +"&ค่าแรง!$E$45&"/ตร.ม."," (เหมา)") -> 175 +45/ตร.ม.
A20: เฟรมใหญ่ | B20: ขึ้นตามเสากุญแจบาน (อัตโนมัติ) | C20: ="ไฟเบอร์ "&J2&" · ไนล่อน "&J3&" · สแตนเลส "&J4&" · กันแมว "&J5 -> ไฟเบอร์ 23 · ไนล่อน 38 · สแตนเลส 352 · กันแมว 82 | D20: =$D$19 -> 5 | E20: =ค่าแรง!$B$46&IF(ค่าแรง!$C$46>0," +"&ค่าแรง!$C$46&"/ตร.ม."," (เหมา)") -> 280 (เหมา) | F20: =ค่าแรง!$D$46&IF(ค่าแรง!$E$46>0," +"&ค่าแรง!$E$46&"/ตร.ม."," (เหมา)") -> 110 (เหมา)
A21: นิรภัย | B21: 1030 | C21: สแตนเลสนิรภัย 650 | D21: =$D$19 -> 5 | E21: =ค่าแรง!$B$47&IF(ค่าแรง!$C$47>0," +"&ค่าแรง!$C$47&"/ตร.ม."," (เหมา)") -> 176 (เหมา) | F21: =ค่าแรง!$D$47&IF(ค่าแรง!$E$47>0," +"&ค่าแรง!$E$47&"/ตร.ม."," (เหมา)") -> 110 (เหมา)
A23: 📌 แก้ราคามุ้งตรงไหน — แก้เฉพาะช่องสีเหลืองเท่านั้น
A24: ① มุ้งซื้อสำเร็จขึ้นราคา → คอลัมน์ B (ราคา/ตร.ม.) แถว 2-12
A25: ② ค่าแรงติดตั้งมุ้งสำเร็จ → คอลัมน์ F แถว 2-12
A26: ③ ราคาผ้า (ไฟเบอร์/ไนล่อน/สแตนเลส/กันแมว) → คอลัมน์ J (บล็อกส้ม)
A27: ④ ค่ากรอบมุ้งผลิตเอง → B19 (เล็ก) · B21 (นิรภัย) [เฟรมใหญ่ใช้เสากุญแจบาน ขึ้นเองตามราคาอลู]
A28: ⑤ ยางอัด → D19
A29: ค่าแรงมุ้ง (ผลิต+ติดตั้ง) ย้ายไปชีท "ค่าแรง" บล็อก ▶ มุ้ง แล้ว — แก้ที่นั่นที่เดียว

Sheet ราคาฝ้าไม้เทียม
A1: คีย์ค้นหา (อัตโนมัติ) | B1: ร้าน | C1: รุ่น/แบบ | D1: กว้าง/เส้น (ม.) | E1: ยาว/เส้น (ม.) | F1: ราคา | G1: หน่วยที่ขาย | H1: ราคาเส้นปิดขอบ | I1: ยาวเส้นปิดขอบ (ม.) | J1: มีขาจับ? 1=มี 0=ไม่มี | K1: ราคารวมทุกอย่าง? 1=รวม 0=ไม่รวม | M1: 🏠 สารบัญ | N1: รายชื่อร้าน (ดรอปดาวน์)
A2: =B2&"|"&C2 -> ไม้ทิพย์|สีพื้น | B2: ไม้ทิพย์ | C2: สีพื้น | D2: 0.085 | E2: 6 | F2: 420 | G2: เส้น | H2: 70 | I2: 6 | J2: 1 | K2: 0 | N2: ไม้ทิพย์
A3: =B3&"|"&C3 -> ไม้ทิพย์|ลายไม้ | B3: ไม้ทิพย์ | C3: ลายไม้ | D3: 0.085 | E3: 6 | F3: 580 | G3: เส้น | H3: 70 | I3: 6 | J3: 1 | K3: 0 | N3: fameline
A4: =B4&"|"&C4 -> fameline|สีมาตรฐาน | B4: fameline | C4: สีมาตรฐาน | D4: 0.085 | E4: 6 | F4: 1300 | G4: ตร.ม. | H4: 0 | I4: 1 | J4: 0 | K4: 1 | N4: HIGO
A5: =B5&"|"&C5 -> fameline|สีอื่น | B5: fameline | C5: สีอื่น | D5: 0.085 | E5: 6 | F5: 1400 | G5: ตร.ม. | H5: 0 | I5: 1 | J5: 0 | K5: 1 | N5: remood
A6: =B6&"|"&C6 -> HIGO|C19 (ใน) | B6: HIGO | C6: C19 (ใน) | D6: 0.204 | E6: 3 | F6: 140 | G6: เส้น | H6: 130 | I6: 3 | J6: 0 | K6: 0
A7: =B7&"|"&C7 -> HIGO|G15 (ใน) | B7: HIGO | C7: G15 (ใน) | D7: 0.153 | E7: 3 | F7: 140 | G7: เส้น | H7: 130 | I7: 3 | J7: 0 | K7: 0
A8: =B8&"|"&C8 -> HIGO|R16 (ใน) | B8: HIGO | C8: R16 (ใน) | D8: 0.16 | E8: 3 | F8: 140 | G8: เส้น | H8: 130 | I8: 3 | J8: 0 | K8: 0
A9: =B9&"|"&C9 -> HIGO|Y18 (ใน) | B9: HIGO | C9: Y18 (ใน) | D9: 0.158 | E9: 3 | F9: 140 | G9: เส้น | H9: 130 | I9: 3 | J9: 0 | K9: 0
A10: =B10&"|"&C10 -> HIGO|P155 (นอก) | B10: HIGO | C10: P155 (นอก) | D10: 0.1524 | E10: 2.9 | F10: 310 | G10: เส้น | H10: 275 | I10: 2.9 | J10: 0 | K10: 0
A11: =B11&"|"&C11 -> HIGO|WH200 (นอก) | B11: HIGO | C11: WH200 (นอก) | D11: 0.185 | E11: 2.9 | F11: 310 | G11: เส้น | H11: 275 | I11: 2.9 | J11: 0 | K11: 0
A12: =B12&"|"&C12 -> remood|Entree เรียบ | B12: remood | C12: Entree เรียบ | D12: 0.14 | E12: 2.8 | F12: 500 | G12: แผ่น | H12: 300 | I12: 2.8 | J12: 0 | K12: 0
A13: =B13&"|"&C13 -> remood|Entree มีลาย | B13: remood | C13: Entree มีลาย | D13: 0.165 | E13: 2.8 | F13: 600 | G13: แผ่น | H13: 300 | I13: 2.8 | J13: 0 | K13: 0
A14: =B14&"|"&C14 -> remood|Entree ชักร่อง | B14: remood | C14: Entree ชักร่อง | D14: 0.219 | E14: 2.8 | F14: 950 | G14: แผ่น | H14: 300 | I14: 2.8 | J14: 0 | K14: 0
A15: =B15&"|"&C15 -> remood|Duratech+ เรียบ13 | B15: remood | C15: Duratech+ เรียบ13 | D15: 0.13 | E15: 2.8 | F15: 730 | G15: แผ่น | H15: 300 | I15: 2.8 | J15: 0 | K15: 0
A16: =B16&"|"&C16 -> remood|Duratech+ เรียบ16 | B16: remood | C16: Duratech+ เรียบ16 | D16: 0.162 | E16: 2.8 | F16: 900 | G16: แผ่น | H16: 300 | I16: 2.8 | J16: 0 | K16: 0
A17: =B17&"|"&C17 -> remood|Duratech+ เรียบ14 | B17: remood | C17: Duratech+ เรียบ14 | D17: 0.14 | E17: 2.8 | F17: 850 | G17: แผ่น | H17: 300 | I17: 2.8 | J17: 0 | K17: 0
... A25: =B25&"|"&C25 -> remood|Duralight+ ชักร่อง | B25: remood | C25: Duralight+ ชักร่อง | D25: 0.116 | E25: 2.8 | F25: 2100 | G25: แผ่น | H25: 300 | I25: 2.8 | J25: 0 | K25: 0

Sheet น้ำหนักโปรไฟล์
A1: น้ำหนักโปรไฟล์อลูมิเนียม — เอาไปเสียบระบบ ราคาเส้น = น้ำหนัก × ราคา/กก. | G1: 🏠 สารบัญ
B2: แบรนด์ | C2: รหัส | D2: หนา/ขนาด | E2: ชื่อ/รายการ | F2: ยาว(ม.) | G2: กก./ม. | H2: กก./เส้น | I2: หมายเหตุ
B3: เมืองทอง — กล่องสี่เหลี่ยมด้านเท่า (ยาว 6 ม.)
B4: เมืองทอง | C4: 705 | D4: 1.00 มม. | E4: แป๊บ 6 หุน | F4: 6 | G4: 0.196 | H4: 1.18
B5: เมืองทอง | C5: 706 | D5: 1.20 มม. | E5: แป๊บ 6 หุน | F5: 6 | G5: 0.232 | H5: 1.39
B6: เมืองทอง | C6: 709 | D6: 1.00 มม. | E6: แป๊บ 1 นิ้ว | F6: 6 | G6: 0.262 | H6: 1.57
B7: เมืองทอง | C7: 710 | D7: 1.10 มม. | E7: แป๊บ 1 นิ้ว | F7: 6 | G7: 0.288 | H7: 1.73
B8: เมืองทอง | C8: 711 | D8: 1.20 มม. | E8: แป๊บ 1 นิ้ว | F8: 6 | G8: 0.314 | H8: 1.88
B9: เมืองทอง | C9: 715 | D9: 1.10 มม. | E9: แป๊บ 1¼ นิ้ว | F9: 6 | G9: 0.363 | H9: 2.18
B10: เมืองทอง | C10: 718 | D10: 1.10 มม. | E10: แป๊บ 1½ นิ้ว | F10: 6 | G10: 0.438 | H10: 2.63
B11: เมืองทอง | C11: 745 | D11: 1.50 มม. | E11: แป๊บ 1½ นิ้ว | F11: 6 | G11: 0.595 | H11: 3.57
B12: เมืองทอง | C12: 724A | D12: 0.80 มม. | E12: แป๊บ 1¾ นิ้ว | F12: 6 | G12: 0.379 | H12: 2.27
B13: เมืองทอง | C13: 724B | D13: 0.90 มม. | E13: แป๊บ 1¾ นิ้ว | F13: 6 | G13: 0.425 | H13: 2.55
B14: เมืองทอง | C14: 724F | D14: 1.10 มม. | E14: แป๊บ 1¾ นิ้ว | F14: 6 | G14: 0.517 | H14: 3.1
B15: เมืองทอง | C15: 726A | D15: 1.35 มม. | E15: แป๊บ 1¾ นิ้ว | F15: 6 | G15: 0.631 | H15: 3.79
... B18: เมืองทอง | C18: 749 | D18: 1.50 มม. | E18: แป๊บ 2 นิ้ว | F18: 6 | G18: 0.801 | H18: 4.81
B19: เมืองทอง — กล่องสี่เหลี่ยมด้านไม่เท่า (ยาว 6 ม.)
B20: เมืองทอง | C20: 802 | D20: 1.00 มม. | E20: ½×1 นิ้ว | F20: 6 | G20: 0.194 | H20: 1.16
B21: เมืองทอง | C21: 808 | D21: 1.00 มม. | E21: 1½×1 นิ้ว | F21: 6 | G21: 0.332 | H21: 1.99
B22: เมืองทอง | C22: 812 | D22: 1.10 มม. | E22: 1¾×1 นิ้ว | F22: 6 | G22: 0.401 | H22: 2.41
B23: เมืองทอง | C23: 0827 | D23: 1.00 มม. | E23: 1×2 นิ้ว | F23: 6 | G23: 0.402 | H23: 2.41
B24: เมืองทอง | C24: 816 | D24: 1.20 มม. | E24: 1×2 นิ้ว | F24: 6 | G24: 0.478 | H24: 2.87
B25: เมืองทอง | C25: 820 | D25: 1.20 มม. | E25: 1×3 นิ้ว | F25: 6 | G25: 0.644 | H25: 3.86
B26: เมืองทอง | C26: 843 | D26: 1.40 มม. | E26: 1×3 นิ้ว | F26: 6 | G26: 0.75 | H26: 4.5
B27: เมืองทอง | C27: 0828 | D27: 1.10 มม. | E27: 1¾×3 นิ้ว | F27: 6 | G27: 0.706 | H27: 4.24
B28: เมืองทอง | C28: 823 | D28: 1.20 มม. | E28: 1¾×3 นิ้ว | F28: 6 | G28: 0.769 | H28: 4.61
B29: เมืองทอง | C29: 848 | D29: 1.40 มม. | E29: 1¾×3 นิ้ว | F29: 6 | G29: 0.894 | H29: 5.36
B30: เมืองทอง | C30: 0806 | D30: 1.20 มม. | E30: 1×4 นิ้ว | F30: 6 | G30: 0.81 | H30: 4.86
B31: เมืองทอง | C31: 831 | D31: 1.50 มม. | E31: 1×4 นิ้ว | F31: 6 | G31: 1.008 | H31: 6.05
... B38: เมืองทอง | C38: 0815 | D38: 2.00 มม. | E38: 2×4 นิ้ว | F38: 6 | G38: 1.873 | H38: 11.24
B39: เมืองทอง — ตัว Z
B40: เมืองทอง | C40: TRT-1419 | D40: 126.3×77.7 ×1.3 | E40: ตัว Z 4 นิ้ว | F40: 6 | G40: 0.677 | H40: 4.062
B41: สลิม KOYO (SlimLux) — ยาว 6 ม.
B42: SlimLux | C42: WM-K01 | D42: - | E42: ไส้เสาบาน | F42: 6 | G42: 0.492 | H42: 2.95 | I42: 9073 กลางบาน (เสากุญแจ)
B43: SlimLux | C43: WM-K02 | D43: - | E43: ฝาเสาเรียบ | F43: 6 | G43: 0.262 | H43: 1.57
B44: SlimLux | C44: WM-K03 | D44: - | E44: ฝาเสาเกี่ยว | F44: 6 | G44: 0.282 | H44: 1.692
B45: SlimLux | C45: WM-K04 | D45: - | E45: ขวางบนล่าง | F45: 6 | G45: 0.782 | H45: 4.69 | I45: 9072 หัวบาน (ขวางบน/ล่าง)
B46: SlimLux | C46: - | D46: - | E46: รางบน 3 ราง | F46: 6 | G46: 1.789 | H46: 10.734
B47: SlimLux | C47: WM-K15 | D47: - | E47: รางแขวน 1 ราง | F47: 6 | G47: 0.91 | H47: 5.46
B48: SlimLux | C48: WM-K19 | D48: - | E48: ข้อต่อรางแขวน | F48: 6 | G48: 0.114 | H48: 0.684
...

Sheet ราคากระจก
A1: ⚠️ แก้ราคาที่นี่ → ราคากระจก (ทุน/ตร.ม.) — แก้ที่นี่ที่เดียว ทุกชีทบาน+หลังคาดึงไปใช้ | F1: 🏠 สารบัญ
A2: ชื่อกระจก (R3.9 ข้อ 31.1) | B2: ทุน/ตร.ม. | C2: เช็คราคาทุก 3 เดือน | D2: ⚠ ต้องเช็คราคาทุก 3 เดือน
A3: เขียว 6มม. | B3: 264
A4: เขียว 8มม. | B4: 592
A5: เขียว 10มม. | B5: 700
A6: เคลือบขาว 6มม. | B6: 1023
A7: ยูโรเกรย์ 6มม. | B7: 517
A8: ยูโรเกรย์ 8มม. | B8: 915
A9: ยูโรเกรย์ 10มม. | B9: 807
A10: ยูโรบรอนซ์ 6มม. | B10: 570
A11: reflective เทา 6มม. | B11: 1184
A12: reflective เขียว 6มม. | B12: 1292
A13: reflective ฟ้า/เทา 6มม. | B13: 1399
A14: เทมเปอร์ 6มม. | B14: 403
... A18: เทมเปอร์ใสพิเศษ 6มม. | B18: 1432
A19: เทมเปอร์ใสพิเศษ 10มม. | B19: 3466 | C19: * | D19: * ราคาสูงผิดปกติ — เช็คกับร้านทุก 3 เดือน · อัปเดตล่าสุด ส.ค.2569 · ครั้งหน้า พ.ย.2569
A20: เทมเปอร์ฝ้า 6มม. | B20: 805
A21: เทมเปอร์ฝ้า 8มม. | B21: 1113
A22: เทมเปอร์ยูโรเกรย์ 4มม. | B22: 646
A23: เทมเปอร์ยูโรเกรย์ 5มม. | B23: 678
A24: เทมเปอร์ยูโรเกรย์ 6มม. | B24: 732
A25: เทมเปอร์ยูโรเกรย์ 10มม. | B25: 1423
A26: เทมเปอร์ยูโรบรอนซ์ 5มม. | B26: 732
A27: เทมเปอร์ยูโรบรอนซ์ 6มม. | B27: 786
A28: เทมเปอร์ยูโรบรอนซ์ 10มม. | B28: 1480
A29: เทมเปอร์ reflective เทา 6มม. | B29: 2422
A30: เทมเปอร์ reflective เขียว 6มม. | B30: 2745
A31: เทมเปอร์ reflective ฟ้า 6มม. | B31: 2960
... A34: ลามิเนตใส 4+4 ฟิล์มสี 0.38 | B34: 1329
A35: ลามิเนต 4+4 Solar Max 0.76 | B35: 1766 | C35: 240 บาท/ตร.ฟ ×10.764
A36: อินซูเลท 6+6+6มม. | B36: 2260 | C36: 352 บาท/ตร.ฟ ×10.764
A37: กระจกชา/ฝ้า/ลายผ้า 5-6มม. | B37: 301
A38: กระจกเงา 5มม. | B38: 398
A39: กระจกลอนแก้ว 5มม. | B39: 646
A40: เทมเปอร์ 8มม. | B40: 716
A41: เทมเปอร์สีชาดำ 6มม. | B41: 700
A42: เทมเปอร์สีชาดำ 10มม. | B42: 6674 | C42: * | D42: * ราคาสูงผิดปกติ — เช็คกับร้านทุก 3 เดือน · อัปเดตล่าสุด ส.ค.2569 · ครั้งหน้า พ.ย.2569
A43: เทมเปอร์สีฟ้า 6มม. | B43: 807
A44: เทมเปอร์ใสพิเศษ 8มม. | B44: 2336
A45: ลามิเนต 6+6 ฟิล์ม 0.38 | B45: 893
...

Sheet คิดทุน SMS
A1: คิดทุนบานเลื่อน SMS — เลือกรูปแบบ + อุปกรณ์แยกชิ้น | G1: 🏠 สารบัญ
A2: กว้างรวม (ซม.) → | B2: 600 | E2: เลื่อน(ล้อ)= | F2: =IF(B5="อิสระ",B4,IF(B5="ลากจูง",B4-1,B4-2)) -> 3
A3: สูง (ซม.) → | B3: 300 | E3: มือจับบาน= | F3: =IF(B5="ลากจูง",1,2) -> 2
A4: จำนวนบาน → | B4: 3 | E4: ล็อคบาน= | F4: =IF(B5="อิสระ",2,1) -> 2
A5: รูปแบบ → (อิสระ/ลากจูง/เปิดคู่กลาง) | B5: อิสระ | C5: =IF(B5="","⚠ ยังไม่เลือกรูปแบบ — จำนวนเสา/ราง จะขาด","") | E5: เสากุญแจ= | F5: =IF(B5="เปิดคู่กลาง",4,2) -> 2
A6: พื้นที่ (ตร.ม.) = | B6: =(B2/100)*(B3/100) -> 18 | E6: รอยต่อ= | F6: =IF(B5="เปิดคู่กลาง",B4-2,B4-1) -> 2
A7: บวกกำไร % → | B7: =$B$62 -> 109 | C7: ← ผูกกับ "กำไรค่าวัสดุ %" ท้ายชีท (แก้ตัวเลขที่นั่น) | E7: รางล่าง → | F7: ภายนอก
A8: ราคาซิลิโคน/หลอด → | B8: 90
A9: กระจก → | B9: เขียว 6มม. | C9: =INDEX(ราคากระจก!$B$3:$B$206,MATCH(B9,ราคากระจก!$A$3:$A$206,0)) -> 264 | D9: ← ราคากระจก/ตร.ม. (อัตโนมัติ) | E9: สี → | F9: สีอบขาว/ดำ
A10: วัสดุ | B10: จำนวน | C10: ราคา/หน่วย | D10: ทุน(บาท)
A11: เฟรมบน | B11: =(1*(B2/100)/6.4)*buf_scrap -> 1.21875 | C11: =IF(F9="สีอบขาว/ดำ",IFERROR(VLOOKUP("B20001",ราคาสี!$A:$D,4,0),1125),IF(OR(F9="เทาซาฮาร่า",F9="สีดำซาฮาร่า"),VLOOKUP("B20001",ราคาสี!$A:$F,5,0),IF(F9="ลายไม้ stock",(VLOOKUP("B20001",ราคาสี!$A:$H,8,0)*mult_wood/mult_sms),IFERROR(VLOOKUP("B20001",ราคาสี!$A:$D,4,0),1125)+IF(F9="สีอบพิเศษ",rate_special,rate_woodbake)*น้ำหนักโปรไฟล์!$C$324))) -> 1265 | D11: =B11*C11*mult_sms -> 1541.7188
