Workbook

Sheet รับเข้า-เบิก
A1: ลำดับเดือน | B1: เดือน | C1: วันที่ | D1: ผู้เบิก | E1: งาน (ชื่อลูกค้า) | F1: หมวดหมู่ | G1: รายการสินค้า | H1: จำนวน | I1: Status | J1: ราคารวม | K1: Remark
C2: 244492 | F2: อุปกรณ์ | G2: STAINLESS STEEL BAR-สแตนเลส-แป๊ปสแตนเลสกลม | I2: รับเข้า
C3: 244492 | F3: อุปกรณ์ | G3: STAINLESS STEEL PIPE -สแตนเลส-แป๊ปสแตนเลสเหลี่ยม | I3: รับเข้า
C4: 244492 | F4: อุปกรณ์ | G4: บานพับ Shower VVP_SW303-สแตนเลส | H4: 6 | I4: รับเข้า
C5: 244492 | F5: อุปกรณ์ | G5: บานพับ Shower VVP_SW3049 (90 ํ)-สแตนเลส | H5: 6 | I5: รับเข้า
C6: 244492 | F6: อุปกรณ์ | G6: บานพับ Shower VVP_SW3041 (135 ํ)-สแตนเลส | H6: 2 | I6: รับเข้า
C7: 244492 | F7: อุปกรณ์ | G7: บานพับ Shower VVP_SW304 (180 ํ)-สแตนเลส | H7: 6 | I7: รับเข้า
C8: 244492 | F8: อุปกรณ์ | G8: ตัวหนีบกระจก shower VVP_GC506-สแตนเลส | H8: 6 | I8: รับเข้า
C9: 244492 | F9: อุปกรณ์ | G9: ตัวยึดร้อยผ่านแป๊ปสแตนเลสกลม VVP_SB900-สแตนเลส | H9: 21 | I9: รับเข้า
C10: 244492 | F10: อุปกรณ์ | G10: ตัวยึดกระจกห้องน้ำกันแกว่งกลม VVP_SB902-สแตนเลส | H10: 25 | I10: รับเข้า
C11: 244492 | F11: อุปกรณ์ | G11: ตัวยึดร้อยผ่านแป๊ปสแตนเลสกลม VVP_SBF906-สแตนเลส-ข้องอปรับได้ | H11: 5 | I11: รับเข้า
C12: 244492 | F12: อุปกรณ์ | G12: ตัวยึดร้อยผ่านแป๊ปสแตนเลสเหลี่ยม VVP_SBQ800-สแตนเลส | H12: 9 | I12: รับเข้า
C13: 244492 | F13: อุปกรณ์ | G13: ตัวยึดกระจกห้องน้ำกันแกว่งเหลี่ยม VVP_SBQ802-สแตนเลส | H13: 3 | I13: รับเข้า
C14: 244492 | F14: อุปกรณ์ | G14: ยางกันชนกลมเล็ก-ใส | H14: 6200 | I14: รับเข้า
C15: 244492 | F15: อุปกรณ์ | G15: ซิลิโคน 1601-ลายไม้มะฮอกนี | H15: 20 | I15: รับเข้า
... C76: 46190 | F76: น็อต | G76: พุกตะกั่ว-46113 | H76: 709 | I76: รับเข้า
C77: 46190 | F77: น็อต

Sheet มือจับ
A1: 2 | B1: รายการสินค้า | C1: รูปแบบ | D1: สี | E1: ราคา | F1: รูป | G1: ยอดคงเหลือ | H1: ยอดเบิกรวม
A2: =CONCATENATE(B2,"-",C2,"-",D2) -> มือจับประตูบานเลื่อนแขวน ทรงโค้ง HOYA-PS-102-สแตนเลส | B2: มือจับประตูบานเลื่อนแขวน ทรงโค้ง HOYA | C2: PS-102 | D2: สแตนเลส | E2: 165 | F2: messageImage_1771731392413.jpg | G2: 7 | H2: {=MAP(ตาราง1[2],LAMBDA(sku,SUMIFS('รับเข้า-เบิก'!H:H,'รับเข้า-เบิก'!G:G,sku,'รับเข้า-เบิก'!I:I,"รับเข้า")))} -> 0
A3: =CONCATENATE(B3,"-",C3,"-",D3) -> มือจับฝังบานเลื่อน Hyda 416-Dummy-ดำ | B3: มือจับฝังบานเลื่อน Hyda 416 | C3: Dummy | D3: ดำ | E3: 52 | F3: https://drive.google.com/file/d/1QDHWO3nr-M5wgnA4elVaJ-eQHqgBD8xw/view?usp=drive_link | H3: 0
A4: =CONCATENATE(B4,"-",C4,"-",D4) -> มือจับฝังบานเลื่อน Hyda 416-Dummy-อบขาว | B4: มือจับฝังบานเลื่อน Hyda 416 | C4: Dummy | D4: อบขาว | E4: 52 | F4: https://drive.google.com/file/d/1QDHWO3nr-M5wgnA4elVaJ-eQHqgBD8xw/view?usp=drive_link | H4: 0
A5: =CONCATENATE(B5,"-",C5,"-",D5) -> มือจับฝังบานเลื่อน Hyda 416-Lock-ดำ | B5: มือจับฝังบานเลื่อน Hyda 416 | C5: Lock | D5: ดำ | E5: 65 | F5: https://drive.google.com/file/d/1QDHWO3nr-M5wgnA4elVaJ-eQHqgBD8xw/view?usp=drive_link | H5: 0
A6: =CONCATENATE(B6,"-",C6,"-",D6) -> มือจับฝังบานเลื่อน Hyda 416-Lock-อบขาว | B6: มือจับฝังบานเลื่อน Hyda 416 | C6: Lock | D6: อบขาว | E6: 65 | F6: https://drive.google.com/file/d/1QDHWO3nr-M5wgnA4elVaJ-eQHqgBD8xw/view?usp=drive_link | H6: 0
A7: =CONCATENATE(B7,"-",C7,"-",D7) -> มือจับฝังบานเลื่อน CMECH-Fixed Recessed Handle-ดำ | B7: มือจับฝังบานเลื่อน CMECH | C7: Fixed Recessed Handle | D7: ดำ | E7: 177 | F7: https://drive.google.com/file/d/16OYjsugZURUYoNJGtGk8Mk_eKUm30fDo/view?usp=drive_link | H7: 0
A8: =CONCATENATE(B8,"-",C8,"-",D8) -> มือจับฝังบานเลื่อน CMECH-Fixed Recessed Handle-อบขาว | B8: มือจับฝังบานเลื่อน CMECH | C8: Fixed Recessed Handle | D8: อบขาว | E8: 177 | F8: https://drive.google.com/file/d/1YPfwbIOTDgAt2T8rjyvCA9bUXGQXI_pW/view?usp=drive_link | H8: 0
A9: =CONCATENATE(B9,"-",C9,"-",D9) -> มือจับฝังบานเลื่อน CMECH-Multi-Point Lock Recessed Handle-ดำ | B9: มือจับฝังบานเลื่อน CMECH | C9: Multi-Point Lock Recessed Handle | D9: ดำ | E9: 205 | F9: https://drive.google.com/file/d/16OYjsugZURUYoNJGtGk8Mk_eKUm30fDo/view?usp=drive_link | H9: 0
A10: =CONCATENATE(B10,"-",C10,"-",D10) -> มือจับฝังบานเลื่อน CMECH-Multi-Point Lock Recessed Handle-อบขาว | B10: มือจับฝังบานเลื่อน CMECH | C10: Multi-Point Lock Recessed Handle | D10: อบขาว | E10: 205 | F10: https://drive.google.com/file/d/1oQ1PFR9FJClH1URFkype7gtG_tI5OMXD/view?usp=drive_link | H10: 0
A11: =CONCATENATE(B11,"-",C11,"-",D11) -> มือจับฝังบานเลื่อน CMECH-Multi-Point Lock Recessed Interior with Key-ดำ | B11: มือจับฝังบานเลื่อน CMECH | C11: Multi-Point Lock Recessed Interior with Key | D11: ดำ | E11: 409 | F11: https://drive.google.com/file/d/16OYjsugZURUYoNJGtGk8Mk_eKUm30fDo/view?usp=drive_link | H11: 0
A12: =CONCATENATE(B12,"-",C12,"-",D12) -> มือจับฝังบานเลื่อน CMECH-Multi-Point Lock Recessed Interior with Key-อบขาว | B12: มือจับฝังบานเลื่อน CMECH | C12: Multi-Point Lock Recessed Interior with Key | D12: อบขาว | E12: 409 | F12: https://drive.google.com/file/d/1A7onapIUsvEaCJjVirEGUCIuIepa73ij/view?usp=drive_link | H12: 0
A13: =CONCATENATE(B13,"-",C13,"-",D13) -> มือจับบานเลื่อน CMECH-Metro Handle_ Dummy-ดำ | B13: มือจับบานเลื่อน CMECH | C13: Metro Handle_ Dummy | D13: ดำ | E13: 310 | F13: https://drive.google.com/file/d/13KMHBhhROiy8TA_iLOEILmrZxELdaCSQ/view?usp=drive_link | H13: 0
A14: =CONCATENATE(B14,"-",C14,"-",D14) -> มือจับบานเลื่อน CMECH-Metro Handle_ Dummy-อบขาว | B14: มือจับบานเลื่อน CMECH | C14: Metro Handle_ Dummy | D14: อบขาว | E14: 310 | F14: https://drive.google.com/file/d/18Iq4OGDLz5gZ3-hGwpCsdZqg0bOmxS23/view?usp=drive_link | H14: 0
... A29: =CONCATENATE(B29,"-",C29,"-",D29) -> มือจับบานกระทุ้ง CZ-HD-004-CENZA_ ( L )-อบขาว | B29: มือจับบานกระทุ้ง CZ-HD-004 | C29: CENZA_ ( L ) | D29: อบขาว | E29: 150 | F29: https://drive.google.com/file/d/1yqTzaZthUyMyVVJ4Hr4kGUZudI-4oSfn/view?usp=drive_link | H29: 0
A30: =CONCATENATE(B30,"-",C30,"-",D30) -> มือจับบานกระทุ้ง CZ-HD-004-CENZA_ ( R )-อบขาว | B30: มือจับบานกระทุ้ง CZ-HD-004 | C30: CENZA_ ( R ) | D30: อบขาว | E30: 150 | F30: https://drive.google.com/file/d/1yqTzaZthUyMyVVJ4Hr4kGUZudI-4oSfn/view?usp=drive_link | G30: 56 | H30: 0
A31: =CONCATENATE(B31,"-",C31,"-",D31) -> มือจับบานกระทุ้ง CZ-HD-004-CENZA_ ( L )-ดำ | B31: มือจับบานกระทุ้ง CZ-HD-004 | C31: CENZA_ ( L ) | D31: ดำ | E31: 150 | F31: https://drive.google.com/file/d/1yqTzaZthUyMyVVJ4Hr4kGUZudI-4oSfn/view?usp=drive_link | G31: 6 | H31: 0
A32: =CONCATENATE(B32,"-",C32,"-",D32) -> มือจับบานกระทุ้ง CZ-HD-004-CENZA_ ( R )-ดำ | B32: มือจับบานกระทุ้ง CZ-HD-004 | C32: CENZA_ ( R ) | D32: ดำ | E32: 150 | F32: https://drive.google.com/file/d/1yqTzaZthUyMyVVJ4Hr4kGUZudI-4oSfn/view?usp=drive_link | G32: 43 | H32: 0
A33: =CONCATENATE(B33,"-",C33,"-",D33) -> มือจับบานกระทุ้งหลบมุ้ง-CMECH_ ( L )-อบขาว | B33: มือจับบานกระทุ้งหลบมุ้ง | C33: CMECH_ ( L ) | D33: อบขาว | E33: 360 | F33: https://drive.google.com/file/d/11sT_smtcC_H80DHesHnGiRfzAbNQbVTe/view?usp=drive_link | H33: 0
A34: =CONCATENATE(B34,"-",C34,"-",D34) -> มือจับบานกระทุ้งหลบมุ้ง-CMECH_ ( R )-อบขาว | B34: มือจับบานกระทุ้งหลบมุ้ง | C34: CMECH_ ( R ) | D34: อบขาว | E34: 360 | F34: https://drive.google.com/file/d/1AdA7WF_sgAFIMtOFdU8oHYru4ATP1V5t/view?usp=drive_link | H34: 0
A35: =CONCATENATE(B35,"-",C35,"-",D35) -> มือจับบานกระทุ้งหลบมุ้ง-CMECH_ ( L )-ดำ | B35: มือจับบานกระทุ้งหลบมุ้ง | C35: CMECH_ ( L ) | D35: ดำ | E35: 360 | F35: https://drive.google.com/file/d/11sT_smtcC_H80DHesHnGiRfzAbNQbVTe/view?usp=drive_link | H35: 0
A36: =CONCATENATE(B36,"-",C36,"-",D36) -> มือจับบานกระทุ้งหลบมุ้ง-CMECH_ ( R )-ดำ | B36: มือจับบานกระทุ้งหลบมุ้ง | C36: CMECH_ ( R ) | D36: ดำ | E36: 360 | F36: https://drive.google.com/file/d/1AdA7WF_sgAFIMtOFdU8oHYru4ATP1V5t/view?usp=drive_link | H36: 0
A37: =CONCATENATE(B37,"-",C37,"-",D37) -> มือจับบานเปิด KINGBO-Dummy-ดำ | B37: มือจับบานเปิด KINGBO | C37: Dummy | D37: ดำ | E37: 330 | F37: https://drive.google.com/file/d/1CzNNZtaQSx58dLHn-v4pek6syK3CjfRh/view?usp=drive_link | H37: 0
A38: =CONCATENATE(B38,"-",C38,"-",D38) -> มือจับบานเปิด KINGBO-Dummy-อบขาว | B38: มือจับบานเปิด KINGBO | C38: Dummy | D38: อบขาว | E38: 330 | F38: https://drive.google.com/file/d/1CzNNZtaQSx58dLHn-v4pek6syK3CjfRh/view?usp=drive_link | H38: 0
A39: =CONCATENATE(B39,"-",C39,"-",D39) -> มือจับบานเปิด KINGBO-Key-ดำ | B39: มือจับบานเปิด KINGBO | C39: Key | D39: ดำ | E39: 330 | F39: https://drive.google.com/file/d/1CzNNZtaQSx58dLHn-v4pek6syK3CjfRh/view?usp=drive_link | H39: 0
A40: =CONCATENATE(B40,"-",C40,"-",D40) -> มือจับบานเปิด KINGBO-Key-อบขาว | B40: มือจับบานเปิด KINGBO | C40: Key | D40: อบขาว | E40: 330 | F40: https://drive.google.com/file/d/1CzNNZtaQSx58dLHn-v4pek6syK3CjfRh/view?usp=drive_link | H40: 0
A41: =CONCATENATE(B41,"-",C41,"-",D41) -> มือจับหลบมุ้ง KINGBO-FH3016 _( L )-ดำ | B41: มือจับหลบมุ้ง KINGBO | C41: FH3016 _( L ) | D41: ดำ | E41: 111 | F41: https://drive.google.com/file/d/1UfA5qP-6SVkGhRa3Tp7xI6eoFKUfCPCB/view?usp=drive_link | H41: 0
A42: =CONCATENATE(B42,"-",C42,"-",D42) -> มือจับหลบมุ้ง KINGBO-FH3016 _ ( R )-ดำ | B42: มือจับหลบมุ้ง KINGBO | C42: FH3016 _ ( R ) | D42: ดำ | E42: 111 | F42: https://drive.google.com/file/d/1UfA5qP-6SVkGhRa3Tp7xI6eoFKUfCPCB/view?usp=drive_link | H42: 0
A43: =CONCATENATE(B43,"-",C43,"-",D43) -> มือจับหลบมุ้ง KINGBO-FH3016 _( L )-อบขาว | B43: มือจับหลบมุ้ง KINGBO | C43: FH3016 _( L ) | D43: อบขาว | E43: 111 | F43: https://drive.google.com/file/d/1UfA5qP-6SVkGhRa3Tp7xI6eoFKUfCPCB/view?usp=drive_link | H43: 0
A44: =CONCATENATE(B44,"-",C44,"-",D44) -> มือจับหลบมุ้ง KINGBO-FH3016 _ ( R )-อบขาว | B44: มือจับหลบมุ้ง KINGBO | C44: FH3016 _ ( R ) | D44: อบขาว | E44: 111 | F44: https://drive.google.com/file/d/1UfA5qP-6SVkGhRa3Tp7xI6eoFKUfCPCB/view?usp=drive_link | H44: 0
A45: =CONCATENATE(B45,"-",C45,"-",D45) -> มือจับฝัง Align-กุญแจ-ดำ | B45: มือจับฝัง Align | C45: กุญแจ | D45: ดำ | F45: https://drive.google.com/file/d/14xn-NCGqq5FDwmKcrNFIH3Y0jgKMHVLR/view?usp=drive_link | H45: 0
A46: =CONCATENATE(B46,"-",C46,"-",D46) -> มือจับฝัง Align-ล็อค-ดำ | B46: มือจับฝัง Align | C46: ล็อค | D46: ดำ | E46: 99 | F46: https://drive.google.com/file/d/17a-BLx9DUbFFvlM65kF9uzsI_cF4hjOa/view?usp=drive_link | H46: 0
A47: =CONCATENATE(B47,"-",C47,"-",D47) -> มือจับฝัง Align-ดัมมี่-ดำ | B47: มือจับฝัง Align | C47: ดัมมี่ | D47: ดำ | F47: https://drive.google.com/file/d/1jkF6sE7gE2qin-TU4c9O6fDTcLPF-VPF/view?usp=drive_link | H47: 0
A48: =CONCATENATE(B48,"-",C48,"-",D48) -> มือจับฝัง Align-กุญแจ-อบขาว | B48: มือจับฝัง Align | C48: กุญแจ | D48: อบขาว | F48: https://drive.google.com/file/d/1kVoAE29b5HZ47jPP3tp3R7cVC2DaPHhF/view?usp=drive_link | H48: 0
A49: =CONCATENATE(B49,"-",C49,"-",D49) -> มือจับฝัง Align-ล็อค-อบขาว | B49: มือจับฝัง Align | C49: ล็อค | D49: อบขาว | E49: 99 | F49: https://drive.google.com/file/d/1--kH-jLxk-mvlxO1VbJG0j2wCNCZ8rJV/view?usp=drive_link | H49: 0
A50: =CONCATENATE(B50,"-",C50,"-",D50) -> มือจับฝัง Align-ดัมมี่-อบขาว | B50: มือจับฝัง Align | C50: ดัมมี่ | D50: อบขาว | F50: https://drive.google.com/file/d/12BkwuHiy8V7tjRcnag-IqhGsEdNncckI/view?usp=drive_link | H50: 0
A51: =CONCATENATE(B51,"-",C51,"-",D51) -> มือจับ Husza-กุญแจ-ดำ | B51: มือจับ Husza | C51: กุญแจ | D51: ดำ | F51: https://drive.google.com/file/d/1Mrx2fZQtLIdGoZ6DayomFj2MIcnyJikb/view?usp=drive_link | G51: 26 | H51: 0
A52: =CONCATENATE(B52,"-",C52,"-",D52) -> มือจับ Husza-ล็อค-ดำ | B52: มือจับ Husza | C52: ล็อค | D52: ดำ | F52: https://drive.google.com/file/d/1PTZJOVslhamOOtBX5JHGOCEzeioveytr/view?usp=drive_link | G52: 20 | H52: 0
A53: =CONCATENATE(B53,"-",C53,"-",D53) -> มือจับ Husza-เรียบมีรู-ดำ | B53: มือจับ Husza | C53: เรียบมีรู | D53: ดำ | F53: https://drive.google.com/file/d/11Yy2PiRWZda70M1rEREhVQ8BnRKRBYET/view | H53: 0
A54: =CONCATENATE(B54,"-",C54,"-",D54) -> มือจับ Husza-เรียบไม่มีรู-ดำ | B54: มือจับ Husza | C54: เรียบไม่มีรู | D54: ดำ | F54: https://drive.google.com/file/d/11Yy2PiRWZda70M1rEREhVQ8BnRKRBYET/view?usp=drive_link | G54: 48 | H54: 0
...

Sheet อุปกรณ์ 
A1: SKU | B1: รายการสินค้า | C1: สี | D1: ขนาด | E1: ราคา | F1: รูป | G1: ยอดคงเหลือ | H1: ยอดเบิกรวม
A2: {=BYROW(ตาราง1_2[[รายการสินค้า]:[ขนาด]], LAMBDA(row, TEXTJOIN("-", TRUE, row)))} -> STAINLESS STEEL PIPE -สแตนเลส-แป๊ปสแตนเลสเหลี่ยม | B2: STAINLESS STEEL PIPE | C2: สแตนเลส | D2: แป๊ปสแตนเลสเหลี่ยม | E2: 360 | F2: https://drive.google.com/file/d/1ksID7nRhz3chKkhg6cWrW0jLPsdB6NaU/view?usp=drive_link | G2: {=MAP(ตาราง1_2[SKU],LAMBDA(sku,LET(in,SUMIFS('รับเข้า-เบิก'!H:H,'รับเข้า-เบิก'!G:G,sku,'รับเข้า-เบิก'!I:I,"รับเข้า"),out,SUMIFS('รับเข้า-เบิก'!H:H,'รับเข้า-เบิก'!G:G,sku,'รับเข้า-เบิก'!I:I,"เบิกออก"),IF(in-out=0,"",in-out))))} -> #REF! | H2: {=MAP(ตาราง1_2[SKU],LAMBDA(sku,SUMIFS('รับเข้า-เบิก'!H:H,'รับเข้า-เบิก'!G:G,sku,'รับเข้า-เบิก'!I:I,"รับเข้า")))} -> 0
A3: STAINLESS STEEL BAR-สแตนเลส-แป๊ปสแตนเลสกลม | B3: STAINLESS STEEL BAR | C3: สแตนเลส | D3: แป๊ปสแตนเลสกลม | E3: 430 | F3: https://drive.google.com/file/d/1f9LDjFr0kE-JpOrBRHx5K8bvBqCzR_lz/view?usp=drive_link | H3: 0
A4: บานพับ Shower VVP_SW303-สแตนเลส | B4: บานพับ Shower VVP_SW303 | C4: สแตนเลส | E4: 750 | F4: https://drive.google.com/file/d/179_ic3tBj9T4rt60oL0qAf3sgYM6XJa5/view?usp=drive_link | G4: 6 | H4: 6
A5: บานพับ Shower VVP_SW3049 (90 ํ)-สแตนเลส | B5: บานพับ Shower VVP_SW3049 (90 ํ) | C5: สแตนเลส | E5: 1450 | F5: https://drive.google.com/file/d/1zcRe5qoyo7DsctL7G5B4eEUcpIDRzG7t/view?usp=drive_link | G5: 6 | H5: 6
A6: บานพับ Shower VVP_SW3041 (135 ํ)-สแตนเลส | B6: บานพับ Shower VVP_SW3041 (135 ํ) | C6: สแตนเลส | E6: 1450 | F6: https://drive.google.com/file/d/1cie-F3YvmhMyeu35k7CkcFYknVdt73hD/view?usp=drive_link | G6: 2 | H6: 2
A7: บานพับ Shower VVP_SW304 (180 ํ)-สแตนเลส | B7: บานพับ Shower VVP_SW304 (180 ํ) | C7: สแตนเลส | E7: 1450 | F7: https://drive.google.com/file/d/12gJnGoI1OJBSf2DUI7DCgx95PPR5ZVe-/view?usp=drive_link | G7: 6 | H7: 6
A8: ชุดอุปกรณ์บานเลื่อนห้องน้ำ Shower Room-สแตนเลส | B8: ชุดอุปกรณ์บานเลื่อนห้องน้ำ Shower Room | C8: สแตนเลส | E8: 3500 | F8: https://drive.google.com/file/d/1CP0SEI1nZrIqu8U2mTgA7aLlIJKiA_HS/view?usp=drive_link | H8: 0
A9: ตัวหนีบกระจก shower VVP_GC506-สแตนเลส | B9: ตัวหนีบกระจก shower VVP_GC506 | C9: สแตนเลส | E9: 175 | F9: https://drive.google.com/file/d/1rVhOBJtk39nfGt1Aho6GwF-jqLP15tjY/view?usp=drive_link | G9: 6 | H9: 6
A10: ตัวยึดร้อยผ่านแป๊ปสแตนเลสกลม VVP_SB900-สแตนเลส | B10: ตัวยึดร้อยผ่านแป๊ปสแตนเลสกลม VVP_SB900 | C10: สแตนเลส | E10: 288 | F10: https://drive.google.com/file/d/1asdMGHOpEWk6YPdQz7a8PPH_2qx7UhwO/view?usp=drive_link | G10: 21 | H10: 21
A11: ตัวยึดกระจกห้องน้ำกันแกว่งกลม VVP_SB902-สแตนเลส | B11: ตัวยึดกระจกห้องน้ำกันแกว่งกลม VVP_SB902 | C11: สแตนเลส | E11: 288 | F11: https://drive.google.com/file/d/1-8sa7LWjZYvYdfio52wWpJjMibJXsUWr/view?usp=drive_link | G11: 25 | H11: 25
A12: ตัวยึดร้อยผ่านแป๊ปสแตนเลสกลม VVP_SBF906-สแตนเลส-ข้องอปรับได้ | B12: ตัวยึดร้อยผ่านแป๊ปสแตนเลสกลม VVP_SBF906 | C12: สแตนเลส | D12: ข้องอปรับได้ | E12: 378 | F12: https://drive.google.com/file/d/13-gR4AOYZ_rK4aJE3Fad5R-J1gfy6OmT/view?usp=drive_link | H12: 5
A13: ตัวยึดร้อยผ่านแป๊ปสแตนเลสเหลี่ยม VVP_SBQ800-สแตนเลส | B13: ตัวยึดร้อยผ่านแป๊ปสแตนเลสเหลี่ยม VVP_SBQ800 | C13: สแตนเลส | E13: 450 | F13: https://drive.google.com/file/d/1vHOxAqyjZmIKUv5ML6lMnC6dhY-LLKlM/view?usp=drive_link | H13: 9
A14: ตัวยึดกระจกห้องน้ำกันแกว่งเหลี่ยม VVP_SBQ802-สแตนเลส | B14: ตัวยึดกระจกห้องน้ำกันแกว่งเหลี่ยม VVP_SBQ802 | C14: สแตนเลส | E14: 468 | F14: https://drive.google.com/file/d/1JkPJBqFqjhV9DF2HNH69Ixh3w17RqlEj/view?usp=drive_link | G14: 3 | H14: 3
A15: ตัวยึดร้อยผ่านแป๊ปสแตนเลสเหลี่ยม VVP_SBQ806-สแตนเลส-ข้องอปรับได้ | B15: ตัวยึดร้อยผ่านแป๊ปสแตนเลสเหลี่ยม VVP_SBQ806 | C15: สแตนเลส | D15: ข้องอปรับได้ | E15: 585 | F15: https://drive.google.com/file/d/1q4KrE1fMzGoSdTKE_rULuYSR9BQTEhCF/view?usp=drive_link | H15: 0
A16: ตัวหนีบกระจกล่าง VVP_ FT10 -สแตนเลส-5.5X17X3.5 cm. | B16: ตัวหนีบกระจกล่าง VVP_ FT10 | C16: สแตนเลส | D16: 5.5X17X3.5 cm. | E16: 505 | F16: https://drive.google.com/file/d/1HsoF6GcgQ96nI5LUH6gUo845IJwpHtxf/view?usp=drive_link | H16: 0
A17: ตัวหนีบกระจกบน VVP_ FT20-สแตนเลส-5.5X17X3.5 cm. | B17: ตัวหนีบกระจกบน VVP_ FT20 | C17: สแตนเลส | D17: 5.5X17X3.5 cm. | E17: 505 | F17: https://drive.google.com/file/d/1VUtnfjeVQxRr2zGWXChcWNVo7ns7Mtdz/view?usp=drive_link | H17: 0
A18: ตัวหนีบกระจกบน VVP_ FT30-สแตนเลส-5.5X17X3.5 cm. | B18: ตัวหนีบกระจกบน VVP_ FT30 | C18: สแตนเลส | D18: 5.5X17X3.5 cm. | E18: 550 | F18: https://drive.google.com/file/d/1TAfZE-ck8oGq9ego9TxG2RQp32Ob0x0o/view?usp=drive_link | H18: 0
A19: กุญแจล็อคประตูกับพื้น VVP_ FT50-สแตนเลส-7.2X17.3X8.2 cm. | B19: กุญแจล็อคประตูกับพื้น VVP_ FT50 | C19: สแตนเลส | D19: 7.2X17.3X8.2 cm. | E19: 1255 | F19: https://drive.google.com/file/d/1aweHuGJKBBI-ITDxY7XznOlbd1DRHkyC/view?usp=drive_link | H19: 0
A20: กุญแจล็อคประตูกับพื้น VVP_ FL50-สแตนเลส-7.2X17.3X8.2 cm. | B20: กุญแจล็อคประตูกับพื้น VVP_ FL50 | C20: สแตนเลส | D20: 7.2X17.3X8.2 cm. | E20: 1255 | F20: https://drive.google.com/file/d/1Xa31m8s8-VoyiieO33yoxHsfTsKTzpZi/view?usp=drive_link | H20: 0
A21: กุญแจล็อคล็อคกลางบาน VVP_ FL52-สแตนเลส-7.5X17X6 cm. | B21: กุญแจล็อคล็อคกลางบาน VVP_ FL52 | C21: สแตนเลส | D21: 7.5X17X6 cm. | E21: 1255 | F21: https://drive.google.com/file/d/1D6ivCfLG7Xjnetl45UYMTSMB-UaBdg87/view?usp=drive_link | H21: 0
A22: โช้คประตูบานสวิง Diamond-800mm | B22: โช้คประตูบานสวิง Diamond | D22: 800mm | E22: 1120 | F22: https://drive.google.com/file/d/1gqLMBoTN0FEvV4sUZuNFNObrdtc157OR/view?usp=drive_link | H22: 0
A23: โช้คประตูบานสวิง Diamond-1000mm | B23: โช้คประตูบานสวิง Diamond | D23: 1000mm | E23: 1120 | F23: https://drive.google.com/file/d/1gqLMBoTN0FEvV4sUZuNFNObrdtc157OR/view?usp=drive_link | H23: 0
A24: โช้คประตูบานสวิง Diamond-1200mm | B24: โช้คประตูบานสวิง Diamond | D24: 1200mm | E24: 1120 | F24: https://drive.google.com/file/d/1gqLMBoTN0FEvV4sUZuNFNObrdtc157OR/view?usp=drive_link | H24: 0
A25: โช้คประตูตั้งค้าง VVP_DC98 -สแตนเลส-27X8.5X8.5 cm. | B25: โช้คประตูตั้งค้าง VVP_DC98 | C25: สแตนเลส | D25: 27X8.5X8.5 cm. | E25: 775 | F25: https://drive.google.com/file/d/1v2V3uSiBIde3fo9U1Z1NA-v144MKSNoC/view?usp=drive_link | H25: 0
A26: โช้คประตูไม่ตั้งค้าง VVP_DC98-สแตนเลส-27X8.5X8.5 cm. | B26: โช้คประตูไม่ตั้งค้าง VVP_DC98 | C26: สแตนเลส | D26: 27X8.5X8.5 cm. | E26: 645 | F26: https://drive.google.com/file/d/1v2V3uSiBIde3fo9U1Z1NA-v144MKSNoC/view?usp=drive_link | H26: 0
A27: โช้คประตูตั้งค้าง VVP_DC98 -ดำ-27X8.5X8.5 cm. | B27: โช้คประตูตั้งค้าง VVP_DC98 | C27: ดำ | D27: 27X8.5X8.5 cm. | E27: 775 | F27: https://drive.google.com/file/d/1Og9EfRVllVvA3LN9IZ8AL613wI9cJRRn/view?usp=drive_link | H27: 0
A28: โช้คประตูไม่ตั้งค้าง VVP_DC98-ดำ-27X8.5X8.5 cm. | B28: โช้คประตูไม่ตั้งค้าง VVP_DC98 | C28: ดำ | D28: 27X8.5X8.5 cm. | E28: 645 | F28: https://drive.google.com/file/d/1Og9EfRVllVvA3LN9IZ8AL613wI9cJRRn/view?usp=drive_link | H28: 0
A29: โช้คประตูตั้งค้าง VVP_DC100-สแตนเลส-31X10X9.5 cm. | B29: โช้คประตูตั้งค้าง VVP_DC100 | C29: สแตนเลส | D29: 31X10X9.5 cm. | E29: 1115 | F29: https://drive.google.com/file/d/1v2V3uSiBIde3fo9U1Z1NA-v144MKSNoC/view?usp=drive_link | H29: 0
A30: โช้คประตูไม่ตั้งค้าง VVP_DC100-สแตนเลส-31X10X9.5 cm. | B30: โช้คประตูไม่ตั้งค้าง VVP_DC100 | C30: สแตนเลส | D30: 31X10X9.5 cm. | E30: 1030 | F30: https://drive.google.com/file/d/1v2V3uSiBIde3fo9U1Z1NA-v144MKSNoC/view?usp=drive_link | H30: 0
A31: โช้คประตูตั้งค้าง VVP_DC100-ดำ-31X10X9.5 cm. | B31: โช้คประตูตั้งค้าง VVP_DC100 | C31: ดำ | D31: 31X10X9.5 cm. | E31: 1115 | F31: https://drive.google.com/file/d/1Og9EfRVllVvA3LN9IZ8AL613wI9cJRRn/view?usp=drive_link | H31: 0
A32: โช้คประตูไม่ตั้งค้าง VVP_DC100-ดำ-31X10X9.5 cm. | B32: โช้คประตูไม่ตั้งค้าง VVP_DC100 | C32: ดำ | D32: 31X10X9.5 cm. | E32: 1030 | F32: https://drive.google.com/file/d/1Og9EfRVllVvA3LN9IZ8AL613wI9cJRRn/view?usp=drive_link | H32: 0
A33: กันชนประตูแม่เหล็กแท่ง SOLO-สแตนเลส | B33: กันชนประตูแม่เหล็กแท่ง SOLO | C33: สแตนเลส | E33: 169 | F33: https://drive.google.com/file/d/1GBa2YgVXlGOd-7hO6GBV7AiULy8xvl-m/view?usp=drive_link | H33: 0
A34: กันชนประตูโดมติดพื้น solex-สแตนเลส | B34: กันชนประตูโดมติดพื้น solex | C34: สแตนเลส | E34: 115 | F34: https://drive.google.com/file/d/14NFWgK4c5mjh3_c0RlLanooN3iRzpM1e/view?usp=drive_link | H34: 0
A35: กันชนประตูแม่เหล็กติดพื้น-สแตนเลส | B35: กันชนประตูแม่เหล็กติดพื้น | C35: สแตนเลส | E35: 90 | F35: https://drive.google.com/file/d/1F8rYuemhlSYEMuYxhfVNxfowuheyOcq1/view?usp=drive_link | H35: 0
A36: กันชนประตูแม่เหล็กติดพื้น-ดำ | B36: กันชนประตูแม่เหล็กติดพื้น | C36: ดำ | E36: 90 | F36: https://drive.google.com/file/d/1HbAtdXWKvM_MVt0_1hD_1ViVSvldSQOM/view?usp=drive_link | H36: 0
A37: ยางกันชนเหลี่ยม-อบขาว | B37: ยางกันชนเหลี่ยม | C37: อบขาว | E37: 3 | F37: https://drive.google.com/file/d/1ouxNB50MyvHVo7pMGVlYj36BmEFSDr8D/view?usp=drive_link | H37: 0
A38: ยางกันชนเหลี่ยม-ดำ | B38: ยางกันชนเหลี่ยม | C38: ดำ | E38: 3 | F38: https://drive.google.com/file/d/15rpGty_WFB58dv-4jIoTRB5NYAts9BUg/view?usp=drive_link | H38: 0
A39: ยางกันชนกลมเล็ก-ดำ | B39: ยางกันชนกลมเล็ก | C39: ดำ | E39: 1.5 | F39: https://drive.google.com/file/d/17-GsJNdO5HsU1VRnag2InV8z6-UpXSQo/view?usp=drive_link | H39: 0
A40: ล็อคกลางบานเลื่อน ( ล็อคก้นหอย )_ L-อบขาว | B40: ล็อคกลางบานเลื่อน ( ล็อคก้นหอย )_ L | C40: อบขาว | E40: 140 | F40: https://drive.google.com/file/d/1gmGd6H2JPr2d3r5X-Sr_DTBGgoHr6VCS/view?usp=drive_link | H40: 0
...

Sheet ยาง สักหลาด
A1: SKU | B1: รายการสินค้า | C1: ขนาด | D1: ราคา | E1: รูป | F1: ยอดคงเหลือ | G1: ยอดเบิกรวม
A2: {=BYROW(ตาราง1_3[[รายการสินค้า]:[ขนาด]], LAMBDA(row, TEXTJOIN("-", TRUE, row)))} -> ยาง 044-40 | B2: ยาง 044 | C2: 40 | D2: 7.5 | E2: https://drive.google.com/file/d/1INtP8GlPhcVtEnMM69njHrcpBQZCPOMI/view?usp=drive_link | F2: 9 | G2: {=MAP(ตาราง1_3[SKU],LAMBDA(sku,SUMIFS('รับเข้า-เบิก'!H:H,'รับเข้า-เบิก'!G:G,sku,'รับเข้า-เบิก'!I:I,"รับเข้า")))} -> 0
A3: ยาง 045 | B3: ยาง 045 | D3: 10.5 | E3: https://drive.google.com/file/d/1W-3wrjOk-j633M1kbAOOAdcIw0q6zk-Q/view?usp=drive_link | F3: 11 | G3: 0
A4: ยางรองกระจก EPK-737 | B4: ยางรองกระจก EPK-737 | D4: 8.5 | E4: https://drive.google.com/file/d/1n4Rsw9Xi0TWL3WYjPp5M5L5-qyB_k-en/view?usp=drive_link | F4: 7 | G4: 0
A5: ยาง epdm sponge EFK77-4.7 | B5: ยาง epdm sponge EFK77-4.7 | D5: 5.5 | E5: https://drive.google.com/file/d/18K6afXdDh21gnHMnXiEdhBgUssJSgUq4/view?usp=drive_link | F5: 20 | G5: 0
A6: ยาง epdm sponge แบน EFK9-4 | B6: ยาง epdm sponge แบน EFK9-4 | D6: 5 | E6: https://drive.google.com/file/d/18K6afXdDh21gnHMnXiEdhBgUssJSgUq4/view?usp=drive_link | F6: 5 | G6: 0
A7: ยางรองหลังคา EPJ-230 | B7: ยางรองหลังคา EPJ-230 | E7: https://drive.google.com/file/d/1KMBkINbZcXgl8pqMkS1gLZsyyDE3hWvz/view?usp=drive_link | F7: 10 | G7: 0
A8: ยางชินโคไลท์ EPT-409-5.8 | B8: ยางชินโคไลท์ EPT-409-5.8 | E8: https://drive.google.com/file/d/1-KoAeIUiHui-cv7C3iGK1pQ8xjte27Ry/view?usp=drive_link | F8: 18 | G8: 0
A9: สักหลาดจีน 5*3 | B9: สักหลาดจีน 5*3 | D9: 1.5 | E9: https://drive.google.com/file/d/1VJgdPdJT7cVKdS06x7Z4GmpfhiL1Lhyr/view?usp=drive_link | G9: 0
A10: สักหลาดจีน 5*4 | B10: สักหลาดจีน 5*4 | D10: 1.5 | E10: https://drive.google.com/file/d/1VJgdPdJT7cVKdS06x7Z4GmpfhiL1Lhyr/view?usp=drive_link | G10: 0
A11: สักหลาดจีน 3.5*4.8 | B11: สักหลาดจีน 3.5*4.8 | D11: 1.5 | E11: https://drive.google.com/file/d/1VJgdPdJT7cVKdS06x7Z4GmpfhiL1Lhyr/view?usp=drive_link | G11: 0
A12: สักหลาดแถบกาว Hyda | B12: สักหลาดแถบกาว Hyda | D12: 10.5 | E12: https://drive.google.com/file/d/1gcvmGbvoWB6VRGktNYNCAaVjTX7F4nd7/view?usp=drive_link | G12: 0
A13: ยางกันน้ำ Shower VVP_PS11 | B13: ยางกันน้ำ Shower VVP_PS11 | E13: https://drive.google.com/file/d/1PQkIKUhKauZmj0VNK3LXbfC7qw1GZi-S/view?usp=drive_link | G13: 0
A14: ยางกันน้ำ Shower VVP_PS12A | B14: ยางกันน้ำ Shower VVP_PS12A | E14: https://drive.google.com/file/d/1AHM5YbMF5E2GiqjG7fIrZ9l4vCgn3qTq/view?usp=drive_link | G14: 0
A15: ยางกันน้ำ Shower VVP_PS14 | B15: ยางกันน้ำ Shower VVP_PS14 | E15: https://drive.google.com/file/d/1Ifo3qmXa24gWSF0DaVPYjleKuQgEL-zj/view?usp=drive_link | G15: 0
A16: ยางอัดตัวเล็ก 044 | B16: ยางอัดตัวเล็ก 044 | E16: https://drive.google.com/file/d/1INtP8GlPhcVtEnMM69njHrcpBQZCPOMI/view?usp=drive_link | G16: 0
A17: ยางอัดตัวใหญ่ 044 | B17: ยางอัดตัวใหญ่ 044 | E17: https://drive.google.com/file/d/1INtP8GlPhcVtEnMM69njHrcpBQZCPOMI/view?usp=drive_link | G17: 0
A18: ยางอัด-5 | B18: ยางอัด | C18: 5 | E18: https://drive.google.com/file/d/1T0btq0YadIEg6cf25v-qKResBXRxoo2x/view?usp=drive_link | F18: 7 | G18: 0
A19: ยางอัด-6 | B19: ยางอัด | C19: 6 | E19: https://drive.google.com/file/d/17LqeJqbwtfMRi-bmJzbw1luHLjkUz7Oq/view?usp=drive_link | F19: 6 | G19: 0
A20: ยางอัด-13 | B20: ยางอัด | C20: 13 | E20: https://drive.google.com/file/d/14I689Lnmyqrya-YjCqfpBndnaJUQdoLm/view?usp=drive_link | F20: 9 | G20: 0
A21: ยางอัด-15 | B21: ยางอัด | C21: 15 | E21: https://drive.google.com/file/d/1kn6FKRXfG19mLgKHF7YvT35kPy2U-Ket/view?usp=drive_link | F21: 7 | G21: 0
A22: ยางเดิน-4 | B22: ยางเดิน | C22: 4 | E22: https://drive.google.com/file/d/1cGe6rhgxKL9NxGkh0OFJ3_DHj_Wn6plN/view?usp=drive_link | F22: 4 | G22: 0
A23: ยางหุ้ม 6mm-1 | B23: ยางหุ้ม 6mm | C23: 1 | E23: https://drive.google.com/file/d/114AkNjl_OkFFTcx9yoEdR_pLT7In7EXJ/view?usp=drive_link | F23: 15 | G23: 0
A24: ยางหุ้ม 5mm-2 | B24: ยางหุ้ม 5mm | C24: 2 | E24: https://drive.google.com/file/d/1_Q1dOetT3K3AYQZnff-cKf3geIIJruTE/view?usp=drive_link | F24: 7 | G24: 0
A25: ยางบานเปิดตัวเตี้ย | B25: ยางบานเปิดตัวเตี้ย | E25: https://drive.google.com/file/d/18K6afXdDh21gnHMnXiEdhBgUssJSgUq4/view?usp=drive_link | G25: 0
A26: ยางแบนหลังคา | B26: ยางแบนหลังคา | E26: https://drive.google.com/file/d/1KMBkINbZcXgl8pqMkS1gLZsyyDE3hWvz/view?usp=drive_link | G26: 0
A27: ยางโพลีคาร์บอเนต | B27: ยางโพลีคาร์บอเนต | E27: https://drive.google.com/file/d/1vx1VsDBZ3oYrmTUtumr4gDMHTOvgXaRl/view?usp=drive_link | F27: 7 | G27: 0
A28: สักหลาดคุณจรูญ | B28: สักหลาดคุณจรูญ | D28: 1100 | E28: https://drive.google.com/file/d/1gcvmGbvoWB6VRGktNYNCAaVjTX7F4nd7/view?usp=drive_link | G28: 0
A29: สักหลาด สีดำ-5X3 | B29: สักหลาด สีดำ | C29: 5X3 | E29: https://drive.google.com/file/d/1c97g7BDEk6nHWVAaQ3uuehJ4D2yA4YPQ/view?usp=drive_link | F29: 104 | G29: 0
A30: สักหลาด สีดำ + สีเทา-5X4 | B30: สักหลาด สีดำ + สีเทา | C30: 5X4 | E30: https://drive.google.com/file/d/1EOxhCmbCO9No1p7MSG1fB7SVFUNftTJZ/view?usp=drive_link | F30: 60 | G30: 0
A31: สักหลาด สีเทา-5X5 | B31: สักหลาด สีเทา | C31: 5X5 | E31: https://drive.google.com/file/d/1q29ExkwQGSd39tXmpOejsFBXDw-UTniU/view?usp=drive_link | F31: 17 | G31: 0
A32: สักหลาด สีเทา-5X6 | B32: สักหลาด สีเทา | C32: 5X6 | E32: https://drive.google.com/file/d/1IkuczwtzmxiBF__BgZPkXZnt47fSPnpR/view?usp=drive_link | F32: 15 | G32: 0
A33: สักหลาด สีเทา-5X7 | B33: สักหลาด สีเทา | C33: 5X7 | E33: https://drive.google.com/file/d/1qA9MMiCtwGG5Ay2P3V8ZgKcNbK_KElF5/view?usp=drive_link | F33: 4 | G33: 0
A34: สักหลาด สีเทา-5X12 | B34: สักหลาด สีเทา | C34: 5X12 | E34: https://drive.google.com/file/d/10iYmud4Db1MnOxkhnZL5jkdyWy3aksKA/view?usp=drive_link | F34: 2 | G34: 0
A35: สักหลาด แบบกาว | B35: สักหลาด แบบกาว | E35: https://drive.google.com/file/d/1Vd3F4oJHVNER99LPnV1xd4koE7e-1t0h/view?usp=drive_link | F35: 1 | G35: 0
A36: สักหลาด บานเลื่อน สลิม จีน | B36: สักหลาด บานเลื่อน สลิม จีน | E36: https://drive.google.com/file/d/1ywls-6XArmlv9J2oFtRJkRCnF9PcvoDQ/view?usp=drive_link | F36: 16 | G36: 0
A37: กาว 2 หน้า 3M กันจิ้งจก | B37: กาว 2 หน้า 3M กันจิ้งจก | E37: https://drive.google.com/file/d/1_PabtCwQSwcjCvymcHx6DRqND3SpEFTL/view?usp=drive_link | F37: 30 | G37: 0
A38: ยางกันจิ้งจก | B38: ยางกันจิ้งจก | E38: https://drive.google.com/file/d/1FOzujPFAOmWaVzPGDMKMUh_etwhhWRHN/view?usp=drive_link | F38: 23 | G38: 0
A39: ยางบานเฟี้ยมตัวใหญ่ | B39: ยางบานเฟี้ยมตัวใหญ่ | E39: https://drive.google.com/file/d/1-mcLmIhq4536FpXrku048eL2NL9fpNYx/view?usp=drive_link | F39: 1 | G39: 0
A40: ยางบานเฟี้ยมตัวเล็ก | B40: ยางบานเฟี้ยมตัวเล็ก | E40: https://drive.google.com/file/d/1VqBcLvbkAiRjllNOY_JREsb0G0wUiol1/view?usp=drive_link | F40: 1 | G40: 0
...

Sheet น็อต
A1: คอลัมน์ 1 | B1: รายการสินค้า | C1: ขนาด | D1: ราคา | E1: รูป | F1: ยอดคงเหลือ | G1: ยอดเบิกรวม | H1: น็อตเป็นโล
A2: =CONCATENATE(B2,"-",C2) -> LB หัวเอฟ สีรุ้ง ปลายสว่าน-#8*3/4"(19mm) | B2: LB หัวเอฟ สีรุ้ง ปลายสว่าน | C2: #8*3/4"(19mm) | D2: 5 | E2: https://drive.google.com/file/d/1qr7os9i4pcG-UvT9kx4NNsGVwYD5xphh/view?usp=drive_link | G2: {=MAP(ตาราง1_5[คอลัมน์ 1],LAMBDA(sku,SUMIFS('รับเข้า-เบิก'!H:H,'รับเข้า-เบิก'!G:G,sku,'รับเข้า-เบิก'!I:I,"รับเข้า")))} -> 0
A3: =CONCATENATE(B3,"-",C3) -> YJ ผนังเบา สีทอง ปลายแหลมไม่ผ่า-#6*3/4"(19mm) | B3: YJ ผนังเบา สีทอง ปลายแหลมไม่ผ่า | C3: #6*3/4"(19mm) | E3: https://drive.google.com/file/d/1MyUgPYoJzKANYQ94RoY63eMx521GyFrd/view?usp=drive_link | G3: 0
A4: =CONCATENATE(B4,"-",C4) -> FSD SUS410 ปลายสว่านF สแตนเลส-#8x25(1") | B4: FSD SUS410 ปลายสว่านF สแตนเลส | C4: #8x25(1") | E4: https://drive.google.com/file/d/10AOlOFveDvCLs62aaEWRJbnNK9e8_qwo/view?usp=drive_link | F4: 650 | G4: 0
A5: =CONCATENATE(B5,"-",C5) -> สกรูเกลียวปล่อย เตเปอร์-#8X1" | B5: สกรูเกลียวปล่อย เตเปอร์ | C5: #8X1" | E5: https://drive.google.com/file/d/1Tj2H9DMYUvr6GJUFmWUz1qGZX2PpFys9/view?usp=drive_link | G5: 0
A6: =CONCATENATE(B6,"-",C6) -> สกรูเกลียวปล่อย เตเปอร์-#8X1-1/2" | B6: สกรูเกลียวปล่อย เตเปอร์ | C6: #8X1-1/2" | E6: https://drive.google.com/file/d/1R7dZqrSu6wiDXDJMooXzTwqpm7I8jLkn/view?usp=drive_link | G6: 0
A7: =CONCATENATE(B7,"-",C7) -> สกรูเกลียวปล่อย เตเปอร์-#8X2" | B7: สกรูเกลียวปล่อย เตเปอร์ | C7: #8X2" | E7: https://drive.google.com/file/d/1R7dZqrSu6wiDXDJMooXzTwqpm7I8jLkn/view?usp=drive_link | G7: 0
A8: =CONCATENATE(B8,"-",C8) -> สกรูเกลียวปล่อย เตเปอร์-#8X3" | B8: สกรูเกลียวปล่อย เตเปอร์ | C8: #8X3" | E8: https://drive.google.com/file/d/1R7dZqrSu6wiDXDJMooXzTwqpm7I8jLkn/view?usp=drive_link | G8: 0
A9: =CONCATENATE(B9,"-",C9) -> Phillip Pan Self Tapping Screws - AB-#7X5/8" | B9: Phillip Pan Self Tapping Screws - AB | C9: #7X5/8" | E9: https://drive.google.com/file/d/1iP2PzWKk4G7gREn35nMLCSS5RaWMta0U/view?usp=drive_link | G9: 0
A10: =CONCATENATE(B10,"-",C10) -> DW07 สกรูไดร์วอลว์ ดำ-#6*1"(25mm) | B10: DW07 สกรูไดร์วอลว์ ดำ | C10: #6*1"(25mm) | E10: https://drive.google.com/file/d/11F5lHmFs5RF_DZ4r-4JkiNL8sNsH3v4x/view?usp=drive_link | G10: 0
A11: =CONCATENATE(B11,"-",C11) -> LB หัวเอฟ สีรุ้ง ปลายสว่าน-#8*3/4"(19mm) | B11: LB หัวเอฟ สีรุ้ง ปลายสว่าน | C11: #8*3/4"(19mm) | E11: https://drive.google.com/file/d/1qr7os9i4pcG-UvT9kx4NNsGVwYD5xphh/view?usp=drive_link | G11: 0
A12: =CONCATENATE(B12,"-",C12) -> Phillip Flat CSK Self Drilling Screws -#8x3.1/2" | B12: Phillip Flat CSK Self Drilling Screws | C12: #8x3.1/2" | E12: https://drive.google.com/file/d/1q2sTNW4iokohNGkeKUBXi0aYb2jFbo71/view?usp=drive_link | G12: 0
A13: =CONCATENATE(B13,"-",C13) -> Phillip Flat CSK Self Drilling Screws -#8x4" | B13: Phillip Flat CSK Self Drilling Screws | C13: #8x4" | E13: https://drive.google.com/file/d/1q2sTNW4iokohNGkeKUBXi0aYb2jFbo71/view?usp=drive_link | G13: 0
A14: =CONCATENATE(B14,"-",C14) -> Phillip Pan Self Tapping Screws - AB-#8x5/8" | B14: Phillip Pan Self Tapping Screws - AB | C14: #8x5/8" | E14: https://drive.google.com/file/d/1iP2PzWKk4G7gREn35nMLCSS5RaWMta0U/view?usp=drive_link | G14: 0
A15: =CONCATENATE(B15,"-",C15) -> LB หัวเอฟ สีรุ้ง ปลายสว่าน-#8*1-1/2"(38mm) | B15: LB หัวเอฟ สีรุ้ง ปลายสว่าน | C15: #8*1-1/2"(38mm) | E15: https://drive.google.com/file/d/1qr7os9i4pcG-UvT9kx4NNsGVwYD5xphh/view?usp=drive_link | G15: 0
A16: =CONCATENATE(B16,"-",C16) -> Hex Head Self Drilling Screws-#10-16x1"(25mm.) | B16: Hex Head Self Drilling Screws | C16: #10-16x1"(25mm.) | E16: https://drive.google.com/file/d/1cRfarLE3uO0flTaEkU434gB2ORMGUT8Z/view?usp=drive_link | G16: 0
... A29: =CONCATENATE(B29,"-",C29) -> ZW ลอนคูู่ ปลายสว่าน สีรุ้ง ยางดำ-#10X4(100mm) | B29: ZW ลอนคูู่ ปลายสว่าน สีรุ้ง ยางดำ | C29: #10X4(100mm) | E29: https://drive.google.com/file/d/1cRfarLE3uO0flTaEkU434gB2ORMGUT8Z/view?usp=drive_link | G29: 0
A30: =CONCATENATE(B30,"-",C30) -> น๊อตเกลียวปล่อย เตเปอร์-1 ½ | B30: น๊อตเกลียวปล่อย เตเปอร์ | C30: 1 ½ | E30: https://drive.google.com/file/d/1zi4jmqt7KARYg9Cf2cF-RfJ-we5euWov/view?usp=drive_link | F30: 10094 | G30: 0 | H30: =F30*0.5/198 -> 25.489899
A31: =CONCATENATE(B31,"-",C31) -> น๊อตเกลียวปล่อย เตเปอร์-2" | B31: น๊อตเกลียวปล่อย เตเปอร์ | C31: 2" | E31: https://drive.google.com/file/d/1HRJb7bv-L7Qxq2C0j5R4jQXy16ThK2g8/view?usp=drive_link | F31: 11643 | G31: 0 | H31: =F31*0.5/143 -> 40.70979
A32: =CONCATENATE(B32,"-",C32) -> น๊อตเกลียวปล่อย เตเปอร์-3" | B32: น๊อตเกลียวปล่อย เตเปอร์ | C32: 3" | E32: https://drive.google.com/file/d/1SIxckNpj07I_c0pCAs-0C3_deGfzDCwd/view?usp=drive_link | F32: 9200 | G32: 0 | H32: =F32*0.5/100 -> 46
A33: =CONCATENATE(B33,"-",C33) -> น๊อตหัวกลม เกลียวปล่อย-7X5/8" | B33: น๊อตหัวกลม เกลียวปล่อย | C33: 7X5/8" | E33: https://drive.google.com/file/d/1RydPdOhADDBQIpUbFT5jnCIrx0Ex1z1K/view?usp=drive_link | F33: 6000 | G33: 0 | H33: =F33*0.5/360 -> 8.3333333
A34: =CONCATENATE(B34,"-",C34) -> น๊อตหัวกลม เกลียวปล่อย-8X5/8" | B34: น๊อตหัวกลม เกลียวปล่อย | C34: 8X5/8" | E34: https://drive.google.com/file/d/1LVVNihAyXvLtC-wzk_JX_rBjKOf04Fao/view?usp=drive_link | F34: 9000 | G34: 0 | H34: =F34*0.5/320 -> 14.0625
A35: =CONCATENATE(B35,"-",C35) -> น๊อตหัวกลม ปลายสว่าน-6x5/8 | B35: น๊อตหัวกลม ปลายสว่าน | C35: 6x5/8 | E35: https://drive.google.com/file/d/1q2poxwwoire2971haNIh5Qyz9anIK4jd/view?usp=drive_link | F35: 10000 | G35: 0 | H35: =F35*0.5/500 -> 10
A36: =CONCATENATE(B36,"-",C36) -> น๊อตหัวกลม เกลียวปล่อย-8x25/1" | B36: น๊อตหัวกลม เกลียวปล่อย | C36: 8x25/1" | E36: https://drive.google.com/file/d/1wZzQrlD1QAqCu4KnE8jIYEJUtfZZrDpn/view?usp=drive_link | F36: 2350 | G36: 0 | H36: =F36*0.5/250 -> 4.7
A37: =CONCATENATE(B37,"-",C37) -> น๊อตหัวกลม ปลายสว่าน-6X3/8" | B37: น๊อตหัวกลม ปลายสว่าน | C37: 6X3/8" | E37: https://drive.google.com/file/d/1wGM5sCqoxY-sYhiDk7vT3yxm6yMJqRCZ/view?usp=drive_link | F37: 1000 | G37: 0 | H37: =F37*0.5/500 -> 1
A38: =CONCATENATE(B38,"-",C38) -> น๊อตหัวกลม ปลายสว่าน-8X1½" | B38: น๊อตหัวกลม ปลายสว่าน | C38: 8X1½" | E38: https://drive.google.com/file/d/1Q4BYH89LNjuRbhK1ryOHiFJKhAV11FSc/view?usp=drive_link | F38: 9200 | G38: 0 | H38: =F38*0.5/200 -> 23
A39: =CONCATENATE(B39,"-",C39) -> น๊อตสแตนเลส หัวกลม-M4-1.4X19(8X3/4) | B39: น๊อตสแตนเลส หัวกลม | C39: M4-1.4X19(8X3/4) | E39: https://drive.google.com/file/d/1K5mpUpwr2EuP1QvdRJQSq9iK7SrzP2aX/view?usp=drive_link | F39: 8468 | G39: 0 | H39: =F39*0.5/400 -> 10.585
A40: =CONCATENATE(B40,"-",C40) -> น๊อตสแตนเลสเลส เตเปอร์ ปลายสว่าน-4.2x19 | B40: น๊อตสแตนเลสเลส เตเปอร์ ปลายสว่าน | C40: 4.2x19 | E40: https://drive.google.com/file/d/16JNKyql-YDvjbloZzFJGysD67MTKc0FD/view?usp=drive_link | F40: 7500 | G40: 0 | H40: =F40*0.5/500 -> 7.5
A41: =CONCATENATE(B41,"-",C41) -> น๊อตสแตนเลสยางก้ามปู-8X25(1") | B41: น๊อตสแตนเลสยางก้ามปู | C41: 8X25(1") | E41: https://drive.google.com/file/d/1nebDTPYv9XLQi0Gz-XtUBhfx9ixpfyPB/view?usp=drive_link | F41: 2350 | G41: 0 | H41: =F41*0.5/250 -> 4.7
A42: =CONCATENATE(B42,"-",C42) -> พุกเหล็ก-46237 | B42: พุกเหล็ก | C42: 46237 | E42: https://drive.google.com/file/d/16s7Q7mJaGy5Ky93JN47dPNpQI5ghQ8Rx/view?usp=drive_link | F42: 240 | G42: 240
A43: =CONCATENATE(B43,"-",C43) -> พุกเหล็ก-46113 | B43: พุกเหล็ก | C43: 46113 | E43: https://drive.google.com/file/d/1MY3feTF2ZA-zuATe-uDmllOa_lH-M3mP/view?usp=drive_link | F43: 5854 | G43: 5854
A44: =CONCATENATE(B44,"-",C44) -> พุกตะปู M10- | B44: พุกตะปู M10 | E44: https://drive.google.com/file/d/1KxuK79LPA2nEHPnFa00qH5xSe3tZ6Ydk/view?usp=drive_link | F44: 320 | G44: 320
A45: =CONCATENATE(B45,"-",C45) -> พุกตะปู M8- | B45: พุกตะปู M8 | E45: https://drive.google.com/file/d/105U5oByCl09p8ySpJSeoWCR7oCdWA8Ep/view?usp=drive_link | F45: 75 | G45: 0
A46: =CONCATENATE(B46,"-",C46) -> พุกตะกั่ว-46113 | B46: พุกตะกั่ว | C46: 46113 | E46: https://drive.google.com/file/d/19wnciIGO8MtpLawdneFPWVbWVt1l-1lM/view?usp=drive_link | F46: 704 | G46: 709
A47: =CONCATENATE(B47,"-",C47) -> พุกตะกั่ว-46237 | B47: พุกตะกั่ว | C47: 46237 | E47: https://drive.google.com/file/d/1iDYIfyLeZ2Ujt3OdtVbRJ8ItmHZsniVA/view?usp=drive_link | F47: 100 | G47: 0
A48: =CONCATENATE(B48,"-",C48) -> พุกเคมี M8- | B48: พุกเคมี M8 | E48: https://drive.google.com/file/d/1_Levv9YGC1HrKTgjAmBj8usLlpjfsWZ7/view?usp=drive_link | F48: 10 | G48: 75
A49: =CONCATENATE(B49,"-",C49) -> พุกเคมี M10- | B49: พุกเคมี M10 | E49: https://drive.google.com/file/d/1_Levv9YGC1HrKTgjAmBj8usLlpjfsWZ7/view?usp=drive_link | F49: 150 | G49: 0
A50: =CONCATENATE(B50,"-",C50) -> พุกผีเสื้อ ยิบซั่ม พุกร่ม- | B50: พุกผีเสื้อ ยิบซั่ม พุกร่ม | E50: https://drive.google.com/file/d/1I-UBWjmEVF9RZBkeTYSlOJmKKm7xyI9a/view?usp=drive_link | F50: 250 | G50: 0
A51: =CONCATENATE(B51,"-",C51) -> พุกพลาสติก- | B51: พุกพลาสติก | E51: https://drive.google.com/file/d/12saAj7pOm7iy9xgRlYO6FlkEoHiq5xkH/view?usp=drive_link | F51: 650 | G51: 0
A52: =CONCATENATE(B52,"-",C52) -> น๊อตยิงฝ้า สีดำ-6X1" | B52: น๊อตยิงฝ้า สีดำ | C52: 6X1" | E52: https://drive.google.com/file/d/1cwdB9HjLoXAAZSu_d4Y1RYHJ5XjgyUkH/view?usp=drive_link | G52: 0
...

Sheet เครื่องมือช่างและอื่น ๆ
A1: SKU | B1: รายการสินค้า | C1: ราคา | D1: รูป | E1: ยอดคงเหลือ | F1: ยอดเบิกรวม
A2: {=BYROW(ตาราง1_4[รายการสินค้า], LAMBDA(row, TEXTJOIN("-", TRUE, row)))} -> เครื่องวัดระดับ เลเซอร์ 5 เส้น | B2: เครื่องวัดระดับ เลเซอร์ 5 เส้น | D2: https://drive.google.com/file/d/1dxUgZ37PuC_ReNis7NN5bCdJU_y2iMRr/view?usp=drive_link | E2: 3
A3: สว่านโรตารี่ สว่านเจาะปูน 3 ระบบ | B3: สว่านโรตารี่ สว่านเจาะปูน 3 ระบบ | D3: https://drive.google.com/file/d/1c0EY8Zs22GjDv2n_INZ_Ps2SlT8YSJb6/view?usp=drive_link | E3: 3
A4: เครื่องเจียร 4" MAKITA | B4: เครื่องเจียร 4" MAKITA | D4: https://drive.google.com/file/d/1p8IRn5nlNcuUj5Ec7GUTMUAVYlZPwj16/view?usp=drive_link
A5: เครื่องเจียร 7" MAKITA | B5: เครื่องเจียร 7" MAKITA | D5: https://drive.google.com/file/d/11KKon3d3WVYdGg1Spd6hBKV1mUKQdp9w/view?usp=drive_link | E5: 1
A6: ชุดเครื่องเจียรไฟฟ้า 4 นิ้ว 750W INGCO | B6: ชุดเครื่องเจียรไฟฟ้า 4 นิ้ว 750W INGCO | D6: https://drive.google.com/file/d/1HFQOceC0wFqvNIayCFJUoEfSOPi5nrvT/view?usp=drive_link
A7: ชุดเครื่องเจียรไฟฟ้า 4 นิ้ว 960W INGCO | B7: ชุดเครื่องเจียรไฟฟ้า 4 นิ้ว 960W INGCO | D7: https://drive.google.com/file/d/1HFQOceC0wFqvNIayCFJUoEfSOPi5nrvT/view?usp=drive_link
A8: เครื่องเจียร ไร้สาย แบตเตอรี่ MAKITA | B8: เครื่องเจียร ไร้สาย แบตเตอรี่ MAKITA | D8: https://drive.google.com/file/d/1EShl9VSfnApe8xVvbDTXnz_7ovKAfdSb/view?usp=drive_link | E8: 1
A9: ชุดเครื่องเจียรไร้สาย INGCO | B9: ชุดเครื่องเจียรไร้สาย INGCO | D9: https://drive.google.com/file/d/1DVtwWbaVkDCQ7JccfmHYx-YIGGgOmPuC/view?usp=drive_link | E9: 1
A10: สว่านแบต INGCO | B10: สว่านแบต INGCO | D10: https://drive.google.com/file/d/1bW8TpiJNi4vpXEXfveyTUHhmornqmoc2/view?usp=drive_link | E10: 1
A11: สว่านสายไฟฟ้า MAKITA | B11: สว่านสายไฟฟ้า MAKITA | D11: https://drive.google.com/file/d/11eEnRS-IAjgRm_4-z_E7Hw6lLZXLOynm/view?usp=drive_link | E11: 14ฅัวเก่าของคืน
A12: ฐานชาร์จแบต + แบตก้อน | B12: ฐานชาร์จแบต + แบตก้อน | D12: https://drive.google.com/file/d/1b4N_wN71TVvc6Ui0gXT0NmfxGl56ETMs/view?usp=drive_link
A13: เร้าเตอร์ INGCO | B13: เร้าเตอร์ INGCO | D13: https://drive.google.com/file/d/1A9fOCjayw3DSEicBnbd5X-sv4DRD4lLN/view?usp=drive_link
A14: เครื่องเป่าลม | B14: เครื่องเป่าลม | D14: https://drive.google.com/file/d/1kHEZTK1C2CBxcT1It4j8bSBmuqGz-SCK/view?usp=drive_link | E14: 4
A15: เครื่องเป่าลมร้อน | B15: เครื่องเป่าลมร้อน | D15: https://drive.google.com/file/d/1yFxpR2xqeElw6KSWxThQR0OiKK4ZhgBd/view?usp=drive_link | E15: 2
A16: เครื่องเจาะผนัง 5 นิ้ว | B16: เครื่องเจาะผนัง 5 นิ้ว | D16: https://drive.google.com/file/d/11_qW2myUnuIckTS-JB6AzkOfHqjvqPwv/view?usp=drive_link | E16: 1
A17: เครืองตัดไม้ MAKITA รุ่น DTM51Z | B17: เครืองตัดไม้ MAKITA รุ่น DTM51Z | D17: https://drive.google.com/file/d/1v6VM6sT2dkccbjsjLz8kGRISEeQr7ky5/view?usp=drive_link | E17: 2
A18: เลื่อยโซ่ไฟฟ้า | B18: เลื่อยโซ่ไฟฟ้า | D18: https://drive.google.com/file/d/17TChlyLWZRqjUfTN6Ox5tnBoqo8QGrTH/view?usp=drive_link | E18: 1
A19: เครื่องจิ๊กซอว์ไฟฟ้า | B19: เครื่องจิ๊กซอว์ไฟฟ้า | D19: https://drive.google.com/file/d/10tDNhjZyFQ_zu034At8oAPsdqEtI5CXh/view?usp=drive_link | E19: 1
A20: เลื่อยวงเดือน MAKITA 7 นิ้ว | B20: เลื่อยวงเดือน MAKITA 7 นิ้ว | D20: https://drive.google.com/file/d/1V_2bGk7pBApR19jQAv466ZkBbMnxyY-S/view?usp=drive_link | E20: 1
A21: เครื่องสกัดคอนกรีต MAKITA | B21: เครื่องสกัดคอนกรีต MAKITA | D21: https://drive.google.com/file/d/1BI1OuGPbS1UNrAay7aVIY45B07sUZh1x/view?usp=drive_link | E21: 1
A22: ปืนยิงตะปูแม็กลมแม็กลมขาเดียว | B22: ปืนยิงตะปูแม็กลมแม็กลมขาเดียว | D22: https://drive.google.com/file/d/1AtVvk8cJOk9_OXW5pGkifwqAynoBN5rG/view?usp=drive_link | E22: 1
A23: ปืนยิงซิลิโคน | B23: ปืนยิงซิลิโคน | D23: https://drive.google.com/file/d/1Uqo-f12winSThhO1EZdEHfut73ziu8bK/view?usp=drive_link | E23: 10
A24: ปืนยิงกาว PU | B24: ปืนยิงกาว PU | D24: https://drive.google.com/file/d/1Qtp107SxEw3hXLteBtUC0CcLzW0pQwHX/view?usp=drive_link | E24: 17
A25: ตู้เชื่อมอาร์กอน | B25: ตู้เชื่อมอาร์กอน | D25: https://drive.google.com/file/d/1GHcTPQB0sKVIz_dXkaA2UIM8L4ZP8_Hg/view?usp=drive_link | E25: 2
A26: เครื่องดูดฝุ่น เล็ก | B26: เครื่องดูดฝุ่น เล็ก | D26: https://drive.google.com/file/d/1b8M3B6t7Qnll9k4-vR-rG0teMFpzoRUb/view?usp=drive_link | E26: 2
A27: เครื่องดูดฝุ่น ใหญ่ | B27: เครื่องดูดฝุ่น ใหญ่ | D27: https://drive.google.com/file/d/1zecESMsQWrruEIUzhlIL1YfMe4ltkNA7/view?usp=drive_link
A28: คีมย้ำรีเวท | B28: คีมย้ำรีเวท | D28: https://drive.google.com/file/d/1CZVI5yeN74o0shGbPfE7eZnOU-9NxTWB/view?usp=drive_link | E28: 8
A29: กล่องเครื่องมือช่าง 2 ชั้น | B29: กล่องเครื่องมือช่าง 2 ชั้น | D29: https://drive.google.com/file/d/1Hvvsm_PkraZMdKMV0mEHTw7EMWYc81mf/view?usp=drive_link | E29: 1
A30: เครื่องอ๊อกเหล็ก | B30: เครื่องอ๊อกเหล็ก | D30: https://drive.google.com/file/d/1GHcTPQB0sKVIz_dXkaA2UIM8L4ZP8_Hg/view?usp=drive_link | E30: 1
A31: มือจับกระจก | B31: มือจับกระจก | D31: https://drive.google.com/file/d/1pCtgZY6OfjUdeWfztCr_Lvmf8NQspiBu/view?usp=drive_link | E31: 3
A32: ไม้กรีดน้ำบนกระจก | B32: ไม้กรีดน้ำบนกระจก | D32: https://drive.google.com/file/d/1mSaXqN2tcC2eV92od3cFAha1bQ9UZcEE/view?usp=drive_link | E32: 9
A33: ไม้กรีดน้ำบนกระจกแบบฟองน้ำ | B33: ไม้กรีดน้ำบนกระจกแบบฟองน้ำ | D33: https://drive.google.com/file/d/1UXQjfpIDT1t3l5VYJl42lEwtQFyebrP-/view?usp=drive_link | E33: 1
A34: ก้านเหล็กปั่นปูน | B34: ก้านเหล็กปั่นปูน | D34: https://drive.google.com/file/d/14kv_bl3NW1M7x29DYWMUFe4TxoYE-tm2/view?usp=drive_link | E34: 5
A35: ลูกกลิ้ง 7" | B35: ลูกกลิ้ง 7" | D35: https://drive.google.com/file/d/1xIXcntlI1K_An1PB_Pg-lnE3meAopVYK/view?usp=drive_link | E35: 7
A36: ลูกกลิ้ง 10" | B36: ลูกกลิ้ง 10" | D36: https://drive.google.com/file/d/1oDBw8QmJHTuf6s02kxEoz1_L0UXBfIZH/view?usp=drive_link | E36: 1
A37: เหล็กจับอลูมิเนียม | B37: เหล็กจับอลูมิเนียม | D37: https://drive.google.com/file/d/1w6O1kBO0C7zxeQk_nwPjq4GIBERQ70vH/view?usp=drive_link | E37: 5
A38: เครื่องเลเซอร์ | B38: เครื่องเลเซอร์ | D38: https://drive.google.com/file/d/1KeNALltoYlW8MvouQ8ATTbAJVAey1MwK/view?usp=drive_link | E38: 3
A39: สว่านเจาะปูน 3 ระบบ | B39: สว่านเจาะปูน 3 ระบบ | D39: https://drive.google.com/file/d/1r46H5K2_bmlA1LUNwAofL7KEqs4TYN2V/view?usp=drive_link | E39: 2
... A44: ปลัีกไฟพ่วง | B44: ปลัีกไฟพ่วง | D44: https://drive.google.com/file/d/13Kerqw7iXmexH_j0x7YlR3FKYbTYs3br/view?usp=drive_link | E44: 3

Sheet อลูมิเนียม
A1: SKU | B1: ประเภท | C1: รหัส | D1: รายการสินค้า | E1: สี | F1: ขนาด ( เมตร ) | G1: ราคา | H1: รูป | I1: ยอดคงเหลือ | J1: ยอดเบิกรวม
A2: {=BYROW(ตาราง1_6[[รหัส]:[สี]], LAMBDA(row, TEXTJOIN("-", TRUE, row)))} -> B20001-เฟรมบนบานเลื่อน-อบขาว | B2: อลูมิเนียม sms | C2: B20001 | D2: เฟรมบนบานเลื่อน | E2: อบขาว | F2: 6.4 | G2: 1125 | H2: https://drive.google.com/file/d/19jyd6Vp8y0So1DxI4DyKAs1pHxlUPDox/view?usp=drive_link | I2: 81
A3: B20001-เฟรมบนบานเลื่อน-ดำ | B3: อลูมิเนียม sms | C3: B20001 | D3: เฟรมบนบานเลื่อน | E3: ดำ | F3: 6.4 | G3: 1125 | H3: https://drive.google.com/file/d/19jyd6Vp8y0So1DxI4DyKAs1pHxlUPDox/view?usp=drive_link | I3: 76
A4: B20001-เฟรมบนบานเลื่อน-เทาซาฮาร่า | B4: อลูมิเนียม sms | C4: B20001 | D4: เฟรมบนบานเลื่อน | E4: เทาซาฮาร่า | F4: 6.4 | G4: 1225 | H4: https://drive.google.com/file/d/19jyd6Vp8y0So1DxI4DyKAs1pHxlUPDox/view?usp=drive_link | I4: 64
A5: B20001-เฟรมบนบานเลื่อน-ลายไม้สักทอง | B5: อลูมิเนียม sms | C5: B20001 | D5: เฟรมบนบานเลื่อน | E5: ลายไม้สักทอง | F5: 6.4 | G5: 1825 | H5: https://drive.google.com/file/d/19jyd6Vp8y0So1DxI4DyKAs1pHxlUPDox/view?usp=drive_link | I5: 6
A6: B20001-เฟรมบนบานเลื่อน-อื่น ๆ | B6: อลูมิเนียม sms | C6: B20001 | D6: เฟรมบนบานเลื่อน | E6: อื่น ๆ | F6: 6.4 | G6: 1074.45 | H6: https://drive.google.com/file/d/19jyd6Vp8y0So1DxI4DyKAs1pHxlUPDox/view?usp=drive_link
A7: B20002-เฟรมล่างบานเลื่อน-อบขาว | B7: อลูมิเนียม sms | C7: B20002 | D7: เฟรมล่างบานเลื่อน | E7: อบขาว | F7: 6.4 | G7: 1205 | H7: https://drive.google.com/file/d/1oAcMkGZgEXDtXBeUibNu61q8v-4GHul4/view?usp=drive_link
A8: B20002-เฟรมล่างบานเลื่อน-ดำ | B8: อลูมิเนียม sms | C8: B20002 | D8: เฟรมล่างบานเลื่อน | E8: ดำ | F8: 6.4 | G8: 1205 | H8: https://drive.google.com/file/d/1oAcMkGZgEXDtXBeUibNu61q8v-4GHul4/view?usp=drive_link
A9: B20002-เฟรมล่างบานเลื่อน-เทาซาฮาร่า | B9: อลูมิเนียม sms | C9: B20002 | D9: เฟรมล่างบานเลื่อน | E9: เทาซาฮาร่า | F9: 6.4 | G9: 1310 | H9: https://drive.google.com/file/d/1oAcMkGZgEXDtXBeUibNu61q8v-4GHul4/view?usp=drive_link
A10: B20002-เฟรมล่างบานเลื่อน-ลายไม้สักทอง | B10: อลูมิเนียม sms | C10: B20002 | D10: เฟรมล่างบานเลื่อน | E10: ลายไม้สักทอง | F10: 6.4 | G10: 1925 | H10: https://drive.google.com/file/d/1oAcMkGZgEXDtXBeUibNu61q8v-4GHul4/view?usp=drive_link
A11: B20002-เฟรมล่างบานเลื่อน-อื่น ๆ | B11: อลูมิเนียม sms | C11: B20002 | D11: เฟรมล่างบานเลื่อน | E11: อื่น ๆ | F11: 6.4 | H11: https://drive.google.com/file/d/1oAcMkGZgEXDtXBeUibNu61q8v-4GHul4/view?usp=drive_link
A12: B20003-เฟรมข้างบานเลื่อน-อบขาว | B12: อลูมิเนียม sms | C12: B20003 | D12: เฟรมข้างบานเลื่อน | E12: อบขาว | F12: 6.4 | G12: 870 | H12: https://drive.google.com/file/d/1Rn9FSXnT0TU-PhwzIKM_XU4dWTYeqoru/view?usp=drive_link | I12: 62
A13: B20003-เฟรมข้างบานเลื่อน-ดำ | B13: อลูมิเนียม sms | C13: B20003 | D13: เฟรมข้างบานเลื่อน | E13: ดำ | F13: 6.4 | G13: 870 | H13: https://drive.google.com/file/d/1Rn9FSXnT0TU-PhwzIKM_XU4dWTYeqoru/view?usp=drive_link | I13: 71
A14: B20003-เฟรมข้างบานเลื่อน-เทาซาฮาร่า | B14: อลูมิเนียม sms | C14: B20003 | D14: เฟรมข้างบานเลื่อน | E14: เทาซาฮาร่า | F14: 6.4 | G14: 950 | H14: https://drive.google.com/file/d/1Rn9FSXnT0TU-PhwzIKM_XU4dWTYeqoru/view?usp=drive_link | I14: 70
A15: B20003-เฟรมข้างบานเลื่อน-ลายไม้สักทอง | B15: อลูมิเนียม sms | C15: B20003 | D15: เฟรมข้างบานเลื่อน | E15: ลายไม้สักทอง | F15: 6.4 | G15: 1450.95 | H15: https://drive.google.com/file/d/1Rn9FSXnT0TU-PhwzIKM_XU4dWTYeqoru/view?usp=drive_link | I15: 12
A16: B20003-เฟรมข้างบานเลื่อน-อื่น ๆ | B16: อลูมิเนียม sms | C16: B20003 | D16: เฟรมข้างบานเลื่อน | E16: อื่น ๆ | F16: 6.4 | G16: 970 | H16: https://drive.google.com/file/d/1Rn9FSXnT0TU-PhwzIKM_XU4dWTYeqoru/view?usp=drive_link
A17: B20004-เฟรมบนเสริมร่องกระจก-อบขาว | B17: อลูมิเนียม sms | C17: B20004 | D17: เฟรมบนเสริมร่องกระจก | E17: อบขาว | F17: 6.4 | G17: 870 | H17: https://drive.google.com/file/d/1c2f42DRgP6pNZVxfgpaAJDbRLiNNO9On/view?usp=drive_link
A18: B20004-เฟรมบนเสริมร่องกระจก-ดำ | B18: อลูมิเนียม sms | C18: B20004 | D18: เฟรมบนเสริมร่องกระจก | E18: ดำ | F18: 6.4 | G18: 870 | H18: https://drive.google.com/file/d/1c2f42DRgP6pNZVxfgpaAJDbRLiNNO9On/view?usp=drive_link
A19: B20004-เฟรมบนเสริมร่องกระจก-เทาซาฮาร่า | B19: อลูมิเนียม sms | C19: B20004 | D19: เฟรมบนเสริมร่องกระจก | E19: เทาซาฮาร่า | F19: 6.4 | G19: 950 | H19: https://drive.google.com/file/d/1c2f42DRgP6pNZVxfgpaAJDbRLiNNO9On/view?usp=drive_link
A20: B20004-เฟรมบนเสริมร่องกระจก-ลายไม้สักทอง | B20: อลูมิเนียม sms | C20: B20004 | D20: เฟรมบนเสริมร่องกระจก | E20: ลายไม้สักทอง | F20: 6.4 | G20: 1395 | H20: https://drive.google.com/file/d/1c2f42DRgP6pNZVxfgpaAJDbRLiNNO9On/view?usp=drive_link
A21: B20004-เฟรมบนเสริมร่องกระจก-อื่น ๆ | B21: อลูมิเนียม sms | C21: B20004 | D21: เฟรมบนเสริมร่องกระจก | E21: อื่น ๆ | F21: 6.4 | H21: https://drive.google.com/file/d/1c2f42DRgP6pNZVxfgpaAJDbRLiNNO9On/view?usp=drive_link
A22: B20007-เสากุญแจ (ตูดตัน)-อบขาว | B22: อลูมิเนียม sms | C22: B20007 | D22: เสากุญแจ (ตูดตัน) | E22: อบขาว | F22: 6.4 | G22: 660 | H22: https://drive.google.com/file/d/1yEbDgRN081wTEjkmM3QY0PEHhRIkOy89/view?usp=drive_link | I22: 39
A23: B20007-เสากุญแจ (ตูดตัน)-ดำ | B23: อลูมิเนียม sms | C23: B20007 | D23: เสากุญแจ (ตูดตัน) | E23: ดำ | F23: 6.4 | G23: 660 | H23: https://drive.google.com/file/d/1yEbDgRN081wTEjkmM3QY0PEHhRIkOy89/view?usp=drive_link | I23: 36
A24: B20007-เสากุญแจ (ตูดตัน)-เทาซาฮาร่า | B24: อลูมิเนียม sms | C24: B20007 | D24: เสากุญแจ (ตูดตัน) | E24: เทาซาฮาร่า | F24: 6.4 | G24: 725 | H24: https://drive.google.com/file/d/1yEbDgRN081wTEjkmM3QY0PEHhRIkOy89/view?usp=drive_link | I24: 42
A25: B20007-เสากุญแจ (ตูดตัน)-ลายไม้สักทอง | B25: อลูมิเนียม sms | C25: B20007 | D25: เสากุญแจ (ตูดตัน) | E25: ลายไม้สักทอง | F25: 6.4 | G25: 1065 | H25: https://drive.google.com/file/d/1yEbDgRN081wTEjkmM3QY0PEHhRIkOy89/view?usp=drive_link | I25: 20
A26: B20007-เสากุญแจ (ตูดตัน)-อื่น ๆ | B26: อลูมิเนียม sms | C26: B20007 | D26: เสากุญแจ (ตูดตัน) | E26: อื่น ๆ | F26: 6.4 | H26: https://drive.google.com/file/d/1yEbDgRN081wTEjkmM3QY0PEHhRIkOy89/view?usp=drive_link
A27: B20008-เสากุญแจแบบรับแรง-อบขาว | B27: อลูมิเนียม sms | C27: B20008 | D27: เสากุญแจแบบรับแรง | E27: อบขาว | F27: 6.4 | G27: 1125 | H27: https://drive.google.com/file/d/1Sx66IFkix9Yg0hjpKsvW_DisZYUG2yuo/view?usp=drive_link
A28: B20008-เสากุญแจแบบรับแรง-ดำ | B28: อลูมิเนียม sms | C28: B20008 | D28: เสากุญแจแบบรับแรง | E28: ดำ | F28: 6.4 | G28: 1125 | H28: https://drive.google.com/file/d/1Sx66IFkix9Yg0hjpKsvW_DisZYUG2yuo/view?usp=drive_link
A29: B20008-เสากุญแจแบบรับแรง-เทาซาฮาร่า | B29: อลูมิเนียม sms | C29: B20008 | D29: เสากุญแจแบบรับแรง | E29: เทาซาฮาร่า | F29: 6.4 | G29: 1225 | H29: https://drive.google.com/file/d/1Sx66IFkix9Yg0hjpKsvW_DisZYUG2yuo/view?usp=drive_link
A30: B20008-เสากุญแจแบบรับแรง-ลายไม้สักทอง | B30: อลูมิเนียม sms | C30: B20008 | D30: เสากุญแจแบบรับแรง | E30: ลายไม้สักทอง | F30: 6.4 | G30: 1800 | H30: https://drive.google.com/file/d/1Sx66IFkix9Yg0hjpKsvW_DisZYUG2yuo/view?usp=drive_link
A31: B20008-เสากุญแจแบบรับแรง-อื่น ๆ | B31: อลูมิเนียม sms | C31: B20008 | D31: เสากุญแจแบบรับแรง | E31: อื่น ๆ | F31: 6.4 | H31: https://drive.google.com/file/d/1Sx66IFkix9Yg0hjpKsvW_DisZYUG2yuo/view?usp=drive_link
A32: B20009-เสาเกี่ยว (ธรรมดา)-อบขาว | B32: อลูมิเนียม sms | C32: B20009 | D32: เสาเกี่ยว (ธรรมดา) | E32: อบขาว | F32: 6.4 | G32: 690 | H32: https://drive.google.com/file/d/1YTN5hqjITv1QkStRnkc-Yb5z3UrXTvTg/view?usp=drive_link | I32: 65
A33: B20009-เสาเกี่ยว (ธรรมดา)-ดำ | B33: อลูมิเนียม sms | C33: B20009 | D33: เสาเกี่ยว (ธรรมดา) | E33: ดำ | F33: 6.4 | G33: 690 | H33: https://drive.google.com/file/d/1YTN5hqjITv1QkStRnkc-Yb5z3UrXTvTg/view?usp=drive_link | I33: 53
A34: B20009-เสาเกี่ยว (ธรรมดา)-เทาซาฮาร่า | B34: อลูมิเนียม sms | C34: B20009 | D34: เสาเกี่ยว (ธรรมดา) | E34: เทาซาฮาร่า | F34: 6.4 | G34: 750 | H34: https://drive.google.com/file/d/1YTN5hqjITv1QkStRnkc-Yb5z3UrXTvTg/view?usp=drive_link | I34: 66
A35: B20009-เสาเกี่ยว (ธรรมดา)-ลายไม้สักทอง | B35: อลูมิเนียม sms | C35: B20009 | D35: เสาเกี่ยว (ธรรมดา) | E35: ลายไม้สักทอง | F35: 6.4 | G35: 1105 | H35: https://drive.google.com/file/d/1YTN5hqjITv1QkStRnkc-Yb5z3UrXTvTg/view?usp=drive_link | I35: 22
A36: B20009-เสาเกี่ยว (ธรรมดา)-อื่น ๆ | B36: อลูมิเนียม sms | C36: B20009 | D36: เสาเกี่ยว (ธรรมดา) | E36: อื่น ๆ | F36: 6.4 | G36: 835.2 | H36: https://drive.google.com/file/d/1YTN5hqjITv1QkStRnkc-Yb5z3UrXTvTg/view?usp=drive_link
A37: B20010-เสาเกี่ยวนอก (สูง 2.4 m)-อบขาว | B37: อลูมิเนียม sms | C37: B20010 | D37: เสาเกี่ยวนอก (สูง 2.4 m) | E37: อบขาว | F37: 6.4 | G37: 1235 | H37: https://drive.google.com/file/d/1anFasLFG_4K_vklSwjnyhMWv98YpO4xL/view?usp=drive_link | I37: 55
A38: B20010-เสาเกี่ยวนอก (สูง 2.4 m)-ดำ | B38: อลูมิเนียม sms | C38: B20010 | D38: เสาเกี่ยวนอก (สูง 2.4 m) | E38: ดำ | F38: 6.4 | G38: 1235 | H38: https://drive.google.com/file/d/1anFasLFG_4K_vklSwjnyhMWv98YpO4xL/view?usp=drive_link | I38: 55
A39: B20010-เสาเกี่ยวนอก (สูง 2.4 m)-เทาซาฮาร่า | B39: อลูมิเนียม sms | C39: B20010 | D39: เสาเกี่ยวนอก (สูง 2.4 m) | E39: เทาซาฮาร่า | F39: 6.4 | G39: 1345 | H39: https://drive.google.com/file/d/1anFasLFG_4K_vklSwjnyhMWv98YpO4xL/view?usp=drive_link | I39: 59
A40: B20010-เสาเกี่ยวนอก (สูง 2.4 m)-ลายไม้สักทอง | B40: อลูมิเนียม sms | C40: B20010 | D40: เสาเกี่ยวนอก (สูง 2.4 m) | E40: ลายไม้สักทอง | F40: 6.4 | G40: 1975 | H40: https://drive.google.com/file/d/1anFasLFG_4K_vklSwjnyhMWv98YpO4xL/view?usp=drive_link | I40: 10
...

Sheet แผ่นหลังคาและผนัง
A1: SKU | B1: ประเภท | C1: รหัส | D1: รายการสินค้า | E1: สี | F1: ขนาด | G1: ราคา | H1: รูป | I1: ยอดคงเหลือ | J1: ยอดเบิกรวม
A2: {=BYROW(ตาราง1_7[[รหัส]:[สี]], LAMBDA(row, TEXTJOIN("-", TRUE, row)))} -> ตัวตบหลังเต่า-มิว | D2: ตัวตบหลังเต่า | E2: มิว | F2: 6 | H2: https://drive.google.com/file/d/14YoUuP9iQNtxRj2fVuhK4sc2KujDf-3T/view?usp=drive_link
A3: ตัวตบหลังเต่า-อบขาว | D3: ตัวตบหลังเต่า | E3: อบขาว | F3: 6 | H3: https://drive.google.com/file/d/14YoUuP9iQNtxRj2fVuhK4sc2KujDf-3T/view?usp=drive_link
A4: ตัวตบหลังเต่า-ดำ | D4: ตัวตบหลังเต่า | E4: ดำ | F4: 6 | H4: https://drive.google.com/file/d/14YoUuP9iQNtxRj2fVuhK4sc2KujDf-3T/view?usp=drive_link
A5: ตัวตบหลังเต่า-เทาซาฮาร่า | D5: ตัวตบหลังเต่า | E5: เทาซาฮาร่า | F5: 6 | H5: https://drive.google.com/file/d/14YoUuP9iQNtxRj2fVuhK4sc2KujDf-3T/view?usp=drive_link
A6: ตัวตบหลังเต่า-Aztec gray | D6: ตัวตบหลังเต่า | E6: Aztec gray | F6: 6 | H6: https://drive.google.com/file/d/14YoUuP9iQNtxRj2fVuhK4sc2KujDf-3T/view?usp=drive_link
A7: ตัวเดินหลังเต่าหลังคา-อบขาว | D7: ตัวเดินหลังเต่าหลังคา | E7: อบขาว | F7: 6 | H7: https://drive.google.com/file/d/1COsFZDP9fptiWLvKn9aNQEkLuXWtE5hZ/view?usp=drive_link | I7: 10
A8: ตัวเดินหลังเต่าหลังคา-ดำ | D8: ตัวเดินหลังเต่าหลังคา | E8: ดำ | F8: 6 | H8: https://drive.google.com/file/d/1COsFZDP9fptiWLvKn9aNQEkLuXWtE5hZ/view?usp=drive_link | I8: 16
A9: ตัวตบหลังเต่าหลังคา-อบขาว | D9: ตัวตบหลังเต่าหลังคา | E9: อบขาว | F9: 6 | H9: https://drive.google.com/file/d/1COsFZDP9fptiWLvKn9aNQEkLuXWtE5hZ/view?usp=drive_link | I9: 32
A10: ตัวตบหลังเต่าหลังคา-ดำ | D10: ตัวตบหลังเต่าหลังคา | E10: ดำ | F10: 6 | H10: https://drive.google.com/file/d/1COsFZDP9fptiWLvKn9aNQEkLuXWtE5hZ/view?usp=drive_link | I10: 12

Sheet เช็ครายการเบิกต่องาน
A1: ชื่องาน (ลูกค้า) | B1: คุณแมว | C1: วันที่ | D1: ผู้เบิก | E1: หมวดหมู่ | F1: รายการสินค้า | G1: จำนวน | H1: ราคารวม | I1: Remark
A2: มูลค่ารวม | C2: =IFERROR(__xludf.DUMMYFUNCTION("IFERROR( FILTER(CHOOSECOLS('รับเข้า-เบิก'!C2:K2112,1,2,4,5,6,8,9),'รับเข้า-เบิก'!$E$2:$E2112=B1))"),"")

Sheet สรุปรายการเบิกต่อเดือน

Sheet รวมรายการสินค้า
A1: หมวดหมู่ | B1: ชื่อรายการ
A2: =IFERROR(__xludf.DUMMYFUNCTION("{QUERY({ตาราง1[2];ตาราง1_2[SKU]},""select 'อุปกรณ์', Col1 label 'อุปกรณ์'''""); QUERY(ตาราง1_3[SKU],""select 'ยาง ลักหลาด', Col1 label 'ยาง ลักหลาด'''""); QUERY(ตาราง1_4[SKU],""select 'เครื่องมือช่าง', Col1 label 'เครื่องมือช่าง'''""); QUERY(ตาราง1_5[คอลั"&"มน์ 1],""select 'น็อต', Col1 label 'น็อต'''""); QUERY(ตาราง1_6[SKU],""select 'อลูมิเนียม', Col1 label 'อลูมิเนียม'''"")}"),"อุปกรณ์") -> อุปกรณ์ | B2: =IFERROR(__xludf.DUMMYFUNCTION("""COMPUTED_VALUE"""),"มือจับประตูบานเลื่อนแขวน ทรงโค้ง HOYA-PS-102-สแตนเลส") -> มือจับประตูบานเลื่อนแขวน ทรงโค้ง HOYA-PS-102-สแตนเลส
A3: =IFERROR(__xludf.DUMMYFUNCTION("""COMPUTED_VALUE"""),"อุปกรณ์") -> อุปกรณ์ | B3: =IFERROR(__xludf.DUMMYFUNCTION("""COMPUTED_VALUE"""),"มือจับฝังบานเลื่อน Hyda 416-Dummy-ดำ") -> มือจับฝังบานเลื่อน Hyda 416-Dummy-ดำ
A4: =IFERROR(__xludf.DUMMYFUNCTION("""COMPUTED_VALUE"""),"อุปกรณ์") -> อุปกรณ์ | B4: =IFERROR(__xludf.DUMMYFUNCTION("""COMPUTED_VALUE"""),"มือจับฝังบานเลื่อน Hyda 416-Dummy-อบขาว") -> มือจับฝังบานเลื่อน Hyda 416-Dummy-อบขาว
A5: =IFERROR(__xludf.DUMMYFUNCTION("""COMPUTED_VALUE"""),"อุปกรณ์") -> อุปกรณ์ | B5: =IFERROR(__xludf.DUMMYFUNCTION("""COMPUTED_VALUE"""),"มือจับฝังบานเลื่อน Hyda 416-Lock-ดำ") -> มือจับฝังบานเลื่อน Hyda 416-Lock-ดำ
A6: =IFERROR(__xludf.DUMMYFUNCTION("""COMPUTED_VALUE"""),"อุปกรณ์") -> อุปกรณ์ | B6: =IFERROR(__xludf.DUMMYFUNCTION("""COMPUTED_VALUE"""),"มือจับฝังบานเลื่อน Hyda 416-Lock-อบขาว") -> มือจับฝังบานเลื่อน Hyda 416-Lock-อบขาว
A7: =IFERROR(__xludf.DUMMYFUNCTION("""COMPUTED_VALUE"""),"อุปกรณ์") -> อุปกรณ์ | B7: =IFERROR(__xludf.DUMMYFUNCTION("""COMPUTED_VALUE"""),"มือจับฝังบานเลื่อน CMECH-Fixed Recessed Handle-ดำ") -> มือจับฝังบานเลื่อน CMECH-Fixed Recessed Handle-ดำ
A8: =IFERROR(__xludf.DUMMYFUNCTION("""COMPUTED_VALUE"""),"อุปกรณ์") -> อุปกรณ์ | B8: =IFERROR(__xludf.DUMMYFUNCTION("""COMPUTED_VALUE"""),"มือจับฝังบานเลื่อน CMECH-Fixed Recessed Handle-อบขาว") -> มือจับฝังบานเลื่อน CMECH-Fixed Recessed Handle-อบขาว
A9: =IFERROR(__xludf.DUMMYFUNCTION("""COMPUTED_VALUE"""),"อุปกรณ์") -> อุปกรณ์ | B9: =IFERROR(__xludf.DUMMYFUNCTION("""COMPUTED_VALUE"""),"มือจับฝังบานเลื่อน CMECH-Multi-Point Lock Recessed Handle-ดำ") -> มือจับฝังบานเลื่อน CMECH-Multi-Point Lock Recessed Handle-ดำ
A10: =IFERROR(__xludf.DUMMYFUNCTION("""COMPUTED_VALUE"""),"อุปกรณ์") -> อุปกรณ์ | B10: =IFERROR(__xludf.DUMMYFUNCTION("""COMPUTED_VALUE"""),"มือจับฝังบานเลื่อน CMECH-Multi-Point Lock Recessed Handle-อบขาว") -> มือจับฝังบานเลื่อน CMECH-Multi-Point Lock Recessed Handle-อบขาว
A11: =IFERROR(__xludf.DUMMYFUNCTION("""COMPUTED_VALUE"""),"อุปกรณ์") -> อุปกรณ์ | B11: =IFERROR(__xludf.DUMMYFUNCTION("""COMPUTED_VALUE"""),"มือจับฝังบานเลื่อน CMECH-Multi-Point Lock Recessed Interior with Key-ดำ") -> มือจับฝังบานเลื่อน CMECH-Multi-Point Lock Recessed Interior with Key-ดำ
A12: =IFERROR(__xludf.DUMMYFUNCTION("""COMPUTED_VALUE"""),"อุปกรณ์") -> อุปกรณ์ | B12: =IFERROR(__xludf.DUMMYFUNCTION("""COMPUTED_VALUE"""),"มือจับฝังบานเลื่อน CMECH-Multi-Point Lock Recessed Interior with Key-อบขาว") -> มือจับฝังบานเลื่อน CMECH-Multi-Point Lock Recessed Interior with Key-อบขาว
A13: =IFERROR(__xludf.DUMMYFUNCTION("""COMPUTED_VALUE"""),"อุปกรณ์") -> อุปกรณ์ | B13: =IFERROR(__xludf.DUMMYFUNCTION("""COMPUTED_VALUE"""),"มือจับบานเลื่อน CMECH-Metro Handle_ Dummy-ดำ") -> มือจับบานเลื่อน CMECH-Metro Handle_ Dummy-ดำ
A14: =IFERROR(__xludf.DUMMYFUNCTION("""COMPUTED_VALUE"""),"อุปกรณ์") -> อุปกรณ์ | B14: =IFERROR(__xludf.DUMMYFUNCTION("""COMPUTED_VALUE"""),"มือจับบานเลื่อน CMECH-Metro Handle_ Dummy-อบขาว") -> มือจับบานเลื่อน CMECH-Metro Handle_ Dummy-อบขาว
A15: =IFERROR(__xludf.DUMMYFUNCTION("""COMPUTED_VALUE"""),"อุปกรณ์") -> อุปกรณ์ | B15: =IFERROR(__xludf.DUMMYFUNCTION("""COMPUTED_VALUE"""),"มือจับบานเลื่อน CMECH-Metro Handle_ Lock-ดำ") -> มือจับบานเลื่อน CMECH-Metro Handle_ Lock-ดำ
A16: =IFERROR(__xludf.DUMMYFUNCTION("""COMPUTED_VALUE"""),"อุปกรณ์") -> อุปกรณ์ | B16: =IFERROR(__xludf.DUMMYFUNCTION("""COMPUTED_VALUE"""),"มือจับบานเลื่อน CMECH-Metro Handle_ Lock-อบขาว") -> มือจับบานเลื่อน CMECH-Metro Handle_ Lock-อบขาว
A17: =IFERROR(__xludf.DUMMYFUNCTION("""COMPUTED_VALUE"""),"อุปกรณ์") -> อุปกรณ์ | B17: =IFERROR(__xludf.DUMMYFUNCTION("""COMPUTED_VALUE"""),"มือจับบานเลื่อน CMECH-Metro Handle_ Key-ดำ") -> มือจับบานเลื่อน CMECH-Metro Handle_ Key-ดำ
A18: =IFERROR(__xludf.DUMMYFUNCTION("""COMPUTED_VALUE"""),"อุปกรณ์") -> อุปกรณ์ | B18: =IFERROR(__xludf.DUMMYFUNCTION("""COMPUTED_VALUE"""),"มือจับบานเลื่อน CMECH-Metro Handle_ Key-อบขาว") -> มือจับบานเลื่อน CMECH-Metro Handle_ Key-อบขาว
A19: =IFERROR(__xludf.DUMMYFUNCTION("""COMPUTED_VALUE"""),"อุปกรณ์") -> อุปกรณ์ | B19: =IFERROR(__xludf.DUMMYFUNCTION("""COMPUTED_VALUE"""),"มือจับฝังบานเลื่อน Align-Dummy-ดำ") -> มือจับฝังบานเลื่อน Align-Dummy-ดำ
A20: =IFERROR(__xludf.DUMMYFUNCTION("""COMPUTED_VALUE"""),"อุปกรณ์") -> อุปกรณ์ | B20: =IFERROR(__xludf.DUMMYFUNCTION("""COMPUTED_VALUE"""),"มือจับฝังบานเลื่อน Align-Dummy-อบขาว") -> มือจับฝังบานเลื่อน Align-Dummy-อบขาว
A21: =IFERROR(__xludf.DUMMYFUNCTION("""COMPUTED_VALUE"""),"อุปกรณ์") -> อุปกรณ์ | B21: =IFERROR(__xludf.DUMMYFUNCTION("""COMPUTED_VALUE"""),"มือจับฝังบานเลื่อน Align-Lock-ดำ") -> มือจับฝังบานเลื่อน Align-Lock-ดำ
A22: =IFERROR(__xludf.DUMMYFUNCTION("""COMPUTED_VALUE"""),"อุปกรณ์") -> อุปกรณ์ | B22: =IFERROR(__xludf.DUMMYFUNCTION("""COMPUTED_VALUE"""),"มือจับฝังบานเลื่อน Align-Lock-อบขาว") -> มือจับฝังบานเลื่อน Align-Lock-อบขาว
A23: =IFERROR(__xludf.DUMMYFUNCTION("""COMPUTED_VALUE"""),"อุปกรณ์") -> อุปกรณ์ | B23: =IFERROR(__xludf.DUMMYFUNCTION("""COMPUTED_VALUE"""),"มือจับฝังบานเลื่อน Align-Key-ดำ") -> มือจับฝังบานเลื่อน Align-Key-ดำ
