Workbook
Name ClothList: ราคามุ้ง!$I$2:$I$5
Name GlassNames: ราคาวัสดุกลาง!$H$2:$H$106
Name mult_euro: อัปเดตราคาอลู!$C$5
Name mult_mtong: อัปเดตราคาอลู!$C$8
Name mult_slim: อัปเดตราคาอลู!$C$6
Name mult_sms: อัปเดตราคาอลู!$C$4
Name mult_velora: อัปเดตราคาอลู!$C$7
Name mult_wood: อัปเดตราคาอลู!$C$20
Name MungList: ราคามุ้ง!$G$1:$G$15
Name MungReady: ราคามุ้ง!$G$1:$G$12
Name rate_grey: อัปเดตราคาอลู!$B$13
Name rate_special: อัปเดตราคาอลู!$B$14
Name rate_woodbake: อัปเดตราคาอลู!$B$15
Name rate_woodstock: อัปเดตราคาอลู!$B$16
Name SlimLuxGlass: 'คิดทุน SlimLux'!$AA$1:$AA$21

Sheet สารบัญ
B1: 📑 สารบัญ — กดลิงก์กระโดดไปหน้าที่ต้องการ
B3: 🔶 ปรับราคา / ค่าวัสดุ (แก้ราคาที่นี่ ทุกชีทขยับเอง)
B4: ▶ อัปเดตราคาอลู | C4: ราคาอลู/กก. ทุกแบรนด์ + ค่าอบสี ★
B5: ▶ ราคาสี | C5: ราคาสีอบ/เทาซาฮารา/ลายไม้
B6: ▶ ราคาวัสดุกลาง | C6: กระจก 98 รุ่น + เฟรม/เสา/อุปกรณ์
B7: ▶ ราคาวัสดุ | C7: วัสดุหลังคา (จันทัน/แป/แผ่น/ราง)
B8: ▶ ราคาออโต้ | C8: มอเตอร์/ออโต้
B9: ▶ ราคามุ้ง | C9: มุ้งซื้อสำเร็จ + ค่าแรงติดตั้ง
B10: ▶ ค่าแรง | C10: ค่าแรงผลิต+ติดตั้ง ทุกแบบ
B11: ▶ น้ำหนักโปรไฟล์ | C11: น้ำหนัก กก./เส้น ทุกโปรไฟล์
B12: ▶ ราคาสี (รวมแล้ว) | C12: ราคา/เส้น ทุกโปรไฟล์ (คำนวณ)
B13: 📊 สรุป / ภาพรวม
B14: ▶ หน้าตารางรวม | D14: ▶ สรุปงานเสริม | F14: ▶ สรุปค่าแรง
B15: 🚪 คิดทุน — ประตู/หน้าต่าง อลู
B16: ▶ SMS | D16: ▶ ยูโร | F16: ▶ SlimLux
B17: ▶ Velora | D17: ▶ E-series | F17: ▶ บานเปิด
B18: ▶ PC Door | D18: ▶ กระทุ้ง | F18: ▶ บานยก
B19: ▶ เฟี้ยม | D19: ▶ เฟี้ยมยูโร | F19: ▶ ติดตาย
B20: ▶ บานเลื่อนรางบน
B21: 🌀 คิดทุน — ดัดโค้ง
B22: ▶ ตายดัดโค้ง | D22: ▶ เปิดดัดโค้ง
B23: ▦ คิดทุน — ระแนง / ประตูรั้ว
B24: ▶ ระแนง | D24: ▶ ระแนงสลับ | F24: ▶ ระแนงสลับ_ประตู
B25: ▶ ประตูรั้ว | D25: ▶ บานเกล็ด | F25: ▶ ระแนงหมุน
B26: 🏠 คิดทุน — หลังคา
B27: ▶ หลังคา (รวม) | D27: ▶ หลังคา | F27: ▶ หลังคาจั่ว
B28: ▶ หลังคาเลื่อน | D28: ▶ ทุนไวนิล | F28: ▶ ทุนดีไลท์
B29: ▶ ทุนโพลีตัน | D29: ▶ ทุนชินโคร์ HC | F29: ▶ ทุนชินโคร์ Sup
B30: ▶ ทุนเมทัลชีท | D30: ▶ ทุนกระจก 4+4 | F30: ▶ ทุนกระจก 5+5
B31: 🧱 คิดทุน — ฝ้า / ผนัง / งานไฟ
B32: ▶ ฝ้ายิปซัม | D32: ▶ สมาร์ทบอร์ด | F32: ▶ ไอโซวอล
B33: ▶ งานไฟ | D33: ▶ ฝ้าไม้เทียม | F33: ▶ LUT_ฝ้าไม้เทียม
B34: ▶ สีฝ้าไม้เทียม
B35: 📐 เทียบ R3.9 / เช็ก
B36: ▶ เทียบ R3.9 SMS | D36: ▶ เทียบ R3.9 ยูโร | F36: ▶ เทียบ E-series
B37: ▶ เทียบ เฟี้ยมยูโร | D37: ▶ เทียบ R3.9 | F37: ▶ log กระจก
B38: ▶ เช็กขนาดกระจก

Sheet อัปเดตราคาอลู
A1: ⚠️ แก้ราคาที่นี่ → 📈 อัปเดตราคาวัสดุ — กรอก "ราคา/กก. ตอนนี้" ทับเมื่อราคาขึ้น (วิธีที่ 1) | G1: 🏠 สารบัญ
A3: แบรนด์ | B3: ราคาอลู/กก. ตอนนี้ | C3: ตัวคูณ | D3: ครอบคลุมบาน | F3: ตั้งต้น (ล็อก-อย่าแก้)
A4: SMS | B4: 187 | C4: =B4/F4 -> 1 | D4: SMS · E-series | F4: 187
A5: ยูโรฟูจิ | B5: 187 | C5: =B5/F5 -> 1 | D5: ยูโร·บานเปิด·PCDoor·กระทุ้ง·บานยก·เฟี้ยม·เฟี้ยมยูโร | F5: 187
A6: SlimLux | B6: 170 | C6: =B6/F6 -> 1 | D6: SlimLux | F6: 170
A7: Velora | B7: 240 | C7: =B7/F7 -> 1 | D7: Velora | F7: 240
A8: เมืองทอง (กล่อง/ฉาก/Z) | B8: 188 | C8: =B8/F8 -> 1 | D8: ระแนง·ประตู·บานเกล็ด·ติดตาย·หลังคา | F8: 188
A10: วิธีใช้: ร้านอลูขึ้นราคา → พิมพ์ราคา/กก. ใหม่ทับช่อง B (เช่น เมืองทอง 188→196) → ทุกโปรไฟล์แบรนด์นั้นขยับ % เท่ากันอัตโนมัติ
A12: ค่าอบสี / ลายไม้ — ราคา บาท/กก. (กรอกทับเมื่อขึ้น · ชุดเดียวทุกแบรนด์)
A13: เทาซาฮาร่า | B13: 100 | C13: ค่าอบเทา 100/กก. (ไม่มีค่าล้างสี)
A14: สีอบพิเศษ | B14: 173 | C14: 138 ค่าอบ + 35 ค่าล้างสี (พี่นัทเคาะ 18 มิ.ย.)
A15: สีลายไม้อบพิเศษ | B15: 190 | C15: 155 ค่าอบ + 35 ค่าล้างสี (พี่นัทเคาะ 18 มิ.ย.)
A16: ลายไม้ stock | B16: 112.5 | C16: factor กล่องเมืองทอง · SMS/ยูโร ลายไม้=ราคาตรงต่อเส้น
A17: + ค่าเปิดตู้อบ 2,000 บาท/งาน เฉพาะสีอบพิเศษ/สีลายไม้อบพิเศษ (คงที่ ไม่ขึ้นตาม กก.)
A19: ── ตัวคูณลายไม้สต็อค (เส้น SMS/ยูโร) — แยกจากเนื้ออลู ──
A20: ลายไม้สต็อค บาท/กก. | B20: 277 | C20: =B20/F20 -> 1 | D20: ตอนนี้ 277 (ของจริง) ÷ ตั้งต้น 258 (ที่ฝังไว้) = ตัวคูณลายไม้ | F20: 277

Sheet ราคาสี
A1: ⚠️ แก้ราคาที่นี่ → ราคาสี/เส้น (จาก Stock.xlsx · ลายไม้เอา max กับที่น้องพิมพ์) — อบพิเศษ/ลายไม้พิเศษ คิดสูตร base+ค่าอบ×นน. · เพิ่มเมืองทอง/SlimLux/Velora/E-series (ราคาประเมิน นน×เรต+ค่าอบ) | G1: 🏠 สารบัญ | H1: ⬇ ราคาใหม่อัตโนมัติเมื่อแก้ราคา/กก. (ของเก่าอยู่ช่องซ้าย ดูว่าขึ้นจริงไหม) | L1: ⬇ น้ำหนักคำนวณ = ราคาขาว/ดำ ÷ เรต/กก. ÷ ยาวเส้น (เอาไปคิดอบสี/ต่อยอดได้)
A2: รหัส | B2: ชื่อ | C2: ระบบ | D2: ขาว/ดำ | E2: เทาซาฮาร่า | F2: ลายไม้สต็อค | H2: ตัวคูณ (จาก/กก.) | I2: ขาว/ดำ ปัจจุบัน | J2: เทา ปัจจุบัน | K2: ลายไม้ ปัจจุบัน | L2: น้ำหนัก กก./เส้น | M2: น้ำหนัก กก./ม. | N2: เพิ่มขึ้น /เส้น
A3: B20001 | B3: เฟรมบนบานเลื่อน | C3: อลูมิเนียม sms | D3: 1125 | E3: 1225 | F3: 1825 | H3: =IF(ISNUMBER(SEARCH("เมืองทอง",C3)),mult_mtong,IF(ISNUMBER(SEARCH("SlimLux",C3)),mult_slim,IF(ISNUMBER(SEARCH("Velora",C3)),mult_velora,IF(ISNUMBER(SEARCH("Fuji",C3)),mult_euro,mult_sms)))) -> 1 | I3: =ROUND(D3*H3,0) -> 1125 | J3: =ROUND(E3*H3,0) -> 1225 | K3: =ROUND(F3*mult_wood,0) -> 1825 | L3: =ROUND(D3/(IF(ISNUMBER(SEARCH("เมืองทอง",C3)),อัปเดตราคาอลู!$F$8,IF(ISNUMBER(SEARCH("SlimLux",C3)),อัปเดตราคาอลู!$F$6,IF(ISNUMBER(SEARCH("Velora",C3)),อัปเดตราคาอลู!$F$7,IF(ISNUMBER(SEARCH("Fuji",C3)),อัปเดตราคาอลู!$F$5,อัปเดตราคาอลู!$F$4))))),3) -> 6.016 | M3: =ROUND(K3/(IF(OR(ISNUMBER(SEARCH("เมืองทอง",C3)),ISNUMBER(SEARCH("SlimLux",C3)),ISNUMBER(SEARCH("Velora",C3))),6,6.4)),3) -> 285.156 | N3: =ROUND(I3-D3,0) -> 0
A4: B20002 | B4: เฟรมล่างบานเลื่อน | C4: อลูมิเนียม sms | D4: 1205 | E4: 1310 | F4: 1925 | H4: =IF(ISNUMBER(SEARCH("เมืองทอง",C4)),mult_mtong,IF(ISNUMBER(SEARCH("SlimLux",C4)),mult_slim,IF(ISNUMBER(SEARCH("Velora",C4)),mult_velora,IF(ISNUMBER(SEARCH("Fuji",C4)),mult_euro,mult_sms)))) -> 1 | I4: =ROUND(D4*H4,0) -> 1205 | J4: =ROUND(E4*H4,0) -> 1310 | K4: =ROUND(F4*mult_wood,0) -> 1925 | L4: =ROUND(D4/(IF(ISNUMBER(SEARCH("เมืองทอง",C4)),อัปเดตราคาอลู!$F$8,IF(ISNUMBER(SEARCH("SlimLux",C4)),อัปเดตราคาอลู!$F$6,IF(ISNUMBER(SEARCH("Velora",C4)),อัปเดตราคาอลู!$F$7,IF(ISNUMBER(SEARCH("Fuji",C4)),อัปเดตราคาอลู!$F$5,อัปเดตราคาอลู!$F$4))))),3) -> 6.444 | M4: =ROUND(K4/(IF(OR(ISNUMBER(SEARCH("เมืองทอง",C4)),ISNUMBER(SEARCH("SlimLux",C4)),ISNUMBER(SEARCH("Velora",C4))),6,6.4)),3) -> 300.781 | N4: =ROUND(I4-D4,0) -> 0
A5: B20003 | B5: เฟรมข้างบานเลื่อน | C5: อลูมิเนียม sms | D5: 870 | E5: 950 | F5: 1395 | H5: =IF(ISNUMBER(SEARCH("เมืองทอง",C5)),mult_mtong,IF(ISNUMBER(SEARCH("SlimLux",C5)),mult_slim,IF(ISNUMBER(SEARCH("Velora",C5)),mult_velora,IF(ISNUMBER(SEARCH("Fuji",C5)),mult_euro,mult_sms)))) -> 1 | I5: =ROUND(D5*H5,0) -> 870 | J5: =ROUND(E5*H5,0) -> 950 | K5: =ROUND(F5*mult_wood,0) -> 1395 | L5: =ROUND(D5/(IF(ISNUMBER(SEARCH("เมืองทอง",C5)),อัปเดตราคาอลู!$F$8,IF(ISNUMBER(SEARCH("SlimLux",C5)),อัปเดตราคาอลู!$F$6,IF(ISNUMBER(SEARCH("Velora",C5)),อัปเดตราคาอลู!$F$7,IF(ISNUMBER(SEARCH("Fuji",C5)),อัปเดตราคาอลู!$F$5,อัปเดตราคาอลู!$F$4))))),3) -> 4.652 | M5: =ROUND(K5/(IF(OR(ISNUMBER(SEARCH("เมืองทอง",C5)),ISNUMBER(SEARCH("SlimLux",C5)),ISNUMBER(SEARCH("Velora",C5))),6,6.4)),3) -> 217.969 | N5: =ROUND(I5-D5,0) -> 0
A6: B20004 | B6: เฟรมบนเสริมร่องกระจก | C6: อลูมิเนียม sms | D6: 870 | E6: 950 | F6: 1395 | H6: =IF(ISNUMBER(SEARCH("เมืองทอง",C6)),mult_mtong,IF(ISNUMBER(SEARCH("SlimLux",C6)),mult_slim,IF(ISNUMBER(SEARCH("Velora",C6)),mult_velora,IF(ISNUMBER(SEARCH("Fuji",C6)),mult_euro,mult_sms)))) -> 1 | I6: =ROUND(D6*H6,0) -> 870 | J6: =ROUND(E6*H6,0) -> 950 | K6: =ROUND(F6*mult_wood,0) -> 1395 | L6: =ROUND(D6/(IF(ISNUMBER(SEARCH("เมืองทอง",C6)),อัปเดตราคาอลู!$F$8,IF(ISNUMBER(SEARCH("SlimLux",C6)),อัปเดตราคาอลู!$F$6,IF(ISNUMBER(SEARCH("Velora",C6)),อัปเดตราคาอลู!$F$7,IF(ISNUMBER(SEARCH("Fuji",C6)),อัปเดตราคาอลู!$F$5,อัปเดตราคาอลู!$F$4))))),3) -> 4.652 | M6: =ROUND(K6/(IF(OR(ISNUMBER(SEARCH("เมืองทอง",C6)),ISNUMBER(SEARCH("SlimLux",C6)),ISNUMBER(SEARCH("Velora",C6))),6,6.4)),3) -> 217.969 | N6: =ROUND(I6-D6,0) -> 0
A7: B20007 | B7: เสากุญแจ (ตูดตัน) | C7: อลูมิเนียม sms | D7: 660 | E7: 725 | F7: 1065 | H7: =IF(ISNUMBER(SEARCH("เมืองทอง",C7)),mult_mtong,IF(ISNUMBER(SEARCH("SlimLux",C7)),mult_slim,IF(ISNUMBER(SEARCH("Velora",C7)),mult_velora,IF(ISNUMBER(SEARCH("Fuji",C7)),mult_euro,mult_sms)))) -> 1 | I7: =ROUND(D7*H7,0) -> 660 | J7: =ROUND(E7*H7,0) -> 725 | K7: =ROUND(F7*mult_wood,0) -> 1065 | L7: =ROUND(D7/(IF(ISNUMBER(SEARCH("เมืองทอง",C7)),อัปเดตราคาอลู!$F$8,IF(ISNUMBER(SEARCH("SlimLux",C7)),อัปเดตราคาอลู!$F$6,IF(ISNUMBER(SEARCH("Velora",C7)),อัปเดตราคาอลู!$F$7,IF(ISNUMBER(SEARCH("Fuji",C7)),อัปเดตราคาอลู!$F$5,อัปเดตราคาอลู!$F$4))))),3) -> 3.529 | M7: =ROUND(K7/(IF(OR(ISNUMBER(SEARCH("เมืองทอง",C7)),ISNUMBER(SEARCH("SlimLux",C7)),ISNUMBER(SEARCH("Velora",C7))),6,6.4)),3) -> 166.406 | N7: =ROUND(I7-D7,0) -> 0
A8: B20008 | B8: เสากุญแจแบบรับแรง | C8: อลูมิเนียม sms | D8: 1125 | E8: 1225 | F8: 1800 | H8: =IF(ISNUMBER(SEARCH("เมืองทอง",C8)),mult_mtong,IF(ISNUMBER(SEARCH("SlimLux",C8)),mult_slim,IF(ISNUMBER(SEARCH("Velora",C8)),mult_velora,IF(ISNUMBER(SEARCH("Fuji",C8)),mult_euro,mult_sms)))) -> 1 | I8: =ROUND(D8*H8,0) -> 1125 | J8: =ROUND(E8*H8,0) -> 1225 | K8: =ROUND(F8*mult_wood,0) -> 1800 | L8: =ROUND(D8/(IF(ISNUMBER(SEARCH("เมืองทอง",C8)),อัปเดตราคาอลู!$F$8,IF(ISNUMBER(SEARCH("SlimLux",C8)),อัปเดตราคาอลู!$F$6,IF(ISNUMBER(SEARCH("Velora",C8)),อัปเดตราคาอลู!$F$7,IF(ISNUMBER(SEARCH("Fuji",C8)),อัปเดตราคาอลู!$F$5,อัปเดตราคาอลู!$F$4))))),3) -> 6.016 | M8: =ROUND(K8/(IF(OR(ISNUMBER(SEARCH("เมืองทอง",C8)),ISNUMBER(SEARCH("SlimLux",C8)),ISNUMBER(SEARCH("Velora",C8))),6,6.4)),3) -> 281.25 | N8: =ROUND(I8-D8,0) -> 0
A9: B20009 | B9: เสาเกี่ยว (ธรรมดา) | C9: อลูมิเนียม sms | D9: 690 | E9: 750 | F9: 1105 | H9: =IF(ISNUMBER(SEARCH("เมืองทอง",C9)),mult_mtong,IF(ISNUMBER(SEARCH("SlimLux",C9)),mult_slim,IF(ISNUMBER(SEARCH("Velora",C9)),mult_velora,IF(ISNUMBER(SEARCH("Fuji",C9)),mult_euro,mult_sms)))) -> 1 | I9: =ROUND(D9*H9,0) -> 690 | J9: =ROUND(E9*H9,0) -> 750 | K9: =ROUND(F9*mult_wood,0) -> 1105 | L9: =ROUND(D9/(IF(ISNUMBER(SEARCH("เมืองทอง",C9)),อัปเดตราคาอลู!$F$8,IF(ISNUMBER(SEARCH("SlimLux",C9)),อัปเดตราคาอลู!$F$6,IF(ISNUMBER(SEARCH("Velora",C9)),อัปเดตราคาอลู!$F$7,IF(ISNUMBER(SEARCH("Fuji",C9)),อัปเดตราคาอลู!$F$5,อัปเดตราคาอลู!$F$4))))),3) -> 3.69 | M9: =ROUND(K9/(IF(OR(ISNUMBER(SEARCH("เมืองทอง",C9)),ISNUMBER(SEARCH("SlimLux",C9)),ISNUMBER(SEARCH("Velora",C9))),6,6.4)),3) -> 172.656 | N9: =ROUND(I9-D9,0) -> 0
A10: B20010 | B10: เสาเกี่ยวนอก (สูง 2.4 m) | C10: อลูมิเนียม sms | D10: 1235 | E10: 1345 | F10: 1975 | H10: =IF(ISNUMBER(SEARCH("เมืองทอง",C10)),mult_mtong,IF(ISNUMBER(SEARCH("SlimLux",C10)),mult_slim,IF(ISNUMBER(SEARCH("Velora",C10)),mult_velora,IF(ISNUMBER(SEARCH("Fuji",C10)),mult_euro,mult_sms)))) -> 1 | I10: =ROUND(D10*H10,0) -> 1235 | J10: =ROUND(E10*H10,0) -> 1345 | K10: =ROUND(F10*mult_wood,0) -> 1975 | L10: =ROUND(D10/(IF(ISNUMBER(SEARCH("เมืองทอง",C10)),อัปเดตราคาอลู!$F$8,IF(ISNUMBER(SEARCH("SlimLux",C10)),อัปเดตราคาอลู!$F$6,IF(ISNUMBER(SEARCH("Velora",C10)),อัปเดตราคาอลู!$F$7,IF(ISNUMBER(SEARCH("Fuji",C10)),อัปเดตราคาอลู!$F$5,อัปเดตราคาอลู!$F$4))))),3) -> 6.604 | M10: =ROUND(K10/(IF(OR(ISNUMBER(SEARCH("เมืองทอง",C10)),ISNUMBER(SEARCH("SlimLux",C10)),ISNUMBER(SEARCH("Velora",C10))),6,6.4)),3) -> 308.594 | N10: =ROUND(I10-D10,0) -> 0
A11: B20019 | B11: ฝาปิดเฟรมข้าง | C11: อลูมิเนียม sms | D11: 175 | E11: 190 | F11: 280 | H11: =IF(ISNUMBER(SEARCH("เมืองทอง",C11)),mult_mtong,IF(ISNUMBER(SEARCH("SlimLux",C11)),mult_slim,IF(ISNUMBER(SEARCH("Velora",C11)),mult_velora,IF(ISNUMBER(SEARCH("Fuji",C11)),mult_euro,mult_sms)))) -> 1 | I11: =ROUND(D11*H11,0) -> 175 | J11: =ROUND(E11*H11,0) -> 190 | K11: =ROUND(F11*mult_wood,0) -> 280 | L11: =ROUND(D11/(IF(ISNUMBER(SEARCH("เมืองทอง",C11)),อัปเดตราคาอลู!$F$8,IF(ISNUMBER(SEARCH("SlimLux",C11)),อัปเดตราคาอลู!$F$6,IF(ISNUMBER(SEARCH("Velora",C11)),อัปเดตราคาอลู!$F$7,IF(ISNUMBER(SEARCH("Fuji",C11)),อัปเดตราคาอลู!$F$5,อัปเดตราคาอลู!$F$4))))),3) -> 0.936 | M11: =ROUND(K11/(IF(OR(ISNUMBER(SEARCH("เมืองทอง",C11)),ISNUMBER(SEARCH("SlimLux",C11)),ISNUMBER(SEARCH("Velora",C11))),6,6.4)),3) -> 43.75 | N11: =ROUND(I11-D11,0) -> 0
A12: B20024 | B12: คิ้วกันตก | C12: อลูมิเนียม sms | D12: 185 | E12: 200 | F12: 295 | H12: =IF(ISNUMBER(SEARCH("เมืองทอง",C12)),mult_mtong,IF(ISNUMBER(SEARCH("SlimLux",C12)),mult_slim,IF(ISNUMBER(SEARCH("Velora",C12)),mult_velora,IF(ISNUMBER(SEARCH("Fuji",C12)),mult_euro,mult_sms)))) -> 1 | I12: =ROUND(D12*H12,0) -> 185 | J12: =ROUND(E12*H12,0) -> 200 | K12: =ROUND(F12*mult_wood,0) -> 295 | L12: =ROUND(D12/(IF(ISNUMBER(SEARCH("เมืองทอง",C12)),อัปเดตราคาอลู!$F$8,IF(ISNUMBER(SEARCH("SlimLux",C12)),อัปเดตราคาอลู!$F$6,IF(ISNUMBER(SEARCH("Velora",C12)),อัปเดตราคาอลู!$F$7,IF(ISNUMBER(SEARCH("Fuji",C12)),อัปเดตราคาอลู!$F$5,อัปเดตราคาอลู!$F$4))))),3) -> 0.989 | M12: =ROUND(K12/(IF(OR(ISNUMBER(SEARCH("เมืองทอง",C12)),ISNUMBER(SEARCH("SlimLux",C12)),ISNUMBER(SEARCH("Velora",C12))),6,6.4)),3) -> 46.094 | N12: =ROUND(I12-D12,0) -> 0
A13: B20041 | B13: เฟรมบานเลื่อน (3รางเสียบ) | C13: อลูมิเนียม sms | D13: 2070 | E13: 2255 | F13: 3424 | H13: =IF(ISNUMBER(SEARCH("เมืองทอง",C13)),mult_mtong,IF(ISNUMBER(SEARCH("SlimLux",C13)),mult_slim,IF(ISNUMBER(SEARCH("Velora",C13)),mult_velora,IF(ISNUMBER(SEARCH("Fuji",C13)),mult_euro,mult_sms)))) -> 1 | I13: =ROUND(D13*H13,0) -> 2070 | J13: =ROUND(E13*H13,0) -> 2255 | K13: =ROUND(F13*mult_wood,0) -> 3424 | L13: =ROUND(D13/(IF(ISNUMBER(SEARCH("เมืองทอง",C13)),อัปเดตราคาอลู!$F$8,IF(ISNUMBER(SEARCH("SlimLux",C13)),อัปเดตราคาอลู!$F$6,IF(ISNUMBER(SEARCH("Velora",C13)),อัปเดตราคาอลู!$F$7,IF(ISNUMBER(SEARCH("Fuji",C13)),อัปเดตราคาอลู!$F$5,อัปเดตราคาอลู!$F$4))))),3) -> 11.07 | M13: =ROUND(K13/(IF(OR(ISNUMBER(SEARCH("เมืองทอง",C13)),ISNUMBER(SEARCH("SlimLux",C13)),ISNUMBER(SEARCH("Velora",C13))),6,6.4)),3) -> 535 | N13: =ROUND(I13-D13,0) -> 0
A14: B20048 | B14: ตัวตบรางมุ้ง | C14: อลูมิเนียม sms | D14: 310 | E14: 340 | F14: 495 | H14: =IF(ISNUMBER(SEARCH("เมืองทอง",C14)),mult_mtong,IF(ISNUMBER(SEARCH("SlimLux",C14)),mult_slim,IF(ISNUMBER(SEARCH("Velora",C14)),mult_velora,IF(ISNUMBER(SEARCH("Fuji",C14)),mult_euro,mult_sms)))) -> 1 | I14: =ROUND(D14*H14,0) -> 310 | J14: =ROUND(E14*H14,0) -> 340 | K14: =ROUND(F14*mult_wood,0) -> 495 | L14: =ROUND(D14/(IF(ISNUMBER(SEARCH("เมืองทอง",C14)),อัปเดตราคาอลู!$F$8,IF(ISNUMBER(SEARCH("SlimLux",C14)),อัปเดตราคาอลู!$F$6,IF(ISNUMBER(SEARCH("Velora",C14)),อัปเดตราคาอลู!$F$7,IF(ISNUMBER(SEARCH("Fuji",C14)),อัปเดตราคาอลู!$F$5,อัปเดตราคาอลู!$F$4))))),3) -> 1.658 | M14: =ROUND(K14/(IF(OR(ISNUMBER(SEARCH("เมืองทอง",C14)),ISNUMBER(SEARCH("SlimLux",C14)),ISNUMBER(SEARCH("Velora",C14))),6,6.4)),3) -> 77.344 | N14: =ROUND(I14-D14,0) -> 0
... A62: F7988 | B62: ตบปิดร่อง | C62: อลูมิเนียม Fuji | D62: 120 | E62: 150 | F62: 170 | H62: =IF(ISNUMBER(SEARCH("เมืองทอง",C62)),mult_mtong,IF(ISNUMBER(SEARCH("SlimLux",C62)),mult_slim,IF(ISNUMBER(SEARCH("Velora",C62)),mult_velora,IF(ISNUMBER(SEARCH("Fuji",C62)),mult_euro,mult_sms)))) -> 1 | I62: =ROUND(D62*H62,0) -> 120 | J62: =ROUND(E62*H62,0) -> 150 | K62: =ROUND(F62*mult_wood,0) -> 170 | L62: =ROUND(D62/(IF(ISNUMBER(SEARCH("เมืองทอง",C62)),อัปเดตราคาอลู!$F$8,IF(ISNUMBER(SEARCH("SlimLux",C62)),อัปเดตราคาอลู!$F$6,IF(ISNUMBER(SEARCH("Velora",C62)),อัปเดตราคาอลู!$F$7,IF(ISNUMBER(SEARCH("Fuji",C62)),อัปเดตราคาอลู!$F$5,อัปเดตราคาอลู!$F$4))))),3) -> 0.642 | M62: =ROUND(K62/(IF(OR(ISNUMBER(SEARCH("เมืองทอง",C62)),ISNUMBER(SEARCH("SlimLux",C62)),ISNUMBER(SEARCH("Velora",C62))),6,6.4)),3) -> 26.563 | N62: =ROUND(I62-D62,0) -> 0
A63: F7994 | B63: เส้นรางเลื่อน | C63: อลูมิเนียม Fuji | D63: 150 | H63: =IF(ISNUMBER(SEARCH("เมืองทอง",C63)),mult_mtong,IF(ISNUMBER(SEARCH("SlimLux",C63)),mult_slim,IF(ISNUMBER(SEARCH("Velora",C63)),mult_velora,IF(ISNUMBER(SEARCH("Fuji",C63)),mult_euro,mult_sms)))) -> 1 | I63: =ROUND(D63*H63,0) -> 150 | J63: =ROUND(E63*H63,0) -> 0 | L63: =ROUND(D63/(IF(ISNUMBER(SEARCH("เมืองทอง",C63)),อัปเดตราคาอลู!$F$8,IF(ISNUMBER(SEARCH("SlimLux",C63)),อัปเดตราคาอลู!$F$6,IF(ISNUMBER(SEARCH("Velora",C63)),อัปเดตราคาอลู!$F$7,IF(ISNUMBER(SEARCH("Fuji",C63)),อัปเดตราคาอลู!$F$5,อัปเดตราคาอลู!$F$4))))),3) -> 0.802 | M63: =ROUND(K63/(IF(OR(ISNUMBER(SEARCH("เมืองทอง",C63)),ISNUMBER(SEARCH("SlimLux",C63)),ISNUMBER(SEARCH("Velora",C63))),6,6.4)),3) -> 0 | N63: =ROUND(I63-D63,0) -> 0
A64: F7987 | B64: คิ้วมุ้งบานเลื่อน | C64: อลูมิเนียม Fuji | D64: 150 | E64: 180 | F64: 270 | H64: =IF(ISNUMBER(SEARCH("เมืองทอง",C64)),mult_mtong,IF(ISNUMBER(SEARCH("SlimLux",C64)),mult_slim,IF(ISNUMBER(SEARCH("Velora",C64)),mult_velora,IF(ISNUMBER(SEARCH("Fuji",C64)),mult_euro,mult_sms)))) -> 1 | I64: =ROUND(D64*H64,0) -> 150 | J64: =ROUND(E64*H64,0) -> 180 | K64: =ROUND(F64*mult_wood,0) -> 270 | L64: =ROUND(D64/(IF(ISNUMBER(SEARCH("เมืองทอง",C64)),อัปเดตราคาอลู!$F$8,IF(ISNUMBER(SEARCH("SlimLux",C64)),อัปเดตราคาอลู!$F$6,IF(ISNUMBER(SEARCH("Velora",C64)),อัปเดตราคาอลู!$F$7,IF(ISNUMBER(SEARCH("Fuji",C64)),อัปเดตราคาอลู!$F$5,อัปเดตราคาอลู!$F$4))))),3) -> 0.802 | M64: =ROUND(K64/(IF(OR(ISNUMBER(SEARCH("เมืองทอง",C64)),ISNUMBER(SEARCH("SlimLux",C64)),ISNUMBER(SEARCH("Velora",C64))),6,6.4)),3) -> 42.188 | N64: =ROUND(I64-D64,0) -> 0
A65: F7996 | B65: คิ้วลอยช่องแสง | C65: อลูมิเนียม Fuji | D65: 455 | E65: 490 | F65: 725 | H65: =IF(ISNUMBER(SEARCH("เมืองทอง",C65)),mult_mtong,IF(ISNUMBER(SEARCH("SlimLux",C65)),mult_slim,IF(ISNUMBER(SEARCH("Velora",C65)),mult_velora,IF(ISNUMBER(SEARCH("Fuji",C65)),mult_euro,mult_sms)))) -> 1 | I65: =ROUND(D65*H65,0) -> 455 | J65: =ROUND(E65*H65,0) -> 490 | K65: =ROUND(F65*mult_wood,0) -> 725 | L65: =ROUND(D65/(IF(ISNUMBER(SEARCH("เมืองทอง",C65)),อัปเดตราคาอลู!$F$8,IF(ISNUMBER(SEARCH("SlimLux",C65)),อัปเดตราคาอลู!$F$6,IF(ISNUMBER(SEARCH("Velora",C65)),อัปเดตราคาอลู!$F$7,IF(ISNUMBER(SEARCH("Fuji",C65)),อัปเดตราคาอลู!$F$5,อัปเดตราคาอลู!$F$4))))),3) -> 2.433 | M65: =ROUND(K65/(IF(OR(ISNUMBER(SEARCH("เมืองทอง",C65)),ISNUMBER(SEARCH("SlimLux",C65)),ISNUMBER(SEARCH("Velora",C65))),6,6.4)),3) -> 113.281 | N65: =ROUND(I65-D65,0) -> 0
A66: F7919 | B66: คิ้วกรอบบาน | C66: อลูมิเนียม Fuji | D66: 185 | E66: 200 | F66: 295 | H66: =IF(ISNUMBER(SEARCH("เมืองทอง",C66)),mult_mtong,IF(ISNUMBER(SEARCH("SlimLux",C66)),mult_slim,IF(ISNUMBER(SEARCH("Velora",C66)),mult_velora,IF(ISNUMBER(SEARCH("Fuji",C66)),mult_euro,mult_sms)))) -> 1 | I66: =ROUND(D66*H66,0) -> 185 | J66: =ROUND(E66*H66,0) -> 200 | K66: =ROUND(F66*mult_wood,0) -> 295 | L66: =ROUND(D66/(IF(ISNUMBER(SEARCH("เมืองทอง",C66)),อัปเดตราคาอลู!$F$8,IF(ISNUMBER(SEARCH("SlimLux",C66)),อัปเดตราคาอลู!$F$6,IF(ISNUMBER(SEARCH("Velora",C66)),อัปเดตราคาอลู!$F$7,IF(ISNUMBER(SEARCH("Fuji",C66)),อัปเดตราคาอลู!$F$5,อัปเดตราคาอลู!$F$4))))),3) -> 0.989 | M66: =ROUND(K66/(IF(OR(ISNUMBER(SEARCH("เมืองทอง",C66)),ISNUMBER(SEARCH("SlimLux",C66)),ISNUMBER(SEARCH("Velora",C66))),6,6.4)),3) -> 46.094 | N66: =ROUND(I66-D66,0) -> 0
A67: F7917 | B67: คิ้วกรอบบาน | C67: อลูมิเนียม Fuji | D67: 160 | E67: 170 | F67: 255 | H67: =IF(ISNUMBER(SEARCH("เมืองทอง",C67)),mult_mtong,IF(ISNUMBER(SEARCH("SlimLux",C67)),mult_slim,IF(ISNUMBER(SEARCH("Velora",C67)),mult_velora,IF(ISNUMBER(SEARCH("Fuji",C67)),mult_euro,mult_sms)))) -> 1 | I67: =ROUND(D67*H67,0) -> 160 | J67: =ROUND(E67*H67,0) -> 170 | K67: =ROUND(F67*mult_wood,0) -> 255 | L67: =ROUND(D67/(IF(ISNUMBER(SEARCH("เมืองทอง",C67)),อัปเดตราคาอลู!$F$8,IF(ISNUMBER(SEARCH("SlimLux",C67)),อัปเดตราคาอลู!$F$6,IF(ISNUMBER(SEARCH("Velora",C67)),อัปเดตราคาอลู!$F$7,IF(ISNUMBER(SEARCH("Fuji",C67)),อัปเดตราคาอลู!$F$5,อัปเดตราคาอลู!$F$4))))),3) -> 0.856 | M67: =ROUND(K67/(IF(OR(ISNUMBER(SEARCH("เมืองทอง",C67)),ISNUMBER(SEARCH("SlimLux",C67)),ISNUMBER(SEARCH("Velora",C67))),6,6.4)),3) -> 39.844 | N67: =ROUND(I67-D67,0) -> 0
A68: F7950 | B68: คิ้วกรอบบาน | C68: อลูมิเนียม Fuji | D68: 160 | E68: 170 | F68: 255 | H68: =IF(ISNUMBER(SEARCH("เมืองทอง",C68)),mult_mtong,IF(ISNUMBER(SEARCH("SlimLux",C68)),mult_slim,IF(ISNUMBER(SEARCH("Velora",C68)),mult_velora,IF(ISNUMBER(SEARCH("Fuji",C68)),mult_euro,mult_sms)))) -> 1 | I68: =ROUND(D68*H68,0) -> 160 | J68: =ROUND(E68*H68,0) -> 170 | K68: =ROUND(F68*mult_wood,0) -> 255 | L68: =ROUND(D68/(IF(ISNUMBER(SEARCH("เมืองทอง",C68)),อัปเดตราคาอลู!$F$8,IF(ISNUMBER(SEARCH("SlimLux",C68)),อัปเดตราคาอลู!$F$6,IF(ISNUMBER(SEARCH("Velora",C68)),อัปเดตราคาอลู!$F$7,IF(ISNUMBER(SEARCH("Fuji",C68)),อัปเดตราคาอลู!$F$5,อัปเดตราคาอลู!$F$4))))),3) -> 0.856 | M68: =ROUND(K68/(IF(OR(ISNUMBER(SEARCH("เมืองทอง",C68)),ISNUMBER(SEARCH("SlimLux",C68)),ISNUMBER(SEARCH("Velora",C68))),6,6.4)),3) -> 39.844 | N68: =ROUND(I68-D68,0) -> 0
A69: F7952 | B69: แผ่นยึดเฟรมล่าง | C69: อลูมิเนียม Fuji | D69: 540 | E69: 580 | F69: 855 | H69: =IF(ISNUMBER(SEARCH("เมืองทอง",C69)),mult_mtong,IF(ISNUMBER(SEARCH("SlimLux",C69)),mult_slim,IF(ISNUMBER(SEARCH("Velora",C69)),mult_velora,IF(ISNUMBER(SEARCH("Fuji",C69)),mult_euro,mult_sms)))) -> 1 | I69: =ROUND(D69*H69,0) -> 540 | J69: =ROUND(E69*H69,0) -> 580 | K69: =ROUND(F69*mult_wood,0) -> 855 | L69: =ROUND(D69/(IF(ISNUMBER(SEARCH("เมืองทอง",C69)),อัปเดตราคาอลู!$F$8,IF(ISNUMBER(SEARCH("SlimLux",C69)),อัปเดตราคาอลู!$F$6,IF(ISNUMBER(SEARCH("Velora",C69)),อัปเดตราคาอลู!$F$7,IF(ISNUMBER(SEARCH("Fuji",C69)),อัปเดตราคาอลู!$F$5,อัปเดตราคาอลู!$F$4))))),3) -> 2.888 | M69: =ROUND(K69/(IF(OR(ISNUMBER(SEARCH("เมืองทอง",C69)),ISNUMBER(SEARCH("SlimLux",C69)),ISNUMBER(SEARCH("Velora",C69))),6,6.4)),3) -> 133.594 | N69: =ROUND(I69-D69,0) -> 0
A70: F7879 | B70: ตบธรณีเรียบตัวกลาง | C70: อลูมิเนียม Fuji | D70: 355 | E70: 380 | F70: 560 | H70: =IF(ISNUMBER(SEARCH("เมืองทอง",C70)),mult_mtong,IF(ISNUMBER(SEARCH("SlimLux",C70)),mult_slim,IF(ISNUMBER(SEARCH("Velora",C70)),mult_velora,IF(ISNUMBER(SEARCH("Fuji",C70)),mult_euro,mult_sms)))) -> 1 | I70: =ROUND(D70*H70,0) -> 355 | J70: =ROUND(E70*H70,0) -> 380 | K70: =ROUND(F70*mult_wood,0) -> 560 | L70: =ROUND(D70/(IF(ISNUMBER(SEARCH("เมืองทอง",C70)),อัปเดตราคาอลู!$F$8,IF(ISNUMBER(SEARCH("SlimLux",C70)),อัปเดตราคาอลู!$F$6,IF(ISNUMBER(SEARCH("Velora",C70)),อัปเดตราคาอลู!$F$7,IF(ISNUMBER(SEARCH("Fuji",C70)),อัปเดตราคาอลู!$F$5,อัปเดตราคาอลู!$F$4))))),3) -> 1.898 | M70: =ROUND(K70/(IF(OR(ISNUMBER(SEARCH("เมืองทอง",C70)),ISNUMBER(SEARCH("SlimLux",C70)),ISNUMBER(SEARCH("Velora",C70))),6,6.4)),3) -> 87.5 | N70: =ROUND(I70-D70,0) -> 0
A71: F7880 | B71: ตบธรณีเรียบตัวริม | C71: อลูมิเนียม Fuji | D71: 355 | E71: 380 | F71: 560 | H71: =IF(ISNUMBER(SEARCH("เมืองทอง",C71)),mult_mtong,IF(ISNUMBER(SEARCH("SlimLux",C71)),mult_slim,IF(ISNUMBER(SEARCH("Velora",C71)),mult_velora,IF(ISNUMBER(SEARCH("Fuji",C71)),mult_euro,mult_sms)))) -> 1 | I71: =ROUND(D71*H71,0) -> 355 | J71: =ROUND(E71*H71,0) -> 380 | K71: =ROUND(F71*mult_wood,0) -> 560 | L71: =ROUND(D71/(IF(ISNUMBER(SEARCH("เมืองทอง",C71)),อัปเดตราคาอลู!$F$8,IF(ISNUMBER(SEARCH("SlimLux",C71)),อัปเดตราคาอลู!$F$6,IF(ISNUMBER(SEARCH("Velora",C71)),อัปเดตราคาอลู!$F$7,IF(ISNUMBER(SEARCH("Fuji",C71)),อัปเดตราคาอลู!$F$5,อัปเดตราคาอลู!$F$4))))),3) -> 1.898 | M71: =ROUND(K71/(IF(OR(ISNUMBER(SEARCH("เมืองทอง",C71)),ISNUMBER(SEARCH("SlimLux",C71)),ISNUMBER(SEARCH("Velora",C71))),6,6.4)),3) -> 87.5 | N71: =ROUND(I71-D71,0) -> 0
A72: F7859 | B72: เฟรมบานกระทุ้ง ไม่มีรูระบายน้ำ | C72: อลูมิเนียม Fuji | D72: 1075 | E72: 1150 | F72: 1700 | H72: =IF(ISNUMBER(SEARCH("เมืองทอง",C72)),mult_mtong,IF(ISNUMBER(SEARCH("SlimLux",C72)),mult_slim,IF(ISNUMBER(SEARCH("Velora",C72)),mult_velora,IF(ISNUMBER(SEARCH("Fuji",C72)),mult_euro,mult_sms)))) -> 1 | I72: =ROUND(D72*H72,0) -> 1075 | J72: =ROUND(E72*H72,0) -> 1150 | K72: =ROUND(F72*mult_wood,0) -> 1700 | L72: =ROUND(D72/(IF(ISNUMBER(SEARCH("เมืองทอง",C72)),อัปเดตราคาอลู!$F$8,IF(ISNUMBER(SEARCH("SlimLux",C72)),อัปเดตราคาอลู!$F$6,IF(ISNUMBER(SEARCH("Velora",C72)),อัปเดตราคาอลู!$F$7,IF(ISNUMBER(SEARCH("Fuji",C72)),อัปเดตราคาอลู!$F$5,อัปเดตราคาอลู!$F$4))))),3) -> 5.749 | M72: =ROUND(K72/(IF(OR(ISNUMBER(SEARCH("เมืองทอง",C72)),ISNUMBER(SEARCH("SlimLux",C72)),ISNUMBER(SEARCH("Velora",C72))),6,6.4)),3) -> 265.625 | N72: =ROUND(I72-D72,0) -> 0
A73: F7858 | B73: เฟรมบานตายคิ้วไม่มีรูระบายน้ำ | C73: อลูมิเนียม Fuji | D73: 1345 | E73: 1440 | F73: 2130 | H73: =IF(ISNUMBER(SEARCH("เมืองทอง",C73)),mult_mtong,IF(ISNUMBER(SEARCH("SlimLux",C73)),mult_slim,IF(ISNUMBER(SEARCH("Velora",C73)),mult_velora,IF(ISNUMBER(SEARCH("Fuji",C73)),mult_euro,mult_sms)))) -> 1 | I73: =ROUND(D73*H73,0) -> 1345 | J73: =ROUND(E73*H73,0) -> 1440 | K73: =ROUND(F73*mult_wood,0) -> 2130 | L73: =ROUND(D73/(IF(ISNUMBER(SEARCH("เมืองทอง",C73)),อัปเดตราคาอลู!$F$8,IF(ISNUMBER(SEARCH("SlimLux",C73)),อัปเดตราคาอลู!$F$6,IF(ISNUMBER(SEARCH("Velora",C73)),อัปเดตราคาอลู!$F$7,IF(ISNUMBER(SEARCH("Fuji",C73)),อัปเดตราคาอลู!$F$5,อัปเดตราคาอลู!$F$4))))),3) -> 7.193 | M73: =ROUND(K73/(IF(OR(ISNUMBER(SEARCH("เมืองทอง",C73)),ISNUMBER(SEARCH("SlimLux",C73)),ISNUMBER(SEARCH("Velora",C73))),6,6.4)),3) -> 332.813 | N73: =ROUND(I73-D73,0) -> 0
A74: F7937 | B74: เฟรมบานตายคิ้วใน | C74: อลูมิเนียม Fuji | D74: 1180 | E74: 1270 | F74: 1875 | H74: =IF(ISNUMBER(SEARCH("เมืองทอง",C74)),mult_mtong,IF(ISNUMBER(SEARCH("SlimLux",C74)),mult_slim,IF(ISNUMBER(SEARCH("Velora",C74)),mult_velora,IF(ISNUMBER(SEARCH("Fuji",C74)),mult_euro,mult_sms)))) -> 1 | I74: =ROUND(D74*H74,0) -> 1180 | J74: =ROUND(E74*H74,0) -> 1270 | K74: =ROUND(F74*mult_wood,0) -> 1875 | L74: =ROUND(D74/(IF(ISNUMBER(SEARCH("เมืองทอง",C74)),อัปเดตราคาอลู!$F$8,IF(ISNUMBER(SEARCH("SlimLux",C74)),อัปเดตราคาอลู!$F$6,IF(ISNUMBER(SEARCH("Velora",C74)),อัปเดตราคาอลู!$F$7,IF(ISNUMBER(SEARCH("Fuji",C74)),อัปเดตราคาอลู!$F$5,อัปเดตราคาอลู!$F$4))))),3) -> 6.31 | M74: =ROUND(K74/(IF(OR(ISNUMBER(SEARCH("เมืองทอง",C74)),ISNUMBER(SEARCH("SlimLux",C74)),ISNUMBER(SEARCH("Velora",C74))),6,6.4)),3) -> 292.969 | N74: =ROUND(I74-D74,0) -> 0
A75: F7871 | B75: เฟรมบานตายคิ้วใน (ตัวหนา) | C75: อลูมิเนียม Fuji | D75: 1505 | E75: 1615 | F75: 2385 | H75: =IF(ISNUMBER(SEARCH("เมืองทอง",C75)),mult_mtong,IF(ISNUMBER(SEARCH("SlimLux",C75)),mult_slim,IF(ISNUMBER(SEARCH("Velora",C75)),mult_velora,IF(ISNUMBER(SEARCH("Fuji",C75)),mult_euro,mult_sms)))) -> 1 | I75: =ROUND(D75*H75,0) -> 1505 | J75: =ROUND(E75*H75,0) -> 1615 | K75: =ROUND(F75*mult_wood,0) -> 2385 | L75: =ROUND(D75/(IF(ISNUMBER(SEARCH("เมืองทอง",C75)),อัปเดตราคาอลู!$F$8,IF(ISNUMBER(SEARCH("SlimLux",C75)),อัปเดตราคาอลู!$F$6,IF(ISNUMBER(SEARCH("Velora",C75)),อัปเดตราคาอลู!$F$7,IF(ISNUMBER(SEARCH("Fuji",C75)),อัปเดตราคาอลู!$F$5,อัปเดตราคาอลู!$F$4))))),3) -> 8.048 | M75: =ROUND(K75/(IF(OR(ISNUMBER(SEARCH("เมืองทอง",C75)),ISNUMBER(SEARCH("SlimLux",C75)),ISNUMBER(SEARCH("Velora",C75))),6,6.4)),3) -> 372.656 | N75: =ROUND(I75-D75,0) -> 0
... A108: F7975 | B108: บังใบสำหรับใส่กลอน | C108: อลูมิเนียม Fuji | D108: 540 | E108: 580 | F108: 855 | H108: =IF(ISNUMBER(SEARCH("เมืองทอง",C108)),mult_mtong,IF(ISNUMBER(SEARCH("SlimLux",C108)),mult_slim,IF(ISNUMBER(SEARCH("Velora",C108)),mult_velora,IF(ISNUMBER(SEARCH("Fuji",C108)),mult_euro,mult_sms)))) -> 1 | I108: =ROUND(D108*H108,0) -> 540 | J108: =ROUND(E108*H108,0) -> 580 | K108: =ROUND(F108*mult_wood,0) -> 855 | L108: =ROUND(D108/(IF(ISNUMBER(SEARCH("เมืองทอง",C108)),อัปเดตราคาอลู!$F$8,IF(ISNUMBER(SEARCH("SlimLux",C108)),อัปเดตราคาอลู!$F$6,IF(ISNUMBER(SEARCH("Velora",C108)),อัปเดตราคาอลู!$F$7,IF(ISNUMBER(SEARCH("Fuji",C108)),อัปเดตราคาอลู!$F$5,อัปเดตราคาอลู!$F$4))))),3) -> 2.888 | M108: =ROUND(K108/(IF(OR(ISNUMBER(SEARCH("เมืองทอง",C108)),ISNUMBER(SEARCH("SlimLux",C108)),ISNUMBER(SEARCH("Velora",C108))),6,6.4)),3) -> 133.594 | N108: =ROUND(I108-D108,0) -> 0
A109: ━ เมืองทอง ━
A110: 705 | B110: แป๊บ 6 หุน | C110: อลูมิเนียม เมืองทอง | D110: 222 | E110: 340 | F110: 355 | H110: =IF(ISNUMBER(SEARCH("เมืองทอง",C110)),mult_mtong,IF(ISNUMBER(SEARCH("SlimLux",C110)),mult_slim,IF(ISNUMBER(SEARCH("Velora",C110)),mult_velora,IF(ISNUMBER(SEARCH("Fuji",C110)),mult_euro,mult_sms)))) -> 1 | I110: =ROUND(D110*H110,0) -> 222 | J110: =ROUND(E110*H110,0) -> 340 | K110: =ROUND(F110*mult_wood,0) -> 355 | L110: =ROUND(D110/(IF(ISNUMBER(SEARCH("เมืองทอง",C110)),อัปเดตราคาอลู!$F$8,IF(ISNUMBER(SEARCH("SlimLux",C110)),อัปเดตราคาอลู!$F$6,IF(ISNUMBER(SEARCH("Velora",C110)),อัปเดตราคาอลู!$F$7,IF(ISNUMBER(SEARCH("Fuji",C110)),อัปเดตราคาอลู!$F$5,อัปเดตราคาอลู!$F$4))))),3) -> 1.181 | M110: =ROUND(K110/(IF(OR(ISNUMBER(SEARCH("เมืองทอง",C110)),ISNUMBER(SEARCH("SlimLux",C110)),ISNUMBER(SEARCH("Velora",C110))),6,6.4)),3) -> 59.167 | N110: =ROUND(I110-D110,0) -> 0
A111: 706 | B111: แป๊บ 6 หุน | C111: อลูมิเนียม เมืองทอง | D111: 261 | E111: 400 | F111: 418 | H111: =IF(ISNUMBER(SEARCH("เมืองทอง",C111)),mult_mtong,IF(ISNUMBER(SEARCH("SlimLux",C111)),mult_slim,IF(ISNUMBER(SEARCH("Velora",C111)),mult_velora,IF(ISNUMBER(SEARCH("Fuji",C111)),mult_euro,mult_sms)))) -> 1 | I111: =ROUND(D111*H111,0) -> 261 | J111: =ROUND(E111*H111,0) -> 400 | K111: =ROUND(F111*mult_wood,0) -> 418 | L111: =ROUND(D111/(IF(ISNUMBER(SEARCH("เมืองทอง",C111)),อัปเดตราคาอลู!$F$8,IF(ISNUMBER(SEARCH("SlimLux",C111)),อัปเดตราคาอลู!$F$6,IF(ISNUMBER(SEARCH("Velora",C111)),อัปเดตราคาอลู!$F$7,IF(ISNUMBER(SEARCH("Fuji",C111)),อัปเดตราคาอลู!$F$5,อัปเดตราคาอลู!$F$4))))),3) -> 1.388 | M111: =ROUND(K111/(IF(OR(ISNUMBER(SEARCH("เมืองทอง",C111)),ISNUMBER(SEARCH("SlimLux",C111)),ISNUMBER(SEARCH("Velora",C111))),6,6.4)),3) -> 69.667 | N111: =ROUND(I111-D111,0) -> 0
A112: 709 | B112: แป๊บ 1 นิ้ว | C112: อลูมิเนียม เมืองทอง | D112: 295 | E112: 452 | F112: 472 | H112: =IF(ISNUMBER(SEARCH("เมืองทอง",C112)),mult_mtong,IF(ISNUMBER(SEARCH("SlimLux",C112)),mult_slim,IF(ISNUMBER(SEARCH("Velora",C112)),mult_velora,IF(ISNUMBER(SEARCH("Fuji",C112)),mult_euro,mult_sms)))) -> 1 | I112: =ROUND(D112*H112,0) -> 295 | J112: =ROUND(E112*H112,0) -> 452 | K112: =ROUND(F112*mult_wood,0) -> 472 | L112: =ROUND(D112/(IF(ISNUMBER(SEARCH("เมืองทอง",C112)),อัปเดตราคาอลู!$F$8,IF(ISNUMBER(SEARCH("SlimLux",C112)),อัปเดตราคาอลู!$F$6,IF(ISNUMBER(SEARCH("Velora",C112)),อัปเดตราคาอลู!$F$7,IF(ISNUMBER(SEARCH("Fuji",C112)),อัปเดตราคาอลู!$F$5,อัปเดตราคาอลู!$F$4))))),3) -> 1.569 | M112: =ROUND(K112/(IF(OR(ISNUMBER(SEARCH("เมืองทอง",C112)),ISNUMBER(SEARCH("SlimLux",C112)),ISNUMBER(SEARCH("Velora",C112))),6,6.4)),3) -> 78.667 | N112: =ROUND(I112-D112,0) -> 0
A113: 710 | B113: แป๊บ 1 นิ้ว | C113: อลูมิเนียม เมืองทอง | D113: 325 | E113: 498 | F113: 520 | H113: =IF(ISNUMBER(SEARCH("เมืองทอง",C113)),mult_mtong,IF(ISNUMBER(SEARCH("SlimLux",C113)),mult_slim,IF(ISNUMBER(SEARCH("Velora",C113)),mult_velora,IF(ISNUMBER(SEARCH("Fuji",C113)),mult_euro,mult_sms)))) -> 1 | I113: =ROUND(D113*H113,0) -> 325 | J113: =ROUND(E113*H113,0) -> 498 | K113: =ROUND(F113*mult_wood,0) -> 520 | L113: =ROUND(D113/(IF(ISNUMBER(SEARCH("เมืองทอง",C113)),อัปเดตราคาอลู!$F$8,IF(ISNUMBER(SEARCH("SlimLux",C113)),อัปเดตราคาอลู!$F$6,IF(ISNUMBER(SEARCH("Velora",C113)),อัปเดตราคาอลู!$F$7,IF(ISNUMBER(SEARCH("Fuji",C113)),อัปเดตราคาอลู!$F$5,อัปเดตราคาอลู!$F$4))))),3) -> 1.729 | M113: =ROUND(K113/(IF(OR(ISNUMBER(SEARCH("เมืองทอง",C113)),ISNUMBER(SEARCH("SlimLux",C113)),ISNUMBER(SEARCH("Velora",C113))),6,6.4)),3) -> 86.667 | N113: =ROUND(I113-D113,0) -> 0
A114: 711 | B114: แป๊บ 1 นิ้ว | C114: อลูมิเนียม เมืองทอง | D114: 353 | E114: 541 | F114: 565 | H114: =IF(ISNUMBER(SEARCH("เมืองทอง",C114)),mult_mtong,IF(ISNUMBER(SEARCH("SlimLux",C114)),mult_slim,IF(ISNUMBER(SEARCH("Velora",C114)),mult_velora,IF(ISNUMBER(SEARCH("Fuji",C114)),mult_euro,mult_sms)))) -> 1 | I114: =ROUND(D114*H114,0) -> 353 | J114: =ROUND(E114*H114,0) -> 541 | K114: =ROUND(F114*mult_wood,0) -> 565 | L114: =ROUND(D114/(IF(ISNUMBER(SEARCH("เมืองทอง",C114)),อัปเดตราคาอลู!$F$8,IF(ISNUMBER(SEARCH("SlimLux",C114)),อัปเดตราคาอลู!$F$6,IF(ISNUMBER(SEARCH("Velora",C114)),อัปเดตราคาอลู!$F$7,IF(ISNUMBER(SEARCH("Fuji",C114)),อัปเดตราคาอลู!$F$5,อัปเดตราคาอลู!$F$4))))),3) -> 1.878 | M114: =ROUND(K114/(IF(OR(ISNUMBER(SEARCH("เมืองทอง",C114)),ISNUMBER(SEARCH("SlimLux",C114)),ISNUMBER(SEARCH("Velora",C114))),6,6.4)),3) -> 94.167 | N114: =ROUND(I114-D114,0) -> 0
A115: 715 | B115: แป๊บ 1¼ นิ้ว | C115: อลูมิเนียม เมืองทอง | D115: 410 | E115: 628 | F115: 655 | H115: =IF(ISNUMBER(SEARCH("เมืองทอง",C115)),mult_mtong,IF(ISNUMBER(SEARCH("SlimLux",C115)),mult_slim,IF(ISNUMBER(SEARCH("Velora",C115)),mult_velora,IF(ISNUMBER(SEARCH("Fuji",C115)),mult_euro,mult_sms)))) -> 1 | I115: =ROUND(D115*H115,0) -> 410 | J115: =ROUND(E115*H115,0) -> 628 | K115: =ROUND(F115*mult_wood,0) -> 655 | L115: =ROUND(D115/(IF(ISNUMBER(SEARCH("เมืองทอง",C115)),อัปเดตราคาอลู!$F$8,IF(ISNUMBER(SEARCH("SlimLux",C115)),อัปเดตราคาอลู!$F$6,IF(ISNUMBER(SEARCH("Velora",C115)),อัปเดตราคาอลู!$F$7,IF(ISNUMBER(SEARCH("Fuji",C115)),อัปเดตราคาอลู!$F$5,อัปเดตราคาอลู!$F$4))))),3) -> 2.181 | M115: =ROUND(K115/(IF(OR(ISNUMBER(SEARCH("เมืองทอง",C115)),ISNUMBER(SEARCH("SlimLux",C115)),ISNUMBER(SEARCH("Velora",C115))),6,6.4)),3) -> 109.167 | N115: =ROUND(I115-D115,0) -> 0
A116: 718 | B116: แป๊บ 1½ นิ้ว | C116: อลูมิเนียม เมืองทอง | D116: 494 | E116: 757 | F116: 790 | H116: =IF(ISNUMBER(SEARCH("เมืองทอง",C116)),mult_mtong,IF(ISNUMBER(SEARCH("SlimLux",C116)),mult_slim,IF(ISNUMBER(SEARCH("Velora",C116)),mult_velora,IF(ISNUMBER(SEARCH("Fuji",C116)),mult_euro,mult_sms)))) -> 1 | I116: =ROUND(D116*H116,0) -> 494 | J116: =ROUND(E116*H116,0) -> 757 | K116: =ROUND(F116*mult_wood,0) -> 790 | L116: =ROUND(D116/(IF(ISNUMBER(SEARCH("เมืองทอง",C116)),อัปเดตราคาอลู!$F$8,IF(ISNUMBER(SEARCH("SlimLux",C116)),อัปเดตราคาอลู!$F$6,IF(ISNUMBER(SEARCH("Velora",C116)),อัปเดตราคาอลู!$F$7,IF(ISNUMBER(SEARCH("Fuji",C116)),อัปเดตราคาอลู!$F$5,อัปเดตราคาอลู!$F$4))))),3) -> 2.628 | M116: =ROUND(K116/(IF(OR(ISNUMBER(SEARCH("เมืองทอง",C116)),ISNUMBER(SEARCH("SlimLux",C116)),ISNUMBER(SEARCH("Velora",C116))),6,6.4)),3) -> 131.667 | N116: =ROUND(I116-D116,0) -> 0
A117: 745 | B117: แป๊บ 1½ นิ้ว | C117: อลูมิเนียม เมืองทอง | D117: 671 | E117: 1028 | F117: 1073 | H117: =IF(ISNUMBER(SEARCH("เมืองทอง",C117)),mult_mtong,IF(ISNUMBER(SEARCH("SlimLux",C117)),mult_slim,IF(ISNUMBER(SEARCH("Velora",C117)),mult_velora,IF(ISNUMBER(SEARCH("Fuji",C117)),mult_euro,mult_sms)))) -> 1 | I117: =ROUND(D117*H117,0) -> 671 | J117: =ROUND(E117*H117,0) -> 1028 | K117: =ROUND(F117*mult_wood,0) -> 1073 | L117: =ROUND(D117/(IF(ISNUMBER(SEARCH("เมืองทอง",C117)),อัปเดตราคาอลู!$F$8,IF(ISNUMBER(SEARCH("SlimLux",C117)),อัปเดตราคาอลู!$F$6,IF(ISNUMBER(SEARCH("Velora",C117)),อัปเดตราคาอลู!$F$7,IF(ISNUMBER(SEARCH("Fuji",C117)),อัปเดตราคาอลู!$F$5,อัปเดตราคาอลู!$F$4))))),3) -> 3.569 | M117: =ROUND(K117/(IF(OR(ISNUMBER(SEARCH("เมืองทอง",C117)),ISNUMBER(SEARCH("SlimLux",C117)),ISNUMBER(SEARCH("Velora",C117))),6,6.4)),3) -> 178.833 | N117: =ROUND(I117-D117,0) -> 0
A118: 724A | B118: แป๊บ 1¾ นิ้ว | C118: อลูมิเนียม เมืองทอง | D118: 427 | E118: 654 | F118: 682 | H118: =IF(ISNUMBER(SEARCH("เมืองทอง",C118)),mult_mtong,IF(ISNUMBER(SEARCH("SlimLux",C118)),mult_slim,IF(ISNUMBER(SEARCH("Velora",C118)),mult_velora,IF(ISNUMBER(SEARCH("Fuji",C118)),mult_euro,mult_sms)))) -> 1 | I118: =ROUND(D118*H118,0) -> 427 | J118: =ROUND(E118*H118,0) -> 654 | K118: =ROUND(F118*mult_wood,0) -> 682 | L118: =ROUND(D118/(IF(ISNUMBER(SEARCH("เมืองทอง",C118)),อัปเดตราคาอลู!$F$8,IF(ISNUMBER(SEARCH("SlimLux",C118)),อัปเดตราคาอลู!$F$6,IF(ISNUMBER(SEARCH("Velora",C118)),อัปเดตราคาอลู!$F$7,IF(ISNUMBER(SEARCH("Fuji",C118)),อัปเดตราคาอลู!$F$5,อัปเดตราคาอลู!$F$4))))),3) -> 2.271 | M118: =ROUND(K118/(IF(OR(ISNUMBER(SEARCH("เมืองทอง",C118)),ISNUMBER(SEARCH("SlimLux",C118)),ISNUMBER(SEARCH("Velora",C118))),6,6.4)),3) -> 113.667 | N118: =ROUND(I118-D118,0) -> 0
A119: 724B | B119: แป๊บ 1¾ นิ้ว | C119: อลูมิเนียม เมืองทอง | D119: 479 | E119: 734 | F119: 766 | H119: =IF(ISNUMBER(SEARCH("เมืองทอง",C119)),mult_mtong,IF(ISNUMBER(SEARCH("SlimLux",C119)),mult_slim,IF(ISNUMBER(SEARCH("Velora",C119)),mult_velora,IF(ISNUMBER(SEARCH("Fuji",C119)),mult_euro,mult_sms)))) -> 1 | I119: =ROUND(D119*H119,0) -> 479 | J119: =ROUND(E119*H119,0) -> 734 | K119: =ROUND(F119*mult_wood,0) -> 766 | L119: =ROUND(D119/(IF(ISNUMBER(SEARCH("เมืองทอง",C119)),อัปเดตราคาอลู!$F$8,IF(ISNUMBER(SEARCH("SlimLux",C119)),อัปเดตราคาอลู!$F$6,IF(ISNUMBER(SEARCH("Velora",C119)),อัปเดตราคาอลู!$F$7,IF(ISNUMBER(SEARCH("Fuji",C119)),อัปเดตราคาอลู!$F$5,อัปเดตราคาอลู!$F$4))))),3) -> 2.548 | M119: =ROUND(K119/(IF(OR(ISNUMBER(SEARCH("เมืองทอง",C119)),ISNUMBER(SEARCH("SlimLux",C119)),ISNUMBER(SEARCH("Velora",C119))),6,6.4)),3) -> 127.667 | N119: =ROUND(I119-D119,0) -> 0
...

Sheet บันทึกราคาขึ้น
A1: 📈 บันทึกราคาขึ้น — ทุน @ บานมาตรฐาน 150×150 ซม (2.25 ตร.ม.) | I1: 🏠 สารบัญ
A2: ทุก ครั้งที่อลู/กก. ขึ้น → มดเพิ่มคอลัมน์วันที่ใหม่ + %ขึ้น · ดูได้ว่าบานไหนขึ้นเท่าไหร่ + ตรวจว่าเพิ่มถูก (ทุน=วัสดุ อลู+กระจก+อุปกรณ์ ไม่รวมค่าแรง · อลูเท่านั้นที่ขึ้นตาม/กก.)
A4: ① ประวัติเรตอลู (บาท/กก.)
A5: วันที่ | B5: SMS | C5: ยูโร/Fuji | D5: SlimLux | E5: Velora | F5: เมืองทอง
A6: 25/6/69 | B6: =อัปเดตราคาอลู!B4 -> 187 | C6: =อัปเดตราคาอลู!B5 -> 187 | D6: =อัปเดตราคาอลู!B6 -> 170 | E6: =อัปเดตราคาอลู!B7 -> 240 | F6: =อัปเดตราคาอลู!B8 -> 188
A9: ② ทุน @150×150 ต่อบาน (บาท)
A10: บาน | B10: config | C10: ทุนอลูฐาน | D10: กระจก+อุปกรณ์ | E10: ทุนรวม ปัจจุบัน (สูตร live) | F10: 25/6/69 (บันทึก) | G10: %ขึ้น
A11: บานเลื่อน SMS | B11: 2 บาน | C11: 7365 | D11: 1881 | E11: =ROUND(C11*mult_sms+D11,0) -> 9246 | F11: 9246 | G11: ฐาน
A12: บานเลื่อน ยูโร | B12: 2 บาน | C12: 11220 | D12: 2145 | E12: =ROUND(C12*mult_euro+D12,0) -> 13365 | F12: 13365 | G12: ฐาน
A13: บานเลื่อน SlimLux | B13: 2 บาน | C13: 5968 | D13: 6953 | E13: =ROUND(C13*mult_slim+D13,0) -> 12921 | F13: 12921 | G13: ฐาน
A14: บานเลื่อน Velora | B14: 2 บาน | C14: 2207 | D14: 3263 | E14: =ROUND(C14*mult_velora+D14,0) -> 5470 | F14: 5470 | G14: ฐาน
A15: บานเลื่อน E-series | B15: 2 บาน | C15: 11158 | D15: 1527 | E15: =ROUND(C15*mult_sms+D15,0) -> 12685 | F15: 12685 | G15: ฐาน
A16: บานเปิด (ยูโร) | B16: 2 บาน | C16: 8560 | D16: 3255 | E16: =ROUND(C16*mult_euro+D16,0) -> 11815 | F16: 11815 | G16: ฐาน
A17: PC Door | B17: 1 บาน | C17: 5430 | D17: 3044 | E17: =ROUND(C17*mult_euro+D17,0) -> 8474 | F17: 8474 | G17: ฐาน
A18: บานกระทุ้ง | B18: 1 บาน | C18: 4340 | D18: 1924 | E18: =ROUND(C18*mult_euro+D18,0) -> 6264 | F18: 6264 | G18: ฐาน
A19: บานยก | B19: 1 บาน | C19: 5005 | D19: 3419 | E19: =ROUND(C19*mult_euro+D19,0) -> 8424 | F19: 8424 | G19: ฐาน
A20: บานเฟี้ยม | B20: 4 บาน | C20: 10470 | D20: 6807 | E20: =ROUND(C20*mult_euro+D20,0) -> 17277 | F20: 17277 | G20: ฐาน
A21: เฟี้ยมยูโร | B21: 4 บาน | C21: 13294 | D21: 2917 | E21: =ROUND(C21*mult_euro+D21,0) -> 16211 | F21: 16211 | G21: ฐาน
A22: บานติดตาย | B22: - | C22: 3240 | D22: 764 | E22: =ROUND(C22*mult_mtong+D22,0) -> 4004 | F22: 4004 | G22: ฐาน
A23: ตายดัดโค้ง | B23: - | C23: 0 | D23: 5100 | E23: =ROUND(C23*mult_mtong+D23,0) -> 5100 | F23: 5100 | G23: ฐาน
A24: เปิดดัดโค้ง | B24: 2 บาน | C24: 0 | D24: 28077 | E24: =ROUND(C24*mult_mtong+D24,0) -> 28077 | F24: 28077 | G24: ฐาน
A25: บานเลื่อนรางบน | B25: 2 บาน | C25: 4770 | D25: 7803 | E25: =ROUND(2990*mult_mtong+1780*mult_sms+D25,0) -> 12573 | F25: 12573 | G25: ฐาน
A27: 🔧 วิธีเพิ่มรอบใหม่เมื่ออลูขึ้น:
A28: 1) แก้ราคา/กก. ที่ชีท "อัปเดตราคาอลู" → ช่อง "ทุนรวม ปัจจุบัน(สูตร)" ขยับเอง
A29: 2) มดเพิ่ม 2 คอลัมน์ใหม่ (วันที่ + %ขึ้น) คัดค่าจากช่องสูตร + เพิ่มแถวเรตใน ① → ได้ประวัติว่าบานไหนขึ้นเท่าไหร่
A30: หมายเหตุ: ตายดัดโค้ง/เปิดดัดโค้ง อลูตั้งราคาตายตัว ไม่ขึ้นตาม/กก. · รางบน/เฟี้ยม สูตร live ประมาณ (เลขเป๊ะดูคอลัมน์บันทึกวันที่)
A32: ⚠️ ทุนอลูฐาน(ส้ม)/กระจก+อุปกรณ์(เทา) = ค่าคงที่ @150×150 · ทุนรวม(เขียว) = อลูฐาน×ตัวคูณ + อื่นๆ → ขึ้นเองเมื่อ/กก.ขึ้น

Sheet ราคางานเสริม
A1: ⚠️ แก้ราคาที่นี่ → 📋 ราคาวัสดุงานเสริม — แก้ราคาที่นี่ที่เดียว (ช่องเหลือง) · ทุกชีทดึงไปใช้อัตโนมัติ | G1: 🏠 สารบัญ
A3: ▶ ฝ้ายิปซัม
A4: งาน | B4: วัสดุ | C4: หน่วย | D4: ราคา (บาท)
A5: ฝ้ายิปซัม | B5: แผ่นยิปซัม 9มม | C5: แผ่น | D5: 284
A6: ฝ้ายิปซัม | B6: โครงซีไลน์ (ฟิวริ่ง) | C6: เส้น | D6: 50
A7: ฝ้ายิปซัม | B7: โครงเคร่าหลัก (อาบ) | C7: เส้น | D7: 50
A8: ฝ้ายิปซัม | B8: ขาแขวน | C8: เส้น | D8: 50
A9: ฝ้ายิปซัม | B9: สกรูยึดแผ่น | C9: ตัว | D9: 0.5
A10: ฝ้ายิปซัม | B10: สกรูยึดโครง | C10: ตัว | D10: 0.5
A11: ฝ้ายิปซัม | B11: ปูนฉาบรอยต่อ | C11: ถุง | D11: 240
A12: ฝ้ายิปซัม | B12: เทป/ตาข่าย | C12: ม้วน | D12: 70
A13: ฝ้ายิปซัม | B13: ฉากโอบ อลู 4หุน | C13: เส้น | D13: 70
A14: ฝ้ายิปซัม | B14: ฉนวน rockwool 3" | C14: แผ่น | D14: 130
A15: ▶ งานไฟ
A16: งาน | B16: วัสดุ | C16: หน่วย | D16: ราคา (บาท)
A17: งานไฟ | B17: ไฟดาวน์ไลท์ | C17: ดวง | D17: 117
A18: งานไฟ | B18: เต้ารับ+หน้ากาก | C18: จุด | D18: 105
A19: งานไฟ | B19: สวิตช์+หน้ากาก | C19: จุด | D19: 45
A20: งานไฟ | B20: กล่องไฟ | C20: กล่อง | D20: 35
A21: งานไฟ | B21: สายไฟ THW/VAF | C21: เมตร | D21: 25
A22: งานไฟ | B22: ท่อ PVC+ข้อต่อ | C22: เมตร | D22: 6.6666667
A23: งานไฟ | B23: เทป+เบ็ดเตล็ด | C23: งาน | D23: 400
A24: ▶ สมาร์ทบอร์ด
A25: งาน | B25: วัสดุ | C25: หน่วย | D25: ราคา (บาท)
A26: สมาร์ทบอร์ด | B26: แผ่นสมาร์ทบอร์ด 12มม | C26: แผ่น | D26: 500
A27: สมาร์ทบอร์ด | B27: โครงเหล็กกรอบ 1½×3" | C27: เส้น | D27: 440
A28: สมาร์ทบอร์ด | B28: ซีไลน์ 3" ดิ่ง | C28: เส้น | D28: 62
A29: สมาร์ทบอร์ด | B29: ซีไลน์ 3" นอน | C29: เส้น | D29: 62
A30: สมาร์ทบอร์ด | B30: ฉนวน 3" | C30: แผ่น | D30: 130
A31: สมาร์ทบอร์ด | B31: สกรูยึดแผ่น | C31: ตัว | D31: 0.5
A32: สมาร์ทบอร์ด | B32: สกรูยึดโครง | C32: ตัว | D32: 0.5
A33: สมาร์ทบอร์ด | B33: ปูนฉาบรอยต่อ | C33: ถุง | D33: 240
A34: สมาร์ทบอร์ด | B34: เทป/ตาข่าย | C34: ม้วน | D34: 70
A35: ▶ ไอโซวอล
A36: งาน | B36: วัสดุ | C36: หน่วย | D36: ราคา (บาท)
A37: ไอโซวอล | B37: แผ่นไอโซวอล ≤2.4ม | C37: แผ่น | D37: 2016
A38: ไอโซวอล | B38: แผ่นไอโซวอล >2.4ม | C38: แผ่น | D38: 2520
A39: ไอโซวอล | B39: กล่อง 1.6×4" โครงรอบ | C39: เส้น | D39: 1220
A40: ไอโซวอล | B40: ฉาก 4หุน | C40: เส้น | D40: 70
A41: ไอโซวอล | B41: สกรู/รีเวท | C41: งาน | D41: 50
...

Sheet ราคาออโต้
A1: ⚠️ แก้ราคาที่นี่ → ราคาออโต้/มอเตอร์ (ทุน) — มดอัปเดตที่นี่ที่เดียว · ชีทบานติ๊กเลือกแล้วดึงมาใช้ | G1: 🏠 สารบัญ
A2: หมวด/บาน | B2: รุ่น/รายการ | C2: ราคา | D2: ค่าส่ง | E2: หน่วย/เงื่อนไข
A3: บานยก / เฟี้ยมยก | B3: ยก 80 กก. | C3: 4500 | D3: 1700
B4: ยก 300 กก. | C4: 12500 | D4: 1700
A5: หลังคาเลื่อน | B5: 80 กก. | C5: 4500 | D5: 1700
B6: 300 กก. | C6: 12500 | D6: 1700
B7: 1500 กก. | C7: 13325 | D7: 1700 | E7: มีฟันเฟือง+เซนเซอร์
B8: ฟันเฟือง (เฉพาะ1500) | C8: 340 | E8: บาท/ม. × ระยะยื่น
B9: เซนเซอร์กันฝน (ออป,1500) | C9: 1100 | E9: ออปชั่น
A10: บานเกล็ด 38.1 | B10: มอเตอร์บานเกล็ด | C10: 1800 | E10: ไม่มีค่าส่ง
A11: ระแนงหมุน | B11: มอเตอร์ระแนงหมุน | C11: 1800 | E11: รวมส่งแล้ว
A12: บานกระทุ้ง | B12: โช็ค เปิด 50 | C12: 3575 | D12: 1700 | E12: 2 ตัว→+อุปกรณ์พิเศษ
B13: โช็ค เปิด 80 | C13: 3725 | D13: 1700 | E13: 2 ตัว→+อุปกรณ์พิเศษ
B14: โซ่เดี่ยว 50 | C14: 1900 | D14: 1700
B15: โซ่คู่ 50 | C15: 2600 | D15: 1700
B16: อุปกรณ์พิเศษ (โช็ค 2 ตัว) | C16: 600 | E16: บวกเมื่อใช้ 2 ตัว
A17: เลื่อน SMS/ยูโร | B17: Evecca (จีน) | C17: 13480 | D17: 1700 | E17: 1 บาน
B18: สายพาน Evecca | C18: 75 | E18: บาท/ม. = กว้างช่อง×2
B19: ออป Smart lock | C19: 6500 | E19: ออปชั่น Evecca
B20: ช่างแซก | C20: 8000 | E20: ไม่มีค่าส่ง
B21: เซฟตี้ตาแมว (บังคับช่างแซก) | C21: 1000 | E21: บวกทุกชุดช่างแซก
B22: ราง ช่างแซก | C22: 950 | E22: บาท/ม. = กว้างช่อง
B23: ออป Touch Switch (ช่างแซก) | C23: 1000 | E23: ออปชั่น
B24: ออป Infrared (ช่างแซก) | C24: 9000 | E24: ออปชั่น
A25: SlimLux | B25: ชุด SlimLux (บานแรก) | C25: 6900 | D25: 1700 | E25: บานแรก
B26: บานเพิ่ม | C26: 2250 | E26: บาท/บานเพิ่ม
B27: ราง SlimLux | C27: 1100 | E27: บาท/ม. = กว้างช่อง×จำนวนบาน
B28: ออป สแกนหน้า (บังคับเลือก1) | C28: 2750 | E28: เลือก 1 ใน 2
B29: ออป Touch Switch (บังคับเลือก1) | C29: 100 | E29: เลือก 1 ใน 2

Sheet ราคาวัสดุ
A1: ⚠️ แก้ราคาที่นี่ → 📋 ราคาวัสดุกลาง — แก้ที่นี่ที่เดียวเมื่อราคาขึ้น | F1: 🏠 สารบัญ | G1: อลูเมืองทองขึ้นราคา? แก้ที่ชีท "อัปเดตราคาอลู" ช่องเมืองทอง (บาท/กก.) → จันทัน/แป/ฉาก/แซด/คาน ขยับเอง
A2: โปรไฟล์อลูมิเนียม (เส้นยาว 6 ม.) | G2: ◀ ราคาอลู (บาท/กก.) · เหล็กแก้ราคา/เส้น ในตารางเลย (สีเหลือง) | H2: 180
B3: วัสดุ | C3: หน่วย | D3: ราคา (บาท) | E3: หมายเหตุ | F3: ราคาฐาน | I3: น้ำหนัก/เส้น(กก.)
B4: กล่อง 1.6"×4" | C4: เส้น | D4: =ROUND(F4*mult_mtong,0) -> 1220 | E4: แกนหลัก / จันทัน | F4: 1220 | I4: =ROUND(F4/180,3) -> 6.778
B5: กล่อง 1.6"×1.6" | C5: เส้น | D5: =ROUND(F5*mult_mtong,0) -> 770 | E5: แป — แปเดี่ยว | F5: 770 | I5: =ROUND(F5/180,3) -> 4.278
B6: กล่อง 1"×1½" | C6: เส้น | D6: =ROUND(F6*mult_mtong,0) -> 393 | E6: แป — แปคู่ | F6: 393 | I6: =ROUND(F6/180,3) -> 2.183
B7: ฉาก 6 หุน | C7: เส้น | D7: =ROUND(F7*mult_mtong,0) -> 140 | E7: ยึดติดผนัง | F7: 140 | I7: =ROUND(F7/180,3) -> 0.778
B8: แซด 4" | C8: เส้น | D8: =ROUND(F8*mult_mtong,0) -> 140 | E8: ร่องน้ำ / ขอบ | F8: 140 | I8: =ROUND(F8/180,3) -> 0.778
B9: กล่องเหล็ก 1"×1" | C9: เส้น | D9: 110 | E9: เสริมโครง | F9: 110
B10: เพลทเหล็ก | C10: แผ่น | D10: 15 | E10: ยึดด้านหลัง | F10: 15
B11: กล่อง 4"×4" | C11: เส้น | D11: =ROUND(2208*mult_mtong,0) -> 2208 | E11: คาน T หลังคาจั่ว | F11: 2208
A12: วัสดุปิดผิว
B13: วัสดุ | C13: หน่วย | D13: ราคา (บาท) | E13: หมายเหตุ
B14: ไวนิล | C14: แผ่น (7 ม.) | D14: 1540 | E14: จันทันห่าง ≤100 ซม.
B15: ฝาครอบไวนิล | C15: เส้น (7 ม.) | D15: 245 | E15: 1 เส้น/แผ่นไวนิล
B16: ดีไลท์ | C16: แผ่น (6 ม.) | D16: 4700 | E16: ฝาครอบแถมฟรี
B17: โพลีตัน | C17: เมตร | D17: 1200 | E17: จันทันห่าง ≤122 ซม.
B18: ตัวครอบโพลีตัน | C18: จุด/จันทัน | D18: 420 | E18: 1 จุดต่อ 1 จันทัน
B19: ชินโคร์ไลท์ Heat Cut | C19: ตร.ม. | D19: 2800 | E19: รวมฝาครอบ
B20: ชินโคร์ไลท์ Superior | C20: ตร.ม. | D20: 2100 | E20: รวมฝาครอบ
B21: เมทัลชีท PU 2" Snap | C21: ตร.ม. | D21: 2200 | E21: จันทันห่าง ≤100 ซม.
B22: กระจกลามิเนต 4+4 | C22: ตร.ม. | D22: 1065 | E22: ฟิล์มเขียว/ใส 0.38
B23: กระจกลามิเนต 5+5 | C23: ตร.ม. | D23: 1270 | E23: ฟิล์มเขียว/ใส 0.38

Sheet ค่าแรง
A1: ⚠️ แก้ราคาที่นี่ → ค่าแรง ผลิต + ติดตั้ง (สูตร: ค่าเริ่มต้น + เรต×ตร.ม.) — จากไฟล์ค่าแรง นิด | G1: 🏠 สารบัญ
A3: เลือกแบบ → | B3: บานเลื่อน SMS
A4: พื้นที่ (ตร.ม.) → | B4: 5
A5: ค่าแรงผลิต = | B5: =MAX(0,VLOOKUP(B3,$A$12:$E$27,2,0)+VLOOKUP(B3,$A$12:$E$27,3,0)*B4) -> 429
A6: ค่าแรงติดตั้ง = | B6: =MAX(0,VLOOKUP(B3,$A$12:$E$27,4,0)+VLOOKUP(B3,$A$12:$E$27,5,0)*B4) -> 429
A7: รวมค่าแรง (ผลิต+ติดตั้ง) = | B7: =B5+B6 -> 858
A10: ตารางค่าแรง (แก้ที่นี่ถ้าค่าแรงเปลี่ยน) — ค่าแรง/ชม.=87.5
A11: แบบบาน | B11: ผลิต: ค่าเริ่มต้น | C11: ผลิต: /ตร.ม. | D11: ติดตั้ง: ค่าเริ่มต้น | E11: ติดตั้ง: /ตร.ม. | G11: ชม.ฐานผลิต | H11: ชม.ฐานติดตั้ง | I11: ค่าแรง/ชม. | J11: ชม.เพิ่มผลิต/ตร.ม. | K11: ชม.เพิ่มติดตั้ง/ตร.ม.
A12: บานเลื่อน SMS | B12: =G12*I12 -> 352 | C12: =J12*I12 -> 15.4 | D12: =H12*I12 -> 352 | E12: =K12*I12 -> 15.4 | G12: 4 | H12: 4 | I12: 88 | J12: 0.175 | K12: 0.175
A13: บานเลื่อน ยูโร | B13: =G13*I13 -> 528 | C13: =J13*I13 -> 15.4 | D13: =H13*I13 -> 440 | E13: =K13*I13 -> 15.4 | G13: 6 | H13: 5 | I13: 88 | J13: 0.175 | K13: 0.175
A14: SlimLux | B14: =G14*I14 -> 704 | C14: =J14*I14 -> 15.4 | D14: =H14*I14 -> 704 | E14: =K14*I14 -> 15.4 | G14: 8 | H14: 8 | I14: 88 | J14: 0.175 | K14: 0.175
A15: Velora | B15: =G15*I15 -> 968 | C15: =J15*I15 -> 15.4 | D15: =H15*I15 -> 440 | E15: =K15*I15 -> 15.4 | G15: 11 | H15: 5 | I15: 88 | J15: 0.175 | K15: 0.175
A16: บานเปิด (ยูโร) | B16: =G16*I16 -> 528 | C16: =J16*I16 -> 15.4 | D16: =H16*I16 -> 440 | E16: =K16*I16 -> 15.4 | G16: 6 | H16: 5 | I16: 88 | J16: 0.175 | K16: 0.175
A17: บานกระทุ้ง (ยูโร) | B17: =G17*I17 -> 528 | C17: =J17*I17 -> 15.4 | D17: =H17*I17 -> 264 | E17: =K17*I17 -> 15.4 | G17: 6 | H17: 3 | I17: 88 | J17: 0.175 | K17: 0.175
A18: บานเฟี้ยม (sms) | B18: =G18*I18 -> 440 | C18: =J18*I18 -> 0 | D18: =H18*I18 -> 176 | E18: =K18*I18 -> 0 | G18: 5 | H18: 2 | I18: 88 | J18: 0 | K18: 0
A19: บานยก (เซมิ) | B19: =G19*I19 -> 352 | C19: =J19*I19 -> 15.4 | D19: =H19*I19 -> 352 | E19: =K19*I19 -> 15.4 | G19: 4 | H19: 4 | I19: 88 | J19: 0.175 | K19: 0.175
A20: หลังคา | B20: =ROUND(G20*I20,0) -> 528 | C20: =J20*I20 -> 15.4 | D20: =ROUND(H20*I20,0) -> 528 | E20: =K20*I20 -> 15.4 | G20: 6 | H20: 6 | I20: 88 | J20: 0.175 | K20: 0.175
A21: บานติดตาย | B21: =G21*I21 -> 176 | C21: =J21*I21 -> 15.4 | D21: =H21*I21 -> 88 | E21: =K21*I21 -> 15.4 | G21: 2 | H21: 1 | I21: 88 | J21: 0.175 | K21: 0.175
A22: ตายดัดโค้ง | B22: =G22*I22 -> 616 | C22: =J22*I22 -> 15.4 | D22: =H22*I22 -> 264 | E22: =K22*I22 -> 15.4 | G22: 7 | H22: 3 | I22: 88 | J22: 0.175 | K22: 0.175
A23: PC Door | B23: =G23*I23 -> 704 | C23: =J23*I23 -> 15.4 | D23: =H23*I23 -> 528 | E23: =K23*I23 -> 15.4 | G23: 8 | H23: 6 | I23: 88 | J23: 0.175 | K23: 0.175
A24: บานเฟี้ยมยูโร | B24: =G24*I24 -> 352 | C24: =J24*I24 -> 0 | D24: =H24*I24 -> 176 | E24: =K24*I24 -> 0 | G24: 4 | H24: 2 | I24: 88 | J24: 0 | K24: 0
A25: มุ้งเฟรมเล็ก | B25: =G25*I25 -> 88 | C25: =J25*I25 -> 15.4 | D25: =H25*I25 -> 22 | E25: =K25*I25 -> 15.4 | G25: 1 | H25: 0.25 | I25: 88 | J25: 0.175 | K25: 0.175
A26: หลังคาจั่ว | B26: =ROUND(G26*I26,0) -> 704 | C26: =J26*I26 -> 15.4 | D26: =ROUND(H26*I26,0) -> 528 | E26: =K26*I26 -> 15.4 | G26: 8 | H26: 6 | I26: 88 | J26: 0.175 | K26: 0.175
A27: หลังคาเลื่อน | B27: =ROUND(G27*I27,0) -> 704 | C27: =J27*I27 -> 15.4 | D27: =ROUND(H27*I27,0) -> 616 | E27: =K27*I27 -> 15.4 | G27: 8 | H27: 7 | I27: 88 | J27: 0.175 | K27: 0.175
A28: บานเลื่อนรางบน | B28: =G28*I28 -> 528 | C28: =J28*I28 -> 15.4 | D28: =H28*I28 -> 704 | E28: =K28*I28 -> 15.4 | G28: 6 | H28: 8 | I28: 88 | J28: 0.175 | K28: 0.175
A30: ▶ งานเสริม (ฝ้า/ผนัง/ไฟ) — บาท
A31: งาน | B31: ค่าแรงผลิต/หลัก | C31: ค่าแรงติดตั้ง | D31: หน่วย
A32: ฝ้ายิปซัมฉาบเรียบ | B32: — ไม่มี | C32: 280 | D32: /ตร.ม. (รวม)
A33: ฝ้าไม้เทียม | B33: — ไม่มี | C33: 352 | D33: /ตร.ม. (รวม)
A34: ผนังสมาร์ทบอร์ด | B34: 700 | C34: 400 | D34: /ตร.ม.
A35: ผนังไอโซวอล | B35: 700 | C35: 440 | D35: /ตร.ม.
A36: งานไฟ — เดินสายไฟ | B36: 90 | D36: /เมตร
A37: งานไฟ — ติดดาวน์ไลท์ | B37: 90 | D37: /ดวง

Sheet ราคามุ้ง
A1: ⚠️ แก้ราคาช่องเหลืองที่นี่ — ทุกบานลิงก์อัตโนมัติ | B1: ราคา ฿/ตร.ม. | C1: ประเภท | D1: บานที่เข้าได้ | E1: หมายเหตุ | F1: ค่าแรงติดตั้ง/ตร.ม. | G1: ไม่มีมุ้ง | H1: 🏠 สารบัญ | I1: ผ้ามุ้ง (กรอกราคา/ม้วน เหลือง → /ตร.ม.คิดเอง) | J1: ฿/ตร.ม. | K1: ราคา/ม้วน (36.6 ตร.ม.) | L1: แรงผลิต พื้นฐาน | M1: แรงผลิต เพิ่ม/ตร.ม. | N1: แรงติดตั้ง พื้นฐาน | O1: แรงติดตั้ง เพิ่ม/ตร.ม.
A2: มุ้งจีบ | B2: 1179 | C2: ซื้อสำเร็จ | D2: ALL | E2: ทุกบาน | F2: 160 | G2: มุ้งจีบ | I2: ไฟเบอร์ | J2: =ROUND(K2/36.6,0) -> 23 | K2: 842 | L2: 0 | M2: 0 | N2: 120 | O2: 40
A3: มุ้งม้วน ขาว/ดำ/น้ำตาล | B3: 1300 | C3: ซื้อสำเร็จ | D3: ALL | F3: 160 | G3: มุ้งม้วน ขาว/ดำ/น้ำตาล | I3: ไนล่อน | J3: =ROUND(K3/36.6,0) -> 38 | K3: 1391 | L3: 0 | M3: 0 | N3: 120 | O3: 40
A4: มุ้งม้วน ซาฮาร่า | B4: 1500 | C4: ซื้อสำเร็จ | D4: ALL | F4: 160 | G4: มุ้งม้วน ซาฮาร่า | I4: สแตนเลส | J4: =ROUND(K4/36.6,0) -> 352 | K4: 12883 | L4: 0 | M4: 0 | N4: 120 | O4: 40
A5: มุ้งม้วน ลายไม้สักทอง | B5: 1600 | C5: ซื้อสำเร็จ | D5: ALL | F5: 160 | G5: มุ้งม้วน ลายไม้สักทอง | I5: กันแมว | J5: =ROUND(K5/36.6,0) -> 82 | K5: 3001 | L5: 0 | M5: 0 | N5: 120 | O5: 40
A6: มุ้งม้วน ไลท์โอ๊ค | B6: 1700 | C6: ซื้อสำเร็จ | D6: ALL | F6: 160 | G6: มุ้งม้วน ไลท์โอ๊ค | L6: 0 | M6: 0 | N6: 120 | O6: 40
A7: มุ้งจีบนิรภัย ≤3ม. ขาว/ดำ | B7: 2750 | C7: ซื้อสำเร็จ | D7: ALL | F7: 180 | G7: มุ้งจีบนิรภัย ≤3ม. ขาว/ดำ | L7: 0 | M7: 0 | N7: 150 | O7: 45
A8: มุ้งจีบนิรภัย ≤3ม. ซาฮาร่า | B8: 3150 | C8: ซื้อสำเร็จ | D8: ALL | E8: +400 | F8: 180 | G8: มุ้งจีบนิรภัย ≤3ม. ซาฮาร่า | L8: 0 | M8: 0 | N8: 150 | O8: 45
A9: มุ้งจีบนิรภัย ≤3ม. สักทอง | B9: 3250 | C9: ซื้อสำเร็จ | D9: ALL | E9: +500 | F9: 180 | G9: มุ้งจีบนิรภัย ≤3ม. สักทอง | L9: 0 | M9: 0 | N9: 150 | O9: 45
A10: มุ้งจีบนิรภัย >3ม. ขาว/ดำ | B10: 4050 | C10: ซื้อสำเร็จ | D10: ALL | F10: 180 | G10: มุ้งจีบนิรภัย >3ม. ขาว/ดำ | L10: 0 | M10: 0 | N10: 150 | O10: 45
A11: มุ้งจีบนิรภัย >3ม. ซาฮาร่า | B11: 4450 | C11: ซื้อสำเร็จ | D11: ALL | E11: +400 | F11: 180 | G11: มุ้งจีบนิรภัย >3ม. ซาฮาร่า | L11: 0 | M11: 0 | N11: 150 | O11: 45
A12: มุ้งจีบนิรภัย >3ม. สักทอง | B12: 4550 | C12: ซื้อสำเร็จ | D12: ALL | E12: +500 | F12: 180 | G12: มุ้งจีบนิรภัย >3ม. สักทอง | L12: 0 | M12: 0 | N12: 150 | O12: 45
A13: มุ้งเฟรมเล็ก | B13: 0 | C13: ผลิตเอง | D13: SMS|เปิด|กระทุ้ง | E13: กรอบ+ยาง+ผ้า+ค่าแรง | F13: 0 | G13: มุ้งเฟรมเล็ก | L13: 120 | M13: 30 | N13: 70 | O13: 18
A14: มุ้งเฟรมใหญ่ | B14: 0 | C14: ผลิตเอง | D14: SMS|ยูโร|เปิด|กระทุ้ง | E14: โปรไฟล์บาน+ยาง+ผ้า+ค่าแรง | F14: 0 | G14: มุ้งเฟรมใหญ่ | L14: 140 | M14: 0 | N14: 44 | O14: 0
A15: มุ้งนิรภัย | B15: 0 | C15: ผลิตเอง | D15: SMS|ยูโร|เปิด|กระทุ้ง | E15: โปรไฟล์บาน+ยาง+ผ้านิรภัย650+ค่าแรง | F15: 0 | G15: มุ้งนิรภัย | L15: 88 | M15: 0 | N15: 44 | O15: 0
A17: 🟢 มุ้งผลิตเอง — แก้ค่ากรอบ(เหลือง)/ยาง/ผ้า · ราคาโชว์อัตโนมัติ
A18: รุ่นมุ้ง | B18: ค่ากรอบ /เส้น | C18: ผ้าที่ใช้ได้ (บาท/ตร.ม.) | D18: ยางอัด /ม. | E18: ค่าแรงผลิต | F18: ค่าแรงติดตั้ง
A19: เฟรมเล็ก | B19: 625 | C19: ="ไฟเบอร์ "&J2&" · ไนล่อน "&J3&" · สแตนเลส "&J4&" · กันแมว "&J5 -> ไฟเบอร์ 23 · ไนล่อน 38 · สแตนเลส 352 · กันแมว 82 | D19: 5 | E19: =L13&IF(M13>0," +"&M13&"/ตร.ม."," (เหมา)") -> 120 +30/ตร.ม. | F19: =N13&IF(O13>0," +"&O13&"/ตร.ม."," (เหมา)") -> 70 +18/ตร.ม.
A20: เฟรมใหญ่ | B20: ขึ้นตามเสากุญแจบาน (อัตโนมัติ) | C20: ="ไฟเบอร์ "&J2&" · ไนล่อน "&J3&" · สแตนเลส "&J4&" · กันแมว "&J5 -> ไฟเบอร์ 23 · ไนล่อน 38 · สแตนเลส 352 · กันแมว 82 | D20: =$D$19 -> 5 | E20: =L14&IF(M14>0," +"&M14&"/ตร.ม."," (เหมา)") -> 140 (เหมา) | F20: =N14&IF(O14>0," +"&O14&"/ตร.ม."," (เหมา)") -> 44 (เหมา)
A21: นิรภัย | B21: 1030 | C21: สแตนเลสนิรภัย 650 | D21: =$D$19 -> 5 | E21: =L15&IF(M15>0," +"&M15&"/ตร.ม."," (เหมา)") -> 88 (เหมา) | F21: =N15&IF(O15>0," +"&O15&"/ตร.ม."," (เหมา)") -> 44 (เหมา)
A23: 📌 แก้ราคามุ้งตรงไหน — แก้เฉพาะช่องสีเหลืองเท่านั้น
A24: ① มุ้งซื้อสำเร็จขึ้นราคา → คอลัมน์ B (ราคา/ตร.ม.) แถว 2-12
A25: ② ค่าแรงติดตั้งมุ้งสำเร็จ → คอลัมน์ F แถว 2-12
A26: ③ ราคาผ้า (ไฟเบอร์/ไนล่อน/สแตนเลส/กันแมว) → คอลัมน์ J (บล็อกส้ม)
A27: ④ ค่ากรอบมุ้งผลิตเอง → B19 (เล็ก) · B21 (นิรภัย) [เฟรมใหญ่ใช้เสากุญแจบาน ขึ้นเองตามราคาอลู]
A28: ⑤ ยางอัด → D19
A29: ค่าแรงผลิตมุ้ง = คอลัมน์ L-O (ซ่อนไว้ ไม่ค่อยเปลี่ยน · จะแก้ คลิกขวาหัวคอลัมน์→ยกเลิกซ่อน)

Sheet log กระจก
A1: log ราคากระจก — R3.9 เดิม vs ใหม่ (ร้าน×10.764) | ช่องว่าง=ยังไม่มีข้อมูลฝั่งนั้น | สี: ส้ม=อัปเดต เขียว=เพิ่ม เทา=ขาดราคา ฟ้า=PDFเกิน แดง=เดา | G1: 🏠 สารบัญ
A2: ลำดับ | B2: ชื่อรุ่น | C2: สถานะ | D2: ราคาเดิม R3.9 | E2: ราคาใหม่ ×10.764 | F2: Δ | G2: หมายเหตุ
A3: 1 | B3: เขียว 8มม. | C3: อัปเดต | D3: 646 | E3: 592 | F3: -54 | G3: เขียว8
A4: 2 | B4: เขียว 10มม. | C4: อัปเดต | D4: 754 | E4: 700 | F4: -54 | G4: เขียว10
A5: 3 | B5: ยูโรเกรย์ 10มม. | C5: อัปเดต | D5: 1023 | E5: 807 | F5: -216 | G5: 75
A6: 4 | B6: ยูโรบรอนซ์ 6มม. | C6: อัปเดต | D6: 571 | E6: 570 | F6: -1 | G6: 53
A7: 5 | B7: เทมเปอร์ 8มม.(เขียว) | C7: อัปเดต | D7: 820 | E7: 716 | F7: -104 | G7: 66.5
A8: 6 | B8: เทมเปอร์ 10มม. | C8: อัปเดต | D8: 1023 | E8: 848 | F8: -175 | G8: 78.75
A9: 7 | B9: เทมเปอร์ 12มม. | C9: อัปเดต | D9: 1159 | E9: 942 | F9: -217 | G9: 87.5
A10: 8 | B10: ชา/ฝ้า 5-6มม. | C10: อัปเดต | D10: 400 | E10: 301 | F10: -99 | G10: 28
A11: 9 | B11: เงา 5มม. | C11: อัปเดต | D11: 600 | E11: 398 | F11: -202 | G11: 37
A12: 10 | B12: ลอนแก้ว 5มม. | C12: อัปเดต | D12: 700 | E12: 646 | F12: -54 | G12: 60
A13: 11 | B13: เงาทอง | C13: อัปเดต | D13: 700 | E13: 872 | F13: +172 | G13: 81 ขึ้น!
A14: 12 | B14: ลามิเนต 4+4 0.38 | C14: อัปเดต | D14: 1065 | E14: 883 | F14: -182 | G14: 82
... A22: 20 | B22: เทมเปอร์ 6มม. | C22: ✓ มีราคา | D22: 439 | E22: 403 | F22: +0 | G22: ใบราคาร้าน (ฉิน/BGF)
A23: 21 | B23: ใส 6มม. | C23: เพิ่ม(ใส) | E23: 242 | G23: แยกใส
A24: 22 | B24: ใส 8มม. | C24: เพิ่ม(ใส) | E24: 409
A25: 23 | B25: ใส 10มม. | C25: เพิ่ม(ใส) | E25: 517
A26: 24 | B26: เทมเปอร์ใส 6มม. | C26: เพิ่ม(ใส) | E26: 403
A27: 25 | B27: เทมเปอร์ใส 8มม. | C27: เพิ่ม(ใส) | E27: 622
A28: 26 | B28: เทมเปอร์ใส 10มม. | C28: เพิ่ม(ใส) | E28: 695
A29: 27 | B29: เทมเปอร์ใส 12มม. | C29: เพิ่ม(ใส) | E29: 787
A30: 28 | B30: ลามิเนตกันเสียง 0.76 | C30: เดา⚠ | D30: 3314 | E30: 969 | F30: -2345 | G30: เดา⚠
A31: 29 | B31: ลามิเนตกันขโมย STG 1.52 | C31: เดา⚠ | D31: 4412 | E31: 1432 | F31: -2980 | G31: เดา⚠
A32: 30 | B32: เคลือบขาว 6มม. | C32: อัปเดต | D32: 915 | E32: 1023 | G32: ร้านแจ้ง 95/ฟุต
A33: 31 | B33: ยูโรบรอนซ์ 10มม. | C33: ✂ ตัดออก (ไม่ใช้) | D33: 3917 | G33: PDF ไม่มี-รอเติม
A34: 32 | B34: reflective เทา 6มม. | C34: อัปเดต | D34: 1216 | E34: 1184 | G34: CH262853 17/6/69
A35: 33 | B35: reflective เขียว 6มม. | C35: อัปเดต | D35: 1388 | E35: 1292 | G35: CH262853 17/6/69
A36: 34 | B36: reflective ฟ้า/เทา 6มม. | C36: อัปเดต | D36: 1517 | E36: 1399 | G36: CH262853 17/6/69
A37: 35 | B37: เทมเปอร์ 15มม. | C37: อัปเดต | D37: 3121 | E37: 3122 | F37: -42 | G37: CH262853 17/6/69
A38: 36 | B38: เทมเปอร์ใสพิเศษ 6มม. | C38: อัปเดต | D38: 1432 | E38: 1432 | F38: 178 | G38: CH262853 17/6/69
A39: 37 | B39: เทมเปอร์ใสพิเศษ 8มม. | C39: อัปเดต | D39: 2200 | E39: 2336 | F39: 227 | G39: CH262853 17/6/69
A40: 38 | B40: เทมเปอร์ใสพิเศษ 10มม. | C40: อัปเดต | D40: 3497 | E40: 3466 | F40: -774 | G40: CH262853 17/6/69
A41: 39 | B41: เทมเปอร์ฝ้า 6มม. | C41: อัปเดต | D41: 1076 | E41: 805 | F41: -271 | G41: ร้านส่ง 74.8/ฟุต
A42: 40 | B42: เทมเปอร์ฝ้า 8มม. | C42: อัปเดต | D42: 1937 | E42: 1113 | F42: -824 | G42: ร้านส่ง 103.4/ฟุต
A43: 41 | B43: เทมเปอร์ยูโรเกรย์ 4มม. | C43: อัปเดต | D43: 824 | E43: 646 | F43: -178 | G43: CH262853 17/6/69
A44: 42 | B44: เทมเปอร์ยูโรเกรย์ 5มม. | C44: อัปเดต | D44: 1006 | E44: 678 | F44: -328 | G44: CH262853 17/6/69
A45: 43 | B45: เทมเปอร์ยูโรเกรย์ 6มม. | C45: อัปเดต | D45: 1033 | E45: 732 | F45: -301 | G45: CH262853 17/6/69
A46: 44 | B46: เทมเปอร์ยูโรเกรย์ 10มม. | C46: อัปเดต | D46: 2637 | E46: 1423 | F46: -1214 | G46: CH262853 17/6/69
A47: 45 | B47: เทมเปอร์ยูโรบรอนซ์ 5มม. | C47: อัปเดต | D47: 1184 | E47: 732 | F47: -452 | G47: CH262853 17/6/69
...

Sheet LUT_ฝ้าไม้เทียม
A1: key | B1: ร้าน | C1: รุ่น | D1: width_m | E1: len_m | F1: price | G1: 🏠 สารบัญ | H1: edge_p | I1: edge_len | J1: carrier | K1: bundled | N1: ร้าน
A2: ไม้ทิพย์|สีพื้น | B2: ไม้ทิพย์ | C2: สีพื้น | D2: 0.085 | E2: 6 | F2: 420 | G2: เส้น | H2: 70 | I2: 6 | J2: 1 | K2: 0 | N2: ไม้ทิพย์
A3: ไม้ทิพย์|ลายไม้ | B3: ไม้ทิพย์ | C3: ลายไม้ | D3: 0.085 | E3: 6 | F3: 580 | G3: เส้น | H3: 70 | I3: 6 | J3: 1 | K3: 0 | N3: fameline
A4: fameline|สีมาตรฐาน | B4: fameline | C4: สีมาตรฐาน | D4: 0.085 | E4: 6 | F4: 1300 | G4: ตร.ม. | H4: 0 | I4: 1 | J4: 0 | K4: 1 | N4: HIGO
A5: fameline|สีอื่น | B5: fameline | C5: สีอื่น | D5: 0.085 | E5: 6 | F5: 1400 | G5: ตร.ม. | H5: 0 | I5: 1 | J5: 0 | K5: 1 | N5: remood
A6: HIGO|C19 (ใน) | B6: HIGO | C6: C19 (ใน) | D6: 0.204 | E6: 3 | F6: 140 | G6: เส้น | H6: 130 | I6: 3 | J6: 0 | K6: 0
A7: HIGO|G15 (ใน) | B7: HIGO | C7: G15 (ใน) | D7: 0.153 | E7: 3 | F7: 140 | G7: เส้น | H7: 130 | I7: 3 | J7: 0 | K7: 0
A8: HIGO|R16 (ใน) | B8: HIGO | C8: R16 (ใน) | D8: 0.16 | E8: 3 | F8: 140 | G8: เส้น | H8: 130 | I8: 3 | J8: 0 | K8: 0
A9: HIGO|Y18 (ใน) | B9: HIGO | C9: Y18 (ใน) | D9: 0.158 | E9: 3 | F9: 140 | G9: เส้น | H9: 130 | I9: 3 | J9: 0 | K9: 0
A10: HIGO|P155 (นอก) | B10: HIGO | C10: P155 (นอก) | D10: 0.1524 | E10: 2.9 | F10: 310 | G10: เส้น | H10: 275 | I10: 2.9 | J10: 0 | K10: 0
A11: HIGO|WH200 (นอก) | B11: HIGO | C11: WH200 (นอก) | D11: 0.185 | E11: 2.9 | F11: 310 | G11: เส้น | H11: 275 | I11: 2.9 | J11: 0 | K11: 0
A12: remood|Entree เรียบ | B12: remood | C12: Entree เรียบ | D12: 0.14 | E12: 2.8 | F12: 500 | G12: แผ่น | H12: 300 | I12: 2.8 | J12: 0 | K12: 0
A13: remood|Entree มีลาย | B13: remood | C13: Entree มีลาย | D13: 0.165 | E13: 2.8 | F13: 600 | G13: แผ่น | H13: 300 | I13: 2.8 | J13: 0 | K13: 0
A14: remood|Entree ชักร่อง | B14: remood | C14: Entree ชักร่อง | D14: 0.219 | E14: 2.8 | F14: 950 | G14: แผ่น | H14: 300 | I14: 2.8 | J14: 0 | K14: 0
A15: remood|Duratech+ เรียบ13 | B15: remood | C15: Duratech+ เรียบ13 | D15: 0.13 | E15: 2.8 | F15: 730 | G15: แผ่น | H15: 300 | I15: 2.8 | J15: 0 | K15: 0
A16: remood|Duratech+ เรียบ16 | B16: remood | C16: Duratech+ เรียบ16 | D16: 0.162 | E16: 2.8 | F16: 900 | G16: แผ่น | H16: 300 | I16: 2.8 | J16: 0 | K16: 0
A17: remood|Duratech+ เรียบ14 | B17: remood | C17: Duratech+ เรียบ14 | D17: 0.14 | E17: 2.8 | F17: 850 | G17: แผ่น | H17: 300 | I17: 2.8 | J17: 0 | K17: 0
... A25: remood|Duralight+ ชักร่อง | B25: remood | C25: Duralight+ ชักร่อง | D25: 0.116 | E25: 2.8 | F25: 2100 | G25: แผ่น | H25: 300 | I25: 2.8 | J25: 0 | K25: 0

Sheet น้ำหนักโปรไฟล์
A1: น้ำหนักโปรไฟล์อลูมิเนียม — เอาไปเสียบระบบ ราคาเส้น = น้ำหนัก × ราคา/กก. | G1: 🏠 สารบัญ
B2: แบรนด์ | C2: รหัส | D2: หนา/ขนาด | E2: ชื่อ/รายการ | F2: ยาว(ม.) | G2: กก./ม. | H2: กก./เส้น | I2: หมายเหตุ
B3: เมืองทอง — กล่องสี่เหลี่ยมด้านเท่า (ยาว 6 ม.)
B4: เมืองทอง | C4: 705 | D4: 1.00 มม. | E4: แป๊บ 6 หุน | F4: 6 | G4: 0.196 | H4: 1.18
B5: เมืองทอง | C5: 706 | D5: 1.20 มม. | E5: แป๊บ 6 หุน | F5: 6 | G5: 0.232 | H5: 1.39
B6: เมืองทอง | C6: 709 | D6: 1.00 มม. | E6: แป๊บ 1 นิ้ว | F6: 6 | G6: 0.262 | H6: 1.57
B7: เมืองทอง | C7: 710 | D7: 1.10 มม. | E7: แป๊บ 1 นิ้ว | F7: 6 | G7: 0.288 | H7: 1.73
B8: เมืองทอง | C8: 711 | D8: 1.20 มม. | E8: แป๊บ 1 นิ้ว | F8: 6 | G8: 0.314 | H8: 1.88
B9: เมืองทอง | C9: 715 | D9: 1.10 มม. | E9: แป๊บ 1¼ นิ้ว | F9: 6 | G9: 0.363 | H9: 2.18
